2024-05-21 10:25:28,287 INFO    StreamThr :1293572 [internal.py:wandb_internal():89] W&B internal server running at pid: 1293572, started at: 2024-05-21 10:25:28.287014
2024-05-21 10:25:28,289 DEBUG   HandlerThread:1293572 [handler.py:handle_request():146] handle_request: status
2024-05-21 10:25:28,291 INFO    WriterThread:1293572 [datastore.py:open_for_write():87] open: /home/lsr/MonoGS_Version_Control/MonoGS/wandb/run-20240521_102528-7i7f5gjm/run-7i7f5gjm.wandb
2024-05-21 10:25:28,292 DEBUG   SenderThread:1293572 [sender.py:send():379] send: header
2024-05-21 10:25:28,305 DEBUG   SenderThread:1293572 [sender.py:send():379] send: run
2024-05-21 10:25:28,965 INFO    SenderThread:1293572 [dir_watcher.py:__init__():211] watching files in: /home/lsr/MonoGS_Version_Control/MonoGS/wandb/run-20240521_102528-7i7f5gjm/files
2024-05-21 10:25:28,965 INFO    SenderThread:1293572 [sender.py:_start_run_threads():1127] run started: 7i7f5gjm with start time 1716258328.286918
2024-05-21 10:25:28,971 DEBUG   HandlerThread:1293572 [handler.py:handle_request():146] handle_request: check_version
2024-05-21 10:25:28,971 DEBUG   SenderThread:1293572 [sender.py:send_request():406] send_request: check_version
2024-05-21 10:25:29,351 DEBUG   HandlerThread:1293572 [handler.py:handle_request():146] handle_request: run_start
2024-05-21 10:25:29,383 DEBUG   HandlerThread:1293572 [system_info.py:__init__():26] System info init
2024-05-21 10:25:29,383 DEBUG   HandlerThread:1293572 [system_info.py:__init__():41] System info init done
2024-05-21 10:25:29,383 INFO    HandlerThread:1293572 [system_monitor.py:start():194] Starting system monitor
2024-05-21 10:25:29,384 INFO    SystemMonitor:1293572 [system_monitor.py:_start():158] Starting system asset monitoring threads
2024-05-21 10:25:29,384 INFO    HandlerThread:1293572 [system_monitor.py:probe():214] Collecting system info
2024-05-21 10:25:29,384 INFO    SystemMonitor:1293572 [interfaces.py:start():190] Started cpu monitoring
2024-05-21 10:25:29,385 INFO    SystemMonitor:1293572 [interfaces.py:start():190] Started disk monitoring
2024-05-21 10:25:29,385 INFO    SystemMonitor:1293572 [interfaces.py:start():190] Started gpu monitoring
2024-05-21 10:25:29,385 INFO    SystemMonitor:1293572 [interfaces.py:start():190] Started memory monitoring
2024-05-21 10:25:29,386 INFO    SystemMonitor:1293572 [interfaces.py:start():190] Started network monitoring
2024-05-21 10:25:29,435 DEBUG   HandlerThread:1293572 [system_info.py:probe():150] Probing system
2024-05-21 10:25:29,446 DEBUG   HandlerThread:1293572 [system_info.py:_probe_git():135] Probing git
2024-05-21 10:25:29,466 DEBUG   HandlerThread:1293572 [system_info.py:_probe_git():143] Probing git done
2024-05-21 10:25:29,466 DEBUG   HandlerThread:1293572 [system_info.py:probe():198] Probing system done
2024-05-21 10:25:29,466 DEBUG   HandlerThread:1293572 [system_monitor.py:probe():223] {'os': 'Linux-5.15.0-105-generic-x86_64-with-debian-bullseye-sid', 'python': '3.7.13', 'heartbeatAt': '2024-05-21T02:25:29.436195', 'startedAt': '2024-05-21T02:25:28.281888', 'docker': None, 'cuda': None, 'args': ('--config', 'configs/rgbd/tum/fr4_office.yaml'), 'state': 'running', 'program': 'slam.py', 'codePathLocal': 'slam.py', 'codePath': 'slam.py', 'git': {'remote': 'https://github.com/IAMXII/MonoGS.git', 'commit': '55e124f658cb987b14427df85d23cc3b34296aa3'}, 'email': '675560021@qq.com', 'root': '/home/lsr/MonoGS_Version_Control/MonoGS', 'host': 'lsr', 'username': 'lsr', 'executable': '/home/lsr/anaconda3/envs/MonoGS/bin/python', 'cpu_count': 12, 'cpu_count_logical': 20, 'cpu_freq': {'current': 2771.0643999999998, 'min': 800.0, 'max': 4580.0}, 'cpu_freq_per_core': [{'current': 2100.0, 'min': 800.0, 'max': 4800.0}, {'current': 2100.0, 'min': 800.0, 'max': 4800.0}, {'current': 2100.0, 'min': 800.0, 'max': 4800.0}, {'current': 2100.0, 'min': 800.0, 'max': 4800.0}, {'current': 889.058, 'min': 800.0, 'max': 4800.0}, {'current': 2100.0, 'min': 800.0, 'max': 4800.0}, {'current': 2100.0, 'min': 800.0, 'max': 4800.0}, {'current': 2100.0, 'min': 800.0, 'max': 4800.0}, {'current': 2100.0, 'min': 800.0, 'max': 4900.0}, {'current': 2100.0, 'min': 800.0, 'max': 4900.0}, {'current': 2100.0, 'min': 800.0, 'max': 4900.0}, {'current': 2100.0, 'min': 800.0, 'max': 4900.0}, {'current': 2100.0, 'min': 800.0, 'max': 4800.0}, {'current': 2100.0, 'min': 800.0, 'max': 4800.0}, {'current': 2100.0, 'min': 800.0, 'max': 4800.0}, {'current': 2100.0, 'min': 800.0, 'max': 4800.0}, {'current': 2100.0, 'min': 800.0, 'max': 3600.0}, {'current': 2100.0, 'min': 800.0, 'max': 3600.0}, {'current': 2100.0, 'min': 800.0, 'max': 3600.0}, {'current': 2100.0, 'min': 800.0, 'max': 3600.0}], 'disk': {'/': {'total': 548.9532012939453, 'used': 140.4793701171875}}, 'gpu': 'NVIDIA GeForce RTX 4090', 'gpu_count': 1, 'gpu_devices': [{'name': 'NVIDIA GeForce RTX 4090', 'memory_total': 25757220864}], 'memory': {'total': 62.535736083984375}}
2024-05-21 10:25:29,467 INFO    HandlerThread:1293572 [system_monitor.py:probe():224] Finished collecting system info
2024-05-21 10:25:29,467 INFO    HandlerThread:1293572 [system_monitor.py:probe():227] Publishing system info
2024-05-21 10:25:29,467 DEBUG   HandlerThread:1293572 [system_info.py:_save_conda():208] Saving list of conda packages installed into the current environment
2024-05-21 10:25:29,965 INFO    Thread-12 :1293572 [dir_watcher.py:_on_file_created():271] file/dir created: /home/lsr/MonoGS_Version_Control/MonoGS/wandb/run-20240521_102528-7i7f5gjm/files/conda-environment.yaml
2024-05-21 10:25:32,139 DEBUG   HandlerThread:1293572 [system_info.py:_save_conda():222] Saving conda packages done
2024-05-21 10:25:32,140 INFO    HandlerThread:1293572 [system_monitor.py:probe():229] Finished publishing system info
2024-05-21 10:25:32,142 DEBUG   SenderThread:1293572 [sender.py:send():379] send: files
2024-05-21 10:25:32,142 INFO    SenderThread:1293572 [sender.py:_save_file():1390] saving file wandb-metadata.json with policy now
2024-05-21 10:25:32,183 DEBUG   HandlerThread:1293572 [handler.py:handle_request():146] handle_request: python_packages
2024-05-21 10:25:32,183 DEBUG   HandlerThread:1293572 [handler.py:handle_request():146] handle_request: stop_status
2024-05-21 10:25:32,183 DEBUG   SenderThread:1293572 [sender.py:send_request():406] send_request: python_packages
2024-05-21 10:25:32,184 DEBUG   SenderThread:1293572 [sender.py:send_request():406] send_request: stop_status
2024-05-21 10:25:32,185 DEBUG   HandlerThread:1293572 [handler.py:handle_request():146] handle_request: internal_messages
2024-05-21 10:25:32,511 DEBUG   SenderThread:1293572 [sender.py:send():379] send: telemetry
2024-05-21 10:25:32,511 DEBUG   SenderThread:1293572 [sender.py:send():379] send: metric
2024-05-21 10:25:32,511 DEBUG   SenderThread:1293572 [sender.py:send():379] send: telemetry
2024-05-21 10:25:32,512 DEBUG   SenderThread:1293572 [sender.py:send():379] send: metric
2024-05-21 10:25:32,512 WARNING SenderThread:1293572 [sender.py:send_metric():1341] Seen metric with glob (shouldn't happen)
2024-05-21 10:25:32,606 ERROR   wandb-upload_0:1293572 [internal_api.py:upload_file():2767] upload_file exception https://storage.googleapis.com/wandb-production.appspot.com/1923354735/MonoGS/7i7f5gjm/wandb-metadata.json?Expires=1716344732&GoogleAccessId=gorilla-files-url-signer-man%40wandb-production.iam.gserviceaccount.com&Signature=cDR3s4Btu8wUHMp7Bq8tJfPSneZs1lKn2s29OU2rf%2FQIynPqqnBm7KTt%2FUEbBkk02uPdYlSFQ9EV28DpKWGSjPzJUwI2lj6lzR%2FVCrCdrmNQF2B6LpGTVwfUfNo%2BgAMipws%2FssygMCuS0ObkO8Ckn4inWWTYBfrsEeAYuXXQ1MpkDWgrDTmFzIWIh7uhGxi5rRZGleTaZq3oxaGDid1%2FfSVTAKln9OgAsZRMb3CU44aJcHVk9lBYHWz9LI%2Fdrn9Se0ZlWbNUG9fX7iLx2N8X7pmCC2x1luKH8B87YHHaoGoUezsZnaVDfAWe31WtqGOpRQoXCjyFDeT%2FQZWmt8yRAA%3D%3D: HTTPSConnectionPool(host='storage.googleapis.com', port=443): Max retries exceeded with url: /wandb-production.appspot.com/1923354735/MonoGS/7i7f5gjm/wandb-metadata.json?Expires=1716344732&GoogleAccessId=gorilla-files-url-signer-man%40wandb-production.iam.gserviceaccount.com&Signature=cDR3s4Btu8wUHMp7Bq8tJfPSneZs1lKn2s29OU2rf%2FQIynPqqnBm7KTt%2FUEbBkk02uPdYlSFQ9EV28DpKWGSjPzJUwI2lj6lzR%2FVCrCdrmNQF2B6LpGTVwfUfNo%2BgAMipws%2FssygMCuS0ObkO8Ckn4inWWTYBfrsEeAYuXXQ1MpkDWgrDTmFzIWIh7uhGxi5rRZGleTaZq3oxaGDid1%2FfSVTAKln9OgAsZRMb3CU44aJcHVk9lBYHWz9LI%2Fdrn9Se0ZlWbNUG9fX7iLx2N8X7pmCC2x1luKH8B87YHHaoGoUezsZnaVDfAWe31WtqGOpRQoXCjyFDeT%2FQZWmt8yRAA%3D%3D (Caused by NewConnectionError('<urllib3.connection.HTTPSConnection object at 0x7f6e84551490>: Failed to establish a new connection: [Errno 111] Connection refused'))
2024-05-21 10:25:32,607 ERROR   wandb-upload_0:1293572 [internal_api.py:upload_file():2769] upload_file request headers: {'User-Agent': 'python-requests/2.31.0', 'Accept-Encoding': 'gzip, deflate, br', 'Accept': '*/*', 'Connection': 'keep-alive', 'Content-Length': '3405'}
2024-05-21 10:25:32,607 ERROR   wandb-upload_0:1293572 [internal_api.py:upload_file():2771] upload_file response body: 
2024-05-21 10:25:32,965 INFO    Thread-12 :1293572 [dir_watcher.py:_on_file_modified():288] file/dir modified: /home/lsr/MonoGS_Version_Control/MonoGS/wandb/run-20240521_102528-7i7f5gjm/files/conda-environment.yaml
2024-05-21 10:25:32,966 INFO    Thread-12 :1293572 [dir_watcher.py:_on_file_created():271] file/dir created: /home/lsr/MonoGS_Version_Control/MonoGS/wandb/run-20240521_102528-7i7f5gjm/files/wandb-metadata.json
2024-05-21 10:25:32,966 INFO    Thread-12 :1293572 [dir_watcher.py:_on_file_created():271] file/dir created: /home/lsr/MonoGS_Version_Control/MonoGS/wandb/run-20240521_102528-7i7f5gjm/files/requirements.txt
2024-05-21 10:25:33,512 DEBUG   HandlerThread:1293572 [handler.py:handle_request():146] handle_request: status_report
2024-05-21 10:25:33,784 ERROR   wandb-upload_0:1293572 [internal_api.py:upload_file():2767] upload_file exception https://storage.googleapis.com/wandb-production.appspot.com/1923354735/MonoGS/7i7f5gjm/wandb-metadata.json?Expires=1716344732&GoogleAccessId=gorilla-files-url-signer-man%40wandb-production.iam.gserviceaccount.com&Signature=cDR3s4Btu8wUHMp7Bq8tJfPSneZs1lKn2s29OU2rf%2FQIynPqqnBm7KTt%2FUEbBkk02uPdYlSFQ9EV28DpKWGSjPzJUwI2lj6lzR%2FVCrCdrmNQF2B6LpGTVwfUfNo%2BgAMipws%2FssygMCuS0ObkO8Ckn4inWWTYBfrsEeAYuXXQ1MpkDWgrDTmFzIWIh7uhGxi5rRZGleTaZq3oxaGDid1%2FfSVTAKln9OgAsZRMb3CU44aJcHVk9lBYHWz9LI%2Fdrn9Se0ZlWbNUG9fX7iLx2N8X7pmCC2x1luKH8B87YHHaoGoUezsZnaVDfAWe31WtqGOpRQoXCjyFDeT%2FQZWmt8yRAA%3D%3D: HTTPSConnectionPool(host='storage.googleapis.com', port=443): Max retries exceeded with url: /wandb-production.appspot.com/1923354735/MonoGS/7i7f5gjm/wandb-metadata.json?Expires=1716344732&GoogleAccessId=gorilla-files-url-signer-man%40wandb-production.iam.gserviceaccount.com&Signature=cDR3s4Btu8wUHMp7Bq8tJfPSneZs1lKn2s29OU2rf%2FQIynPqqnBm7KTt%2FUEbBkk02uPdYlSFQ9EV28DpKWGSjPzJUwI2lj6lzR%2FVCrCdrmNQF2B6LpGTVwfUfNo%2BgAMipws%2FssygMCuS0ObkO8Ckn4inWWTYBfrsEeAYuXXQ1MpkDWgrDTmFzIWIh7uhGxi5rRZGleTaZq3oxaGDid1%2FfSVTAKln9OgAsZRMb3CU44aJcHVk9lBYHWz9LI%2Fdrn9Se0ZlWbNUG9fX7iLx2N8X7pmCC2x1luKH8B87YHHaoGoUezsZnaVDfAWe31WtqGOpRQoXCjyFDeT%2FQZWmt8yRAA%3D%3D (Caused by NewConnectionError('<urllib3.connection.HTTPSConnection object at 0x7f6e8458c290>: Failed to establish a new connection: [Errno 111] Connection refused'))
2024-05-21 10:25:33,784 ERROR   wandb-upload_0:1293572 [internal_api.py:upload_file():2769] upload_file request headers: {'User-Agent': 'python-requests/2.31.0', 'Accept-Encoding': 'gzip, deflate, br', 'Accept': '*/*', 'Connection': 'keep-alive', 'Content-Length': '3405'}
2024-05-21 10:25:33,784 ERROR   wandb-upload_0:1293572 [internal_api.py:upload_file():2771] upload_file response body: 
2024-05-21 10:25:36,126 ERROR   wandb-upload_0:1293572 [internal_api.py:upload_file():2767] upload_file exception https://storage.googleapis.com/wandb-production.appspot.com/1923354735/MonoGS/7i7f5gjm/wandb-metadata.json?Expires=1716344732&GoogleAccessId=gorilla-files-url-signer-man%40wandb-production.iam.gserviceaccount.com&Signature=cDR3s4Btu8wUHMp7Bq8tJfPSneZs1lKn2s29OU2rf%2FQIynPqqnBm7KTt%2FUEbBkk02uPdYlSFQ9EV28DpKWGSjPzJUwI2lj6lzR%2FVCrCdrmNQF2B6LpGTVwfUfNo%2BgAMipws%2FssygMCuS0ObkO8Ckn4inWWTYBfrsEeAYuXXQ1MpkDWgrDTmFzIWIh7uhGxi5rRZGleTaZq3oxaGDid1%2FfSVTAKln9OgAsZRMb3CU44aJcHVk9lBYHWz9LI%2Fdrn9Se0ZlWbNUG9fX7iLx2N8X7pmCC2x1luKH8B87YHHaoGoUezsZnaVDfAWe31WtqGOpRQoXCjyFDeT%2FQZWmt8yRAA%3D%3D: HTTPSConnectionPool(host='storage.googleapis.com', port=443): Max retries exceeded with url: /wandb-production.appspot.com/1923354735/MonoGS/7i7f5gjm/wandb-metadata.json?Expires=1716344732&GoogleAccessId=gorilla-files-url-signer-man%40wandb-production.iam.gserviceaccount.com&Signature=cDR3s4Btu8wUHMp7Bq8tJfPSneZs1lKn2s29OU2rf%2FQIynPqqnBm7KTt%2FUEbBkk02uPdYlSFQ9EV28DpKWGSjPzJUwI2lj6lzR%2FVCrCdrmNQF2B6LpGTVwfUfNo%2BgAMipws%2FssygMCuS0ObkO8Ckn4inWWTYBfrsEeAYuXXQ1MpkDWgrDTmFzIWIh7uhGxi5rRZGleTaZq3oxaGDid1%2FfSVTAKln9OgAsZRMb3CU44aJcHVk9lBYHWz9LI%2Fdrn9Se0ZlWbNUG9fX7iLx2N8X7pmCC2x1luKH8B87YHHaoGoUezsZnaVDfAWe31WtqGOpRQoXCjyFDeT%2FQZWmt8yRAA%3D%3D (Caused by NewConnectionError('<urllib3.connection.HTTPSConnection object at 0x7f6e84408510>: Failed to establish a new connection: [Errno 111] Connection refused'))
2024-05-21 10:25:36,126 ERROR   wandb-upload_0:1293572 [internal_api.py:upload_file():2769] upload_file request headers: {'User-Agent': 'python-requests/2.31.0', 'Accept-Encoding': 'gzip, deflate, br', 'Accept': '*/*', 'Connection': 'keep-alive', 'Content-Length': '3405'}
2024-05-21 10:25:36,126 ERROR   wandb-upload_0:1293572 [internal_api.py:upload_file():2771] upload_file response body: 
2024-05-21 10:25:36,126 INFO    wandb-upload_0:1293572 [retry.py:__call__():172] Retry attempt failed:
Traceback (most recent call last):
  File "/home/lsr/anaconda3/envs/MonoGS/lib/python3.7/site-packages/urllib3/connection.py", line 202, in _new_conn
    socket_options=self.socket_options,
  File "/home/lsr/anaconda3/envs/MonoGS/lib/python3.7/site-packages/urllib3/util/connection.py", line 85, in create_connection
    raise err
  File "/home/lsr/anaconda3/envs/MonoGS/lib/python3.7/site-packages/urllib3/util/connection.py", line 73, in create_connection
    sock.connect(sa)
ConnectionRefusedError: [Errno 111] Connection refused

The above exception was the direct cause of the following exception:

Traceback (most recent call last):
  File "/home/lsr/anaconda3/envs/MonoGS/lib/python3.7/site-packages/urllib3/connectionpool.py", line 805, in urlopen
    **response_kw,
  File "/home/lsr/anaconda3/envs/MonoGS/lib/python3.7/site-packages/urllib3/connectionpool.py", line 491, in _make_request
    raise new_e
  File "/home/lsr/anaconda3/envs/MonoGS/lib/python3.7/site-packages/urllib3/connectionpool.py", line 467, in _make_request
    self._validate_conn(conn)
  File "/home/lsr/anaconda3/envs/MonoGS/lib/python3.7/site-packages/urllib3/connectionpool.py", line 1099, in _validate_conn
    conn.connect()
  File "/home/lsr/anaconda3/envs/MonoGS/lib/python3.7/site-packages/urllib3/connection.py", line 616, in connect
    self.sock = sock = self._new_conn()
  File "/home/lsr/anaconda3/envs/MonoGS/lib/python3.7/site-packages/urllib3/connection.py", line 215, in _new_conn
    ) from e
urllib3.exceptions.NewConnectionError: <urllib3.connection.HTTPSConnection object at 0x7f6e84408510>: Failed to establish a new connection: [Errno 111] Connection refused

The above exception was the direct cause of the following exception:

Traceback (most recent call last):
  File "/home/lsr/anaconda3/envs/MonoGS/lib/python3.7/site-packages/requests/adapters.py", line 497, in send
    chunked=chunked,
  File "/home/lsr/anaconda3/envs/MonoGS/lib/python3.7/site-packages/urllib3/connectionpool.py", line 848, in urlopen
    method, url, error=new_e, _pool=self, _stacktrace=sys.exc_info()[2]
  File "/home/lsr/anaconda3/envs/MonoGS/lib/python3.7/site-packages/urllib3/util/retry.py", line 515, in increment
    raise MaxRetryError(_pool, url, reason) from reason  # type: ignore[arg-type]
urllib3.exceptions.MaxRetryError: HTTPSConnectionPool(host='storage.googleapis.com', port=443): Max retries exceeded with url: /wandb-production.appspot.com/1923354735/MonoGS/7i7f5gjm/wandb-metadata.json?Expires=1716344732&GoogleAccessId=gorilla-files-url-signer-man%40wandb-production.iam.gserviceaccount.com&Signature=cDR3s4Btu8wUHMp7Bq8tJfPSneZs1lKn2s29OU2rf%2FQIynPqqnBm7KTt%2FUEbBkk02uPdYlSFQ9EV28DpKWGSjPzJUwI2lj6lzR%2FVCrCdrmNQF2B6LpGTVwfUfNo%2BgAMipws%2FssygMCuS0ObkO8Ckn4inWWTYBfrsEeAYuXXQ1MpkDWgrDTmFzIWIh7uhGxi5rRZGleTaZq3oxaGDid1%2FfSVTAKln9OgAsZRMb3CU44aJcHVk9lBYHWz9LI%2Fdrn9Se0ZlWbNUG9fX7iLx2N8X7pmCC2x1luKH8B87YHHaoGoUezsZnaVDfAWe31WtqGOpRQoXCjyFDeT%2FQZWmt8yRAA%3D%3D (Caused by NewConnectionError('<urllib3.connection.HTTPSConnection object at 0x7f6e84408510>: Failed to establish a new connection: [Errno 111] Connection refused'))

During handling of the above exception, another exception occurred:

Traceback (most recent call last):
  File "/home/lsr/anaconda3/envs/MonoGS/lib/python3.7/site-packages/wandb/sdk/internal/internal_api.py", line 2761, in upload_file
    url, data=progress, headers=extra_headers
  File "/home/lsr/anaconda3/envs/MonoGS/lib/python3.7/site-packages/requests/sessions.py", line 649, in put
    return self.request("PUT", url, data=data, **kwargs)
  File "/home/lsr/anaconda3/envs/MonoGS/lib/python3.7/site-packages/requests/sessions.py", line 589, in request
    resp = self.send(prep, **send_kwargs)
  File "/home/lsr/anaconda3/envs/MonoGS/lib/python3.7/site-packages/requests/sessions.py", line 703, in send
    r = adapter.send(request, **kwargs)
  File "/home/lsr/anaconda3/envs/MonoGS/lib/python3.7/site-packages/requests/adapters.py", line 519, in send
    raise ConnectionError(e, request=request)
requests.exceptions.ConnectionError: HTTPSConnectionPool(host='storage.googleapis.com', port=443): Max retries exceeded with url: /wandb-production.appspot.com/1923354735/MonoGS/7i7f5gjm/wandb-metadata.json?Expires=1716344732&GoogleAccessId=gorilla-files-url-signer-man%40wandb-production.iam.gserviceaccount.com&Signature=cDR3s4Btu8wUHMp7Bq8tJfPSneZs1lKn2s29OU2rf%2FQIynPqqnBm7KTt%2FUEbBkk02uPdYlSFQ9EV28DpKWGSjPzJUwI2lj6lzR%2FVCrCdrmNQF2B6LpGTVwfUfNo%2BgAMipws%2FssygMCuS0ObkO8Ckn4inWWTYBfrsEeAYuXXQ1MpkDWgrDTmFzIWIh7uhGxi5rRZGleTaZq3oxaGDid1%2FfSVTAKln9OgAsZRMb3CU44aJcHVk9lBYHWz9LI%2Fdrn9Se0ZlWbNUG9fX7iLx2N8X7pmCC2x1luKH8B87YHHaoGoUezsZnaVDfAWe31WtqGOpRQoXCjyFDeT%2FQZWmt8yRAA%3D%3D (Caused by NewConnectionError('<urllib3.connection.HTTPSConnection object at 0x7f6e84408510>: Failed to establish a new connection: [Errno 111] Connection refused'))

During handling of the above exception, another exception occurred:

Traceback (most recent call last):
  File "/home/lsr/anaconda3/envs/MonoGS/lib/python3.7/site-packages/wandb/sdk/lib/retry.py", line 131, in __call__
    result = self._call_fn(*args, **kwargs)
  File "/home/lsr/anaconda3/envs/MonoGS/lib/python3.7/site-packages/wandb/sdk/internal/internal_api.py", line 2791, in upload_file
    raise _e.with_traceback(sys.exc_info()[2])
  File "/home/lsr/anaconda3/envs/MonoGS/lib/python3.7/site-packages/wandb/sdk/internal/internal_api.py", line 2761, in upload_file
    url, data=progress, headers=extra_headers
  File "/home/lsr/anaconda3/envs/MonoGS/lib/python3.7/site-packages/requests/sessions.py", line 649, in put
    return self.request("PUT", url, data=data, **kwargs)
  File "/home/lsr/anaconda3/envs/MonoGS/lib/python3.7/site-packages/requests/sessions.py", line 589, in request
    resp = self.send(prep, **send_kwargs)
  File "/home/lsr/anaconda3/envs/MonoGS/lib/python3.7/site-packages/requests/sessions.py", line 703, in send
    r = adapter.send(request, **kwargs)
  File "/home/lsr/anaconda3/envs/MonoGS/lib/python3.7/site-packages/requests/adapters.py", line 519, in send
    raise ConnectionError(e, request=request)
wandb.sdk.lib.retry.TransientError: None
2024-05-21 10:25:38,512 DEBUG   HandlerThread:1293572 [handler.py:handle_request():146] handle_request: status_report
2024-05-21 10:25:39,967 INFO    Thread-12 :1293572 [dir_watcher.py:_on_file_created():271] file/dir created: /home/lsr/MonoGS_Version_Control/MonoGS/wandb/run-20240521_102528-7i7f5gjm/files/output.log
2024-05-21 10:25:40,323 ERROR   wandb-upload_0:1293572 [internal_api.py:upload_file():2767] upload_file exception https://storage.googleapis.com/wandb-production.appspot.com/1923354735/MonoGS/7i7f5gjm/wandb-metadata.json?Expires=1716344732&GoogleAccessId=gorilla-files-url-signer-man%40wandb-production.iam.gserviceaccount.com&Signature=cDR3s4Btu8wUHMp7Bq8tJfPSneZs1lKn2s29OU2rf%2FQIynPqqnBm7KTt%2FUEbBkk02uPdYlSFQ9EV28DpKWGSjPzJUwI2lj6lzR%2FVCrCdrmNQF2B6LpGTVwfUfNo%2BgAMipws%2FssygMCuS0ObkO8Ckn4inWWTYBfrsEeAYuXXQ1MpkDWgrDTmFzIWIh7uhGxi5rRZGleTaZq3oxaGDid1%2FfSVTAKln9OgAsZRMb3CU44aJcHVk9lBYHWz9LI%2Fdrn9Se0ZlWbNUG9fX7iLx2N8X7pmCC2x1luKH8B87YHHaoGoUezsZnaVDfAWe31WtqGOpRQoXCjyFDeT%2FQZWmt8yRAA%3D%3D: HTTPSConnectionPool(host='storage.googleapis.com', port=443): Max retries exceeded with url: /wandb-production.appspot.com/1923354735/MonoGS/7i7f5gjm/wandb-metadata.json?Expires=1716344732&GoogleAccessId=gorilla-files-url-signer-man%40wandb-production.iam.gserviceaccount.com&Signature=cDR3s4Btu8wUHMp7Bq8tJfPSneZs1lKn2s29OU2rf%2FQIynPqqnBm7KTt%2FUEbBkk02uPdYlSFQ9EV28DpKWGSjPzJUwI2lj6lzR%2FVCrCdrmNQF2B6LpGTVwfUfNo%2BgAMipws%2FssygMCuS0ObkO8Ckn4inWWTYBfrsEeAYuXXQ1MpkDWgrDTmFzIWIh7uhGxi5rRZGleTaZq3oxaGDid1%2FfSVTAKln9OgAsZRMb3CU44aJcHVk9lBYHWz9LI%2Fdrn9Se0ZlWbNUG9fX7iLx2N8X7pmCC2x1luKH8B87YHHaoGoUezsZnaVDfAWe31WtqGOpRQoXCjyFDeT%2FQZWmt8yRAA%3D%3D (Caused by NewConnectionError('<urllib3.connection.HTTPSConnection object at 0x7f6e8442e050>: Failed to establish a new connection: [Errno 111] Connection refused'))
2024-05-21 10:25:40,323 ERROR   wandb-upload_0:1293572 [internal_api.py:upload_file():2769] upload_file request headers: {'User-Agent': 'python-requests/2.31.0', 'Accept-Encoding': 'gzip, deflate, br', 'Accept': '*/*', 'Connection': 'keep-alive', 'Content-Length': '3405'}
2024-05-21 10:25:40,323 ERROR   wandb-upload_0:1293572 [internal_api.py:upload_file():2771] upload_file response body: 
2024-05-21 10:25:41,967 INFO    Thread-12 :1293572 [dir_watcher.py:_on_file_modified():288] file/dir modified: /home/lsr/MonoGS_Version_Control/MonoGS/wandb/run-20240521_102528-7i7f5gjm/files/output.log
2024-05-21 10:25:44,060 DEBUG   HandlerThread:1293572 [handler.py:handle_request():146] handle_request: status_report
2024-05-21 10:25:47,184 DEBUG   HandlerThread:1293572 [handler.py:handle_request():146] handle_request: stop_status
2024-05-21 10:25:47,184 DEBUG   SenderThread:1293572 [sender.py:send_request():406] send_request: stop_status
2024-05-21 10:25:47,184 DEBUG   HandlerThread:1293572 [handler.py:handle_request():146] handle_request: internal_messages
2024-05-21 10:25:49,012 ERROR   wandb-upload_0:1293572 [internal_api.py:upload_file():2767] upload_file exception https://storage.googleapis.com/wandb-production.appspot.com/1923354735/MonoGS/7i7f5gjm/wandb-metadata.json?Expires=1716344732&GoogleAccessId=gorilla-files-url-signer-man%40wandb-production.iam.gserviceaccount.com&Signature=cDR3s4Btu8wUHMp7Bq8tJfPSneZs1lKn2s29OU2rf%2FQIynPqqnBm7KTt%2FUEbBkk02uPdYlSFQ9EV28DpKWGSjPzJUwI2lj6lzR%2FVCrCdrmNQF2B6LpGTVwfUfNo%2BgAMipws%2FssygMCuS0ObkO8Ckn4inWWTYBfrsEeAYuXXQ1MpkDWgrDTmFzIWIh7uhGxi5rRZGleTaZq3oxaGDid1%2FfSVTAKln9OgAsZRMb3CU44aJcHVk9lBYHWz9LI%2Fdrn9Se0ZlWbNUG9fX7iLx2N8X7pmCC2x1luKH8B87YHHaoGoUezsZnaVDfAWe31WtqGOpRQoXCjyFDeT%2FQZWmt8yRAA%3D%3D: HTTPSConnectionPool(host='storage.googleapis.com', port=443): Max retries exceeded with url: /wandb-production.appspot.com/1923354735/MonoGS/7i7f5gjm/wandb-metadata.json?Expires=1716344732&GoogleAccessId=gorilla-files-url-signer-man%40wandb-production.iam.gserviceaccount.com&Signature=cDR3s4Btu8wUHMp7Bq8tJfPSneZs1lKn2s29OU2rf%2FQIynPqqnBm7KTt%2FUEbBkk02uPdYlSFQ9EV28DpKWGSjPzJUwI2lj6lzR%2FVCrCdrmNQF2B6LpGTVwfUfNo%2BgAMipws%2FssygMCuS0ObkO8Ckn4inWWTYBfrsEeAYuXXQ1MpkDWgrDTmFzIWIh7uhGxi5rRZGleTaZq3oxaGDid1%2FfSVTAKln9OgAsZRMb3CU44aJcHVk9lBYHWz9LI%2Fdrn9Se0ZlWbNUG9fX7iLx2N8X7pmCC2x1luKH8B87YHHaoGoUezsZnaVDfAWe31WtqGOpRQoXCjyFDeT%2FQZWmt8yRAA%3D%3D (Caused by NewConnectionError('<urllib3.connection.HTTPSConnection object at 0x7f6e8458ca10>: Failed to establish a new connection: [Errno 111] Connection refused'))
2024-05-21 10:25:49,012 ERROR   wandb-upload_0:1293572 [internal_api.py:upload_file():2769] upload_file request headers: {'User-Agent': 'python-requests/2.31.0', 'Accept-Encoding': 'gzip, deflate, br', 'Accept': '*/*', 'Connection': 'keep-alive', 'Content-Length': '3405'}
2024-05-21 10:25:49,012 ERROR   wandb-upload_0:1293572 [internal_api.py:upload_file():2771] upload_file response body: 
2024-05-21 10:25:49,478 DEBUG   HandlerThread:1293572 [handler.py:handle_request():146] handle_request: status_report
2024-05-21 10:25:54,478 DEBUG   HandlerThread:1293572 [handler.py:handle_request():146] handle_request: status_report
2024-05-21 10:25:59,481 DEBUG   HandlerThread:1293572 [handler.py:handle_request():146] handle_request: status_report
2024-05-21 10:25:59,971 INFO    Thread-12 :1293572 [dir_watcher.py:_on_file_modified():288] file/dir modified: /home/lsr/MonoGS_Version_Control/MonoGS/wandb/run-20240521_102528-7i7f5gjm/files/config.yaml
2024-05-21 10:26:02,210 DEBUG   HandlerThread:1293572 [handler.py:handle_request():146] handle_request: stop_status
2024-05-21 10:26:02,210 DEBUG   SenderThread:1293572 [sender.py:send_request():406] send_request: stop_status
2024-05-21 10:26:02,255 DEBUG   HandlerThread:1293572 [handler.py:handle_request():146] handle_request: internal_messages
2024-05-21 10:26:05,455 DEBUG   HandlerThread:1293572 [handler.py:handle_request():146] handle_request: status_report
2024-05-21 10:26:05,935 ERROR   wandb-upload_0:1293572 [internal_api.py:upload_file():2767] upload_file exception https://storage.googleapis.com/wandb-production.appspot.com/1923354735/MonoGS/7i7f5gjm/wandb-metadata.json?Expires=1716344732&GoogleAccessId=gorilla-files-url-signer-man%40wandb-production.iam.gserviceaccount.com&Signature=cDR3s4Btu8wUHMp7Bq8tJfPSneZs1lKn2s29OU2rf%2FQIynPqqnBm7KTt%2FUEbBkk02uPdYlSFQ9EV28DpKWGSjPzJUwI2lj6lzR%2FVCrCdrmNQF2B6LpGTVwfUfNo%2BgAMipws%2FssygMCuS0ObkO8Ckn4inWWTYBfrsEeAYuXXQ1MpkDWgrDTmFzIWIh7uhGxi5rRZGleTaZq3oxaGDid1%2FfSVTAKln9OgAsZRMb3CU44aJcHVk9lBYHWz9LI%2Fdrn9Se0ZlWbNUG9fX7iLx2N8X7pmCC2x1luKH8B87YHHaoGoUezsZnaVDfAWe31WtqGOpRQoXCjyFDeT%2FQZWmt8yRAA%3D%3D: HTTPSConnectionPool(host='storage.googleapis.com', port=443): Max retries exceeded with url: /wandb-production.appspot.com/1923354735/MonoGS/7i7f5gjm/wandb-metadata.json?Expires=1716344732&GoogleAccessId=gorilla-files-url-signer-man%40wandb-production.iam.gserviceaccount.com&Signature=cDR3s4Btu8wUHMp7Bq8tJfPSneZs1lKn2s29OU2rf%2FQIynPqqnBm7KTt%2FUEbBkk02uPdYlSFQ9EV28DpKWGSjPzJUwI2lj6lzR%2FVCrCdrmNQF2B6LpGTVwfUfNo%2BgAMipws%2FssygMCuS0ObkO8Ckn4inWWTYBfrsEeAYuXXQ1MpkDWgrDTmFzIWIh7uhGxi5rRZGleTaZq3oxaGDid1%2FfSVTAKln9OgAsZRMb3CU44aJcHVk9lBYHWz9LI%2Fdrn9Se0ZlWbNUG9fX7iLx2N8X7pmCC2x1luKH8B87YHHaoGoUezsZnaVDfAWe31WtqGOpRQoXCjyFDeT%2FQZWmt8yRAA%3D%3D (Caused by NewConnectionError('<urllib3.connection.HTTPSConnection object at 0x7f6e843785d0>: Failed to establish a new connection: [Errno 111] Connection refused'))
2024-05-21 10:26:05,935 ERROR   wandb-upload_0:1293572 [internal_api.py:upload_file():2769] upload_file request headers: {'User-Agent': 'python-requests/2.31.0', 'Accept-Encoding': 'gzip, deflate, br', 'Accept': '*/*', 'Connection': 'keep-alive', 'Content-Length': '3405'}
2024-05-21 10:26:05,935 ERROR   wandb-upload_0:1293572 [internal_api.py:upload_file():2771] upload_file response body: 
2024-05-21 10:26:10,456 DEBUG   HandlerThread:1293572 [handler.py:handle_request():146] handle_request: status_report
2024-05-21 10:26:15,456 DEBUG   HandlerThread:1293572 [handler.py:handle_request():146] handle_request: status_report
2024-05-21 10:26:17,197 DEBUG   HandlerThread:1293572 [handler.py:handle_request():146] handle_request: internal_messages
2024-05-21 10:26:17,211 DEBUG   HandlerThread:1293572 [handler.py:handle_request():146] handle_request: stop_status
2024-05-21 10:26:17,211 DEBUG   SenderThread:1293572 [sender.py:send_request():406] send_request: stop_status
2024-05-21 10:26:20,541 DEBUG   HandlerThread:1293572 [handler.py:handle_request():146] handle_request: status_report
2024-05-21 10:26:20,785 DEBUG   SenderThread:1293572 [sender.py:send():379] send: exit
2024-05-21 10:26:20,785 INFO    SenderThread:1293572 [sender.py:send_exit():586] handling exit code: 255
2024-05-21 10:26:20,785 INFO    SenderThread:1293572 [sender.py:send_exit():588] handling runtime: 51
2024-05-21 10:26:20,786 INFO    SenderThread:1293572 [sender.py:_save_file():1390] saving file wandb-summary.json with policy end
2024-05-21 10:26:20,787 INFO    SenderThread:1293572 [sender.py:send_exit():594] send defer
2024-05-21 10:26:20,787 DEBUG   HandlerThread:1293572 [handler.py:handle_request():146] handle_request: defer
2024-05-21 10:26:20,787 INFO    HandlerThread:1293572 [handler.py:handle_request_defer():172] handle defer: 0
2024-05-21 10:26:20,787 DEBUG   SenderThread:1293572 [sender.py:send_request():406] send_request: defer
2024-05-21 10:26:20,787 INFO    SenderThread:1293572 [sender.py:send_request_defer():610] handle sender defer: 0
2024-05-21 10:26:20,787 INFO    SenderThread:1293572 [sender.py:transition_state():614] send defer: 1
2024-05-21 10:26:20,787 DEBUG   HandlerThread:1293572 [handler.py:handle_request():146] handle_request: defer
2024-05-21 10:26:20,787 INFO    HandlerThread:1293572 [handler.py:handle_request_defer():172] handle defer: 1
2024-05-21 10:26:20,787 DEBUG   SenderThread:1293572 [sender.py:send_request():406] send_request: defer
2024-05-21 10:26:20,787 INFO    SenderThread:1293572 [sender.py:send_request_defer():610] handle sender defer: 1
2024-05-21 10:26:20,787 INFO    SenderThread:1293572 [sender.py:transition_state():614] send defer: 2
2024-05-21 10:26:20,787 DEBUG   HandlerThread:1293572 [handler.py:handle_request():146] handle_request: defer
2024-05-21 10:26:20,787 INFO    HandlerThread:1293572 [handler.py:handle_request_defer():172] handle defer: 2
2024-05-21 10:26:20,788 INFO    HandlerThread:1293572 [system_monitor.py:finish():203] Stopping system monitor
2024-05-21 10:26:20,788 INFO    HandlerThread:1293572 [interfaces.py:finish():202] Joined cpu monitor
2024-05-21 10:26:20,788 DEBUG   SystemMonitor:1293572 [system_monitor.py:_start():172] Starting system metrics aggregation loop
2024-05-21 10:26:20,788 DEBUG   SystemMonitor:1293572 [system_monitor.py:_start():179] Finished system metrics aggregation loop
2024-05-21 10:26:20,788 INFO    HandlerThread:1293572 [interfaces.py:finish():202] Joined disk monitor
2024-05-21 10:26:20,788 DEBUG   SystemMonitor:1293572 [system_monitor.py:_start():183] Publishing last batch of metrics
2024-05-21 10:26:20,846 INFO    HandlerThread:1293572 [interfaces.py:finish():202] Joined gpu monitor
2024-05-21 10:26:20,846 INFO    HandlerThread:1293572 [interfaces.py:finish():202] Joined memory monitor
2024-05-21 10:26:20,846 INFO    HandlerThread:1293572 [interfaces.py:finish():202] Joined network monitor
2024-05-21 10:26:20,847 DEBUG   SenderThread:1293572 [sender.py:send_request():406] send_request: defer
2024-05-21 10:26:20,847 INFO    SenderThread:1293572 [sender.py:send_request_defer():610] handle sender defer: 2
2024-05-21 10:26:20,847 INFO    SenderThread:1293572 [sender.py:transition_state():614] send defer: 3
2024-05-21 10:26:20,847 DEBUG   SenderThread:1293572 [sender.py:send():379] send: stats
2024-05-21 10:26:20,847 DEBUG   HandlerThread:1293572 [handler.py:handle_request():146] handle_request: defer
2024-05-21 10:26:20,847 INFO    HandlerThread:1293572 [handler.py:handle_request_defer():172] handle defer: 3
2024-05-21 10:26:20,847 DEBUG   SenderThread:1293572 [sender.py:send_request():406] send_request: defer
2024-05-21 10:26:20,847 INFO    SenderThread:1293572 [sender.py:send_request_defer():610] handle sender defer: 3
2024-05-21 10:26:20,847 INFO    SenderThread:1293572 [sender.py:transition_state():614] send defer: 4
2024-05-21 10:26:20,847 DEBUG   HandlerThread:1293572 [handler.py:handle_request():146] handle_request: defer
2024-05-21 10:26:20,847 INFO    HandlerThread:1293572 [handler.py:handle_request_defer():172] handle defer: 4
2024-05-21 10:26:20,847 DEBUG   SenderThread:1293572 [sender.py:send_request():406] send_request: defer
2024-05-21 10:26:20,847 INFO    SenderThread:1293572 [sender.py:send_request_defer():610] handle sender defer: 4
2024-05-21 10:26:20,847 INFO    SenderThread:1293572 [sender.py:transition_state():614] send defer: 5
2024-05-21 10:26:20,848 DEBUG   HandlerThread:1293572 [handler.py:handle_request():146] handle_request: defer
2024-05-21 10:26:20,848 INFO    HandlerThread:1293572 [handler.py:handle_request_defer():172] handle defer: 5
2024-05-21 10:26:20,848 DEBUG   SenderThread:1293572 [sender.py:send():379] send: summary
2024-05-21 10:26:20,848 INFO    SenderThread:1293572 [sender.py:_save_file():1390] saving file wandb-summary.json with policy end
2024-05-21 10:26:20,848 DEBUG   SenderThread:1293572 [sender.py:send_request():406] send_request: defer
2024-05-21 10:26:20,848 INFO    SenderThread:1293572 [sender.py:send_request_defer():610] handle sender defer: 5
2024-05-21 10:26:20,848 INFO    SenderThread:1293572 [sender.py:transition_state():614] send defer: 6
2024-05-21 10:26:20,848 DEBUG   HandlerThread:1293572 [handler.py:handle_request():146] handle_request: defer
2024-05-21 10:26:20,848 INFO    HandlerThread:1293572 [handler.py:handle_request_defer():172] handle defer: 6
2024-05-21 10:26:20,848 DEBUG   SenderThread:1293572 [sender.py:send_request():406] send_request: defer
2024-05-21 10:26:20,848 INFO    SenderThread:1293572 [sender.py:send_request_defer():610] handle sender defer: 6
2024-05-21 10:26:20,849 INFO    SenderThread:1293572 [sender.py:transition_state():614] send defer: 7
2024-05-21 10:26:20,849 DEBUG   HandlerThread:1293572 [handler.py:handle_request():146] handle_request: status_report
2024-05-21 10:26:20,849 DEBUG   HandlerThread:1293572 [handler.py:handle_request():146] handle_request: defer
2024-05-21 10:26:20,849 INFO    HandlerThread:1293572 [handler.py:handle_request_defer():172] handle defer: 7
2024-05-21 10:26:20,849 DEBUG   SenderThread:1293572 [sender.py:send_request():406] send_request: defer
2024-05-21 10:26:20,849 INFO    SenderThread:1293572 [sender.py:send_request_defer():610] handle sender defer: 7
2024-05-21 10:26:20,977 INFO    Thread-12 :1293572 [dir_watcher.py:_on_file_created():271] file/dir created: /home/lsr/MonoGS_Version_Control/MonoGS/wandb/run-20240521_102528-7i7f5gjm/files/wandb-summary.json
2024-05-21 10:26:21,785 DEBUG   HandlerThread:1293572 [handler.py:handle_request():146] handle_request: poll_exit
2024-05-21 10:26:22,790 INFO    SenderThread:1293572 [sender.py:transition_state():614] send defer: 8
2024-05-21 10:26:22,790 DEBUG   SenderThread:1293572 [sender.py:send_request():406] send_request: poll_exit
2024-05-21 10:26:22,790 DEBUG   HandlerThread:1293572 [handler.py:handle_request():146] handle_request: defer
2024-05-21 10:26:22,791 INFO    HandlerThread:1293572 [handler.py:handle_request_defer():172] handle defer: 8
2024-05-21 10:26:22,791 DEBUG   SenderThread:1293572 [sender.py:send_request():406] send_request: defer
2024-05-21 10:26:22,791 INFO    SenderThread:1293572 [sender.py:send_request_defer():610] handle sender defer: 8
2024-05-21 10:26:22,791 INFO    SenderThread:1293572 [job_builder.py:build():318] Attempting to build job artifact
2024-05-21 10:26:22,793 INFO    SenderThread:1293572 [job_builder.py:_get_source_type():455] is repo sourced job
2024-05-21 10:26:22,820 INFO    SenderThread:1293572 [job_builder.py:build():431] adding wandb-job metadata file
2024-05-21 10:26:22,837 INFO    SenderThread:1293572 [sender.py:transition_state():614] send defer: 9
2024-05-21 10:26:22,838 DEBUG   HandlerThread:1293572 [handler.py:handle_request():146] handle_request: defer
2024-05-21 10:26:22,838 DEBUG   SenderThread:1293572 [sender.py:send():379] send: artifact
2024-05-21 10:26:22,838 INFO    HandlerThread:1293572 [handler.py:handle_request_defer():172] handle defer: 9
2024-05-21 10:26:22,979 INFO    Thread-12 :1293572 [dir_watcher.py:_on_file_modified():288] file/dir modified: /home/lsr/MonoGS_Version_Control/MonoGS/wandb/run-20240521_102528-7i7f5gjm/files/output.log
2024-05-21 10:26:23,786 DEBUG   HandlerThread:1293572 [handler.py:handle_request():146] handle_request: poll_exit
2024-05-21 10:26:23,987 INFO    SenderThread:1293572 [sender.py:send_artifact():1468] sent artifact job-https___github.com_IAMXII_MonoGS.git_slam.py - {'id': 'QXJ0aWZhY3Q6ODQzNTQ0NjQw', 'state': 'COMMITTED', 'artifactSequence': {'id': 'QXJ0aWZhY3RDb2xsZWN0aW9uOjE3NzE1NjYxOQ==', 'latestArtifact': {'id': 'QXJ0aWZhY3Q6ODQzNTQ0NjQw', 'versionIndex': 0}}}
2024-05-21 10:26:23,988 DEBUG   SenderThread:1293572 [sender.py:send_request():406] send_request: defer
2024-05-21 10:26:23,988 INFO    SenderThread:1293572 [sender.py:send_request_defer():610] handle sender defer: 9
2024-05-21 10:26:23,988 INFO    SenderThread:1293572 [dir_watcher.py:finish():358] shutting down directory watcher
2024-05-21 10:26:24,981 INFO    SenderThread:1293572 [dir_watcher.py:finish():388] scan: /home/lsr/MonoGS_Version_Control/MonoGS/wandb/run-20240521_102528-7i7f5gjm/files
2024-05-21 10:26:24,982 INFO    SenderThread:1293572 [dir_watcher.py:finish():402] scan save: /home/lsr/MonoGS_Version_Control/MonoGS/wandb/run-20240521_102528-7i7f5gjm/files/wandb-summary.json wandb-summary.json
2024-05-21 10:26:24,983 INFO    SenderThread:1293572 [dir_watcher.py:finish():402] scan save: /home/lsr/MonoGS_Version_Control/MonoGS/wandb/run-20240521_102528-7i7f5gjm/files/output.log output.log
2024-05-21 10:26:24,989 INFO    SenderThread:1293572 [dir_watcher.py:finish():402] scan save: /home/lsr/MonoGS_Version_Control/MonoGS/wandb/run-20240521_102528-7i7f5gjm/files/wandb-metadata.json wandb-metadata.json
2024-05-21 10:26:24,990 INFO    SenderThread:1293572 [dir_watcher.py:finish():402] scan save: /home/lsr/MonoGS_Version_Control/MonoGS/wandb/run-20240521_102528-7i7f5gjm/files/requirements.txt requirements.txt
2024-05-21 10:26:24,996 INFO    SenderThread:1293572 [dir_watcher.py:finish():402] scan save: /home/lsr/MonoGS_Version_Control/MonoGS/wandb/run-20240521_102528-7i7f5gjm/files/conda-environment.yaml conda-environment.yaml
2024-05-21 10:26:24,996 INFO    SenderThread:1293572 [dir_watcher.py:finish():402] scan save: /home/lsr/MonoGS_Version_Control/MonoGS/wandb/run-20240521_102528-7i7f5gjm/files/config.yaml config.yaml
2024-05-21 10:26:24,997 INFO    SenderThread:1293572 [sender.py:transition_state():614] send defer: 10
2024-05-21 10:26:24,997 DEBUG   SenderThread:1293572 [sender.py:send_request():406] send_request: poll_exit
2024-05-21 10:26:25,004 DEBUG   HandlerThread:1293572 [handler.py:handle_request():146] handle_request: defer
2024-05-21 10:26:25,004 INFO    HandlerThread:1293572 [handler.py:handle_request_defer():172] handle defer: 10
2024-05-21 10:26:25,017 DEBUG   SenderThread:1293572 [sender.py:send_request():406] send_request: defer
2024-05-21 10:26:25,022 INFO    SenderThread:1293572 [sender.py:send_request_defer():610] handle sender defer: 10
2024-05-21 10:26:25,022 INFO    SenderThread:1293572 [file_pusher.py:finish():172] shutting down file pusher
2024-05-21 10:26:25,231 ERROR   wandb-upload_1:1293572 [internal_api.py:upload_file():2767] upload_file exception https://storage.googleapis.com/wandb-production.appspot.com/1923354735/MonoGS/7i7f5gjm/wandb-summary.json?Expires=1716344785&GoogleAccessId=gorilla-files-url-signer-man%40wandb-production.iam.gserviceaccount.com&Signature=jeBYHZuazMllAswE5cCuYPIOXrsDk%2Fi%2Byxjsv9qWnxV%2BGNVzIHitPZSoDMj6MWk0TNlGqYZGlH4B%2BPF%2BhJiqKeqhL2OuOHBETtdtsiWdwH0tIXK1ZdLZnOfccEagnoMyHjd%2BI8iVtowEJcGh5WKQ7a4%2B47kjR3lcOIzwzXrjed270X%2FoNcanSDRgV8xNpf603zC1Vf1qsRhzc6BJ684LVu0rN5GfkVItbl5nymffb%2F%2B%2BzcjF%2BZLQmZ17RQ0QV7xUR7ur9fhcaGfCDFhLfuBOx%2BIisR%2BQ%2Bec%2BD9ldoKK0mB7eEItITzgUcPVBv2GxH5sqHE5OJHUsFgZ0AGP%2Fxp5TXQ%3D%3D: HTTPSConnectionPool(host='storage.googleapis.com', port=443): Max retries exceeded with url: /wandb-production.appspot.com/1923354735/MonoGS/7i7f5gjm/wandb-summary.json?Expires=1716344785&GoogleAccessId=gorilla-files-url-signer-man%40wandb-production.iam.gserviceaccount.com&Signature=jeBYHZuazMllAswE5cCuYPIOXrsDk%2Fi%2Byxjsv9qWnxV%2BGNVzIHitPZSoDMj6MWk0TNlGqYZGlH4B%2BPF%2BhJiqKeqhL2OuOHBETtdtsiWdwH0tIXK1ZdLZnOfccEagnoMyHjd%2BI8iVtowEJcGh5WKQ7a4%2B47kjR3lcOIzwzXrjed270X%2FoNcanSDRgV8xNpf603zC1Vf1qsRhzc6BJ684LVu0rN5GfkVItbl5nymffb%2F%2B%2BzcjF%2BZLQmZ17RQ0QV7xUR7ur9fhcaGfCDFhLfuBOx%2BIisR%2BQ%2Bec%2BD9ldoKK0mB7eEItITzgUcPVBv2GxH5sqHE5OJHUsFgZ0AGP%2Fxp5TXQ%3D%3D (Caused by NewConnectionError('<urllib3.connection.HTTPSConnection object at 0x7f6e84395410>: Failed to establish a new connection: [Errno 111] Connection refused'))
2024-05-21 10:26:25,231 ERROR   wandb-upload_1:1293572 [internal_api.py:upload_file():2769] upload_file request headers: {'User-Agent': 'python-requests/2.31.0', 'Accept-Encoding': 'gzip, deflate, br', 'Accept': '*/*', 'Connection': 'keep-alive', 'Content-Length': '27'}
2024-05-21 10:26:25,231 ERROR   wandb-upload_1:1293572 [internal_api.py:upload_file():2771] upload_file response body: 
2024-05-21 10:26:25,233 ERROR   wandb-upload_2:1293572 [internal_api.py:upload_file():2767] upload_file exception https://storage.googleapis.com/wandb-production.appspot.com/1923354735/MonoGS/7i7f5gjm/output.log?Expires=1716344785&GoogleAccessId=gorilla-files-url-signer-man%40wandb-production.iam.gserviceaccount.com&Signature=VLoFH2QdZgsVeMSF7%2BZme2jkQEB5BuWJAxPRoHnj5FpmgAhWt%2BYchg0RqCx7PqoSN03WZ48TzcE1HZY%2Fag0rhCj1rwVp5EzKy%2FSKz%2B5KjD8scah61BdOHMmprbP8zg20%2FgV25YS8%2FOIlmG2G1EbWJ6NgRpjmbFhmC4WPPQ0LMaJ36bnQynJS%2Forxr6%2BpfjJ5SugurpujGl1HCP2FHd5qIGo5fc2oL7RxoOKTKhW02hzUUUoYzhY5fON9KtU4ixGYyAkLpKTUBhzVl%2Fr7rx7pzQJTS8e5gQ3loeJZJoh%2Fj4kHeCpLWmVRkb7VMOchgUDivO0he6tvugSp17daenhjLQ%3D%3D: HTTPSConnectionPool(host='storage.googleapis.com', port=443): Max retries exceeded with url: /wandb-production.appspot.com/1923354735/MonoGS/7i7f5gjm/output.log?Expires=1716344785&GoogleAccessId=gorilla-files-url-signer-man%40wandb-production.iam.gserviceaccount.com&Signature=VLoFH2QdZgsVeMSF7%2BZme2jkQEB5BuWJAxPRoHnj5FpmgAhWt%2BYchg0RqCx7PqoSN03WZ48TzcE1HZY%2Fag0rhCj1rwVp5EzKy%2FSKz%2B5KjD8scah61BdOHMmprbP8zg20%2FgV25YS8%2FOIlmG2G1EbWJ6NgRpjmbFhmC4WPPQ0LMaJ36bnQynJS%2Forxr6%2BpfjJ5SugurpujGl1HCP2FHd5qIGo5fc2oL7RxoOKTKhW02hzUUUoYzhY5fON9KtU4ixGYyAkLpKTUBhzVl%2Fr7rx7pzQJTS8e5gQ3loeJZJoh%2Fj4kHeCpLWmVRkb7VMOchgUDivO0he6tvugSp17daenhjLQ%3D%3D (Caused by NewConnectionError('<urllib3.connection.HTTPSConnection object at 0x7f6e8443da90>: Failed to establish a new connection: [Errno 111] Connection refused'))
2024-05-21 10:26:25,233 ERROR   wandb-upload_2:1293572 [internal_api.py:upload_file():2769] upload_file request headers: {'User-Agent': 'python-requests/2.31.0', 'Accept-Encoding': 'gzip, deflate, br', 'Accept': '*/*', 'Connection': 'keep-alive', 'Content-Length': '1015'}
2024-05-21 10:26:25,233 ERROR   wandb-upload_2:1293572 [internal_api.py:upload_file():2771] upload_file response body: 
2024-05-21 10:26:25,340 WARNING StreamThr :1293572 [internal.py:is_dead():415] Internal process exiting, parent pid 1293394 disappeared
2024-05-21 10:26:25,340 ERROR   StreamThr :1293572 [internal.py:wandb_internal():152] Internal process shutdown.
2024-05-21 10:26:25,349 ERROR   wandb-upload_3:1293572 [internal_api.py:upload_file():2767] upload_file exception https://storage.googleapis.com/wandb-production.appspot.com/1923354735/MonoGS/7i7f5gjm/requirements.txt?Expires=1716344785&GoogleAccessId=gorilla-files-url-signer-man%40wandb-production.iam.gserviceaccount.com&Signature=PUX7QA4OqH2opVL%2Be4xGiUyiSEcJKghhy2ZzJ0ADva78BQw5wvJXcgxmEJhDVPlLvZNtRuCTDz8V5b8xGLORRPLQOCVuu%2FJQrLuJ%2FLBwmKtWfURkzUEK4Bvp7hdQSXE9Bdo%2BIUELc%2FollYAUIR9cLuXGB4LcF3MbuEnRMsx0fmew59GnKSrUTM30OgPMe7XfvvyMYbcrsx0ad8QQYCZfT92VDfDcsSK9EkcnqibOKBeVz6c6NsG0mXNJy%2FjdmeikZD%2B0SnRLK%2B1DJ%2BM%2FD%2FM0HCIJyurX7%2BmrEqThDoVqPZ0dRfK4dmITQg3mu015FcX6P9lNVn6ovViNSvSU0t1JUA%3D%3D: HTTPSConnectionPool(host='storage.googleapis.com', port=443): Max retries exceeded with url: /wandb-production.appspot.com/1923354735/MonoGS/7i7f5gjm/requirements.txt?Expires=1716344785&GoogleAccessId=gorilla-files-url-signer-man%40wandb-production.iam.gserviceaccount.com&Signature=PUX7QA4OqH2opVL%2Be4xGiUyiSEcJKghhy2ZzJ0ADva78BQw5wvJXcgxmEJhDVPlLvZNtRuCTDz8V5b8xGLORRPLQOCVuu%2FJQrLuJ%2FLBwmKtWfURkzUEK4Bvp7hdQSXE9Bdo%2BIUELc%2FollYAUIR9cLuXGB4LcF3MbuEnRMsx0fmew59GnKSrUTM30OgPMe7XfvvyMYbcrsx0ad8QQYCZfT92VDfDcsSK9EkcnqibOKBeVz6c6NsG0mXNJy%2FjdmeikZD%2B0SnRLK%2B1DJ%2BM%2FD%2FM0HCIJyurX7%2BmrEqThDoVqPZ0dRfK4dmITQg3mu015FcX6P9lNVn6ovViNSvSU0t1JUA%3D%3D (Caused by NewConnectionError('<urllib3.connection.HTTPSConnection object at 0x7f6e84393d90>: Failed to establish a new connection: [Errno 111] Connection refused'))
2024-05-21 10:26:25,349 ERROR   wandb-upload_3:1293572 [internal_api.py:upload_file():2769] upload_file request headers: {'User-Agent': 'python-requests/2.31.0', 'Accept-Encoding': 'gzip, deflate, br', 'Accept': '*/*', 'Connection': 'keep-alive', 'Content-Length': '2267'}
2024-05-21 10:26:25,349 ERROR   wandb-upload_3:1293572 [internal_api.py:upload_file():2771] upload_file response body: 
2024-05-21 10:26:25,374 ERROR   wandb-upload_5:1293572 [internal_api.py:upload_file():2767] upload_file exception https://storage.googleapis.com/wandb-production.appspot.com/1923354735/MonoGS/7i7f5gjm/config.yaml?Expires=1716344785&GoogleAccessId=gorilla-files-url-signer-man%40wandb-production.iam.gserviceaccount.com&Signature=BMJwBO0b014Q1rvgox%2BYqw0pIWvynCGKcHXP81FuKhooGhVUhYqaVBmViVNciwVsqNKp%2BvW6awp8zq7bi9R7C1S9SMcftKvFNNZTi3MFZUocgiR6bDXJN6BK87FW4A4x3HBA3lUNs%2BWeyT07hWtUTpF3yauVUa0ysE7bU4lqzsHw6wjbYscL%2BUPwtsOABX2fk5Cq9c2xOXBjo76eTHr2dXmLEuUI2yZjhoAw9dyVlAaRkeS3kpnJCE3msbu06izwRBdLpfjl2PnIPuJW32O1U80Rm8bWPcZ5hnthAMzzOX3Junrz0ThnCdN67XHlY6kYXWb2tSdx4J%2BT7ulxfZmRPw%3D%3D: HTTPSConnectionPool(host='storage.googleapis.com', port=443): Max retries exceeded with url: /wandb-production.appspot.com/1923354735/MonoGS/7i7f5gjm/config.yaml?Expires=1716344785&GoogleAccessId=gorilla-files-url-signer-man%40wandb-production.iam.gserviceaccount.com&Signature=BMJwBO0b014Q1rvgox%2BYqw0pIWvynCGKcHXP81FuKhooGhVUhYqaVBmViVNciwVsqNKp%2BvW6awp8zq7bi9R7C1S9SMcftKvFNNZTi3MFZUocgiR6bDXJN6BK87FW4A4x3HBA3lUNs%2BWeyT07hWtUTpF3yauVUa0ysE7bU4lqzsHw6wjbYscL%2BUPwtsOABX2fk5Cq9c2xOXBjo76eTHr2dXmLEuUI2yZjhoAw9dyVlAaRkeS3kpnJCE3msbu06izwRBdLpfjl2PnIPuJW32O1U80Rm8bWPcZ5hnthAMzzOX3Junrz0ThnCdN67XHlY6kYXWb2tSdx4J%2BT7ulxfZmRPw%3D%3D (Caused by NewConnectionError('<urllib3.connection.HTTPSConnection object at 0x7f6e843ad510>: Failed to establish a new connection: [Errno 111] Connection refused'))
2024-05-21 10:26:25,374 ERROR   wandb-upload_5:1293572 [internal_api.py:upload_file():2769] upload_file request headers: {'User-Agent': 'python-requests/2.31.0', 'Accept-Encoding': 'gzip, deflate, br', 'Accept': '*/*', 'Connection': 'keep-alive', 'Content-Length': '2747'}
2024-05-21 10:26:25,374 ERROR   wandb-upload_5:1293572 [internal_api.py:upload_file():2771] upload_file response body: 
2024-05-21 10:26:25,407 ERROR   wandb-upload_4:1293572 [internal_api.py:upload_file():2767] upload_file exception https://storage.googleapis.com/wandb-production.appspot.com/1923354735/MonoGS/7i7f5gjm/conda-environment.yaml?Expires=1716344785&GoogleAccessId=gorilla-files-url-signer-man%40wandb-production.iam.gserviceaccount.com&Signature=EVDYObbaalBfRuHPuIIs4NJTCdppmKpHxAnNLjdSe1QDN6a6hLjmiC11aQSD4qP%2FLgPOBp45zUTn6TBcUhpaHqlZNygjhiEZX7Ca6B8klTArywRWcGYmvUpGy7O%2BleSulQSIXobSwqU%2BnRTR07PRCuNcBPTnbqW4CuC37R8fHKLlfmAI1UHGfP2sI%2BlboaOgAd5r%2BM%2FcJppRU2DfKWKWnp6t7v4yZJja%2BYwr7UjygyGHX5lL9hp2spsgl904SnGzFL7U%2FmLKAckP6yFEIZwTv6OhtL0G4DCGbJCOtPnMRFsrapLi2lTX5L4uZH%2Fmk1S6S69x4FC7L5%2Bpmj6gh7nsiA%3D%3D: HTTPSConnectionPool(host='storage.googleapis.com', port=443): Max retries exceeded with url: /wandb-production.appspot.com/1923354735/MonoGS/7i7f5gjm/conda-environment.yaml?Expires=1716344785&GoogleAccessId=gorilla-files-url-signer-man%40wandb-production.iam.gserviceaccount.com&Signature=EVDYObbaalBfRuHPuIIs4NJTCdppmKpHxAnNLjdSe1QDN6a6hLjmiC11aQSD4qP%2FLgPOBp45zUTn6TBcUhpaHqlZNygjhiEZX7Ca6B8klTArywRWcGYmvUpGy7O%2BleSulQSIXobSwqU%2BnRTR07PRCuNcBPTnbqW4CuC37R8fHKLlfmAI1UHGfP2sI%2BlboaOgAd5r%2BM%2FcJppRU2DfKWKWnp6t7v4yZJja%2BYwr7UjygyGHX5lL9hp2spsgl904SnGzFL7U%2FmLKAckP6yFEIZwTv6OhtL0G4DCGbJCOtPnMRFsrapLi2lTX5L4uZH%2Fmk1S6S69x4FC7L5%2Bpmj6gh7nsiA%3D%3D (Caused by NewConnectionError('<urllib3.connection.HTTPSConnection object at 0x7f6e843a8590>: Failed to establish a new connection: [Errno 111] Connection refused'))
2024-05-21 10:26:25,408 ERROR   wandb-upload_4:1293572 [internal_api.py:upload_file():2769] upload_file request headers: {'User-Agent': 'python-requests/2.31.0', 'Accept-Encoding': 'gzip, deflate, br', 'Accept': '*/*', 'Connection': 'keep-alive', 'Content-Length': '4690'}
2024-05-21 10:26:25,408 ERROR   wandb-upload_4:1293572 [internal_api.py:upload_file():2771] upload_file response body: 
2024-05-21 10:26:25,787 DEBUG   HandlerThread:1293572 [handler.py:handle_request():146] handle_request: poll_exit
2024-05-21 10:26:25,788 INFO    HandlerThread:1293572 [handler.py:finish():866] shutting down handler
2024-05-21 10:26:25,788 INFO    WriterThread:1293572 [datastore.py:close():296] close: /home/lsr/MonoGS_Version_Control/MonoGS/wandb/run-20240521_102528-7i7f5gjm/run-7i7f5gjm.wandb
2024-05-21 10:26:25,788 DEBUG   SenderThread:1293572 [sender.py:send_request():406] send_request: poll_exit
2024-05-21 10:26:25,788 INFO    SenderThread:1293572 [sender.py:finish():1546] shutting down sender
2024-05-21 10:26:25,788 INFO    SenderThread:1293572 [file_pusher.py:finish():172] shutting down file pusher
2024-05-21 10:26:25,788 INFO    SenderThread:1293572 [file_pusher.py:join():178] waiting for file pusher
2024-05-21 10:26:26,413 ERROR   wandb-upload_5:1293572 [internal_api.py:upload_file():2767] upload_file exception https://storage.googleapis.com/wandb-production.appspot.com/1923354735/MonoGS/7i7f5gjm/config.yaml?Expires=1716344785&GoogleAccessId=gorilla-files-url-signer-man%40wandb-production.iam.gserviceaccount.com&Signature=BMJwBO0b014Q1rvgox%2BYqw0pIWvynCGKcHXP81FuKhooGhVUhYqaVBmViVNciwVsqNKp%2BvW6awp8zq7bi9R7C1S9SMcftKvFNNZTi3MFZUocgiR6bDXJN6BK87FW4A4x3HBA3lUNs%2BWeyT07hWtUTpF3yauVUa0ysE7bU4lqzsHw6wjbYscL%2BUPwtsOABX2fk5Cq9c2xOXBjo76eTHr2dXmLEuUI2yZjhoAw9dyVlAaRkeS3kpnJCE3msbu06izwRBdLpfjl2PnIPuJW32O1U80Rm8bWPcZ5hnthAMzzOX3Junrz0ThnCdN67XHlY6kYXWb2tSdx4J%2BT7ulxfZmRPw%3D%3D: HTTPSConnectionPool(host='storage.googleapis.com', port=443): Max retries exceeded with url: /wandb-production.appspot.com/1923354735/MonoGS/7i7f5gjm/config.yaml?Expires=1716344785&GoogleAccessId=gorilla-files-url-signer-man%40wandb-production.iam.gserviceaccount.com&Signature=BMJwBO0b014Q1rvgox%2BYqw0pIWvynCGKcHXP81FuKhooGhVUhYqaVBmViVNciwVsqNKp%2BvW6awp8zq7bi9R7C1S9SMcftKvFNNZTi3MFZUocgiR6bDXJN6BK87FW4A4x3HBA3lUNs%2BWeyT07hWtUTpF3yauVUa0ysE7bU4lqzsHw6wjbYscL%2BUPwtsOABX2fk5Cq9c2xOXBjo76eTHr2dXmLEuUI2yZjhoAw9dyVlAaRkeS3kpnJCE3msbu06izwRBdLpfjl2PnIPuJW32O1U80Rm8bWPcZ5hnthAMzzOX3Junrz0ThnCdN67XHlY6kYXWb2tSdx4J%2BT7ulxfZmRPw%3D%3D (Caused by NewConnectionError('<urllib3.connection.HTTPSConnection object at 0x7f6e843b0290>: Failed to establish a new connection: [Errno 111] Connection refused'))
2024-05-21 10:26:26,414 ERROR   wandb-upload_5:1293572 [internal_api.py:upload_file():2769] upload_file request headers: {'User-Agent': 'python-requests/2.31.0', 'Accept-Encoding': 'gzip, deflate, br', 'Accept': '*/*', 'Connection': 'keep-alive', 'Content-Length': '2747'}
2024-05-21 10:26:26,414 ERROR   wandb-upload_5:1293572 [internal_api.py:upload_file():2771] upload_file response body: 
2024-05-21 10:26:26,434 ERROR   wandb-upload_1:1293572 [internal_api.py:upload_file():2767] upload_file exception https://storage.googleapis.com/wandb-production.appspot.com/1923354735/MonoGS/7i7f5gjm/wandb-summary.json?Expires=1716344785&GoogleAccessId=gorilla-files-url-signer-man%40wandb-production.iam.gserviceaccount.com&Signature=jeBYHZuazMllAswE5cCuYPIOXrsDk%2Fi%2Byxjsv9qWnxV%2BGNVzIHitPZSoDMj6MWk0TNlGqYZGlH4B%2BPF%2BhJiqKeqhL2OuOHBETtdtsiWdwH0tIXK1ZdLZnOfccEagnoMyHjd%2BI8iVtowEJcGh5WKQ7a4%2B47kjR3lcOIzwzXrjed270X%2FoNcanSDRgV8xNpf603zC1Vf1qsRhzc6BJ684LVu0rN5GfkVItbl5nymffb%2F%2B%2BzcjF%2BZLQmZ17RQ0QV7xUR7ur9fhcaGfCDFhLfuBOx%2BIisR%2BQ%2Bec%2BD9ldoKK0mB7eEItITzgUcPVBv2GxH5sqHE5OJHUsFgZ0AGP%2Fxp5TXQ%3D%3D: HTTPSConnectionPool(host='storage.googleapis.com', port=443): Max retries exceeded with url: /wandb-production.appspot.com/1923354735/MonoGS/7i7f5gjm/wandb-summary.json?Expires=1716344785&GoogleAccessId=gorilla-files-url-signer-man%40wandb-production.iam.gserviceaccount.com&Signature=jeBYHZuazMllAswE5cCuYPIOXrsDk%2Fi%2Byxjsv9qWnxV%2BGNVzIHitPZSoDMj6MWk0TNlGqYZGlH4B%2BPF%2BhJiqKeqhL2OuOHBETtdtsiWdwH0tIXK1ZdLZnOfccEagnoMyHjd%2BI8iVtowEJcGh5WKQ7a4%2B47kjR3lcOIzwzXrjed270X%2FoNcanSDRgV8xNpf603zC1Vf1qsRhzc6BJ684LVu0rN5GfkVItbl5nymffb%2F%2B%2BzcjF%2BZLQmZ17RQ0QV7xUR7ur9fhcaGfCDFhLfuBOx%2BIisR%2BQ%2Bec%2BD9ldoKK0mB7eEItITzgUcPVBv2GxH5sqHE5OJHUsFgZ0AGP%2Fxp5TXQ%3D%3D (Caused by NewConnectionError('<urllib3.connection.HTTPSConnection object at 0x7f6e84393990>: Failed to establish a new connection: [Errno 111] Connection refused'))
2024-05-21 10:26:26,435 ERROR   wandb-upload_1:1293572 [internal_api.py:upload_file():2769] upload_file request headers: {'User-Agent': 'python-requests/2.31.0', 'Accept-Encoding': 'gzip, deflate, br', 'Accept': '*/*', 'Connection': 'keep-alive', 'Content-Length': '27'}
2024-05-21 10:26:26,435 ERROR   wandb-upload_1:1293572 [internal_api.py:upload_file():2771] upload_file response body: 
2024-05-21 10:26:26,436 ERROR   wandb-upload_4:1293572 [internal_api.py:upload_file():2767] upload_file exception https://storage.googleapis.com/wandb-production.appspot.com/1923354735/MonoGS/7i7f5gjm/conda-environment.yaml?Expires=1716344785&GoogleAccessId=gorilla-files-url-signer-man%40wandb-production.iam.gserviceaccount.com&Signature=EVDYObbaalBfRuHPuIIs4NJTCdppmKpHxAnNLjdSe1QDN6a6hLjmiC11aQSD4qP%2FLgPOBp45zUTn6TBcUhpaHqlZNygjhiEZX7Ca6B8klTArywRWcGYmvUpGy7O%2BleSulQSIXobSwqU%2BnRTR07PRCuNcBPTnbqW4CuC37R8fHKLlfmAI1UHGfP2sI%2BlboaOgAd5r%2BM%2FcJppRU2DfKWKWnp6t7v4yZJja%2BYwr7UjygyGHX5lL9hp2spsgl904SnGzFL7U%2FmLKAckP6yFEIZwTv6OhtL0G4DCGbJCOtPnMRFsrapLi2lTX5L4uZH%2Fmk1S6S69x4FC7L5%2Bpmj6gh7nsiA%3D%3D: HTTPSConnectionPool(host='storage.googleapis.com', port=443): Max retries exceeded with url: /wandb-production.appspot.com/1923354735/MonoGS/7i7f5gjm/conda-environment.yaml?Expires=1716344785&GoogleAccessId=gorilla-files-url-signer-man%40wandb-production.iam.gserviceaccount.com&Signature=EVDYObbaalBfRuHPuIIs4NJTCdppmKpHxAnNLjdSe1QDN6a6hLjmiC11aQSD4qP%2FLgPOBp45zUTn6TBcUhpaHqlZNygjhiEZX7Ca6B8klTArywRWcGYmvUpGy7O%2BleSulQSIXobSwqU%2BnRTR07PRCuNcBPTnbqW4CuC37R8fHKLlfmAI1UHGfP2sI%2BlboaOgAd5r%2BM%2FcJppRU2DfKWKWnp6t7v4yZJja%2BYwr7UjygyGHX5lL9hp2spsgl904SnGzFL7U%2FmLKAckP6yFEIZwTv6OhtL0G4DCGbJCOtPnMRFsrapLi2lTX5L4uZH%2Fmk1S6S69x4FC7L5%2Bpmj6gh7nsiA%3D%3D (Caused by NewConnectionError('<urllib3.connection.HTTPSConnection object at 0x7f6e8438e950>: Failed to establish a new connection: [Errno 111] Connection refused'))
2024-05-21 10:26:26,437 ERROR   wandb-upload_4:1293572 [internal_api.py:upload_file():2769] upload_file request headers: {'User-Agent': 'python-requests/2.31.0', 'Accept-Encoding': 'gzip, deflate, br', 'Accept': '*/*', 'Connection': 'keep-alive', 'Content-Length': '4690'}
2024-05-21 10:26:26,437 ERROR   wandb-upload_4:1293572 [internal_api.py:upload_file():2771] upload_file response body: 
2024-05-21 10:26:26,490 ERROR   wandb-upload_2:1293572 [internal_api.py:upload_file():2767] upload_file exception https://storage.googleapis.com/wandb-production.appspot.com/1923354735/MonoGS/7i7f5gjm/output.log?Expires=1716344785&GoogleAccessId=gorilla-files-url-signer-man%40wandb-production.iam.gserviceaccount.com&Signature=VLoFH2QdZgsVeMSF7%2BZme2jkQEB5BuWJAxPRoHnj5FpmgAhWt%2BYchg0RqCx7PqoSN03WZ48TzcE1HZY%2Fag0rhCj1rwVp5EzKy%2FSKz%2B5KjD8scah61BdOHMmprbP8zg20%2FgV25YS8%2FOIlmG2G1EbWJ6NgRpjmbFhmC4WPPQ0LMaJ36bnQynJS%2Forxr6%2BpfjJ5SugurpujGl1HCP2FHd5qIGo5fc2oL7RxoOKTKhW02hzUUUoYzhY5fON9KtU4ixGYyAkLpKTUBhzVl%2Fr7rx7pzQJTS8e5gQ3loeJZJoh%2Fj4kHeCpLWmVRkb7VMOchgUDivO0he6tvugSp17daenhjLQ%3D%3D: HTTPSConnectionPool(host='storage.googleapis.com', port=443): Max retries exceeded with url: /wandb-production.appspot.com/1923354735/MonoGS/7i7f5gjm/output.log?Expires=1716344785&GoogleAccessId=gorilla-files-url-signer-man%40wandb-production.iam.gserviceaccount.com&Signature=VLoFH2QdZgsVeMSF7%2BZme2jkQEB5BuWJAxPRoHnj5FpmgAhWt%2BYchg0RqCx7PqoSN03WZ48TzcE1HZY%2Fag0rhCj1rwVp5EzKy%2FSKz%2B5KjD8scah61BdOHMmprbP8zg20%2FgV25YS8%2FOIlmG2G1EbWJ6NgRpjmbFhmC4WPPQ0LMaJ36bnQynJS%2Forxr6%2BpfjJ5SugurpujGl1HCP2FHd5qIGo5fc2oL7RxoOKTKhW02hzUUUoYzhY5fON9KtU4ixGYyAkLpKTUBhzVl%2Fr7rx7pzQJTS8e5gQ3loeJZJoh%2Fj4kHeCpLWmVRkb7VMOchgUDivO0he6tvugSp17daenhjLQ%3D%3D (Caused by NewConnectionError('<urllib3.connection.HTTPSConnection object at 0x7f6e8438ee90>: Failed to establish a new connection: [Errno 111] Connection refused'))
2024-05-21 10:26:26,490 ERROR   wandb-upload_2:1293572 [internal_api.py:upload_file():2769] upload_file request headers: {'User-Agent': 'python-requests/2.31.0', 'Accept-Encoding': 'gzip, deflate, br', 'Accept': '*/*', 'Connection': 'keep-alive', 'Content-Length': '1015'}
2024-05-21 10:26:26,490 ERROR   wandb-upload_2:1293572 [internal_api.py:upload_file():2771] upload_file response body: 
2024-05-21 10:26:26,585 ERROR   wandb-upload_3:1293572 [internal_api.py:upload_file():2767] upload_file exception https://storage.googleapis.com/wandb-production.appspot.com/1923354735/MonoGS/7i7f5gjm/requirements.txt?Expires=1716344785&GoogleAccessId=gorilla-files-url-signer-man%40wandb-production.iam.gserviceaccount.com&Signature=PUX7QA4OqH2opVL%2Be4xGiUyiSEcJKghhy2ZzJ0ADva78BQw5wvJXcgxmEJhDVPlLvZNtRuCTDz8V5b8xGLORRPLQOCVuu%2FJQrLuJ%2FLBwmKtWfURkzUEK4Bvp7hdQSXE9Bdo%2BIUELc%2FollYAUIR9cLuXGB4LcF3MbuEnRMsx0fmew59GnKSrUTM30OgPMe7XfvvyMYbcrsx0ad8QQYCZfT92VDfDcsSK9EkcnqibOKBeVz6c6NsG0mXNJy%2FjdmeikZD%2B0SnRLK%2B1DJ%2BM%2FD%2FM0HCIJyurX7%2BmrEqThDoVqPZ0dRfK4dmITQg3mu015FcX6P9lNVn6ovViNSvSU0t1JUA%3D%3D: HTTPSConnectionPool(host='storage.googleapis.com', port=443): Max retries exceeded with url: /wandb-production.appspot.com/1923354735/MonoGS/7i7f5gjm/requirements.txt?Expires=1716344785&GoogleAccessId=gorilla-files-url-signer-man%40wandb-production.iam.gserviceaccount.com&Signature=PUX7QA4OqH2opVL%2Be4xGiUyiSEcJKghhy2ZzJ0ADva78BQw5wvJXcgxmEJhDVPlLvZNtRuCTDz8V5b8xGLORRPLQOCVuu%2FJQrLuJ%2FLBwmKtWfURkzUEK4Bvp7hdQSXE9Bdo%2BIUELc%2FollYAUIR9cLuXGB4LcF3MbuEnRMsx0fmew59GnKSrUTM30OgPMe7XfvvyMYbcrsx0ad8QQYCZfT92VDfDcsSK9EkcnqibOKBeVz6c6NsG0mXNJy%2FjdmeikZD%2B0SnRLK%2B1DJ%2BM%2FD%2FM0HCIJyurX7%2BmrEqThDoVqPZ0dRfK4dmITQg3mu015FcX6P9lNVn6ovViNSvSU0t1JUA%3D%3D (Caused by NewConnectionError('<urllib3.connection.HTTPSConnection object at 0x7f6e843a3810>: Failed to establish a new connection: [Errno 111] Connection refused'))
2024-05-21 10:26:26,585 ERROR   wandb-upload_3:1293572 [internal_api.py:upload_file():2769] upload_file request headers: {'User-Agent': 'python-requests/2.31.0', 'Accept-Encoding': 'gzip, deflate, br', 'Accept': '*/*', 'Connection': 'keep-alive', 'Content-Length': '2267'}
2024-05-21 10:26:26,585 ERROR   wandb-upload_3:1293572 [internal_api.py:upload_file():2771] upload_file response body: 
2024-05-21 10:26:28,650 ERROR   wandb-upload_2:1293572 [internal_api.py:upload_file():2767] upload_file exception https://storage.googleapis.com/wandb-production.appspot.com/1923354735/MonoGS/7i7f5gjm/output.log?Expires=1716344785&GoogleAccessId=gorilla-files-url-signer-man%40wandb-production.iam.gserviceaccount.com&Signature=VLoFH2QdZgsVeMSF7%2BZme2jkQEB5BuWJAxPRoHnj5FpmgAhWt%2BYchg0RqCx7PqoSN03WZ48TzcE1HZY%2Fag0rhCj1rwVp5EzKy%2FSKz%2B5KjD8scah61BdOHMmprbP8zg20%2FgV25YS8%2FOIlmG2G1EbWJ6NgRpjmbFhmC4WPPQ0LMaJ36bnQynJS%2Forxr6%2BpfjJ5SugurpujGl1HCP2FHd5qIGo5fc2oL7RxoOKTKhW02hzUUUoYzhY5fON9KtU4ixGYyAkLpKTUBhzVl%2Fr7rx7pzQJTS8e5gQ3loeJZJoh%2Fj4kHeCpLWmVRkb7VMOchgUDivO0he6tvugSp17daenhjLQ%3D%3D: HTTPSConnectionPool(host='storage.googleapis.com', port=443): Max retries exceeded with url: /wandb-production.appspot.com/1923354735/MonoGS/7i7f5gjm/output.log?Expires=1716344785&GoogleAccessId=gorilla-files-url-signer-man%40wandb-production.iam.gserviceaccount.com&Signature=VLoFH2QdZgsVeMSF7%2BZme2jkQEB5BuWJAxPRoHnj5FpmgAhWt%2BYchg0RqCx7PqoSN03WZ48TzcE1HZY%2Fag0rhCj1rwVp5EzKy%2FSKz%2B5KjD8scah61BdOHMmprbP8zg20%2FgV25YS8%2FOIlmG2G1EbWJ6NgRpjmbFhmC4WPPQ0LMaJ36bnQynJS%2Forxr6%2BpfjJ5SugurpujGl1HCP2FHd5qIGo5fc2oL7RxoOKTKhW02hzUUUoYzhY5fON9KtU4ixGYyAkLpKTUBhzVl%2Fr7rx7pzQJTS8e5gQ3loeJZJoh%2Fj4kHeCpLWmVRkb7VMOchgUDivO0he6tvugSp17daenhjLQ%3D%3D (Caused by NewConnectionError('<urllib3.connection.HTTPSConnection object at 0x7f6e84395690>: Failed to establish a new connection: [Errno 111] Connection refused'))
2024-05-21 10:26:28,650 ERROR   wandb-upload_2:1293572 [internal_api.py:upload_file():2769] upload_file request headers: {'User-Agent': 'python-requests/2.31.0', 'Accept-Encoding': 'gzip, deflate, br', 'Accept': '*/*', 'Connection': 'keep-alive', 'Content-Length': '1015'}
2024-05-21 10:26:28,650 ERROR   wandb-upload_2:1293572 [internal_api.py:upload_file():2771] upload_file response body: 
2024-05-21 10:26:28,714 ERROR   wandb-upload_3:1293572 [internal_api.py:upload_file():2767] upload_file exception https://storage.googleapis.com/wandb-production.appspot.com/1923354735/MonoGS/7i7f5gjm/requirements.txt?Expires=1716344785&GoogleAccessId=gorilla-files-url-signer-man%40wandb-production.iam.gserviceaccount.com&Signature=PUX7QA4OqH2opVL%2Be4xGiUyiSEcJKghhy2ZzJ0ADva78BQw5wvJXcgxmEJhDVPlLvZNtRuCTDz8V5b8xGLORRPLQOCVuu%2FJQrLuJ%2FLBwmKtWfURkzUEK4Bvp7hdQSXE9Bdo%2BIUELc%2FollYAUIR9cLuXGB4LcF3MbuEnRMsx0fmew59GnKSrUTM30OgPMe7XfvvyMYbcrsx0ad8QQYCZfT92VDfDcsSK9EkcnqibOKBeVz6c6NsG0mXNJy%2FjdmeikZD%2B0SnRLK%2B1DJ%2BM%2FD%2FM0HCIJyurX7%2BmrEqThDoVqPZ0dRfK4dmITQg3mu015FcX6P9lNVn6ovViNSvSU0t1JUA%3D%3D: HTTPSConnectionPool(host='storage.googleapis.com', port=443): Max retries exceeded with url: /wandb-production.appspot.com/1923354735/MonoGS/7i7f5gjm/requirements.txt?Expires=1716344785&GoogleAccessId=gorilla-files-url-signer-man%40wandb-production.iam.gserviceaccount.com&Signature=PUX7QA4OqH2opVL%2Be4xGiUyiSEcJKghhy2ZzJ0ADva78BQw5wvJXcgxmEJhDVPlLvZNtRuCTDz8V5b8xGLORRPLQOCVuu%2FJQrLuJ%2FLBwmKtWfURkzUEK4Bvp7hdQSXE9Bdo%2BIUELc%2FollYAUIR9cLuXGB4LcF3MbuEnRMsx0fmew59GnKSrUTM30OgPMe7XfvvyMYbcrsx0ad8QQYCZfT92VDfDcsSK9EkcnqibOKBeVz6c6NsG0mXNJy%2FjdmeikZD%2B0SnRLK%2B1DJ%2BM%2FD%2FM0HCIJyurX7%2BmrEqThDoVqPZ0dRfK4dmITQg3mu015FcX6P9lNVn6ovViNSvSU0t1JUA%3D%3D (Caused by NewConnectionError('<urllib3.connection.HTTPSConnection object at 0x7f6e8443f3d0>: Failed to establish a new connection: [Errno 111] Connection refused'))
2024-05-21 10:26:28,714 ERROR   wandb-upload_3:1293572 [internal_api.py:upload_file():2769] upload_file request headers: {'User-Agent': 'python-requests/2.31.0', 'Accept-Encoding': 'gzip, deflate, br', 'Accept': '*/*', 'Connection': 'keep-alive', 'Content-Length': '2267'}
2024-05-21 10:26:28,715 ERROR   wandb-upload_3:1293572 [internal_api.py:upload_file():2771] upload_file response body: 
2024-05-21 10:26:28,764 ERROR   wandb-upload_4:1293572 [internal_api.py:upload_file():2767] upload_file exception https://storage.googleapis.com/wandb-production.appspot.com/1923354735/MonoGS/7i7f5gjm/conda-environment.yaml?Expires=1716344785&GoogleAccessId=gorilla-files-url-signer-man%40wandb-production.iam.gserviceaccount.com&Signature=EVDYObbaalBfRuHPuIIs4NJTCdppmKpHxAnNLjdSe1QDN6a6hLjmiC11aQSD4qP%2FLgPOBp45zUTn6TBcUhpaHqlZNygjhiEZX7Ca6B8klTArywRWcGYmvUpGy7O%2BleSulQSIXobSwqU%2BnRTR07PRCuNcBPTnbqW4CuC37R8fHKLlfmAI1UHGfP2sI%2BlboaOgAd5r%2BM%2FcJppRU2DfKWKWnp6t7v4yZJja%2BYwr7UjygyGHX5lL9hp2spsgl904SnGzFL7U%2FmLKAckP6yFEIZwTv6OhtL0G4DCGbJCOtPnMRFsrapLi2lTX5L4uZH%2Fmk1S6S69x4FC7L5%2Bpmj6gh7nsiA%3D%3D: HTTPSConnectionPool(host='storage.googleapis.com', port=443): Max retries exceeded with url: /wandb-production.appspot.com/1923354735/MonoGS/7i7f5gjm/conda-environment.yaml?Expires=1716344785&GoogleAccessId=gorilla-files-url-signer-man%40wandb-production.iam.gserviceaccount.com&Signature=EVDYObbaalBfRuHPuIIs4NJTCdppmKpHxAnNLjdSe1QDN6a6hLjmiC11aQSD4qP%2FLgPOBp45zUTn6TBcUhpaHqlZNygjhiEZX7Ca6B8klTArywRWcGYmvUpGy7O%2BleSulQSIXobSwqU%2BnRTR07PRCuNcBPTnbqW4CuC37R8fHKLlfmAI1UHGfP2sI%2BlboaOgAd5r%2BM%2FcJppRU2DfKWKWnp6t7v4yZJja%2BYwr7UjygyGHX5lL9hp2spsgl904SnGzFL7U%2FmLKAckP6yFEIZwTv6OhtL0G4DCGbJCOtPnMRFsrapLi2lTX5L4uZH%2Fmk1S6S69x4FC7L5%2Bpmj6gh7nsiA%3D%3D (Caused by NewConnectionError('<urllib3.connection.HTTPSConnection object at 0x7f6e843a37d0>: Failed to establish a new connection: [Errno 111] Connection refused'))
2024-05-21 10:26:28,764 ERROR   wandb-upload_4:1293572 [internal_api.py:upload_file():2769] upload_file request headers: {'User-Agent': 'python-requests/2.31.0', 'Accept-Encoding': 'gzip, deflate, br', 'Accept': '*/*', 'Connection': 'keep-alive', 'Content-Length': '4690'}
2024-05-21 10:26:28,764 ERROR   wandb-upload_4:1293572 [internal_api.py:upload_file():2771] upload_file response body: 
2024-05-21 10:26:28,781 ERROR   wandb-upload_1:1293572 [internal_api.py:upload_file():2767] upload_file exception https://storage.googleapis.com/wandb-production.appspot.com/1923354735/MonoGS/7i7f5gjm/wandb-summary.json?Expires=1716344785&GoogleAccessId=gorilla-files-url-signer-man%40wandb-production.iam.gserviceaccount.com&Signature=jeBYHZuazMllAswE5cCuYPIOXrsDk%2Fi%2Byxjsv9qWnxV%2BGNVzIHitPZSoDMj6MWk0TNlGqYZGlH4B%2BPF%2BhJiqKeqhL2OuOHBETtdtsiWdwH0tIXK1ZdLZnOfccEagnoMyHjd%2BI8iVtowEJcGh5WKQ7a4%2B47kjR3lcOIzwzXrjed270X%2FoNcanSDRgV8xNpf603zC1Vf1qsRhzc6BJ684LVu0rN5GfkVItbl5nymffb%2F%2B%2BzcjF%2BZLQmZ17RQ0QV7xUR7ur9fhcaGfCDFhLfuBOx%2BIisR%2BQ%2Bec%2BD9ldoKK0mB7eEItITzgUcPVBv2GxH5sqHE5OJHUsFgZ0AGP%2Fxp5TXQ%3D%3D: HTTPSConnectionPool(host='storage.googleapis.com', port=443): Max retries exceeded with url: /wandb-production.appspot.com/1923354735/MonoGS/7i7f5gjm/wandb-summary.json?Expires=1716344785&GoogleAccessId=gorilla-files-url-signer-man%40wandb-production.iam.gserviceaccount.com&Signature=jeBYHZuazMllAswE5cCuYPIOXrsDk%2Fi%2Byxjsv9qWnxV%2BGNVzIHitPZSoDMj6MWk0TNlGqYZGlH4B%2BPF%2BhJiqKeqhL2OuOHBETtdtsiWdwH0tIXK1ZdLZnOfccEagnoMyHjd%2BI8iVtowEJcGh5WKQ7a4%2B47kjR3lcOIzwzXrjed270X%2FoNcanSDRgV8xNpf603zC1Vf1qsRhzc6BJ684LVu0rN5GfkVItbl5nymffb%2F%2B%2BzcjF%2BZLQmZ17RQ0QV7xUR7ur9fhcaGfCDFhLfuBOx%2BIisR%2BQ%2Bec%2BD9ldoKK0mB7eEItITzgUcPVBv2GxH5sqHE5OJHUsFgZ0AGP%2Fxp5TXQ%3D%3D (Caused by NewConnectionError('<urllib3.connection.HTTPSConnection object at 0x7f6e8438e690>: Failed to establish a new connection: [Errno 111] Connection refused'))
2024-05-21 10:26:28,782 ERROR   wandb-upload_1:1293572 [internal_api.py:upload_file():2769] upload_file request headers: {'User-Agent': 'python-requests/2.31.0', 'Accept-Encoding': 'gzip, deflate, br', 'Accept': '*/*', 'Connection': 'keep-alive', 'Content-Length': '27'}
2024-05-21 10:26:28,782 ERROR   wandb-upload_1:1293572 [internal_api.py:upload_file():2771] upload_file response body: 
2024-05-21 10:26:28,854 ERROR   wandb-upload_5:1293572 [internal_api.py:upload_file():2767] upload_file exception https://storage.googleapis.com/wandb-production.appspot.com/1923354735/MonoGS/7i7f5gjm/config.yaml?Expires=1716344785&GoogleAccessId=gorilla-files-url-signer-man%40wandb-production.iam.gserviceaccount.com&Signature=BMJwBO0b014Q1rvgox%2BYqw0pIWvynCGKcHXP81FuKhooGhVUhYqaVBmViVNciwVsqNKp%2BvW6awp8zq7bi9R7C1S9SMcftKvFNNZTi3MFZUocgiR6bDXJN6BK87FW4A4x3HBA3lUNs%2BWeyT07hWtUTpF3yauVUa0ysE7bU4lqzsHw6wjbYscL%2BUPwtsOABX2fk5Cq9c2xOXBjo76eTHr2dXmLEuUI2yZjhoAw9dyVlAaRkeS3kpnJCE3msbu06izwRBdLpfjl2PnIPuJW32O1U80Rm8bWPcZ5hnthAMzzOX3Junrz0ThnCdN67XHlY6kYXWb2tSdx4J%2BT7ulxfZmRPw%3D%3D: HTTPSConnectionPool(host='storage.googleapis.com', port=443): Max retries exceeded with url: /wandb-production.appspot.com/1923354735/MonoGS/7i7f5gjm/config.yaml?Expires=1716344785&GoogleAccessId=gorilla-files-url-signer-man%40wandb-production.iam.gserviceaccount.com&Signature=BMJwBO0b014Q1rvgox%2BYqw0pIWvynCGKcHXP81FuKhooGhVUhYqaVBmViVNciwVsqNKp%2BvW6awp8zq7bi9R7C1S9SMcftKvFNNZTi3MFZUocgiR6bDXJN6BK87FW4A4x3HBA3lUNs%2BWeyT07hWtUTpF3yauVUa0ysE7bU4lqzsHw6wjbYscL%2BUPwtsOABX2fk5Cq9c2xOXBjo76eTHr2dXmLEuUI2yZjhoAw9dyVlAaRkeS3kpnJCE3msbu06izwRBdLpfjl2PnIPuJW32O1U80Rm8bWPcZ5hnthAMzzOX3Junrz0ThnCdN67XHlY6kYXWb2tSdx4J%2BT7ulxfZmRPw%3D%3D (Caused by NewConnectionError('<urllib3.connection.HTTPSConnection object at 0x7f6e8438e610>: Failed to establish a new connection: [Errno 111] Connection refused'))
2024-05-21 10:26:28,854 ERROR   wandb-upload_5:1293572 [internal_api.py:upload_file():2769] upload_file request headers: {'User-Agent': 'python-requests/2.31.0', 'Accept-Encoding': 'gzip, deflate, br', 'Accept': '*/*', 'Connection': 'keep-alive', 'Content-Length': '2747'}
2024-05-21 10:26:28,854 ERROR   wandb-upload_5:1293572 [internal_api.py:upload_file():2771] upload_file response body: 
2024-05-21 10:26:32,809 ERROR   wandb-upload_4:1293572 [internal_api.py:upload_file():2767] upload_file exception https://storage.googleapis.com/wandb-production.appspot.com/1923354735/MonoGS/7i7f5gjm/conda-environment.yaml?Expires=1716344785&GoogleAccessId=gorilla-files-url-signer-man%40wandb-production.iam.gserviceaccount.com&Signature=EVDYObbaalBfRuHPuIIs4NJTCdppmKpHxAnNLjdSe1QDN6a6hLjmiC11aQSD4qP%2FLgPOBp45zUTn6TBcUhpaHqlZNygjhiEZX7Ca6B8klTArywRWcGYmvUpGy7O%2BleSulQSIXobSwqU%2BnRTR07PRCuNcBPTnbqW4CuC37R8fHKLlfmAI1UHGfP2sI%2BlboaOgAd5r%2BM%2FcJppRU2DfKWKWnp6t7v4yZJja%2BYwr7UjygyGHX5lL9hp2spsgl904SnGzFL7U%2FmLKAckP6yFEIZwTv6OhtL0G4DCGbJCOtPnMRFsrapLi2lTX5L4uZH%2Fmk1S6S69x4FC7L5%2Bpmj6gh7nsiA%3D%3D: HTTPSConnectionPool(host='storage.googleapis.com', port=443): Max retries exceeded with url: /wandb-production.appspot.com/1923354735/MonoGS/7i7f5gjm/conda-environment.yaml?Expires=1716344785&GoogleAccessId=gorilla-files-url-signer-man%40wandb-production.iam.gserviceaccount.com&Signature=EVDYObbaalBfRuHPuIIs4NJTCdppmKpHxAnNLjdSe1QDN6a6hLjmiC11aQSD4qP%2FLgPOBp45zUTn6TBcUhpaHqlZNygjhiEZX7Ca6B8klTArywRWcGYmvUpGy7O%2BleSulQSIXobSwqU%2BnRTR07PRCuNcBPTnbqW4CuC37R8fHKLlfmAI1UHGfP2sI%2BlboaOgAd5r%2BM%2FcJppRU2DfKWKWnp6t7v4yZJja%2BYwr7UjygyGHX5lL9hp2spsgl904SnGzFL7U%2FmLKAckP6yFEIZwTv6OhtL0G4DCGbJCOtPnMRFsrapLi2lTX5L4uZH%2Fmk1S6S69x4FC7L5%2Bpmj6gh7nsiA%3D%3D (Caused by NewConnectionError('<urllib3.connection.HTTPSConnection object at 0x7f6e843ada50>: Failed to establish a new connection: [Errno 111] Connection refused'))
2024-05-21 10:26:32,810 ERROR   wandb-upload_4:1293572 [internal_api.py:upload_file():2769] upload_file request headers: {'User-Agent': 'python-requests/2.31.0', 'Accept-Encoding': 'gzip, deflate, br', 'Accept': '*/*', 'Connection': 'keep-alive', 'Content-Length': '4690'}
2024-05-21 10:26:32,810 ERROR   wandb-upload_4:1293572 [internal_api.py:upload_file():2771] upload_file response body: 
2024-05-21 10:26:33,057 ERROR   wandb-upload_3:1293572 [internal_api.py:upload_file():2767] upload_file exception https://storage.googleapis.com/wandb-production.appspot.com/1923354735/MonoGS/7i7f5gjm/requirements.txt?Expires=1716344785&GoogleAccessId=gorilla-files-url-signer-man%40wandb-production.iam.gserviceaccount.com&Signature=PUX7QA4OqH2opVL%2Be4xGiUyiSEcJKghhy2ZzJ0ADva78BQw5wvJXcgxmEJhDVPlLvZNtRuCTDz8V5b8xGLORRPLQOCVuu%2FJQrLuJ%2FLBwmKtWfURkzUEK4Bvp7hdQSXE9Bdo%2BIUELc%2FollYAUIR9cLuXGB4LcF3MbuEnRMsx0fmew59GnKSrUTM30OgPMe7XfvvyMYbcrsx0ad8QQYCZfT92VDfDcsSK9EkcnqibOKBeVz6c6NsG0mXNJy%2FjdmeikZD%2B0SnRLK%2B1DJ%2BM%2FD%2FM0HCIJyurX7%2BmrEqThDoVqPZ0dRfK4dmITQg3mu015FcX6P9lNVn6ovViNSvSU0t1JUA%3D%3D: HTTPSConnectionPool(host='storage.googleapis.com', port=443): Max retries exceeded with url: /wandb-production.appspot.com/1923354735/MonoGS/7i7f5gjm/requirements.txt?Expires=1716344785&GoogleAccessId=gorilla-files-url-signer-man%40wandb-production.iam.gserviceaccount.com&Signature=PUX7QA4OqH2opVL%2Be4xGiUyiSEcJKghhy2ZzJ0ADva78BQw5wvJXcgxmEJhDVPlLvZNtRuCTDz8V5b8xGLORRPLQOCVuu%2FJQrLuJ%2FLBwmKtWfURkzUEK4Bvp7hdQSXE9Bdo%2BIUELc%2FollYAUIR9cLuXGB4LcF3MbuEnRMsx0fmew59GnKSrUTM30OgPMe7XfvvyMYbcrsx0ad8QQYCZfT92VDfDcsSK9EkcnqibOKBeVz6c6NsG0mXNJy%2FjdmeikZD%2B0SnRLK%2B1DJ%2BM%2FD%2FM0HCIJyurX7%2BmrEqThDoVqPZ0dRfK4dmITQg3mu015FcX6P9lNVn6ovViNSvSU0t1JUA%3D%3D (Caused by NewConnectionError('<urllib3.connection.HTTPSConnection object at 0x7f6e843933d0>: Failed to establish a new connection: [Errno 111] Connection refused'))
2024-05-21 10:26:33,057 ERROR   wandb-upload_3:1293572 [internal_api.py:upload_file():2769] upload_file request headers: {'User-Agent': 'python-requests/2.31.0', 'Accept-Encoding': 'gzip, deflate, br', 'Accept': '*/*', 'Connection': 'keep-alive', 'Content-Length': '2267'}
2024-05-21 10:26:33,057 ERROR   wandb-upload_3:1293572 [internal_api.py:upload_file():2771] upload_file response body: 
2024-05-21 10:26:33,338 ERROR   wandb-upload_1:1293572 [internal_api.py:upload_file():2767] upload_file exception https://storage.googleapis.com/wandb-production.appspot.com/1923354735/MonoGS/7i7f5gjm/wandb-summary.json?Expires=1716344785&GoogleAccessId=gorilla-files-url-signer-man%40wandb-production.iam.gserviceaccount.com&Signature=jeBYHZuazMllAswE5cCuYPIOXrsDk%2Fi%2Byxjsv9qWnxV%2BGNVzIHitPZSoDMj6MWk0TNlGqYZGlH4B%2BPF%2BhJiqKeqhL2OuOHBETtdtsiWdwH0tIXK1ZdLZnOfccEagnoMyHjd%2BI8iVtowEJcGh5WKQ7a4%2B47kjR3lcOIzwzXrjed270X%2FoNcanSDRgV8xNpf603zC1Vf1qsRhzc6BJ684LVu0rN5GfkVItbl5nymffb%2F%2B%2BzcjF%2BZLQmZ17RQ0QV7xUR7ur9fhcaGfCDFhLfuBOx%2BIisR%2BQ%2Bec%2BD9ldoKK0mB7eEItITzgUcPVBv2GxH5sqHE5OJHUsFgZ0AGP%2Fxp5TXQ%3D%3D: HTTPSConnectionPool(host='storage.googleapis.com', port=443): Max retries exceeded with url: /wandb-production.appspot.com/1923354735/MonoGS/7i7f5gjm/wandb-summary.json?Expires=1716344785&GoogleAccessId=gorilla-files-url-signer-man%40wandb-production.iam.gserviceaccount.com&Signature=jeBYHZuazMllAswE5cCuYPIOXrsDk%2Fi%2Byxjsv9qWnxV%2BGNVzIHitPZSoDMj6MWk0TNlGqYZGlH4B%2BPF%2BhJiqKeqhL2OuOHBETtdtsiWdwH0tIXK1ZdLZnOfccEagnoMyHjd%2BI8iVtowEJcGh5WKQ7a4%2B47kjR3lcOIzwzXrjed270X%2FoNcanSDRgV8xNpf603zC1Vf1qsRhzc6BJ684LVu0rN5GfkVItbl5nymffb%2F%2B%2BzcjF%2BZLQmZ17RQ0QV7xUR7ur9fhcaGfCDFhLfuBOx%2BIisR%2BQ%2Bec%2BD9ldoKK0mB7eEItITzgUcPVBv2GxH5sqHE5OJHUsFgZ0AGP%2Fxp5TXQ%3D%3D (Caused by NewConnectionError('<urllib3.connection.HTTPSConnection object at 0x7f6e843a8190>: Failed to establish a new connection: [Errno 111] Connection refused'))
2024-05-21 10:26:33,338 ERROR   wandb-upload_1:1293572 [internal_api.py:upload_file():2769] upload_file request headers: {'User-Agent': 'python-requests/2.31.0', 'Accept-Encoding': 'gzip, deflate, br', 'Accept': '*/*', 'Connection': 'keep-alive', 'Content-Length': '27'}
2024-05-21 10:26:33,338 ERROR   wandb-upload_1:1293572 [internal_api.py:upload_file():2771] upload_file response body: 
2024-05-21 10:26:33,364 ERROR   wandb-upload_5:1293572 [internal_api.py:upload_file():2767] upload_file exception https://storage.googleapis.com/wandb-production.appspot.com/1923354735/MonoGS/7i7f5gjm/config.yaml?Expires=1716344785&GoogleAccessId=gorilla-files-url-signer-man%40wandb-production.iam.gserviceaccount.com&Signature=BMJwBO0b014Q1rvgox%2BYqw0pIWvynCGKcHXP81FuKhooGhVUhYqaVBmViVNciwVsqNKp%2BvW6awp8zq7bi9R7C1S9SMcftKvFNNZTi3MFZUocgiR6bDXJN6BK87FW4A4x3HBA3lUNs%2BWeyT07hWtUTpF3yauVUa0ysE7bU4lqzsHw6wjbYscL%2BUPwtsOABX2fk5Cq9c2xOXBjo76eTHr2dXmLEuUI2yZjhoAw9dyVlAaRkeS3kpnJCE3msbu06izwRBdLpfjl2PnIPuJW32O1U80Rm8bWPcZ5hnthAMzzOX3Junrz0ThnCdN67XHlY6kYXWb2tSdx4J%2BT7ulxfZmRPw%3D%3D: HTTPSConnectionPool(host='storage.googleapis.com', port=443): Max retries exceeded with url: /wandb-production.appspot.com/1923354735/MonoGS/7i7f5gjm/config.yaml?Expires=1716344785&GoogleAccessId=gorilla-files-url-signer-man%40wandb-production.iam.gserviceaccount.com&Signature=BMJwBO0b014Q1rvgox%2BYqw0pIWvynCGKcHXP81FuKhooGhVUhYqaVBmViVNciwVsqNKp%2BvW6awp8zq7bi9R7C1S9SMcftKvFNNZTi3MFZUocgiR6bDXJN6BK87FW4A4x3HBA3lUNs%2BWeyT07hWtUTpF3yauVUa0ysE7bU4lqzsHw6wjbYscL%2BUPwtsOABX2fk5Cq9c2xOXBjo76eTHr2dXmLEuUI2yZjhoAw9dyVlAaRkeS3kpnJCE3msbu06izwRBdLpfjl2PnIPuJW32O1U80Rm8bWPcZ5hnthAMzzOX3Junrz0ThnCdN67XHlY6kYXWb2tSdx4J%2BT7ulxfZmRPw%3D%3D (Caused by NewConnectionError('<urllib3.connection.HTTPSConnection object at 0x7f6e843b0bd0>: Failed to establish a new connection: [Errno 111] Connection refused'))
2024-05-21 10:26:33,365 ERROR   wandb-upload_5:1293572 [internal_api.py:upload_file():2769] upload_file request headers: {'User-Agent': 'python-requests/2.31.0', 'Accept-Encoding': 'gzip, deflate, br', 'Accept': '*/*', 'Connection': 'keep-alive', 'Content-Length': '2747'}
2024-05-21 10:26:33,365 ERROR   wandb-upload_5:1293572 [internal_api.py:upload_file():2771] upload_file response body: 
2024-05-21 10:26:33,383 ERROR   wandb-upload_2:1293572 [internal_api.py:upload_file():2767] upload_file exception https://storage.googleapis.com/wandb-production.appspot.com/1923354735/MonoGS/7i7f5gjm/output.log?Expires=1716344785&GoogleAccessId=gorilla-files-url-signer-man%40wandb-production.iam.gserviceaccount.com&Signature=VLoFH2QdZgsVeMSF7%2BZme2jkQEB5BuWJAxPRoHnj5FpmgAhWt%2BYchg0RqCx7PqoSN03WZ48TzcE1HZY%2Fag0rhCj1rwVp5EzKy%2FSKz%2B5KjD8scah61BdOHMmprbP8zg20%2FgV25YS8%2FOIlmG2G1EbWJ6NgRpjmbFhmC4WPPQ0LMaJ36bnQynJS%2Forxr6%2BpfjJ5SugurpujGl1HCP2FHd5qIGo5fc2oL7RxoOKTKhW02hzUUUoYzhY5fON9KtU4ixGYyAkLpKTUBhzVl%2Fr7rx7pzQJTS8e5gQ3loeJZJoh%2Fj4kHeCpLWmVRkb7VMOchgUDivO0he6tvugSp17daenhjLQ%3D%3D: HTTPSConnectionPool(host='storage.googleapis.com', port=443): Max retries exceeded with url: /wandb-production.appspot.com/1923354735/MonoGS/7i7f5gjm/output.log?Expires=1716344785&GoogleAccessId=gorilla-files-url-signer-man%40wandb-production.iam.gserviceaccount.com&Signature=VLoFH2QdZgsVeMSF7%2BZme2jkQEB5BuWJAxPRoHnj5FpmgAhWt%2BYchg0RqCx7PqoSN03WZ48TzcE1HZY%2Fag0rhCj1rwVp5EzKy%2FSKz%2B5KjD8scah61BdOHMmprbP8zg20%2FgV25YS8%2FOIlmG2G1EbWJ6NgRpjmbFhmC4WPPQ0LMaJ36bnQynJS%2Forxr6%2BpfjJ5SugurpujGl1HCP2FHd5qIGo5fc2oL7RxoOKTKhW02hzUUUoYzhY5fON9KtU4ixGYyAkLpKTUBhzVl%2Fr7rx7pzQJTS8e5gQ3loeJZJoh%2Fj4kHeCpLWmVRkb7VMOchgUDivO0he6tvugSp17daenhjLQ%3D%3D (Caused by NewConnectionError('<urllib3.connection.HTTPSConnection object at 0x7f6e843b0d50>: Failed to establish a new connection: [Errno 111] Connection refused'))
2024-05-21 10:26:33,383 ERROR   wandb-upload_2:1293572 [internal_api.py:upload_file():2769] upload_file request headers: {'User-Agent': 'python-requests/2.31.0', 'Accept-Encoding': 'gzip, deflate, br', 'Accept': '*/*', 'Connection': 'keep-alive', 'Content-Length': '1015'}
2024-05-21 10:26:33,383 ERROR   wandb-upload_2:1293572 [internal_api.py:upload_file():2771] upload_file response body: 
2024-05-21 10:26:41,425 ERROR   wandb-upload_1:1293572 [internal_api.py:upload_file():2767] upload_file exception https://storage.googleapis.com/wandb-production.appspot.com/1923354735/MonoGS/7i7f5gjm/wandb-summary.json?Expires=1716344785&GoogleAccessId=gorilla-files-url-signer-man%40wandb-production.iam.gserviceaccount.com&Signature=jeBYHZuazMllAswE5cCuYPIOXrsDk%2Fi%2Byxjsv9qWnxV%2BGNVzIHitPZSoDMj6MWk0TNlGqYZGlH4B%2BPF%2BhJiqKeqhL2OuOHBETtdtsiWdwH0tIXK1ZdLZnOfccEagnoMyHjd%2BI8iVtowEJcGh5WKQ7a4%2B47kjR3lcOIzwzXrjed270X%2FoNcanSDRgV8xNpf603zC1Vf1qsRhzc6BJ684LVu0rN5GfkVItbl5nymffb%2F%2B%2BzcjF%2BZLQmZ17RQ0QV7xUR7ur9fhcaGfCDFhLfuBOx%2BIisR%2BQ%2Bec%2BD9ldoKK0mB7eEItITzgUcPVBv2GxH5sqHE5OJHUsFgZ0AGP%2Fxp5TXQ%3D%3D: HTTPSConnectionPool(host='storage.googleapis.com', port=443): Max retries exceeded with url: /wandb-production.appspot.com/1923354735/MonoGS/7i7f5gjm/wandb-summary.json?Expires=1716344785&GoogleAccessId=gorilla-files-url-signer-man%40wandb-production.iam.gserviceaccount.com&Signature=jeBYHZuazMllAswE5cCuYPIOXrsDk%2Fi%2Byxjsv9qWnxV%2BGNVzIHitPZSoDMj6MWk0TNlGqYZGlH4B%2BPF%2BhJiqKeqhL2OuOHBETtdtsiWdwH0tIXK1ZdLZnOfccEagnoMyHjd%2BI8iVtowEJcGh5WKQ7a4%2B47kjR3lcOIzwzXrjed270X%2FoNcanSDRgV8xNpf603zC1Vf1qsRhzc6BJ684LVu0rN5GfkVItbl5nymffb%2F%2B%2BzcjF%2BZLQmZ17RQ0QV7xUR7ur9fhcaGfCDFhLfuBOx%2BIisR%2BQ%2Bec%2BD9ldoKK0mB7eEItITzgUcPVBv2GxH5sqHE5OJHUsFgZ0AGP%2Fxp5TXQ%3D%3D (Caused by NewConnectionError('<urllib3.connection.HTTPSConnection object at 0x7f6e8443d350>: Failed to establish a new connection: [Errno 111] Connection refused'))
2024-05-21 10:26:41,425 ERROR   wandb-upload_1:1293572 [internal_api.py:upload_file():2769] upload_file request headers: {'User-Agent': 'python-requests/2.31.0', 'Accept-Encoding': 'gzip, deflate, br', 'Accept': '*/*', 'Connection': 'keep-alive', 'Content-Length': '27'}
2024-05-21 10:26:41,425 ERROR   wandb-upload_1:1293572 [internal_api.py:upload_file():2771] upload_file response body: 
2024-05-21 10:26:42,560 ERROR   wandb-upload_4:1293572 [internal_api.py:upload_file():2767] upload_file exception https://storage.googleapis.com/wandb-production.appspot.com/1923354735/MonoGS/7i7f5gjm/conda-environment.yaml?Expires=1716344785&GoogleAccessId=gorilla-files-url-signer-man%40wandb-production.iam.gserviceaccount.com&Signature=EVDYObbaalBfRuHPuIIs4NJTCdppmKpHxAnNLjdSe1QDN6a6hLjmiC11aQSD4qP%2FLgPOBp45zUTn6TBcUhpaHqlZNygjhiEZX7Ca6B8klTArywRWcGYmvUpGy7O%2BleSulQSIXobSwqU%2BnRTR07PRCuNcBPTnbqW4CuC37R8fHKLlfmAI1UHGfP2sI%2BlboaOgAd5r%2BM%2FcJppRU2DfKWKWnp6t7v4yZJja%2BYwr7UjygyGHX5lL9hp2spsgl904SnGzFL7U%2FmLKAckP6yFEIZwTv6OhtL0G4DCGbJCOtPnMRFsrapLi2lTX5L4uZH%2Fmk1S6S69x4FC7L5%2Bpmj6gh7nsiA%3D%3D: HTTPSConnectionPool(host='storage.googleapis.com', port=443): Max retries exceeded with url: /wandb-production.appspot.com/1923354735/MonoGS/7i7f5gjm/conda-environment.yaml?Expires=1716344785&GoogleAccessId=gorilla-files-url-signer-man%40wandb-production.iam.gserviceaccount.com&Signature=EVDYObbaalBfRuHPuIIs4NJTCdppmKpHxAnNLjdSe1QDN6a6hLjmiC11aQSD4qP%2FLgPOBp45zUTn6TBcUhpaHqlZNygjhiEZX7Ca6B8klTArywRWcGYmvUpGy7O%2BleSulQSIXobSwqU%2BnRTR07PRCuNcBPTnbqW4CuC37R8fHKLlfmAI1UHGfP2sI%2BlboaOgAd5r%2BM%2FcJppRU2DfKWKWnp6t7v4yZJja%2BYwr7UjygyGHX5lL9hp2spsgl904SnGzFL7U%2FmLKAckP6yFEIZwTv6OhtL0G4DCGbJCOtPnMRFsrapLi2lTX5L4uZH%2Fmk1S6S69x4FC7L5%2Bpmj6gh7nsiA%3D%3D (Caused by NewConnectionError('<urllib3.connection.HTTPSConnection object at 0x7f6e84395690>: Failed to establish a new connection: [Errno 111] Connection refused'))
2024-05-21 10:26:42,560 ERROR   wandb-upload_4:1293572 [internal_api.py:upload_file():2769] upload_file request headers: {'User-Agent': 'python-requests/2.31.0', 'Accept-Encoding': 'gzip, deflate, br', 'Accept': '*/*', 'Connection': 'keep-alive', 'Content-Length': '4690'}
2024-05-21 10:26:42,560 ERROR   wandb-upload_4:1293572 [internal_api.py:upload_file():2771] upload_file response body: 
2024-05-21 10:26:42,718 ERROR   wandb-upload_2:1293572 [internal_api.py:upload_file():2767] upload_file exception https://storage.googleapis.com/wandb-production.appspot.com/1923354735/MonoGS/7i7f5gjm/output.log?Expires=1716344785&GoogleAccessId=gorilla-files-url-signer-man%40wandb-production.iam.gserviceaccount.com&Signature=VLoFH2QdZgsVeMSF7%2BZme2jkQEB5BuWJAxPRoHnj5FpmgAhWt%2BYchg0RqCx7PqoSN03WZ48TzcE1HZY%2Fag0rhCj1rwVp5EzKy%2FSKz%2B5KjD8scah61BdOHMmprbP8zg20%2FgV25YS8%2FOIlmG2G1EbWJ6NgRpjmbFhmC4WPPQ0LMaJ36bnQynJS%2Forxr6%2BpfjJ5SugurpujGl1HCP2FHd5qIGo5fc2oL7RxoOKTKhW02hzUUUoYzhY5fON9KtU4ixGYyAkLpKTUBhzVl%2Fr7rx7pzQJTS8e5gQ3loeJZJoh%2Fj4kHeCpLWmVRkb7VMOchgUDivO0he6tvugSp17daenhjLQ%3D%3D: HTTPSConnectionPool(host='storage.googleapis.com', port=443): Max retries exceeded with url: /wandb-production.appspot.com/1923354735/MonoGS/7i7f5gjm/output.log?Expires=1716344785&GoogleAccessId=gorilla-files-url-signer-man%40wandb-production.iam.gserviceaccount.com&Signature=VLoFH2QdZgsVeMSF7%2BZme2jkQEB5BuWJAxPRoHnj5FpmgAhWt%2BYchg0RqCx7PqoSN03WZ48TzcE1HZY%2Fag0rhCj1rwVp5EzKy%2FSKz%2B5KjD8scah61BdOHMmprbP8zg20%2FgV25YS8%2FOIlmG2G1EbWJ6NgRpjmbFhmC4WPPQ0LMaJ36bnQynJS%2Forxr6%2BpfjJ5SugurpujGl1HCP2FHd5qIGo5fc2oL7RxoOKTKhW02hzUUUoYzhY5fON9KtU4ixGYyAkLpKTUBhzVl%2Fr7rx7pzQJTS8e5gQ3loeJZJoh%2Fj4kHeCpLWmVRkb7VMOchgUDivO0he6tvugSp17daenhjLQ%3D%3D (Caused by NewConnectionError('<urllib3.connection.HTTPSConnection object at 0x7f6e8443da90>: Failed to establish a new connection: [Errno 111] Connection refused'))
2024-05-21 10:26:42,718 ERROR   wandb-upload_2:1293572 [internal_api.py:upload_file():2769] upload_file request headers: {'User-Agent': 'python-requests/2.31.0', 'Accept-Encoding': 'gzip, deflate, br', 'Accept': '*/*', 'Connection': 'keep-alive', 'Content-Length': '1015'}
2024-05-21 10:26:42,718 ERROR   wandb-upload_2:1293572 [internal_api.py:upload_file():2771] upload_file response body: 
2024-05-21 10:26:42,731 ERROR   wandb-upload_5:1293572 [internal_api.py:upload_file():2767] upload_file exception https://storage.googleapis.com/wandb-production.appspot.com/1923354735/MonoGS/7i7f5gjm/config.yaml?Expires=1716344785&GoogleAccessId=gorilla-files-url-signer-man%40wandb-production.iam.gserviceaccount.com&Signature=BMJwBO0b014Q1rvgox%2BYqw0pIWvynCGKcHXP81FuKhooGhVUhYqaVBmViVNciwVsqNKp%2BvW6awp8zq7bi9R7C1S9SMcftKvFNNZTi3MFZUocgiR6bDXJN6BK87FW4A4x3HBA3lUNs%2BWeyT07hWtUTpF3yauVUa0ysE7bU4lqzsHw6wjbYscL%2BUPwtsOABX2fk5Cq9c2xOXBjo76eTHr2dXmLEuUI2yZjhoAw9dyVlAaRkeS3kpnJCE3msbu06izwRBdLpfjl2PnIPuJW32O1U80Rm8bWPcZ5hnthAMzzOX3Junrz0ThnCdN67XHlY6kYXWb2tSdx4J%2BT7ulxfZmRPw%3D%3D: HTTPSConnectionPool(host='storage.googleapis.com', port=443): Max retries exceeded with url: /wandb-production.appspot.com/1923354735/MonoGS/7i7f5gjm/config.yaml?Expires=1716344785&GoogleAccessId=gorilla-files-url-signer-man%40wandb-production.iam.gserviceaccount.com&Signature=BMJwBO0b014Q1rvgox%2BYqw0pIWvynCGKcHXP81FuKhooGhVUhYqaVBmViVNciwVsqNKp%2BvW6awp8zq7bi9R7C1S9SMcftKvFNNZTi3MFZUocgiR6bDXJN6BK87FW4A4x3HBA3lUNs%2BWeyT07hWtUTpF3yauVUa0ysE7bU4lqzsHw6wjbYscL%2BUPwtsOABX2fk5Cq9c2xOXBjo76eTHr2dXmLEuUI2yZjhoAw9dyVlAaRkeS3kpnJCE3msbu06izwRBdLpfjl2PnIPuJW32O1U80Rm8bWPcZ5hnthAMzzOX3Junrz0ThnCdN67XHlY6kYXWb2tSdx4J%2BT7ulxfZmRPw%3D%3D (Caused by NewConnectionError('<urllib3.connection.HTTPSConnection object at 0x7f6e843b0810>: Failed to establish a new connection: [Errno 111] Connection refused'))
2024-05-21 10:26:42,731 ERROR   wandb-upload_5:1293572 [internal_api.py:upload_file():2769] upload_file request headers: {'User-Agent': 'python-requests/2.31.0', 'Accept-Encoding': 'gzip, deflate, br', 'Accept': '*/*', 'Connection': 'keep-alive', 'Content-Length': '2747'}
2024-05-21 10:26:42,731 ERROR   wandb-upload_5:1293572 [internal_api.py:upload_file():2771] upload_file response body: 
2024-05-21 10:26:42,745 ERROR   wandb-upload_3:1293572 [internal_api.py:upload_file():2767] upload_file exception https://storage.googleapis.com/wandb-production.appspot.com/1923354735/MonoGS/7i7f5gjm/requirements.txt?Expires=1716344785&GoogleAccessId=gorilla-files-url-signer-man%40wandb-production.iam.gserviceaccount.com&Signature=PUX7QA4OqH2opVL%2Be4xGiUyiSEcJKghhy2ZzJ0ADva78BQw5wvJXcgxmEJhDVPlLvZNtRuCTDz8V5b8xGLORRPLQOCVuu%2FJQrLuJ%2FLBwmKtWfURkzUEK4Bvp7hdQSXE9Bdo%2BIUELc%2FollYAUIR9cLuXGB4LcF3MbuEnRMsx0fmew59GnKSrUTM30OgPMe7XfvvyMYbcrsx0ad8QQYCZfT92VDfDcsSK9EkcnqibOKBeVz6c6NsG0mXNJy%2FjdmeikZD%2B0SnRLK%2B1DJ%2BM%2FD%2FM0HCIJyurX7%2BmrEqThDoVqPZ0dRfK4dmITQg3mu015FcX6P9lNVn6ovViNSvSU0t1JUA%3D%3D: HTTPSConnectionPool(host='storage.googleapis.com', port=443): Max retries exceeded with url: /wandb-production.appspot.com/1923354735/MonoGS/7i7f5gjm/requirements.txt?Expires=1716344785&GoogleAccessId=gorilla-files-url-signer-man%40wandb-production.iam.gserviceaccount.com&Signature=PUX7QA4OqH2opVL%2Be4xGiUyiSEcJKghhy2ZzJ0ADva78BQw5wvJXcgxmEJhDVPlLvZNtRuCTDz8V5b8xGLORRPLQOCVuu%2FJQrLuJ%2FLBwmKtWfURkzUEK4Bvp7hdQSXE9Bdo%2BIUELc%2FollYAUIR9cLuXGB4LcF3MbuEnRMsx0fmew59GnKSrUTM30OgPMe7XfvvyMYbcrsx0ad8QQYCZfT92VDfDcsSK9EkcnqibOKBeVz6c6NsG0mXNJy%2FjdmeikZD%2B0SnRLK%2B1DJ%2BM%2FD%2FM0HCIJyurX7%2BmrEqThDoVqPZ0dRfK4dmITQg3mu015FcX6P9lNVn6ovViNSvSU0t1JUA%3D%3D (Caused by NewConnectionError('<urllib3.connection.HTTPSConnection object at 0x7f6e843a8ad0>: Failed to establish a new connection: [Errno 111] Connection refused'))
2024-05-21 10:26:42,745 ERROR   wandb-upload_3:1293572 [internal_api.py:upload_file():2769] upload_file request headers: {'User-Agent': 'python-requests/2.31.0', 'Accept-Encoding': 'gzip, deflate, br', 'Accept': '*/*', 'Connection': 'keep-alive', 'Content-Length': '2267'}
2024-05-21 10:26:42,745 ERROR   wandb-upload_3:1293572 [internal_api.py:upload_file():2771] upload_file response body: 
2024-05-21 10:26:43,574 ERROR   wandb-upload_0:1293572 [internal_api.py:upload_file():2767] upload_file exception https://storage.googleapis.com/wandb-production.appspot.com/1923354735/MonoGS/7i7f5gjm/wandb-metadata.json?Expires=1716344732&GoogleAccessId=gorilla-files-url-signer-man%40wandb-production.iam.gserviceaccount.com&Signature=cDR3s4Btu8wUHMp7Bq8tJfPSneZs1lKn2s29OU2rf%2FQIynPqqnBm7KTt%2FUEbBkk02uPdYlSFQ9EV28DpKWGSjPzJUwI2lj6lzR%2FVCrCdrmNQF2B6LpGTVwfUfNo%2BgAMipws%2FssygMCuS0ObkO8Ckn4inWWTYBfrsEeAYuXXQ1MpkDWgrDTmFzIWIh7uhGxi5rRZGleTaZq3oxaGDid1%2FfSVTAKln9OgAsZRMb3CU44aJcHVk9lBYHWz9LI%2Fdrn9Se0ZlWbNUG9fX7iLx2N8X7pmCC2x1luKH8B87YHHaoGoUezsZnaVDfAWe31WtqGOpRQoXCjyFDeT%2FQZWmt8yRAA%3D%3D: HTTPSConnectionPool(host='storage.googleapis.com', port=443): Max retries exceeded with url: /wandb-production.appspot.com/1923354735/MonoGS/7i7f5gjm/wandb-metadata.json?Expires=1716344732&GoogleAccessId=gorilla-files-url-signer-man%40wandb-production.iam.gserviceaccount.com&Signature=cDR3s4Btu8wUHMp7Bq8tJfPSneZs1lKn2s29OU2rf%2FQIynPqqnBm7KTt%2FUEbBkk02uPdYlSFQ9EV28DpKWGSjPzJUwI2lj6lzR%2FVCrCdrmNQF2B6LpGTVwfUfNo%2BgAMipws%2FssygMCuS0ObkO8Ckn4inWWTYBfrsEeAYuXXQ1MpkDWgrDTmFzIWIh7uhGxi5rRZGleTaZq3oxaGDid1%2FfSVTAKln9OgAsZRMb3CU44aJcHVk9lBYHWz9LI%2Fdrn9Se0ZlWbNUG9fX7iLx2N8X7pmCC2x1luKH8B87YHHaoGoUezsZnaVDfAWe31WtqGOpRQoXCjyFDeT%2FQZWmt8yRAA%3D%3D (Caused by NewConnectionError('<urllib3.connection.HTTPSConnection object at 0x7f6e843935d0>: Failed to establish a new connection: [Errno 111] Connection refused'))
2024-05-21 10:26:43,574 ERROR   wandb-upload_0:1293572 [internal_api.py:upload_file():2769] upload_file request headers: {'User-Agent': 'python-requests/2.31.0', 'Accept-Encoding': 'gzip, deflate, br', 'Accept': '*/*', 'Connection': 'keep-alive', 'Content-Length': '3405'}
2024-05-21 10:26:43,574 ERROR   wandb-upload_0:1293572 [internal_api.py:upload_file():2771] upload_file response body: 
2024-05-21 10:26:57,625 ERROR   wandb-upload_1:1293572 [internal_api.py:upload_file():2767] upload_file exception https://storage.googleapis.com/wandb-production.appspot.com/1923354735/MonoGS/7i7f5gjm/wandb-summary.json?Expires=1716344785&GoogleAccessId=gorilla-files-url-signer-man%40wandb-production.iam.gserviceaccount.com&Signature=jeBYHZuazMllAswE5cCuYPIOXrsDk%2Fi%2Byxjsv9qWnxV%2BGNVzIHitPZSoDMj6MWk0TNlGqYZGlH4B%2BPF%2BhJiqKeqhL2OuOHBETtdtsiWdwH0tIXK1ZdLZnOfccEagnoMyHjd%2BI8iVtowEJcGh5WKQ7a4%2B47kjR3lcOIzwzXrjed270X%2FoNcanSDRgV8xNpf603zC1Vf1qsRhzc6BJ684LVu0rN5GfkVItbl5nymffb%2F%2B%2BzcjF%2BZLQmZ17RQ0QV7xUR7ur9fhcaGfCDFhLfuBOx%2BIisR%2BQ%2Bec%2BD9ldoKK0mB7eEItITzgUcPVBv2GxH5sqHE5OJHUsFgZ0AGP%2Fxp5TXQ%3D%3D: HTTPSConnectionPool(host='storage.googleapis.com', port=443): Max retries exceeded with url: /wandb-production.appspot.com/1923354735/MonoGS/7i7f5gjm/wandb-summary.json?Expires=1716344785&GoogleAccessId=gorilla-files-url-signer-man%40wandb-production.iam.gserviceaccount.com&Signature=jeBYHZuazMllAswE5cCuYPIOXrsDk%2Fi%2Byxjsv9qWnxV%2BGNVzIHitPZSoDMj6MWk0TNlGqYZGlH4B%2BPF%2BhJiqKeqhL2OuOHBETtdtsiWdwH0tIXK1ZdLZnOfccEagnoMyHjd%2BI8iVtowEJcGh5WKQ7a4%2B47kjR3lcOIzwzXrjed270X%2FoNcanSDRgV8xNpf603zC1Vf1qsRhzc6BJ684LVu0rN5GfkVItbl5nymffb%2F%2B%2BzcjF%2BZLQmZ17RQ0QV7xUR7ur9fhcaGfCDFhLfuBOx%2BIisR%2BQ%2Bec%2BD9ldoKK0mB7eEItITzgUcPVBv2GxH5sqHE5OJHUsFgZ0AGP%2Fxp5TXQ%3D%3D (Caused by NewConnectionError('<urllib3.connection.HTTPSConnection object at 0x7f6e843addd0>: Failed to establish a new connection: [Errno 111] Connection refused'))
2024-05-21 10:26:57,626 ERROR   wandb-upload_1:1293572 [internal_api.py:upload_file():2769] upload_file request headers: {'User-Agent': 'python-requests/2.31.0', 'Accept-Encoding': 'gzip, deflate, br', 'Accept': '*/*', 'Connection': 'keep-alive', 'Content-Length': '27'}
2024-05-21 10:26:57,626 ERROR   wandb-upload_1:1293572 [internal_api.py:upload_file():2771] upload_file response body: 
2024-05-21 10:27:00,108 ERROR   wandb-upload_5:1293572 [internal_api.py:upload_file():2767] upload_file exception https://storage.googleapis.com/wandb-production.appspot.com/1923354735/MonoGS/7i7f5gjm/config.yaml?Expires=1716344785&GoogleAccessId=gorilla-files-url-signer-man%40wandb-production.iam.gserviceaccount.com&Signature=BMJwBO0b014Q1rvgox%2BYqw0pIWvynCGKcHXP81FuKhooGhVUhYqaVBmViVNciwVsqNKp%2BvW6awp8zq7bi9R7C1S9SMcftKvFNNZTi3MFZUocgiR6bDXJN6BK87FW4A4x3HBA3lUNs%2BWeyT07hWtUTpF3yauVUa0ysE7bU4lqzsHw6wjbYscL%2BUPwtsOABX2fk5Cq9c2xOXBjo76eTHr2dXmLEuUI2yZjhoAw9dyVlAaRkeS3kpnJCE3msbu06izwRBdLpfjl2PnIPuJW32O1U80Rm8bWPcZ5hnthAMzzOX3Junrz0ThnCdN67XHlY6kYXWb2tSdx4J%2BT7ulxfZmRPw%3D%3D: HTTPSConnectionPool(host='storage.googleapis.com', port=443): Max retries exceeded with url: /wandb-production.appspot.com/1923354735/MonoGS/7i7f5gjm/config.yaml?Expires=1716344785&GoogleAccessId=gorilla-files-url-signer-man%40wandb-production.iam.gserviceaccount.com&Signature=BMJwBO0b014Q1rvgox%2BYqw0pIWvynCGKcHXP81FuKhooGhVUhYqaVBmViVNciwVsqNKp%2BvW6awp8zq7bi9R7C1S9SMcftKvFNNZTi3MFZUocgiR6bDXJN6BK87FW4A4x3HBA3lUNs%2BWeyT07hWtUTpF3yauVUa0ysE7bU4lqzsHw6wjbYscL%2BUPwtsOABX2fk5Cq9c2xOXBjo76eTHr2dXmLEuUI2yZjhoAw9dyVlAaRkeS3kpnJCE3msbu06izwRBdLpfjl2PnIPuJW32O1U80Rm8bWPcZ5hnthAMzzOX3Junrz0ThnCdN67XHlY6kYXWb2tSdx4J%2BT7ulxfZmRPw%3D%3D (Caused by NewConnectionError('<urllib3.connection.HTTPSConnection object at 0x7f6e8438e9d0>: Failed to establish a new connection: [Errno 111] Connection refused'))
2024-05-21 10:27:00,108 ERROR   wandb-upload_5:1293572 [internal_api.py:upload_file():2769] upload_file request headers: {'User-Agent': 'python-requests/2.31.0', 'Accept-Encoding': 'gzip, deflate, br', 'Accept': '*/*', 'Connection': 'keep-alive', 'Content-Length': '2747'}
2024-05-21 10:27:00,108 ERROR   wandb-upload_5:1293572 [internal_api.py:upload_file():2771] upload_file response body: 
2024-05-21 10:27:00,189 ERROR   wandb-upload_2:1293572 [internal_api.py:upload_file():2767] upload_file exception https://storage.googleapis.com/wandb-production.appspot.com/1923354735/MonoGS/7i7f5gjm/output.log?Expires=1716344785&GoogleAccessId=gorilla-files-url-signer-man%40wandb-production.iam.gserviceaccount.com&Signature=VLoFH2QdZgsVeMSF7%2BZme2jkQEB5BuWJAxPRoHnj5FpmgAhWt%2BYchg0RqCx7PqoSN03WZ48TzcE1HZY%2Fag0rhCj1rwVp5EzKy%2FSKz%2B5KjD8scah61BdOHMmprbP8zg20%2FgV25YS8%2FOIlmG2G1EbWJ6NgRpjmbFhmC4WPPQ0LMaJ36bnQynJS%2Forxr6%2BpfjJ5SugurpujGl1HCP2FHd5qIGo5fc2oL7RxoOKTKhW02hzUUUoYzhY5fON9KtU4ixGYyAkLpKTUBhzVl%2Fr7rx7pzQJTS8e5gQ3loeJZJoh%2Fj4kHeCpLWmVRkb7VMOchgUDivO0he6tvugSp17daenhjLQ%3D%3D: HTTPSConnectionPool(host='storage.googleapis.com', port=443): Max retries exceeded with url: /wandb-production.appspot.com/1923354735/MonoGS/7i7f5gjm/output.log?Expires=1716344785&GoogleAccessId=gorilla-files-url-signer-man%40wandb-production.iam.gserviceaccount.com&Signature=VLoFH2QdZgsVeMSF7%2BZme2jkQEB5BuWJAxPRoHnj5FpmgAhWt%2BYchg0RqCx7PqoSN03WZ48TzcE1HZY%2Fag0rhCj1rwVp5EzKy%2FSKz%2B5KjD8scah61BdOHMmprbP8zg20%2FgV25YS8%2FOIlmG2G1EbWJ6NgRpjmbFhmC4WPPQ0LMaJ36bnQynJS%2Forxr6%2BpfjJ5SugurpujGl1HCP2FHd5qIGo5fc2oL7RxoOKTKhW02hzUUUoYzhY5fON9KtU4ixGYyAkLpKTUBhzVl%2Fr7rx7pzQJTS8e5gQ3loeJZJoh%2Fj4kHeCpLWmVRkb7VMOchgUDivO0he6tvugSp17daenhjLQ%3D%3D (Caused by NewConnectionError('<urllib3.connection.HTTPSConnection object at 0x7f6e8438e710>: Failed to establish a new connection: [Errno 111] Connection refused'))
2024-05-21 10:27:00,189 ERROR   wandb-upload_2:1293572 [internal_api.py:upload_file():2769] upload_file request headers: {'User-Agent': 'python-requests/2.31.0', 'Accept-Encoding': 'gzip, deflate, br', 'Accept': '*/*', 'Connection': 'keep-alive', 'Content-Length': '1015'}
2024-05-21 10:27:00,189 ERROR   wandb-upload_2:1293572 [internal_api.py:upload_file():2771] upload_file response body: 
2024-05-21 10:27:01,504 ERROR   wandb-upload_4:1293572 [internal_api.py:upload_file():2767] upload_file exception https://storage.googleapis.com/wandb-production.appspot.com/1923354735/MonoGS/7i7f5gjm/conda-environment.yaml?Expires=1716344785&GoogleAccessId=gorilla-files-url-signer-man%40wandb-production.iam.gserviceaccount.com&Signature=EVDYObbaalBfRuHPuIIs4NJTCdppmKpHxAnNLjdSe1QDN6a6hLjmiC11aQSD4qP%2FLgPOBp45zUTn6TBcUhpaHqlZNygjhiEZX7Ca6B8klTArywRWcGYmvUpGy7O%2BleSulQSIXobSwqU%2BnRTR07PRCuNcBPTnbqW4CuC37R8fHKLlfmAI1UHGfP2sI%2BlboaOgAd5r%2BM%2FcJppRU2DfKWKWnp6t7v4yZJja%2BYwr7UjygyGHX5lL9hp2spsgl904SnGzFL7U%2FmLKAckP6yFEIZwTv6OhtL0G4DCGbJCOtPnMRFsrapLi2lTX5L4uZH%2Fmk1S6S69x4FC7L5%2Bpmj6gh7nsiA%3D%3D: HTTPSConnectionPool(host='storage.googleapis.com', port=443): Max retries exceeded with url: /wandb-production.appspot.com/1923354735/MonoGS/7i7f5gjm/conda-environment.yaml?Expires=1716344785&GoogleAccessId=gorilla-files-url-signer-man%40wandb-production.iam.gserviceaccount.com&Signature=EVDYObbaalBfRuHPuIIs4NJTCdppmKpHxAnNLjdSe1QDN6a6hLjmiC11aQSD4qP%2FLgPOBp45zUTn6TBcUhpaHqlZNygjhiEZX7Ca6B8klTArywRWcGYmvUpGy7O%2BleSulQSIXobSwqU%2BnRTR07PRCuNcBPTnbqW4CuC37R8fHKLlfmAI1UHGfP2sI%2BlboaOgAd5r%2BM%2FcJppRU2DfKWKWnp6t7v4yZJja%2BYwr7UjygyGHX5lL9hp2spsgl904SnGzFL7U%2FmLKAckP6yFEIZwTv6OhtL0G4DCGbJCOtPnMRFsrapLi2lTX5L4uZH%2Fmk1S6S69x4FC7L5%2Bpmj6gh7nsiA%3D%3D (Caused by NewConnectionError('<urllib3.connection.HTTPSConnection object at 0x7f6e843a3cd0>: Failed to establish a new connection: [Errno 111] Connection refused'))
2024-05-21 10:27:01,504 ERROR   wandb-upload_4:1293572 [internal_api.py:upload_file():2769] upload_file request headers: {'User-Agent': 'python-requests/2.31.0', 'Accept-Encoding': 'gzip, deflate, br', 'Accept': '*/*', 'Connection': 'keep-alive', 'Content-Length': '4690'}
2024-05-21 10:27:01,505 ERROR   wandb-upload_4:1293572 [internal_api.py:upload_file():2771] upload_file response body: 
2024-05-21 10:27:02,437 ERROR   wandb-upload_3:1293572 [internal_api.py:upload_file():2767] upload_file exception https://storage.googleapis.com/wandb-production.appspot.com/1923354735/MonoGS/7i7f5gjm/requirements.txt?Expires=1716344785&GoogleAccessId=gorilla-files-url-signer-man%40wandb-production.iam.gserviceaccount.com&Signature=PUX7QA4OqH2opVL%2Be4xGiUyiSEcJKghhy2ZzJ0ADva78BQw5wvJXcgxmEJhDVPlLvZNtRuCTDz8V5b8xGLORRPLQOCVuu%2FJQrLuJ%2FLBwmKtWfURkzUEK4Bvp7hdQSXE9Bdo%2BIUELc%2FollYAUIR9cLuXGB4LcF3MbuEnRMsx0fmew59GnKSrUTM30OgPMe7XfvvyMYbcrsx0ad8QQYCZfT92VDfDcsSK9EkcnqibOKBeVz6c6NsG0mXNJy%2FjdmeikZD%2B0SnRLK%2B1DJ%2BM%2FD%2FM0HCIJyurX7%2BmrEqThDoVqPZ0dRfK4dmITQg3mu015FcX6P9lNVn6ovViNSvSU0t1JUA%3D%3D: HTTPSConnectionPool(host='storage.googleapis.com', port=443): Max retries exceeded with url: /wandb-production.appspot.com/1923354735/MonoGS/7i7f5gjm/requirements.txt?Expires=1716344785&GoogleAccessId=gorilla-files-url-signer-man%40wandb-production.iam.gserviceaccount.com&Signature=PUX7QA4OqH2opVL%2Be4xGiUyiSEcJKghhy2ZzJ0ADva78BQw5wvJXcgxmEJhDVPlLvZNtRuCTDz8V5b8xGLORRPLQOCVuu%2FJQrLuJ%2FLBwmKtWfURkzUEK4Bvp7hdQSXE9Bdo%2BIUELc%2FollYAUIR9cLuXGB4LcF3MbuEnRMsx0fmew59GnKSrUTM30OgPMe7XfvvyMYbcrsx0ad8QQYCZfT92VDfDcsSK9EkcnqibOKBeVz6c6NsG0mXNJy%2FjdmeikZD%2B0SnRLK%2B1DJ%2BM%2FD%2FM0HCIJyurX7%2BmrEqThDoVqPZ0dRfK4dmITQg3mu015FcX6P9lNVn6ovViNSvSU0t1JUA%3D%3D (Caused by NewConnectionError('<urllib3.connection.HTTPSConnection object at 0x7f6e84395b10>: Failed to establish a new connection: [Errno 111] Connection refused'))
2024-05-21 10:27:02,438 ERROR   wandb-upload_3:1293572 [internal_api.py:upload_file():2769] upload_file request headers: {'User-Agent': 'python-requests/2.31.0', 'Accept-Encoding': 'gzip, deflate, br', 'Accept': '*/*', 'Connection': 'keep-alive', 'Content-Length': '2267'}
2024-05-21 10:27:02,438 ERROR   wandb-upload_3:1293572 [internal_api.py:upload_file():2771] upload_file response body: 
2024-05-21 10:27:35,015 ERROR   wandb-upload_4:1293572 [internal_api.py:upload_file():2767] upload_file exception https://storage.googleapis.com/wandb-production.appspot.com/1923354735/MonoGS/7i7f5gjm/conda-environment.yaml?Expires=1716344785&GoogleAccessId=gorilla-files-url-signer-man%40wandb-production.iam.gserviceaccount.com&Signature=EVDYObbaalBfRuHPuIIs4NJTCdppmKpHxAnNLjdSe1QDN6a6hLjmiC11aQSD4qP%2FLgPOBp45zUTn6TBcUhpaHqlZNygjhiEZX7Ca6B8klTArywRWcGYmvUpGy7O%2BleSulQSIXobSwqU%2BnRTR07PRCuNcBPTnbqW4CuC37R8fHKLlfmAI1UHGfP2sI%2BlboaOgAd5r%2BM%2FcJppRU2DfKWKWnp6t7v4yZJja%2BYwr7UjygyGHX5lL9hp2spsgl904SnGzFL7U%2FmLKAckP6yFEIZwTv6OhtL0G4DCGbJCOtPnMRFsrapLi2lTX5L4uZH%2Fmk1S6S69x4FC7L5%2Bpmj6gh7nsiA%3D%3D: HTTPSConnectionPool(host='storage.googleapis.com', port=443): Max retries exceeded with url: /wandb-production.appspot.com/1923354735/MonoGS/7i7f5gjm/conda-environment.yaml?Expires=1716344785&GoogleAccessId=gorilla-files-url-signer-man%40wandb-production.iam.gserviceaccount.com&Signature=EVDYObbaalBfRuHPuIIs4NJTCdppmKpHxAnNLjdSe1QDN6a6hLjmiC11aQSD4qP%2FLgPOBp45zUTn6TBcUhpaHqlZNygjhiEZX7Ca6B8klTArywRWcGYmvUpGy7O%2BleSulQSIXobSwqU%2BnRTR07PRCuNcBPTnbqW4CuC37R8fHKLlfmAI1UHGfP2sI%2BlboaOgAd5r%2BM%2FcJppRU2DfKWKWnp6t7v4yZJja%2BYwr7UjygyGHX5lL9hp2spsgl904SnGzFL7U%2FmLKAckP6yFEIZwTv6OhtL0G4DCGbJCOtPnMRFsrapLi2lTX5L4uZH%2Fmk1S6S69x4FC7L5%2Bpmj6gh7nsiA%3D%3D (Caused by NewConnectionError('<urllib3.connection.HTTPSConnection object at 0x7f6e843957d0>: Failed to establish a new connection: [Errno 111] Connection refused'))
2024-05-21 10:27:35,015 ERROR   wandb-upload_4:1293572 [internal_api.py:upload_file():2769] upload_file request headers: {'User-Agent': 'python-requests/2.31.0', 'Accept-Encoding': 'gzip, deflate, br', 'Accept': '*/*', 'Connection': 'keep-alive', 'Content-Length': '4690'}
2024-05-21 10:27:35,016 ERROR   wandb-upload_4:1293572 [internal_api.py:upload_file():2771] upload_file response body: 
2024-05-21 10:27:35,254 ERROR   wandb-upload_3:1293572 [internal_api.py:upload_file():2767] upload_file exception https://storage.googleapis.com/wandb-production.appspot.com/1923354735/MonoGS/7i7f5gjm/requirements.txt?Expires=1716344785&GoogleAccessId=gorilla-files-url-signer-man%40wandb-production.iam.gserviceaccount.com&Signature=PUX7QA4OqH2opVL%2Be4xGiUyiSEcJKghhy2ZzJ0ADva78BQw5wvJXcgxmEJhDVPlLvZNtRuCTDz8V5b8xGLORRPLQOCVuu%2FJQrLuJ%2FLBwmKtWfURkzUEK4Bvp7hdQSXE9Bdo%2BIUELc%2FollYAUIR9cLuXGB4LcF3MbuEnRMsx0fmew59GnKSrUTM30OgPMe7XfvvyMYbcrsx0ad8QQYCZfT92VDfDcsSK9EkcnqibOKBeVz6c6NsG0mXNJy%2FjdmeikZD%2B0SnRLK%2B1DJ%2BM%2FD%2FM0HCIJyurX7%2BmrEqThDoVqPZ0dRfK4dmITQg3mu015FcX6P9lNVn6ovViNSvSU0t1JUA%3D%3D: HTTPSConnectionPool(host='storage.googleapis.com', port=443): Max retries exceeded with url: /wandb-production.appspot.com/1923354735/MonoGS/7i7f5gjm/requirements.txt?Expires=1716344785&GoogleAccessId=gorilla-files-url-signer-man%40wandb-production.iam.gserviceaccount.com&Signature=PUX7QA4OqH2opVL%2Be4xGiUyiSEcJKghhy2ZzJ0ADva78BQw5wvJXcgxmEJhDVPlLvZNtRuCTDz8V5b8xGLORRPLQOCVuu%2FJQrLuJ%2FLBwmKtWfURkzUEK4Bvp7hdQSXE9Bdo%2BIUELc%2FollYAUIR9cLuXGB4LcF3MbuEnRMsx0fmew59GnKSrUTM30OgPMe7XfvvyMYbcrsx0ad8QQYCZfT92VDfDcsSK9EkcnqibOKBeVz6c6NsG0mXNJy%2FjdmeikZD%2B0SnRLK%2B1DJ%2BM%2FD%2FM0HCIJyurX7%2BmrEqThDoVqPZ0dRfK4dmITQg3mu015FcX6P9lNVn6ovViNSvSU0t1JUA%3D%3D (Caused by NewConnectionError('<urllib3.connection.HTTPSConnection object at 0x7f6e843a3a90>: Failed to establish a new connection: [Errno 111] Connection refused'))
2024-05-21 10:27:35,254 ERROR   wandb-upload_3:1293572 [internal_api.py:upload_file():2769] upload_file request headers: {'User-Agent': 'python-requests/2.31.0', 'Accept-Encoding': 'gzip, deflate, br', 'Accept': '*/*', 'Connection': 'keep-alive', 'Content-Length': '2267'}
2024-05-21 10:27:35,254 ERROR   wandb-upload_3:1293572 [internal_api.py:upload_file():2771] upload_file response body: 
2024-05-21 10:27:35,447 ERROR   wandb-upload_5:1293572 [internal_api.py:upload_file():2767] upload_file exception https://storage.googleapis.com/wandb-production.appspot.com/1923354735/MonoGS/7i7f5gjm/config.yaml?Expires=1716344785&GoogleAccessId=gorilla-files-url-signer-man%40wandb-production.iam.gserviceaccount.com&Signature=BMJwBO0b014Q1rvgox%2BYqw0pIWvynCGKcHXP81FuKhooGhVUhYqaVBmViVNciwVsqNKp%2BvW6awp8zq7bi9R7C1S9SMcftKvFNNZTi3MFZUocgiR6bDXJN6BK87FW4A4x3HBA3lUNs%2BWeyT07hWtUTpF3yauVUa0ysE7bU4lqzsHw6wjbYscL%2BUPwtsOABX2fk5Cq9c2xOXBjo76eTHr2dXmLEuUI2yZjhoAw9dyVlAaRkeS3kpnJCE3msbu06izwRBdLpfjl2PnIPuJW32O1U80Rm8bWPcZ5hnthAMzzOX3Junrz0ThnCdN67XHlY6kYXWb2tSdx4J%2BT7ulxfZmRPw%3D%3D: HTTPSConnectionPool(host='storage.googleapis.com', port=443): Max retries exceeded with url: /wandb-production.appspot.com/1923354735/MonoGS/7i7f5gjm/config.yaml?Expires=1716344785&GoogleAccessId=gorilla-files-url-signer-man%40wandb-production.iam.gserviceaccount.com&Signature=BMJwBO0b014Q1rvgox%2BYqw0pIWvynCGKcHXP81FuKhooGhVUhYqaVBmViVNciwVsqNKp%2BvW6awp8zq7bi9R7C1S9SMcftKvFNNZTi3MFZUocgiR6bDXJN6BK87FW4A4x3HBA3lUNs%2BWeyT07hWtUTpF3yauVUa0ysE7bU4lqzsHw6wjbYscL%2BUPwtsOABX2fk5Cq9c2xOXBjo76eTHr2dXmLEuUI2yZjhoAw9dyVlAaRkeS3kpnJCE3msbu06izwRBdLpfjl2PnIPuJW32O1U80Rm8bWPcZ5hnthAMzzOX3Junrz0ThnCdN67XHlY6kYXWb2tSdx4J%2BT7ulxfZmRPw%3D%3D (Caused by NewConnectionError('<urllib3.connection.HTTPSConnection object at 0x7f6e8438e550>: Failed to establish a new connection: [Errno 111] Connection refused'))
2024-05-21 10:27:35,447 ERROR   wandb-upload_5:1293572 [internal_api.py:upload_file():2769] upload_file request headers: {'User-Agent': 'python-requests/2.31.0', 'Accept-Encoding': 'gzip, deflate, br', 'Accept': '*/*', 'Connection': 'keep-alive', 'Content-Length': '2747'}
2024-05-21 10:27:35,447 ERROR   wandb-upload_5:1293572 [internal_api.py:upload_file():2771] upload_file response body: 
2024-05-21 10:27:35,599 ERROR   wandb-upload_1:1293572 [internal_api.py:upload_file():2767] upload_file exception https://storage.googleapis.com/wandb-production.appspot.com/1923354735/MonoGS/7i7f5gjm/wandb-summary.json?Expires=1716344785&GoogleAccessId=gorilla-files-url-signer-man%40wandb-production.iam.gserviceaccount.com&Signature=jeBYHZuazMllAswE5cCuYPIOXrsDk%2Fi%2Byxjsv9qWnxV%2BGNVzIHitPZSoDMj6MWk0TNlGqYZGlH4B%2BPF%2BhJiqKeqhL2OuOHBETtdtsiWdwH0tIXK1ZdLZnOfccEagnoMyHjd%2BI8iVtowEJcGh5WKQ7a4%2B47kjR3lcOIzwzXrjed270X%2FoNcanSDRgV8xNpf603zC1Vf1qsRhzc6BJ684LVu0rN5GfkVItbl5nymffb%2F%2B%2BzcjF%2BZLQmZ17RQ0QV7xUR7ur9fhcaGfCDFhLfuBOx%2BIisR%2BQ%2Bec%2BD9ldoKK0mB7eEItITzgUcPVBv2GxH5sqHE5OJHUsFgZ0AGP%2Fxp5TXQ%3D%3D: HTTPSConnectionPool(host='storage.googleapis.com', port=443): Max retries exceeded with url: /wandb-production.appspot.com/1923354735/MonoGS/7i7f5gjm/wandb-summary.json?Expires=1716344785&GoogleAccessId=gorilla-files-url-signer-man%40wandb-production.iam.gserviceaccount.com&Signature=jeBYHZuazMllAswE5cCuYPIOXrsDk%2Fi%2Byxjsv9qWnxV%2BGNVzIHitPZSoDMj6MWk0TNlGqYZGlH4B%2BPF%2BhJiqKeqhL2OuOHBETtdtsiWdwH0tIXK1ZdLZnOfccEagnoMyHjd%2BI8iVtowEJcGh5WKQ7a4%2B47kjR3lcOIzwzXrjed270X%2FoNcanSDRgV8xNpf603zC1Vf1qsRhzc6BJ684LVu0rN5GfkVItbl5nymffb%2F%2B%2BzcjF%2BZLQmZ17RQ0QV7xUR7ur9fhcaGfCDFhLfuBOx%2BIisR%2BQ%2Bec%2BD9ldoKK0mB7eEItITzgUcPVBv2GxH5sqHE5OJHUsFgZ0AGP%2Fxp5TXQ%3D%3D (Caused by NewConnectionError('<urllib3.connection.HTTPSConnection object at 0x7f6e8438e150>: Failed to establish a new connection: [Errno 111] Connection refused'))
2024-05-21 10:27:35,599 ERROR   wandb-upload_1:1293572 [internal_api.py:upload_file():2769] upload_file request headers: {'User-Agent': 'python-requests/2.31.0', 'Accept-Encoding': 'gzip, deflate, br', 'Accept': '*/*', 'Connection': 'keep-alive', 'Content-Length': '27'}
2024-05-21 10:27:35,599 ERROR   wandb-upload_1:1293572 [internal_api.py:upload_file():2771] upload_file response body: 
2024-05-21 10:27:39,832 ERROR   wandb-upload_2:1293572 [internal_api.py:upload_file():2767] upload_file exception https://storage.googleapis.com/wandb-production.appspot.com/1923354735/MonoGS/7i7f5gjm/output.log?Expires=1716344785&GoogleAccessId=gorilla-files-url-signer-man%40wandb-production.iam.gserviceaccount.com&Signature=VLoFH2QdZgsVeMSF7%2BZme2jkQEB5BuWJAxPRoHnj5FpmgAhWt%2BYchg0RqCx7PqoSN03WZ48TzcE1HZY%2Fag0rhCj1rwVp5EzKy%2FSKz%2B5KjD8scah61BdOHMmprbP8zg20%2FgV25YS8%2FOIlmG2G1EbWJ6NgRpjmbFhmC4WPPQ0LMaJ36bnQynJS%2Forxr6%2BpfjJ5SugurpujGl1HCP2FHd5qIGo5fc2oL7RxoOKTKhW02hzUUUoYzhY5fON9KtU4ixGYyAkLpKTUBhzVl%2Fr7rx7pzQJTS8e5gQ3loeJZJoh%2Fj4kHeCpLWmVRkb7VMOchgUDivO0he6tvugSp17daenhjLQ%3D%3D: HTTPSConnectionPool(host='storage.googleapis.com', port=443): Max retries exceeded with url: /wandb-production.appspot.com/1923354735/MonoGS/7i7f5gjm/output.log?Expires=1716344785&GoogleAccessId=gorilla-files-url-signer-man%40wandb-production.iam.gserviceaccount.com&Signature=VLoFH2QdZgsVeMSF7%2BZme2jkQEB5BuWJAxPRoHnj5FpmgAhWt%2BYchg0RqCx7PqoSN03WZ48TzcE1HZY%2Fag0rhCj1rwVp5EzKy%2FSKz%2B5KjD8scah61BdOHMmprbP8zg20%2FgV25YS8%2FOIlmG2G1EbWJ6NgRpjmbFhmC4WPPQ0LMaJ36bnQynJS%2Forxr6%2BpfjJ5SugurpujGl1HCP2FHd5qIGo5fc2oL7RxoOKTKhW02hzUUUoYzhY5fON9KtU4ixGYyAkLpKTUBhzVl%2Fr7rx7pzQJTS8e5gQ3loeJZJoh%2Fj4kHeCpLWmVRkb7VMOchgUDivO0he6tvugSp17daenhjLQ%3D%3D (Caused by NewConnectionError('<urllib3.connection.HTTPSConnection object at 0x7f6e843ad350>: Failed to establish a new connection: [Errno 111] Connection refused'))
2024-05-21 10:27:39,832 ERROR   wandb-upload_2:1293572 [internal_api.py:upload_file():2769] upload_file request headers: {'User-Agent': 'python-requests/2.31.0', 'Accept-Encoding': 'gzip, deflate, br', 'Accept': '*/*', 'Connection': 'keep-alive', 'Content-Length': '1015'}
2024-05-21 10:27:39,832 ERROR   wandb-upload_2:1293572 [internal_api.py:upload_file():2771] upload_file response body: 
2024-05-21 10:27:58,699 ERROR   wandb-upload_0:1293572 [internal_api.py:upload_file():2767] upload_file exception https://storage.googleapis.com/wandb-production.appspot.com/1923354735/MonoGS/7i7f5gjm/wandb-metadata.json?Expires=1716344732&GoogleAccessId=gorilla-files-url-signer-man%40wandb-production.iam.gserviceaccount.com&Signature=cDR3s4Btu8wUHMp7Bq8tJfPSneZs1lKn2s29OU2rf%2FQIynPqqnBm7KTt%2FUEbBkk02uPdYlSFQ9EV28DpKWGSjPzJUwI2lj6lzR%2FVCrCdrmNQF2B6LpGTVwfUfNo%2BgAMipws%2FssygMCuS0ObkO8Ckn4inWWTYBfrsEeAYuXXQ1MpkDWgrDTmFzIWIh7uhGxi5rRZGleTaZq3oxaGDid1%2FfSVTAKln9OgAsZRMb3CU44aJcHVk9lBYHWz9LI%2Fdrn9Se0ZlWbNUG9fX7iLx2N8X7pmCC2x1luKH8B87YHHaoGoUezsZnaVDfAWe31WtqGOpRQoXCjyFDeT%2FQZWmt8yRAA%3D%3D: HTTPSConnectionPool(host='storage.googleapis.com', port=443): Max retries exceeded with url: /wandb-production.appspot.com/1923354735/MonoGS/7i7f5gjm/wandb-metadata.json?Expires=1716344732&GoogleAccessId=gorilla-files-url-signer-man%40wandb-production.iam.gserviceaccount.com&Signature=cDR3s4Btu8wUHMp7Bq8tJfPSneZs1lKn2s29OU2rf%2FQIynPqqnBm7KTt%2FUEbBkk02uPdYlSFQ9EV28DpKWGSjPzJUwI2lj6lzR%2FVCrCdrmNQF2B6LpGTVwfUfNo%2BgAMipws%2FssygMCuS0ObkO8Ckn4inWWTYBfrsEeAYuXXQ1MpkDWgrDTmFzIWIh7uhGxi5rRZGleTaZq3oxaGDid1%2FfSVTAKln9OgAsZRMb3CU44aJcHVk9lBYHWz9LI%2Fdrn9Se0ZlWbNUG9fX7iLx2N8X7pmCC2x1luKH8B87YHHaoGoUezsZnaVDfAWe31WtqGOpRQoXCjyFDeT%2FQZWmt8yRAA%3D%3D (Caused by NewConnectionError('<urllib3.connection.HTTPSConnection object at 0x7f6e84393990>: Failed to establish a new connection: [Errno 111] Connection refused'))
2024-05-21 10:27:58,699 ERROR   wandb-upload_0:1293572 [internal_api.py:upload_file():2769] upload_file request headers: {'User-Agent': 'python-requests/2.31.0', 'Accept-Encoding': 'gzip, deflate, br', 'Accept': '*/*', 'Connection': 'keep-alive', 'Content-Length': '3405'}
2024-05-21 10:27:58,699 ERROR   wandb-upload_0:1293572 [internal_api.py:upload_file():2771] upload_file response body: 
2024-05-21 10:28:44,903 ERROR   wandb-upload_4:1293572 [internal_api.py:upload_file():2767] upload_file exception https://storage.googleapis.com/wandb-production.appspot.com/1923354735/MonoGS/7i7f5gjm/conda-environment.yaml?Expires=1716344785&GoogleAccessId=gorilla-files-url-signer-man%40wandb-production.iam.gserviceaccount.com&Signature=EVDYObbaalBfRuHPuIIs4NJTCdppmKpHxAnNLjdSe1QDN6a6hLjmiC11aQSD4qP%2FLgPOBp45zUTn6TBcUhpaHqlZNygjhiEZX7Ca6B8klTArywRWcGYmvUpGy7O%2BleSulQSIXobSwqU%2BnRTR07PRCuNcBPTnbqW4CuC37R8fHKLlfmAI1UHGfP2sI%2BlboaOgAd5r%2BM%2FcJppRU2DfKWKWnp6t7v4yZJja%2BYwr7UjygyGHX5lL9hp2spsgl904SnGzFL7U%2FmLKAckP6yFEIZwTv6OhtL0G4DCGbJCOtPnMRFsrapLi2lTX5L4uZH%2Fmk1S6S69x4FC7L5%2Bpmj6gh7nsiA%3D%3D: HTTPSConnectionPool(host='storage.googleapis.com', port=443): Max retries exceeded with url: /wandb-production.appspot.com/1923354735/MonoGS/7i7f5gjm/conda-environment.yaml?Expires=1716344785&GoogleAccessId=gorilla-files-url-signer-man%40wandb-production.iam.gserviceaccount.com&Signature=EVDYObbaalBfRuHPuIIs4NJTCdppmKpHxAnNLjdSe1QDN6a6hLjmiC11aQSD4qP%2FLgPOBp45zUTn6TBcUhpaHqlZNygjhiEZX7Ca6B8klTArywRWcGYmvUpGy7O%2BleSulQSIXobSwqU%2BnRTR07PRCuNcBPTnbqW4CuC37R8fHKLlfmAI1UHGfP2sI%2BlboaOgAd5r%2BM%2FcJppRU2DfKWKWnp6t7v4yZJja%2BYwr7UjygyGHX5lL9hp2spsgl904SnGzFL7U%2FmLKAckP6yFEIZwTv6OhtL0G4DCGbJCOtPnMRFsrapLi2lTX5L4uZH%2Fmk1S6S69x4FC7L5%2Bpmj6gh7nsiA%3D%3D (Caused by NewConnectionError('<urllib3.connection.HTTPSConnection object at 0x7f6e843a8690>: Failed to establish a new connection: [Errno 111] Connection refused'))
2024-05-21 10:28:44,903 ERROR   wandb-upload_4:1293572 [internal_api.py:upload_file():2769] upload_file request headers: {'User-Agent': 'python-requests/2.31.0', 'Accept-Encoding': 'gzip, deflate, br', 'Accept': '*/*', 'Connection': 'keep-alive', 'Content-Length': '4690'}
2024-05-21 10:28:44,903 ERROR   wandb-upload_4:1293572 [internal_api.py:upload_file():2771] upload_file response body: 
2024-05-21 10:28:45,571 ERROR   wandb-upload_1:1293572 [internal_api.py:upload_file():2767] upload_file exception https://storage.googleapis.com/wandb-production.appspot.com/1923354735/MonoGS/7i7f5gjm/wandb-summary.json?Expires=1716344785&GoogleAccessId=gorilla-files-url-signer-man%40wandb-production.iam.gserviceaccount.com&Signature=jeBYHZuazMllAswE5cCuYPIOXrsDk%2Fi%2Byxjsv9qWnxV%2BGNVzIHitPZSoDMj6MWk0TNlGqYZGlH4B%2BPF%2BhJiqKeqhL2OuOHBETtdtsiWdwH0tIXK1ZdLZnOfccEagnoMyHjd%2BI8iVtowEJcGh5WKQ7a4%2B47kjR3lcOIzwzXrjed270X%2FoNcanSDRgV8xNpf603zC1Vf1qsRhzc6BJ684LVu0rN5GfkVItbl5nymffb%2F%2B%2BzcjF%2BZLQmZ17RQ0QV7xUR7ur9fhcaGfCDFhLfuBOx%2BIisR%2BQ%2Bec%2BD9ldoKK0mB7eEItITzgUcPVBv2GxH5sqHE5OJHUsFgZ0AGP%2Fxp5TXQ%3D%3D: HTTPSConnectionPool(host='storage.googleapis.com', port=443): Max retries exceeded with url: /wandb-production.appspot.com/1923354735/MonoGS/7i7f5gjm/wandb-summary.json?Expires=1716344785&GoogleAccessId=gorilla-files-url-signer-man%40wandb-production.iam.gserviceaccount.com&Signature=jeBYHZuazMllAswE5cCuYPIOXrsDk%2Fi%2Byxjsv9qWnxV%2BGNVzIHitPZSoDMj6MWk0TNlGqYZGlH4B%2BPF%2BhJiqKeqhL2OuOHBETtdtsiWdwH0tIXK1ZdLZnOfccEagnoMyHjd%2BI8iVtowEJcGh5WKQ7a4%2B47kjR3lcOIzwzXrjed270X%2FoNcanSDRgV8xNpf603zC1Vf1qsRhzc6BJ684LVu0rN5GfkVItbl5nymffb%2F%2B%2BzcjF%2BZLQmZ17RQ0QV7xUR7ur9fhcaGfCDFhLfuBOx%2BIisR%2BQ%2Bec%2BD9ldoKK0mB7eEItITzgUcPVBv2GxH5sqHE5OJHUsFgZ0AGP%2Fxp5TXQ%3D%3D (Caused by NewConnectionError('<urllib3.connection.HTTPSConnection object at 0x7f6e843b0450>: Failed to establish a new connection: [Errno 111] Connection refused'))
2024-05-21 10:28:45,571 ERROR   wandb-upload_1:1293572 [internal_api.py:upload_file():2769] upload_file request headers: {'User-Agent': 'python-requests/2.31.0', 'Accept-Encoding': 'gzip, deflate, br', 'Accept': '*/*', 'Connection': 'keep-alive', 'Content-Length': '27'}
2024-05-21 10:28:45,571 ERROR   wandb-upload_1:1293572 [internal_api.py:upload_file():2771] upload_file response body: 
2024-05-21 10:28:47,688 ERROR   wandb-upload_5:1293572 [internal_api.py:upload_file():2767] upload_file exception https://storage.googleapis.com/wandb-production.appspot.com/1923354735/MonoGS/7i7f5gjm/config.yaml?Expires=1716344785&GoogleAccessId=gorilla-files-url-signer-man%40wandb-production.iam.gserviceaccount.com&Signature=BMJwBO0b014Q1rvgox%2BYqw0pIWvynCGKcHXP81FuKhooGhVUhYqaVBmViVNciwVsqNKp%2BvW6awp8zq7bi9R7C1S9SMcftKvFNNZTi3MFZUocgiR6bDXJN6BK87FW4A4x3HBA3lUNs%2BWeyT07hWtUTpF3yauVUa0ysE7bU4lqzsHw6wjbYscL%2BUPwtsOABX2fk5Cq9c2xOXBjo76eTHr2dXmLEuUI2yZjhoAw9dyVlAaRkeS3kpnJCE3msbu06izwRBdLpfjl2PnIPuJW32O1U80Rm8bWPcZ5hnthAMzzOX3Junrz0ThnCdN67XHlY6kYXWb2tSdx4J%2BT7ulxfZmRPw%3D%3D: HTTPSConnectionPool(host='storage.googleapis.com', port=443): Max retries exceeded with url: /wandb-production.appspot.com/1923354735/MonoGS/7i7f5gjm/config.yaml?Expires=1716344785&GoogleAccessId=gorilla-files-url-signer-man%40wandb-production.iam.gserviceaccount.com&Signature=BMJwBO0b014Q1rvgox%2BYqw0pIWvynCGKcHXP81FuKhooGhVUhYqaVBmViVNciwVsqNKp%2BvW6awp8zq7bi9R7C1S9SMcftKvFNNZTi3MFZUocgiR6bDXJN6BK87FW4A4x3HBA3lUNs%2BWeyT07hWtUTpF3yauVUa0ysE7bU4lqzsHw6wjbYscL%2BUPwtsOABX2fk5Cq9c2xOXBjo76eTHr2dXmLEuUI2yZjhoAw9dyVlAaRkeS3kpnJCE3msbu06izwRBdLpfjl2PnIPuJW32O1U80Rm8bWPcZ5hnthAMzzOX3Junrz0ThnCdN67XHlY6kYXWb2tSdx4J%2BT7ulxfZmRPw%3D%3D (Caused by NewConnectionError('<urllib3.connection.HTTPSConnection object at 0x7f6e8443d1d0>: Failed to establish a new connection: [Errno 111] Connection refused'))
2024-05-21 10:28:47,688 ERROR   wandb-upload_5:1293572 [internal_api.py:upload_file():2769] upload_file request headers: {'User-Agent': 'python-requests/2.31.0', 'Accept-Encoding': 'gzip, deflate, br', 'Accept': '*/*', 'Connection': 'keep-alive', 'Content-Length': '2747'}
2024-05-21 10:28:47,688 ERROR   wandb-upload_5:1293572 [internal_api.py:upload_file():2771] upload_file response body: 
2024-05-21 10:28:51,821 ERROR   wandb-upload_2:1293572 [internal_api.py:upload_file():2767] upload_file exception https://storage.googleapis.com/wandb-production.appspot.com/1923354735/MonoGS/7i7f5gjm/output.log?Expires=1716344785&GoogleAccessId=gorilla-files-url-signer-man%40wandb-production.iam.gserviceaccount.com&Signature=VLoFH2QdZgsVeMSF7%2BZme2jkQEB5BuWJAxPRoHnj5FpmgAhWt%2BYchg0RqCx7PqoSN03WZ48TzcE1HZY%2Fag0rhCj1rwVp5EzKy%2FSKz%2B5KjD8scah61BdOHMmprbP8zg20%2FgV25YS8%2FOIlmG2G1EbWJ6NgRpjmbFhmC4WPPQ0LMaJ36bnQynJS%2Forxr6%2BpfjJ5SugurpujGl1HCP2FHd5qIGo5fc2oL7RxoOKTKhW02hzUUUoYzhY5fON9KtU4ixGYyAkLpKTUBhzVl%2Fr7rx7pzQJTS8e5gQ3loeJZJoh%2Fj4kHeCpLWmVRkb7VMOchgUDivO0he6tvugSp17daenhjLQ%3D%3D: HTTPSConnectionPool(host='storage.googleapis.com', port=443): Max retries exceeded with url: /wandb-production.appspot.com/1923354735/MonoGS/7i7f5gjm/output.log?Expires=1716344785&GoogleAccessId=gorilla-files-url-signer-man%40wandb-production.iam.gserviceaccount.com&Signature=VLoFH2QdZgsVeMSF7%2BZme2jkQEB5BuWJAxPRoHnj5FpmgAhWt%2BYchg0RqCx7PqoSN03WZ48TzcE1HZY%2Fag0rhCj1rwVp5EzKy%2FSKz%2B5KjD8scah61BdOHMmprbP8zg20%2FgV25YS8%2FOIlmG2G1EbWJ6NgRpjmbFhmC4WPPQ0LMaJ36bnQynJS%2Forxr6%2BpfjJ5SugurpujGl1HCP2FHd5qIGo5fc2oL7RxoOKTKhW02hzUUUoYzhY5fON9KtU4ixGYyAkLpKTUBhzVl%2Fr7rx7pzQJTS8e5gQ3loeJZJoh%2Fj4kHeCpLWmVRkb7VMOchgUDivO0he6tvugSp17daenhjLQ%3D%3D (Caused by NewConnectionError('<urllib3.connection.HTTPSConnection object at 0x7f6e8443f8d0>: Failed to establish a new connection: [Errno 111] Connection refused'))
2024-05-21 10:28:51,821 ERROR   wandb-upload_2:1293572 [internal_api.py:upload_file():2769] upload_file request headers: {'User-Agent': 'python-requests/2.31.0', 'Accept-Encoding': 'gzip, deflate, br', 'Accept': '*/*', 'Connection': 'keep-alive', 'Content-Length': '1015'}
2024-05-21 10:28:51,821 ERROR   wandb-upload_2:1293572 [internal_api.py:upload_file():2771] upload_file response body: 
2024-05-21 10:28:52,960 ERROR   wandb-upload_3:1293572 [internal_api.py:upload_file():2767] upload_file exception https://storage.googleapis.com/wandb-production.appspot.com/1923354735/MonoGS/7i7f5gjm/requirements.txt?Expires=1716344785&GoogleAccessId=gorilla-files-url-signer-man%40wandb-production.iam.gserviceaccount.com&Signature=PUX7QA4OqH2opVL%2Be4xGiUyiSEcJKghhy2ZzJ0ADva78BQw5wvJXcgxmEJhDVPlLvZNtRuCTDz8V5b8xGLORRPLQOCVuu%2FJQrLuJ%2FLBwmKtWfURkzUEK4Bvp7hdQSXE9Bdo%2BIUELc%2FollYAUIR9cLuXGB4LcF3MbuEnRMsx0fmew59GnKSrUTM30OgPMe7XfvvyMYbcrsx0ad8QQYCZfT92VDfDcsSK9EkcnqibOKBeVz6c6NsG0mXNJy%2FjdmeikZD%2B0SnRLK%2B1DJ%2BM%2FD%2FM0HCIJyurX7%2BmrEqThDoVqPZ0dRfK4dmITQg3mu015FcX6P9lNVn6ovViNSvSU0t1JUA%3D%3D: HTTPSConnectionPool(host='storage.googleapis.com', port=443): Max retries exceeded with url: /wandb-production.appspot.com/1923354735/MonoGS/7i7f5gjm/requirements.txt?Expires=1716344785&GoogleAccessId=gorilla-files-url-signer-man%40wandb-production.iam.gserviceaccount.com&Signature=PUX7QA4OqH2opVL%2Be4xGiUyiSEcJKghhy2ZzJ0ADva78BQw5wvJXcgxmEJhDVPlLvZNtRuCTDz8V5b8xGLORRPLQOCVuu%2FJQrLuJ%2FLBwmKtWfURkzUEK4Bvp7hdQSXE9Bdo%2BIUELc%2FollYAUIR9cLuXGB4LcF3MbuEnRMsx0fmew59GnKSrUTM30OgPMe7XfvvyMYbcrsx0ad8QQYCZfT92VDfDcsSK9EkcnqibOKBeVz6c6NsG0mXNJy%2FjdmeikZD%2B0SnRLK%2B1DJ%2BM%2FD%2FM0HCIJyurX7%2BmrEqThDoVqPZ0dRfK4dmITQg3mu015FcX6P9lNVn6ovViNSvSU0t1JUA%3D%3D (Caused by NewConnectionError('<urllib3.connection.HTTPSConnection object at 0x7f6e8443da90>: Failed to establish a new connection: [Errno 111] Connection refused'))
2024-05-21 10:28:52,960 ERROR   wandb-upload_3:1293572 [internal_api.py:upload_file():2769] upload_file request headers: {'User-Agent': 'python-requests/2.31.0', 'Accept-Encoding': 'gzip, deflate, br', 'Accept': '*/*', 'Connection': 'keep-alive', 'Content-Length': '2267'}
2024-05-21 10:28:52,960 ERROR   wandb-upload_3:1293572 [internal_api.py:upload_file():2771] upload_file response body: 
2024-05-21 10:30:09,845 ERROR   wandb-upload_0:1293572 [internal_api.py:upload_file():2767] upload_file exception https://storage.googleapis.com/wandb-production.appspot.com/1923354735/MonoGS/7i7f5gjm/wandb-metadata.json?Expires=1716344732&GoogleAccessId=gorilla-files-url-signer-man%40wandb-production.iam.gserviceaccount.com&Signature=cDR3s4Btu8wUHMp7Bq8tJfPSneZs1lKn2s29OU2rf%2FQIynPqqnBm7KTt%2FUEbBkk02uPdYlSFQ9EV28DpKWGSjPzJUwI2lj6lzR%2FVCrCdrmNQF2B6LpGTVwfUfNo%2BgAMipws%2FssygMCuS0ObkO8Ckn4inWWTYBfrsEeAYuXXQ1MpkDWgrDTmFzIWIh7uhGxi5rRZGleTaZq3oxaGDid1%2FfSVTAKln9OgAsZRMb3CU44aJcHVk9lBYHWz9LI%2Fdrn9Se0ZlWbNUG9fX7iLx2N8X7pmCC2x1luKH8B87YHHaoGoUezsZnaVDfAWe31WtqGOpRQoXCjyFDeT%2FQZWmt8yRAA%3D%3D: HTTPSConnectionPool(host='storage.googleapis.com', port=443): Max retries exceeded with url: /wandb-production.appspot.com/1923354735/MonoGS/7i7f5gjm/wandb-metadata.json?Expires=1716344732&GoogleAccessId=gorilla-files-url-signer-man%40wandb-production.iam.gserviceaccount.com&Signature=cDR3s4Btu8wUHMp7Bq8tJfPSneZs1lKn2s29OU2rf%2FQIynPqqnBm7KTt%2FUEbBkk02uPdYlSFQ9EV28DpKWGSjPzJUwI2lj6lzR%2FVCrCdrmNQF2B6LpGTVwfUfNo%2BgAMipws%2FssygMCuS0ObkO8Ckn4inWWTYBfrsEeAYuXXQ1MpkDWgrDTmFzIWIh7uhGxi5rRZGleTaZq3oxaGDid1%2FfSVTAKln9OgAsZRMb3CU44aJcHVk9lBYHWz9LI%2Fdrn9Se0ZlWbNUG9fX7iLx2N8X7pmCC2x1luKH8B87YHHaoGoUezsZnaVDfAWe31WtqGOpRQoXCjyFDeT%2FQZWmt8yRAA%3D%3D (Caused by NewConnectionError('<urllib3.connection.HTTPSConnection object at 0x7f6e843a80d0>: Failed to establish a new connection: [Errno 111] Connection refused'))
2024-05-21 10:30:09,845 ERROR   wandb-upload_0:1293572 [internal_api.py:upload_file():2769] upload_file request headers: {'User-Agent': 'python-requests/2.31.0', 'Accept-Encoding': 'gzip, deflate, br', 'Accept': '*/*', 'Connection': 'keep-alive', 'Content-Length': '3405'}
2024-05-21 10:30:09,845 ERROR   wandb-upload_0:1293572 [internal_api.py:upload_file():2771] upload_file response body: 
2024-05-21 10:31:02,820 ERROR   wandb-upload_1:1293572 [internal_api.py:upload_file():2767] upload_file exception https://storage.googleapis.com/wandb-production.appspot.com/1923354735/MonoGS/7i7f5gjm/wandb-summary.json?Expires=1716344785&GoogleAccessId=gorilla-files-url-signer-man%40wandb-production.iam.gserviceaccount.com&Signature=jeBYHZuazMllAswE5cCuYPIOXrsDk%2Fi%2Byxjsv9qWnxV%2BGNVzIHitPZSoDMj6MWk0TNlGqYZGlH4B%2BPF%2BhJiqKeqhL2OuOHBETtdtsiWdwH0tIXK1ZdLZnOfccEagnoMyHjd%2BI8iVtowEJcGh5WKQ7a4%2B47kjR3lcOIzwzXrjed270X%2FoNcanSDRgV8xNpf603zC1Vf1qsRhzc6BJ684LVu0rN5GfkVItbl5nymffb%2F%2B%2BzcjF%2BZLQmZ17RQ0QV7xUR7ur9fhcaGfCDFhLfuBOx%2BIisR%2BQ%2Bec%2BD9ldoKK0mB7eEItITzgUcPVBv2GxH5sqHE5OJHUsFgZ0AGP%2Fxp5TXQ%3D%3D: HTTPSConnectionPool(host='storage.googleapis.com', port=443): Max retries exceeded with url: /wandb-production.appspot.com/1923354735/MonoGS/7i7f5gjm/wandb-summary.json?Expires=1716344785&GoogleAccessId=gorilla-files-url-signer-man%40wandb-production.iam.gserviceaccount.com&Signature=jeBYHZuazMllAswE5cCuYPIOXrsDk%2Fi%2Byxjsv9qWnxV%2BGNVzIHitPZSoDMj6MWk0TNlGqYZGlH4B%2BPF%2BhJiqKeqhL2OuOHBETtdtsiWdwH0tIXK1ZdLZnOfccEagnoMyHjd%2BI8iVtowEJcGh5WKQ7a4%2B47kjR3lcOIzwzXrjed270X%2FoNcanSDRgV8xNpf603zC1Vf1qsRhzc6BJ684LVu0rN5GfkVItbl5nymffb%2F%2B%2BzcjF%2BZLQmZ17RQ0QV7xUR7ur9fhcaGfCDFhLfuBOx%2BIisR%2BQ%2Bec%2BD9ldoKK0mB7eEItITzgUcPVBv2GxH5sqHE5OJHUsFgZ0AGP%2Fxp5TXQ%3D%3D (Caused by NewConnectionError('<urllib3.connection.HTTPSConnection object at 0x7f6e843a83d0>: Failed to establish a new connection: [Errno 111] Connection refused'))
2024-05-21 10:31:02,820 ERROR   wandb-upload_1:1293572 [internal_api.py:upload_file():2769] upload_file request headers: {'User-Agent': 'python-requests/2.31.0', 'Accept-Encoding': 'gzip, deflate, br', 'Accept': '*/*', 'Connection': 'keep-alive', 'Content-Length': '27'}
2024-05-21 10:31:02,820 ERROR   wandb-upload_1:1293572 [internal_api.py:upload_file():2771] upload_file response body: 
2024-05-21 10:31:03,111 ERROR   wandb-upload_2:1293572 [internal_api.py:upload_file():2767] upload_file exception https://storage.googleapis.com/wandb-production.appspot.com/1923354735/MonoGS/7i7f5gjm/output.log?Expires=1716344785&GoogleAccessId=gorilla-files-url-signer-man%40wandb-production.iam.gserviceaccount.com&Signature=VLoFH2QdZgsVeMSF7%2BZme2jkQEB5BuWJAxPRoHnj5FpmgAhWt%2BYchg0RqCx7PqoSN03WZ48TzcE1HZY%2Fag0rhCj1rwVp5EzKy%2FSKz%2B5KjD8scah61BdOHMmprbP8zg20%2FgV25YS8%2FOIlmG2G1EbWJ6NgRpjmbFhmC4WPPQ0LMaJ36bnQynJS%2Forxr6%2BpfjJ5SugurpujGl1HCP2FHd5qIGo5fc2oL7RxoOKTKhW02hzUUUoYzhY5fON9KtU4ixGYyAkLpKTUBhzVl%2Fr7rx7pzQJTS8e5gQ3loeJZJoh%2Fj4kHeCpLWmVRkb7VMOchgUDivO0he6tvugSp17daenhjLQ%3D%3D: HTTPSConnectionPool(host='storage.googleapis.com', port=443): Max retries exceeded with url: /wandb-production.appspot.com/1923354735/MonoGS/7i7f5gjm/output.log?Expires=1716344785&GoogleAccessId=gorilla-files-url-signer-man%40wandb-production.iam.gserviceaccount.com&Signature=VLoFH2QdZgsVeMSF7%2BZme2jkQEB5BuWJAxPRoHnj5FpmgAhWt%2BYchg0RqCx7PqoSN03WZ48TzcE1HZY%2Fag0rhCj1rwVp5EzKy%2FSKz%2B5KjD8scah61BdOHMmprbP8zg20%2FgV25YS8%2FOIlmG2G1EbWJ6NgRpjmbFhmC4WPPQ0LMaJ36bnQynJS%2Forxr6%2BpfjJ5SugurpujGl1HCP2FHd5qIGo5fc2oL7RxoOKTKhW02hzUUUoYzhY5fON9KtU4ixGYyAkLpKTUBhzVl%2Fr7rx7pzQJTS8e5gQ3loeJZJoh%2Fj4kHeCpLWmVRkb7VMOchgUDivO0he6tvugSp17daenhjLQ%3D%3D (Caused by NewConnectionError('<urllib3.connection.HTTPSConnection object at 0x7f6e843adb50>: Failed to establish a new connection: [Errno 111] Connection refused'))
2024-05-21 10:31:03,111 ERROR   wandb-upload_2:1293572 [internal_api.py:upload_file():2769] upload_file request headers: {'User-Agent': 'python-requests/2.31.0', 'Accept-Encoding': 'gzip, deflate, br', 'Accept': '*/*', 'Connection': 'keep-alive', 'Content-Length': '1015'}
2024-05-21 10:31:03,111 ERROR   wandb-upload_2:1293572 [internal_api.py:upload_file():2771] upload_file response body: 
2024-05-21 10:31:08,875 ERROR   wandb-upload_4:1293572 [internal_api.py:upload_file():2767] upload_file exception https://storage.googleapis.com/wandb-production.appspot.com/1923354735/MonoGS/7i7f5gjm/conda-environment.yaml?Expires=1716344785&GoogleAccessId=gorilla-files-url-signer-man%40wandb-production.iam.gserviceaccount.com&Signature=EVDYObbaalBfRuHPuIIs4NJTCdppmKpHxAnNLjdSe1QDN6a6hLjmiC11aQSD4qP%2FLgPOBp45zUTn6TBcUhpaHqlZNygjhiEZX7Ca6B8klTArywRWcGYmvUpGy7O%2BleSulQSIXobSwqU%2BnRTR07PRCuNcBPTnbqW4CuC37R8fHKLlfmAI1UHGfP2sI%2BlboaOgAd5r%2BM%2FcJppRU2DfKWKWnp6t7v4yZJja%2BYwr7UjygyGHX5lL9hp2spsgl904SnGzFL7U%2FmLKAckP6yFEIZwTv6OhtL0G4DCGbJCOtPnMRFsrapLi2lTX5L4uZH%2Fmk1S6S69x4FC7L5%2Bpmj6gh7nsiA%3D%3D: HTTPSConnectionPool(host='storage.googleapis.com', port=443): Max retries exceeded with url: /wandb-production.appspot.com/1923354735/MonoGS/7i7f5gjm/conda-environment.yaml?Expires=1716344785&GoogleAccessId=gorilla-files-url-signer-man%40wandb-production.iam.gserviceaccount.com&Signature=EVDYObbaalBfRuHPuIIs4NJTCdppmKpHxAnNLjdSe1QDN6a6hLjmiC11aQSD4qP%2FLgPOBp45zUTn6TBcUhpaHqlZNygjhiEZX7Ca6B8klTArywRWcGYmvUpGy7O%2BleSulQSIXobSwqU%2BnRTR07PRCuNcBPTnbqW4CuC37R8fHKLlfmAI1UHGfP2sI%2BlboaOgAd5r%2BM%2FcJppRU2DfKWKWnp6t7v4yZJja%2BYwr7UjygyGHX5lL9hp2spsgl904SnGzFL7U%2FmLKAckP6yFEIZwTv6OhtL0G4DCGbJCOtPnMRFsrapLi2lTX5L4uZH%2Fmk1S6S69x4FC7L5%2Bpmj6gh7nsiA%3D%3D (Caused by NewConnectionError('<urllib3.connection.HTTPSConnection object at 0x7f6e8438e310>: Failed to establish a new connection: [Errno 111] Connection refused'))
2024-05-21 10:31:08,875 ERROR   wandb-upload_4:1293572 [internal_api.py:upload_file():2769] upload_file request headers: {'User-Agent': 'python-requests/2.31.0', 'Accept-Encoding': 'gzip, deflate, br', 'Accept': '*/*', 'Connection': 'keep-alive', 'Content-Length': '4690'}
2024-05-21 10:31:08,875 ERROR   wandb-upload_4:1293572 [internal_api.py:upload_file():2771] upload_file response body: 
2024-05-21 10:31:16,900 ERROR   wandb-upload_5:1293572 [internal_api.py:upload_file():2767] upload_file exception https://storage.googleapis.com/wandb-production.appspot.com/1923354735/MonoGS/7i7f5gjm/config.yaml?Expires=1716344785&GoogleAccessId=gorilla-files-url-signer-man%40wandb-production.iam.gserviceaccount.com&Signature=BMJwBO0b014Q1rvgox%2BYqw0pIWvynCGKcHXP81FuKhooGhVUhYqaVBmViVNciwVsqNKp%2BvW6awp8zq7bi9R7C1S9SMcftKvFNNZTi3MFZUocgiR6bDXJN6BK87FW4A4x3HBA3lUNs%2BWeyT07hWtUTpF3yauVUa0ysE7bU4lqzsHw6wjbYscL%2BUPwtsOABX2fk5Cq9c2xOXBjo76eTHr2dXmLEuUI2yZjhoAw9dyVlAaRkeS3kpnJCE3msbu06izwRBdLpfjl2PnIPuJW32O1U80Rm8bWPcZ5hnthAMzzOX3Junrz0ThnCdN67XHlY6kYXWb2tSdx4J%2BT7ulxfZmRPw%3D%3D: HTTPSConnectionPool(host='storage.googleapis.com', port=443): Max retries exceeded with url: /wandb-production.appspot.com/1923354735/MonoGS/7i7f5gjm/config.yaml?Expires=1716344785&GoogleAccessId=gorilla-files-url-signer-man%40wandb-production.iam.gserviceaccount.com&Signature=BMJwBO0b014Q1rvgox%2BYqw0pIWvynCGKcHXP81FuKhooGhVUhYqaVBmViVNciwVsqNKp%2BvW6awp8zq7bi9R7C1S9SMcftKvFNNZTi3MFZUocgiR6bDXJN6BK87FW4A4x3HBA3lUNs%2BWeyT07hWtUTpF3yauVUa0ysE7bU4lqzsHw6wjbYscL%2BUPwtsOABX2fk5Cq9c2xOXBjo76eTHr2dXmLEuUI2yZjhoAw9dyVlAaRkeS3kpnJCE3msbu06izwRBdLpfjl2PnIPuJW32O1U80Rm8bWPcZ5hnthAMzzOX3Junrz0ThnCdN67XHlY6kYXWb2tSdx4J%2BT7ulxfZmRPw%3D%3D (Caused by NewConnectionError('<urllib3.connection.HTTPSConnection object at 0x7f6e843a3290>: Failed to establish a new connection: [Errno 111] Connection refused'))
2024-05-21 10:31:16,901 ERROR   wandb-upload_5:1293572 [internal_api.py:upload_file():2769] upload_file request headers: {'User-Agent': 'python-requests/2.31.0', 'Accept-Encoding': 'gzip, deflate, br', 'Accept': '*/*', 'Connection': 'keep-alive', 'Content-Length': '2747'}
2024-05-21 10:31:16,901 ERROR   wandb-upload_5:1293572 [internal_api.py:upload_file():2771] upload_file response body: 
2024-05-21 10:31:26,293 ERROR   wandb-upload_3:1293572 [internal_api.py:upload_file():2767] upload_file exception https://storage.googleapis.com/wandb-production.appspot.com/1923354735/MonoGS/7i7f5gjm/requirements.txt?Expires=1716344785&GoogleAccessId=gorilla-files-url-signer-man%40wandb-production.iam.gserviceaccount.com&Signature=PUX7QA4OqH2opVL%2Be4xGiUyiSEcJKghhy2ZzJ0ADva78BQw5wvJXcgxmEJhDVPlLvZNtRuCTDz8V5b8xGLORRPLQOCVuu%2FJQrLuJ%2FLBwmKtWfURkzUEK4Bvp7hdQSXE9Bdo%2BIUELc%2FollYAUIR9cLuXGB4LcF3MbuEnRMsx0fmew59GnKSrUTM30OgPMe7XfvvyMYbcrsx0ad8QQYCZfT92VDfDcsSK9EkcnqibOKBeVz6c6NsG0mXNJy%2FjdmeikZD%2B0SnRLK%2B1DJ%2BM%2FD%2FM0HCIJyurX7%2BmrEqThDoVqPZ0dRfK4dmITQg3mu015FcX6P9lNVn6ovViNSvSU0t1JUA%3D%3D: HTTPSConnectionPool(host='storage.googleapis.com', port=443): Max retries exceeded with url: /wandb-production.appspot.com/1923354735/MonoGS/7i7f5gjm/requirements.txt?Expires=1716344785&GoogleAccessId=gorilla-files-url-signer-man%40wandb-production.iam.gserviceaccount.com&Signature=PUX7QA4OqH2opVL%2Be4xGiUyiSEcJKghhy2ZzJ0ADva78BQw5wvJXcgxmEJhDVPlLvZNtRuCTDz8V5b8xGLORRPLQOCVuu%2FJQrLuJ%2FLBwmKtWfURkzUEK4Bvp7hdQSXE9Bdo%2BIUELc%2FollYAUIR9cLuXGB4LcF3MbuEnRMsx0fmew59GnKSrUTM30OgPMe7XfvvyMYbcrsx0ad8QQYCZfT92VDfDcsSK9EkcnqibOKBeVz6c6NsG0mXNJy%2FjdmeikZD%2B0SnRLK%2B1DJ%2BM%2FD%2FM0HCIJyurX7%2BmrEqThDoVqPZ0dRfK4dmITQg3mu015FcX6P9lNVn6ovViNSvSU0t1JUA%3D%3D (Caused by NewConnectionError('<urllib3.connection.HTTPSConnection object at 0x7f6e843a3e50>: Failed to establish a new connection: [Errno 111] Connection refused'))
2024-05-21 10:31:26,294 ERROR   wandb-upload_3:1293572 [internal_api.py:upload_file():2769] upload_file request headers: {'User-Agent': 'python-requests/2.31.0', 'Accept-Encoding': 'gzip, deflate, br', 'Accept': '*/*', 'Connection': 'keep-alive', 'Content-Length': '2267'}
2024-05-21 10:31:26,294 ERROR   wandb-upload_3:1293572 [internal_api.py:upload_file():2771] upload_file response body: 
2024-05-21 10:34:57,855 ERROR   wandb-upload_0:1293572 [internal_api.py:upload_file():2767] upload_file exception https://storage.googleapis.com/wandb-production.appspot.com/1923354735/MonoGS/7i7f5gjm/wandb-metadata.json?Expires=1716344732&GoogleAccessId=gorilla-files-url-signer-man%40wandb-production.iam.gserviceaccount.com&Signature=cDR3s4Btu8wUHMp7Bq8tJfPSneZs1lKn2s29OU2rf%2FQIynPqqnBm7KTt%2FUEbBkk02uPdYlSFQ9EV28DpKWGSjPzJUwI2lj6lzR%2FVCrCdrmNQF2B6LpGTVwfUfNo%2BgAMipws%2FssygMCuS0ObkO8Ckn4inWWTYBfrsEeAYuXXQ1MpkDWgrDTmFzIWIh7uhGxi5rRZGleTaZq3oxaGDid1%2FfSVTAKln9OgAsZRMb3CU44aJcHVk9lBYHWz9LI%2Fdrn9Se0ZlWbNUG9fX7iLx2N8X7pmCC2x1luKH8B87YHHaoGoUezsZnaVDfAWe31WtqGOpRQoXCjyFDeT%2FQZWmt8yRAA%3D%3D: HTTPSConnectionPool(host='storage.googleapis.com', port=443): Max retries exceeded with url: /wandb-production.appspot.com/1923354735/MonoGS/7i7f5gjm/wandb-metadata.json?Expires=1716344732&GoogleAccessId=gorilla-files-url-signer-man%40wandb-production.iam.gserviceaccount.com&Signature=cDR3s4Btu8wUHMp7Bq8tJfPSneZs1lKn2s29OU2rf%2FQIynPqqnBm7KTt%2FUEbBkk02uPdYlSFQ9EV28DpKWGSjPzJUwI2lj6lzR%2FVCrCdrmNQF2B6LpGTVwfUfNo%2BgAMipws%2FssygMCuS0ObkO8Ckn4inWWTYBfrsEeAYuXXQ1MpkDWgrDTmFzIWIh7uhGxi5rRZGleTaZq3oxaGDid1%2FfSVTAKln9OgAsZRMb3CU44aJcHVk9lBYHWz9LI%2Fdrn9Se0ZlWbNUG9fX7iLx2N8X7pmCC2x1luKH8B87YHHaoGoUezsZnaVDfAWe31WtqGOpRQoXCjyFDeT%2FQZWmt8yRAA%3D%3D (Caused by NewConnectionError('<urllib3.connection.HTTPSConnection object at 0x7f6e8443f7d0>: Failed to establish a new connection: [Errno 111] Connection refused'))
2024-05-21 10:34:57,855 ERROR   wandb-upload_0:1293572 [internal_api.py:upload_file():2769] upload_file request headers: {'User-Agent': 'python-requests/2.31.0', 'Accept-Encoding': 'gzip, deflate, br', 'Accept': '*/*', 'Connection': 'keep-alive', 'Content-Length': '3405'}
2024-05-21 10:34:57,855 ERROR   wandb-upload_0:1293572 [internal_api.py:upload_file():2771] upload_file response body: 
2024-05-21 10:35:36,096 ERROR   wandb-upload_4:1293572 [internal_api.py:upload_file():2767] upload_file exception https://storage.googleapis.com/wandb-production.appspot.com/1923354735/MonoGS/7i7f5gjm/conda-environment.yaml?Expires=1716344785&GoogleAccessId=gorilla-files-url-signer-man%40wandb-production.iam.gserviceaccount.com&Signature=EVDYObbaalBfRuHPuIIs4NJTCdppmKpHxAnNLjdSe1QDN6a6hLjmiC11aQSD4qP%2FLgPOBp45zUTn6TBcUhpaHqlZNygjhiEZX7Ca6B8klTArywRWcGYmvUpGy7O%2BleSulQSIXobSwqU%2BnRTR07PRCuNcBPTnbqW4CuC37R8fHKLlfmAI1UHGfP2sI%2BlboaOgAd5r%2BM%2FcJppRU2DfKWKWnp6t7v4yZJja%2BYwr7UjygyGHX5lL9hp2spsgl904SnGzFL7U%2FmLKAckP6yFEIZwTv6OhtL0G4DCGbJCOtPnMRFsrapLi2lTX5L4uZH%2Fmk1S6S69x4FC7L5%2Bpmj6gh7nsiA%3D%3D: HTTPSConnectionPool(host='storage.googleapis.com', port=443): Max retries exceeded with url: /wandb-production.appspot.com/1923354735/MonoGS/7i7f5gjm/conda-environment.yaml?Expires=1716344785&GoogleAccessId=gorilla-files-url-signer-man%40wandb-production.iam.gserviceaccount.com&Signature=EVDYObbaalBfRuHPuIIs4NJTCdppmKpHxAnNLjdSe1QDN6a6hLjmiC11aQSD4qP%2FLgPOBp45zUTn6TBcUhpaHqlZNygjhiEZX7Ca6B8klTArywRWcGYmvUpGy7O%2BleSulQSIXobSwqU%2BnRTR07PRCuNcBPTnbqW4CuC37R8fHKLlfmAI1UHGfP2sI%2BlboaOgAd5r%2BM%2FcJppRU2DfKWKWnp6t7v4yZJja%2BYwr7UjygyGHX5lL9hp2spsgl904SnGzFL7U%2FmLKAckP6yFEIZwTv6OhtL0G4DCGbJCOtPnMRFsrapLi2lTX5L4uZH%2Fmk1S6S69x4FC7L5%2Bpmj6gh7nsiA%3D%3D (Caused by NewConnectionError('<urllib3.connection.HTTPSConnection object at 0x7f6e84551f10>: Failed to establish a new connection: [Errno 111] Connection refused'))
2024-05-21 10:35:36,096 ERROR   wandb-upload_4:1293572 [internal_api.py:upload_file():2769] upload_file request headers: {'User-Agent': 'python-requests/2.31.0', 'Accept-Encoding': 'gzip, deflate, br', 'Accept': '*/*', 'Connection': 'keep-alive', 'Content-Length': '4690'}
2024-05-21 10:35:36,096 ERROR   wandb-upload_4:1293572 [internal_api.py:upload_file():2771] upload_file response body: 
2024-05-21 10:35:49,667 ERROR   wandb-upload_2:1293572 [internal_api.py:upload_file():2767] upload_file exception https://storage.googleapis.com/wandb-production.appspot.com/1923354735/MonoGS/7i7f5gjm/output.log?Expires=1716344785&GoogleAccessId=gorilla-files-url-signer-man%40wandb-production.iam.gserviceaccount.com&Signature=VLoFH2QdZgsVeMSF7%2BZme2jkQEB5BuWJAxPRoHnj5FpmgAhWt%2BYchg0RqCx7PqoSN03WZ48TzcE1HZY%2Fag0rhCj1rwVp5EzKy%2FSKz%2B5KjD8scah61BdOHMmprbP8zg20%2FgV25YS8%2FOIlmG2G1EbWJ6NgRpjmbFhmC4WPPQ0LMaJ36bnQynJS%2Forxr6%2BpfjJ5SugurpujGl1HCP2FHd5qIGo5fc2oL7RxoOKTKhW02hzUUUoYzhY5fON9KtU4ixGYyAkLpKTUBhzVl%2Fr7rx7pzQJTS8e5gQ3loeJZJoh%2Fj4kHeCpLWmVRkb7VMOchgUDivO0he6tvugSp17daenhjLQ%3D%3D: HTTPSConnectionPool(host='storage.googleapis.com', port=443): Max retries exceeded with url: /wandb-production.appspot.com/1923354735/MonoGS/7i7f5gjm/output.log?Expires=1716344785&GoogleAccessId=gorilla-files-url-signer-man%40wandb-production.iam.gserviceaccount.com&Signature=VLoFH2QdZgsVeMSF7%2BZme2jkQEB5BuWJAxPRoHnj5FpmgAhWt%2BYchg0RqCx7PqoSN03WZ48TzcE1HZY%2Fag0rhCj1rwVp5EzKy%2FSKz%2B5KjD8scah61BdOHMmprbP8zg20%2FgV25YS8%2FOIlmG2G1EbWJ6NgRpjmbFhmC4WPPQ0LMaJ36bnQynJS%2Forxr6%2BpfjJ5SugurpujGl1HCP2FHd5qIGo5fc2oL7RxoOKTKhW02hzUUUoYzhY5fON9KtU4ixGYyAkLpKTUBhzVl%2Fr7rx7pzQJTS8e5gQ3loeJZJoh%2Fj4kHeCpLWmVRkb7VMOchgUDivO0he6tvugSp17daenhjLQ%3D%3D (Caused by NewConnectionError('<urllib3.connection.HTTPSConnection object at 0x7f6e843b45d0>: Failed to establish a new connection: [Errno 111] Connection refused'))
2024-05-21 10:35:49,667 ERROR   wandb-upload_2:1293572 [internal_api.py:upload_file():2769] upload_file request headers: {'User-Agent': 'python-requests/2.31.0', 'Accept-Encoding': 'gzip, deflate, br', 'Accept': '*/*', 'Connection': 'keep-alive', 'Content-Length': '1015'}
2024-05-21 10:35:49,667 ERROR   wandb-upload_2:1293572 [internal_api.py:upload_file():2771] upload_file response body: 
2024-05-21 10:36:12,358 ERROR   wandb-upload_3:1293572 [internal_api.py:upload_file():2767] upload_file exception https://storage.googleapis.com/wandb-production.appspot.com/1923354735/MonoGS/7i7f5gjm/requirements.txt?Expires=1716344785&GoogleAccessId=gorilla-files-url-signer-man%40wandb-production.iam.gserviceaccount.com&Signature=PUX7QA4OqH2opVL%2Be4xGiUyiSEcJKghhy2ZzJ0ADva78BQw5wvJXcgxmEJhDVPlLvZNtRuCTDz8V5b8xGLORRPLQOCVuu%2FJQrLuJ%2FLBwmKtWfURkzUEK4Bvp7hdQSXE9Bdo%2BIUELc%2FollYAUIR9cLuXGB4LcF3MbuEnRMsx0fmew59GnKSrUTM30OgPMe7XfvvyMYbcrsx0ad8QQYCZfT92VDfDcsSK9EkcnqibOKBeVz6c6NsG0mXNJy%2FjdmeikZD%2B0SnRLK%2B1DJ%2BM%2FD%2FM0HCIJyurX7%2BmrEqThDoVqPZ0dRfK4dmITQg3mu015FcX6P9lNVn6ovViNSvSU0t1JUA%3D%3D: HTTPSConnectionPool(host='storage.googleapis.com', port=443): Max retries exceeded with url: /wandb-production.appspot.com/1923354735/MonoGS/7i7f5gjm/requirements.txt?Expires=1716344785&GoogleAccessId=gorilla-files-url-signer-man%40wandb-production.iam.gserviceaccount.com&Signature=PUX7QA4OqH2opVL%2Be4xGiUyiSEcJKghhy2ZzJ0ADva78BQw5wvJXcgxmEJhDVPlLvZNtRuCTDz8V5b8xGLORRPLQOCVuu%2FJQrLuJ%2FLBwmKtWfURkzUEK4Bvp7hdQSXE9Bdo%2BIUELc%2FollYAUIR9cLuXGB4LcF3MbuEnRMsx0fmew59GnKSrUTM30OgPMe7XfvvyMYbcrsx0ad8QQYCZfT92VDfDcsSK9EkcnqibOKBeVz6c6NsG0mXNJy%2FjdmeikZD%2B0SnRLK%2B1DJ%2BM%2FD%2FM0HCIJyurX7%2BmrEqThDoVqPZ0dRfK4dmITQg3mu015FcX6P9lNVn6ovViNSvSU0t1JUA%3D%3D (Caused by NewConnectionError('<urllib3.connection.HTTPSConnection object at 0x7f6e843b4c50>: Failed to establish a new connection: [Errno 111] Connection refused'))
2024-05-21 10:36:12,359 ERROR   wandb-upload_3:1293572 [internal_api.py:upload_file():2769] upload_file request headers: {'User-Agent': 'python-requests/2.31.0', 'Accept-Encoding': 'gzip, deflate, br', 'Accept': '*/*', 'Connection': 'keep-alive', 'Content-Length': '2267'}
2024-05-21 10:36:12,359 ERROR   wandb-upload_3:1293572 [internal_api.py:upload_file():2771] upload_file response body: 
2024-05-21 10:36:21,727 ERROR   wandb-upload_1:1293572 [internal_api.py:upload_file():2767] upload_file exception https://storage.googleapis.com/wandb-production.appspot.com/1923354735/MonoGS/7i7f5gjm/wandb-summary.json?Expires=1716344785&GoogleAccessId=gorilla-files-url-signer-man%40wandb-production.iam.gserviceaccount.com&Signature=jeBYHZuazMllAswE5cCuYPIOXrsDk%2Fi%2Byxjsv9qWnxV%2BGNVzIHitPZSoDMj6MWk0TNlGqYZGlH4B%2BPF%2BhJiqKeqhL2OuOHBETtdtsiWdwH0tIXK1ZdLZnOfccEagnoMyHjd%2BI8iVtowEJcGh5WKQ7a4%2B47kjR3lcOIzwzXrjed270X%2FoNcanSDRgV8xNpf603zC1Vf1qsRhzc6BJ684LVu0rN5GfkVItbl5nymffb%2F%2B%2BzcjF%2BZLQmZ17RQ0QV7xUR7ur9fhcaGfCDFhLfuBOx%2BIisR%2BQ%2Bec%2BD9ldoKK0mB7eEItITzgUcPVBv2GxH5sqHE5OJHUsFgZ0AGP%2Fxp5TXQ%3D%3D: HTTPSConnectionPool(host='storage.googleapis.com', port=443): Max retries exceeded with url: /wandb-production.appspot.com/1923354735/MonoGS/7i7f5gjm/wandb-summary.json?Expires=1716344785&GoogleAccessId=gorilla-files-url-signer-man%40wandb-production.iam.gserviceaccount.com&Signature=jeBYHZuazMllAswE5cCuYPIOXrsDk%2Fi%2Byxjsv9qWnxV%2BGNVzIHitPZSoDMj6MWk0TNlGqYZGlH4B%2BPF%2BhJiqKeqhL2OuOHBETtdtsiWdwH0tIXK1ZdLZnOfccEagnoMyHjd%2BI8iVtowEJcGh5WKQ7a4%2B47kjR3lcOIzwzXrjed270X%2FoNcanSDRgV8xNpf603zC1Vf1qsRhzc6BJ684LVu0rN5GfkVItbl5nymffb%2F%2B%2BzcjF%2BZLQmZ17RQ0QV7xUR7ur9fhcaGfCDFhLfuBOx%2BIisR%2BQ%2Bec%2BD9ldoKK0mB7eEItITzgUcPVBv2GxH5sqHE5OJHUsFgZ0AGP%2Fxp5TXQ%3D%3D (Caused by NewConnectionError('<urllib3.connection.HTTPSConnection object at 0x7f6e845c73d0>: Failed to establish a new connection: [Errno 111] Connection refused'))
2024-05-21 10:36:21,727 ERROR   wandb-upload_1:1293572 [internal_api.py:upload_file():2769] upload_file request headers: {'User-Agent': 'python-requests/2.31.0', 'Accept-Encoding': 'gzip, deflate, br', 'Accept': '*/*', 'Connection': 'keep-alive', 'Content-Length': '27'}
2024-05-21 10:36:21,727 ERROR   wandb-upload_1:1293572 [internal_api.py:upload_file():2771] upload_file response body: 
2024-05-21 10:36:30,159 ERROR   wandb-upload_5:1293572 [internal_api.py:upload_file():2767] upload_file exception https://storage.googleapis.com/wandb-production.appspot.com/1923354735/MonoGS/7i7f5gjm/config.yaml?Expires=1716344785&GoogleAccessId=gorilla-files-url-signer-man%40wandb-production.iam.gserviceaccount.com&Signature=BMJwBO0b014Q1rvgox%2BYqw0pIWvynCGKcHXP81FuKhooGhVUhYqaVBmViVNciwVsqNKp%2BvW6awp8zq7bi9R7C1S9SMcftKvFNNZTi3MFZUocgiR6bDXJN6BK87FW4A4x3HBA3lUNs%2BWeyT07hWtUTpF3yauVUa0ysE7bU4lqzsHw6wjbYscL%2BUPwtsOABX2fk5Cq9c2xOXBjo76eTHr2dXmLEuUI2yZjhoAw9dyVlAaRkeS3kpnJCE3msbu06izwRBdLpfjl2PnIPuJW32O1U80Rm8bWPcZ5hnthAMzzOX3Junrz0ThnCdN67XHlY6kYXWb2tSdx4J%2BT7ulxfZmRPw%3D%3D: ('Connection aborted.', ConnectionResetError(104, 'Connection reset by peer'))
2024-05-21 10:36:30,159 ERROR   wandb-upload_5:1293572 [internal_api.py:upload_file():2769] upload_file request headers: {'User-Agent': 'python-requests/2.31.0', 'Accept-Encoding': 'gzip, deflate, br', 'Accept': '*/*', 'Connection': 'keep-alive', 'Content-Length': '2747'}
2024-05-21 10:36:30,160 ERROR   wandb-upload_5:1293572 [internal_api.py:upload_file():2771] upload_file response body: 
2024-05-21 10:40:00,782 ERROR   wandb-upload_0:1293572 [internal_api.py:upload_file():2767] upload_file exception https://storage.googleapis.com/wandb-production.appspot.com/1923354735/MonoGS/7i7f5gjm/wandb-metadata.json?Expires=1716344732&GoogleAccessId=gorilla-files-url-signer-man%40wandb-production.iam.gserviceaccount.com&Signature=cDR3s4Btu8wUHMp7Bq8tJfPSneZs1lKn2s29OU2rf%2FQIynPqqnBm7KTt%2FUEbBkk02uPdYlSFQ9EV28DpKWGSjPzJUwI2lj6lzR%2FVCrCdrmNQF2B6LpGTVwfUfNo%2BgAMipws%2FssygMCuS0ObkO8Ckn4inWWTYBfrsEeAYuXXQ1MpkDWgrDTmFzIWIh7uhGxi5rRZGleTaZq3oxaGDid1%2FfSVTAKln9OgAsZRMb3CU44aJcHVk9lBYHWz9LI%2Fdrn9Se0ZlWbNUG9fX7iLx2N8X7pmCC2x1luKH8B87YHHaoGoUezsZnaVDfAWe31WtqGOpRQoXCjyFDeT%2FQZWmt8yRAA%3D%3D: HTTPSConnectionPool(host='storage.googleapis.com', port=443): Max retries exceeded with url: /wandb-production.appspot.com/1923354735/MonoGS/7i7f5gjm/wandb-metadata.json?Expires=1716344732&GoogleAccessId=gorilla-files-url-signer-man%40wandb-production.iam.gserviceaccount.com&Signature=cDR3s4Btu8wUHMp7Bq8tJfPSneZs1lKn2s29OU2rf%2FQIynPqqnBm7KTt%2FUEbBkk02uPdYlSFQ9EV28DpKWGSjPzJUwI2lj6lzR%2FVCrCdrmNQF2B6LpGTVwfUfNo%2BgAMipws%2FssygMCuS0ObkO8Ckn4inWWTYBfrsEeAYuXXQ1MpkDWgrDTmFzIWIh7uhGxi5rRZGleTaZq3oxaGDid1%2FfSVTAKln9OgAsZRMb3CU44aJcHVk9lBYHWz9LI%2Fdrn9Se0ZlWbNUG9fX7iLx2N8X7pmCC2x1luKH8B87YHHaoGoUezsZnaVDfAWe31WtqGOpRQoXCjyFDeT%2FQZWmt8yRAA%3D%3D (Caused by NewConnectionError('<urllib3.connection.HTTPSConnection object at 0x7f6e8438ebd0>: Failed to establish a new connection: [Errno 111] Connection refused'))
2024-05-21 10:40:00,783 ERROR   wandb-upload_0:1293572 [internal_api.py:upload_file():2769] upload_file request headers: {'User-Agent': 'python-requests/2.31.0', 'Accept-Encoding': 'gzip, deflate, br', 'Accept': '*/*', 'Connection': 'keep-alive', 'Content-Length': '3405'}
2024-05-21 10:40:00,783 ERROR   wandb-upload_0:1293572 [internal_api.py:upload_file():2771] upload_file response body: 
2024-05-21 10:40:55,831 ERROR   wandb-upload_4:1293572 [internal_api.py:upload_file():2767] upload_file exception https://storage.googleapis.com/wandb-production.appspot.com/1923354735/MonoGS/7i7f5gjm/conda-environment.yaml?Expires=1716344785&GoogleAccessId=gorilla-files-url-signer-man%40wandb-production.iam.gserviceaccount.com&Signature=EVDYObbaalBfRuHPuIIs4NJTCdppmKpHxAnNLjdSe1QDN6a6hLjmiC11aQSD4qP%2FLgPOBp45zUTn6TBcUhpaHqlZNygjhiEZX7Ca6B8klTArywRWcGYmvUpGy7O%2BleSulQSIXobSwqU%2BnRTR07PRCuNcBPTnbqW4CuC37R8fHKLlfmAI1UHGfP2sI%2BlboaOgAd5r%2BM%2FcJppRU2DfKWKWnp6t7v4yZJja%2BYwr7UjygyGHX5lL9hp2spsgl904SnGzFL7U%2FmLKAckP6yFEIZwTv6OhtL0G4DCGbJCOtPnMRFsrapLi2lTX5L4uZH%2Fmk1S6S69x4FC7L5%2Bpmj6gh7nsiA%3D%3D: HTTPSConnectionPool(host='storage.googleapis.com', port=443): Max retries exceeded with url: /wandb-production.appspot.com/1923354735/MonoGS/7i7f5gjm/conda-environment.yaml?Expires=1716344785&GoogleAccessId=gorilla-files-url-signer-man%40wandb-production.iam.gserviceaccount.com&Signature=EVDYObbaalBfRuHPuIIs4NJTCdppmKpHxAnNLjdSe1QDN6a6hLjmiC11aQSD4qP%2FLgPOBp45zUTn6TBcUhpaHqlZNygjhiEZX7Ca6B8klTArywRWcGYmvUpGy7O%2BleSulQSIXobSwqU%2BnRTR07PRCuNcBPTnbqW4CuC37R8fHKLlfmAI1UHGfP2sI%2BlboaOgAd5r%2BM%2FcJppRU2DfKWKWnp6t7v4yZJja%2BYwr7UjygyGHX5lL9hp2spsgl904SnGzFL7U%2FmLKAckP6yFEIZwTv6OhtL0G4DCGbJCOtPnMRFsrapLi2lTX5L4uZH%2Fmk1S6S69x4FC7L5%2Bpmj6gh7nsiA%3D%3D (Caused by NewConnectionError('<urllib3.connection.HTTPSConnection object at 0x7f6e8438e9d0>: Failed to establish a new connection: [Errno 111] Connection refused'))
2024-05-21 10:40:55,831 ERROR   wandb-upload_4:1293572 [internal_api.py:upload_file():2769] upload_file request headers: {'User-Agent': 'python-requests/2.31.0', 'Accept-Encoding': 'gzip, deflate, br', 'Accept': '*/*', 'Connection': 'keep-alive', 'Content-Length': '4690'}
2024-05-21 10:40:55,831 ERROR   wandb-upload_4:1293572 [internal_api.py:upload_file():2771] upload_file response body: 
2024-05-21 10:41:25,187 ERROR   wandb-upload_2:1293572 [internal_api.py:upload_file():2767] upload_file exception https://storage.googleapis.com/wandb-production.appspot.com/1923354735/MonoGS/7i7f5gjm/output.log?Expires=1716344785&GoogleAccessId=gorilla-files-url-signer-man%40wandb-production.iam.gserviceaccount.com&Signature=VLoFH2QdZgsVeMSF7%2BZme2jkQEB5BuWJAxPRoHnj5FpmgAhWt%2BYchg0RqCx7PqoSN03WZ48TzcE1HZY%2Fag0rhCj1rwVp5EzKy%2FSKz%2B5KjD8scah61BdOHMmprbP8zg20%2FgV25YS8%2FOIlmG2G1EbWJ6NgRpjmbFhmC4WPPQ0LMaJ36bnQynJS%2Forxr6%2BpfjJ5SugurpujGl1HCP2FHd5qIGo5fc2oL7RxoOKTKhW02hzUUUoYzhY5fON9KtU4ixGYyAkLpKTUBhzVl%2Fr7rx7pzQJTS8e5gQ3loeJZJoh%2Fj4kHeCpLWmVRkb7VMOchgUDivO0he6tvugSp17daenhjLQ%3D%3D: HTTPSConnectionPool(host='storage.googleapis.com', port=443): Max retries exceeded with url: /wandb-production.appspot.com/1923354735/MonoGS/7i7f5gjm/output.log?Expires=1716344785&GoogleAccessId=gorilla-files-url-signer-man%40wandb-production.iam.gserviceaccount.com&Signature=VLoFH2QdZgsVeMSF7%2BZme2jkQEB5BuWJAxPRoHnj5FpmgAhWt%2BYchg0RqCx7PqoSN03WZ48TzcE1HZY%2Fag0rhCj1rwVp5EzKy%2FSKz%2B5KjD8scah61BdOHMmprbP8zg20%2FgV25YS8%2FOIlmG2G1EbWJ6NgRpjmbFhmC4WPPQ0LMaJ36bnQynJS%2Forxr6%2BpfjJ5SugurpujGl1HCP2FHd5qIGo5fc2oL7RxoOKTKhW02hzUUUoYzhY5fON9KtU4ixGYyAkLpKTUBhzVl%2Fr7rx7pzQJTS8e5gQ3loeJZJoh%2Fj4kHeCpLWmVRkb7VMOchgUDivO0he6tvugSp17daenhjLQ%3D%3D (Caused by NewConnectionError('<urllib3.connection.HTTPSConnection object at 0x7f6e843a8bd0>: Failed to establish a new connection: [Errno 111] Connection refused'))
2024-05-21 10:41:25,187 ERROR   wandb-upload_2:1293572 [internal_api.py:upload_file():2769] upload_file request headers: {'User-Agent': 'python-requests/2.31.0', 'Accept-Encoding': 'gzip, deflate, br', 'Accept': '*/*', 'Connection': 'keep-alive', 'Content-Length': '1015'}
2024-05-21 10:41:25,187 ERROR   wandb-upload_2:1293572 [internal_api.py:upload_file():2771] upload_file response body: 
2024-05-21 10:41:32,978 ERROR   wandb-upload_5:1293572 [internal_api.py:upload_file():2767] upload_file exception https://storage.googleapis.com/wandb-production.appspot.com/1923354735/MonoGS/7i7f5gjm/config.yaml?Expires=1716344785&GoogleAccessId=gorilla-files-url-signer-man%40wandb-production.iam.gserviceaccount.com&Signature=BMJwBO0b014Q1rvgox%2BYqw0pIWvynCGKcHXP81FuKhooGhVUhYqaVBmViVNciwVsqNKp%2BvW6awp8zq7bi9R7C1S9SMcftKvFNNZTi3MFZUocgiR6bDXJN6BK87FW4A4x3HBA3lUNs%2BWeyT07hWtUTpF3yauVUa0ysE7bU4lqzsHw6wjbYscL%2BUPwtsOABX2fk5Cq9c2xOXBjo76eTHr2dXmLEuUI2yZjhoAw9dyVlAaRkeS3kpnJCE3msbu06izwRBdLpfjl2PnIPuJW32O1U80Rm8bWPcZ5hnthAMzzOX3Junrz0ThnCdN67XHlY6kYXWb2tSdx4J%2BT7ulxfZmRPw%3D%3D: HTTPSConnectionPool(host='storage.googleapis.com', port=443): Max retries exceeded with url: /wandb-production.appspot.com/1923354735/MonoGS/7i7f5gjm/config.yaml?Expires=1716344785&GoogleAccessId=gorilla-files-url-signer-man%40wandb-production.iam.gserviceaccount.com&Signature=BMJwBO0b014Q1rvgox%2BYqw0pIWvynCGKcHXP81FuKhooGhVUhYqaVBmViVNciwVsqNKp%2BvW6awp8zq7bi9R7C1S9SMcftKvFNNZTi3MFZUocgiR6bDXJN6BK87FW4A4x3HBA3lUNs%2BWeyT07hWtUTpF3yauVUa0ysE7bU4lqzsHw6wjbYscL%2BUPwtsOABX2fk5Cq9c2xOXBjo76eTHr2dXmLEuUI2yZjhoAw9dyVlAaRkeS3kpnJCE3msbu06izwRBdLpfjl2PnIPuJW32O1U80Rm8bWPcZ5hnthAMzzOX3Junrz0ThnCdN67XHlY6kYXWb2tSdx4J%2BT7ulxfZmRPw%3D%3D (Caused by NewConnectionError('<urllib3.connection.HTTPSConnection object at 0x7f6e8443fc90>: Failed to establish a new connection: [Errno 111] Connection refused'))
2024-05-21 10:41:32,978 ERROR   wandb-upload_5:1293572 [internal_api.py:upload_file():2769] upload_file request headers: {'User-Agent': 'python-requests/2.31.0', 'Accept-Encoding': 'gzip, deflate, br', 'Accept': '*/*', 'Connection': 'keep-alive', 'Content-Length': '2747'}
2024-05-21 10:41:32,978 ERROR   wandb-upload_5:1293572 [internal_api.py:upload_file():2771] upload_file response body: 
2024-05-21 10:41:49,779 ERROR   wandb-upload_1:1293572 [internal_api.py:upload_file():2767] upload_file exception https://storage.googleapis.com/wandb-production.appspot.com/1923354735/MonoGS/7i7f5gjm/wandb-summary.json?Expires=1716344785&GoogleAccessId=gorilla-files-url-signer-man%40wandb-production.iam.gserviceaccount.com&Signature=jeBYHZuazMllAswE5cCuYPIOXrsDk%2Fi%2Byxjsv9qWnxV%2BGNVzIHitPZSoDMj6MWk0TNlGqYZGlH4B%2BPF%2BhJiqKeqhL2OuOHBETtdtsiWdwH0tIXK1ZdLZnOfccEagnoMyHjd%2BI8iVtowEJcGh5WKQ7a4%2B47kjR3lcOIzwzXrjed270X%2FoNcanSDRgV8xNpf603zC1Vf1qsRhzc6BJ684LVu0rN5GfkVItbl5nymffb%2F%2B%2BzcjF%2BZLQmZ17RQ0QV7xUR7ur9fhcaGfCDFhLfuBOx%2BIisR%2BQ%2Bec%2BD9ldoKK0mB7eEItITzgUcPVBv2GxH5sqHE5OJHUsFgZ0AGP%2Fxp5TXQ%3D%3D: HTTPSConnectionPool(host='storage.googleapis.com', port=443): Max retries exceeded with url: /wandb-production.appspot.com/1923354735/MonoGS/7i7f5gjm/wandb-summary.json?Expires=1716344785&GoogleAccessId=gorilla-files-url-signer-man%40wandb-production.iam.gserviceaccount.com&Signature=jeBYHZuazMllAswE5cCuYPIOXrsDk%2Fi%2Byxjsv9qWnxV%2BGNVzIHitPZSoDMj6MWk0TNlGqYZGlH4B%2BPF%2BhJiqKeqhL2OuOHBETtdtsiWdwH0tIXK1ZdLZnOfccEagnoMyHjd%2BI8iVtowEJcGh5WKQ7a4%2B47kjR3lcOIzwzXrjed270X%2FoNcanSDRgV8xNpf603zC1Vf1qsRhzc6BJ684LVu0rN5GfkVItbl5nymffb%2F%2B%2BzcjF%2BZLQmZ17RQ0QV7xUR7ur9fhcaGfCDFhLfuBOx%2BIisR%2BQ%2Bec%2BD9ldoKK0mB7eEItITzgUcPVBv2GxH5sqHE5OJHUsFgZ0AGP%2Fxp5TXQ%3D%3D (Caused by NewConnectionError('<urllib3.connection.HTTPSConnection object at 0x7f6e843b01d0>: Failed to establish a new connection: [Errno 111] Connection refused'))
2024-05-21 10:41:49,779 ERROR   wandb-upload_1:1293572 [internal_api.py:upload_file():2769] upload_file request headers: {'User-Agent': 'python-requests/2.31.0', 'Accept-Encoding': 'gzip, deflate, br', 'Accept': '*/*', 'Connection': 'keep-alive', 'Content-Length': '27'}
2024-05-21 10:41:49,779 ERROR   wandb-upload_1:1293572 [internal_api.py:upload_file():2771] upload_file response body: 
2024-05-21 10:42:00,510 ERROR   wandb-upload_3:1293572 [internal_api.py:upload_file():2767] upload_file exception https://storage.googleapis.com/wandb-production.appspot.com/1923354735/MonoGS/7i7f5gjm/requirements.txt?Expires=1716344785&GoogleAccessId=gorilla-files-url-signer-man%40wandb-production.iam.gserviceaccount.com&Signature=PUX7QA4OqH2opVL%2Be4xGiUyiSEcJKghhy2ZzJ0ADva78BQw5wvJXcgxmEJhDVPlLvZNtRuCTDz8V5b8xGLORRPLQOCVuu%2FJQrLuJ%2FLBwmKtWfURkzUEK4Bvp7hdQSXE9Bdo%2BIUELc%2FollYAUIR9cLuXGB4LcF3MbuEnRMsx0fmew59GnKSrUTM30OgPMe7XfvvyMYbcrsx0ad8QQYCZfT92VDfDcsSK9EkcnqibOKBeVz6c6NsG0mXNJy%2FjdmeikZD%2B0SnRLK%2B1DJ%2BM%2FD%2FM0HCIJyurX7%2BmrEqThDoVqPZ0dRfK4dmITQg3mu015FcX6P9lNVn6ovViNSvSU0t1JUA%3D%3D: HTTPSConnectionPool(host='storage.googleapis.com', port=443): Max retries exceeded with url: /wandb-production.appspot.com/1923354735/MonoGS/7i7f5gjm/requirements.txt?Expires=1716344785&GoogleAccessId=gorilla-files-url-signer-man%40wandb-production.iam.gserviceaccount.com&Signature=PUX7QA4OqH2opVL%2Be4xGiUyiSEcJKghhy2ZzJ0ADva78BQw5wvJXcgxmEJhDVPlLvZNtRuCTDz8V5b8xGLORRPLQOCVuu%2FJQrLuJ%2FLBwmKtWfURkzUEK4Bvp7hdQSXE9Bdo%2BIUELc%2FollYAUIR9cLuXGB4LcF3MbuEnRMsx0fmew59GnKSrUTM30OgPMe7XfvvyMYbcrsx0ad8QQYCZfT92VDfDcsSK9EkcnqibOKBeVz6c6NsG0mXNJy%2FjdmeikZD%2B0SnRLK%2B1DJ%2BM%2FD%2FM0HCIJyurX7%2BmrEqThDoVqPZ0dRfK4dmITQg3mu015FcX6P9lNVn6ovViNSvSU0t1JUA%3D%3D (Caused by NewConnectionError('<urllib3.connection.HTTPSConnection object at 0x7f6e843b8190>: Failed to establish a new connection: [Errno 111] Connection refused'))
2024-05-21 10:42:00,511 ERROR   wandb-upload_3:1293572 [internal_api.py:upload_file():2769] upload_file request headers: {'User-Agent': 'python-requests/2.31.0', 'Accept-Encoding': 'gzip, deflate, br', 'Accept': '*/*', 'Connection': 'keep-alive', 'Content-Length': '2267'}
2024-05-21 10:42:00,511 ERROR   wandb-upload_3:1293572 [internal_api.py:upload_file():2771] upload_file response body: 
2024-05-21 10:45:29,980 ERROR   wandb-upload_0:1293572 [internal_api.py:upload_file():2767] upload_file exception https://storage.googleapis.com/wandb-production.appspot.com/1923354735/MonoGS/7i7f5gjm/wandb-metadata.json?Expires=1716344732&GoogleAccessId=gorilla-files-url-signer-man%40wandb-production.iam.gserviceaccount.com&Signature=cDR3s4Btu8wUHMp7Bq8tJfPSneZs1lKn2s29OU2rf%2FQIynPqqnBm7KTt%2FUEbBkk02uPdYlSFQ9EV28DpKWGSjPzJUwI2lj6lzR%2FVCrCdrmNQF2B6LpGTVwfUfNo%2BgAMipws%2FssygMCuS0ObkO8Ckn4inWWTYBfrsEeAYuXXQ1MpkDWgrDTmFzIWIh7uhGxi5rRZGleTaZq3oxaGDid1%2FfSVTAKln9OgAsZRMb3CU44aJcHVk9lBYHWz9LI%2Fdrn9Se0ZlWbNUG9fX7iLx2N8X7pmCC2x1luKH8B87YHHaoGoUezsZnaVDfAWe31WtqGOpRQoXCjyFDeT%2FQZWmt8yRAA%3D%3D: HTTPSConnectionPool(host='storage.googleapis.com', port=443): Max retries exceeded with url: /wandb-production.appspot.com/1923354735/MonoGS/7i7f5gjm/wandb-metadata.json?Expires=1716344732&GoogleAccessId=gorilla-files-url-signer-man%40wandb-production.iam.gserviceaccount.com&Signature=cDR3s4Btu8wUHMp7Bq8tJfPSneZs1lKn2s29OU2rf%2FQIynPqqnBm7KTt%2FUEbBkk02uPdYlSFQ9EV28DpKWGSjPzJUwI2lj6lzR%2FVCrCdrmNQF2B6LpGTVwfUfNo%2BgAMipws%2FssygMCuS0ObkO8Ckn4inWWTYBfrsEeAYuXXQ1MpkDWgrDTmFzIWIh7uhGxi5rRZGleTaZq3oxaGDid1%2FfSVTAKln9OgAsZRMb3CU44aJcHVk9lBYHWz9LI%2Fdrn9Se0ZlWbNUG9fX7iLx2N8X7pmCC2x1luKH8B87YHHaoGoUezsZnaVDfAWe31WtqGOpRQoXCjyFDeT%2FQZWmt8yRAA%3D%3D (Caused by NewConnectionError('<urllib3.connection.HTTPSConnection object at 0x7f6e843b0750>: Failed to establish a new connection: [Errno 111] Connection refused'))
2024-05-21 10:45:29,980 ERROR   wandb-upload_0:1293572 [internal_api.py:upload_file():2769] upload_file request headers: {'User-Agent': 'python-requests/2.31.0', 'Accept-Encoding': 'gzip, deflate, br', 'Accept': '*/*', 'Connection': 'keep-alive', 'Content-Length': '3405'}
2024-05-21 10:45:29,980 ERROR   wandb-upload_0:1293572 [internal_api.py:upload_file():2771] upload_file response body: 
2024-05-21 10:45:59,804 ERROR   wandb-upload_4:1293572 [internal_api.py:upload_file():2767] upload_file exception https://storage.googleapis.com/wandb-production.appspot.com/1923354735/MonoGS/7i7f5gjm/conda-environment.yaml?Expires=1716344785&GoogleAccessId=gorilla-files-url-signer-man%40wandb-production.iam.gserviceaccount.com&Signature=EVDYObbaalBfRuHPuIIs4NJTCdppmKpHxAnNLjdSe1QDN6a6hLjmiC11aQSD4qP%2FLgPOBp45zUTn6TBcUhpaHqlZNygjhiEZX7Ca6B8klTArywRWcGYmvUpGy7O%2BleSulQSIXobSwqU%2BnRTR07PRCuNcBPTnbqW4CuC37R8fHKLlfmAI1UHGfP2sI%2BlboaOgAd5r%2BM%2FcJppRU2DfKWKWnp6t7v4yZJja%2BYwr7UjygyGHX5lL9hp2spsgl904SnGzFL7U%2FmLKAckP6yFEIZwTv6OhtL0G4DCGbJCOtPnMRFsrapLi2lTX5L4uZH%2Fmk1S6S69x4FC7L5%2Bpmj6gh7nsiA%3D%3D: HTTPSConnectionPool(host='storage.googleapis.com', port=443): Max retries exceeded with url: /wandb-production.appspot.com/1923354735/MonoGS/7i7f5gjm/conda-environment.yaml?Expires=1716344785&GoogleAccessId=gorilla-files-url-signer-man%40wandb-production.iam.gserviceaccount.com&Signature=EVDYObbaalBfRuHPuIIs4NJTCdppmKpHxAnNLjdSe1QDN6a6hLjmiC11aQSD4qP%2FLgPOBp45zUTn6TBcUhpaHqlZNygjhiEZX7Ca6B8klTArywRWcGYmvUpGy7O%2BleSulQSIXobSwqU%2BnRTR07PRCuNcBPTnbqW4CuC37R8fHKLlfmAI1UHGfP2sI%2BlboaOgAd5r%2BM%2FcJppRU2DfKWKWnp6t7v4yZJja%2BYwr7UjygyGHX5lL9hp2spsgl904SnGzFL7U%2FmLKAckP6yFEIZwTv6OhtL0G4DCGbJCOtPnMRFsrapLi2lTX5L4uZH%2Fmk1S6S69x4FC7L5%2Bpmj6gh7nsiA%3D%3D (Caused by NewConnectionError('<urllib3.connection.HTTPSConnection object at 0x7f6e8443f650>: Failed to establish a new connection: [Errno 111] Connection refused'))
2024-05-21 10:45:59,805 ERROR   wandb-upload_4:1293572 [internal_api.py:upload_file():2769] upload_file request headers: {'User-Agent': 'python-requests/2.31.0', 'Accept-Encoding': 'gzip, deflate, br', 'Accept': '*/*', 'Connection': 'keep-alive', 'Content-Length': '4690'}
2024-05-21 10:45:59,805 ERROR   wandb-upload_4:1293572 [internal_api.py:upload_file():2771] upload_file response body: 
2024-05-21 10:46:39,098 ERROR   wandb-upload_5:1293572 [internal_api.py:upload_file():2767] upload_file exception https://storage.googleapis.com/wandb-production.appspot.com/1923354735/MonoGS/7i7f5gjm/config.yaml?Expires=1716344785&GoogleAccessId=gorilla-files-url-signer-man%40wandb-production.iam.gserviceaccount.com&Signature=BMJwBO0b014Q1rvgox%2BYqw0pIWvynCGKcHXP81FuKhooGhVUhYqaVBmViVNciwVsqNKp%2BvW6awp8zq7bi9R7C1S9SMcftKvFNNZTi3MFZUocgiR6bDXJN6BK87FW4A4x3HBA3lUNs%2BWeyT07hWtUTpF3yauVUa0ysE7bU4lqzsHw6wjbYscL%2BUPwtsOABX2fk5Cq9c2xOXBjo76eTHr2dXmLEuUI2yZjhoAw9dyVlAaRkeS3kpnJCE3msbu06izwRBdLpfjl2PnIPuJW32O1U80Rm8bWPcZ5hnthAMzzOX3Junrz0ThnCdN67XHlY6kYXWb2tSdx4J%2BT7ulxfZmRPw%3D%3D: HTTPSConnectionPool(host='storage.googleapis.com', port=443): Max retries exceeded with url: /wandb-production.appspot.com/1923354735/MonoGS/7i7f5gjm/config.yaml?Expires=1716344785&GoogleAccessId=gorilla-files-url-signer-man%40wandb-production.iam.gserviceaccount.com&Signature=BMJwBO0b014Q1rvgox%2BYqw0pIWvynCGKcHXP81FuKhooGhVUhYqaVBmViVNciwVsqNKp%2BvW6awp8zq7bi9R7C1S9SMcftKvFNNZTi3MFZUocgiR6bDXJN6BK87FW4A4x3HBA3lUNs%2BWeyT07hWtUTpF3yauVUa0ysE7bU4lqzsHw6wjbYscL%2BUPwtsOABX2fk5Cq9c2xOXBjo76eTHr2dXmLEuUI2yZjhoAw9dyVlAaRkeS3kpnJCE3msbu06izwRBdLpfjl2PnIPuJW32O1U80Rm8bWPcZ5hnthAMzzOX3Junrz0ThnCdN67XHlY6kYXWb2tSdx4J%2BT7ulxfZmRPw%3D%3D (Caused by NewConnectionError('<urllib3.connection.HTTPSConnection object at 0x7f6e843a8a10>: Failed to establish a new connection: [Errno 111] Connection refused'))
2024-05-21 10:46:39,098 ERROR   wandb-upload_5:1293572 [internal_api.py:upload_file():2769] upload_file request headers: {'User-Agent': 'python-requests/2.31.0', 'Accept-Encoding': 'gzip, deflate, br', 'Accept': '*/*', 'Connection': 'keep-alive', 'Content-Length': '2747'}
2024-05-21 10:46:39,098 ERROR   wandb-upload_5:1293572 [internal_api.py:upload_file():2771] upload_file response body: 
2024-05-21 10:47:22,071 ERROR   wandb-upload_2:1293572 [internal_api.py:upload_file():2767] upload_file exception https://storage.googleapis.com/wandb-production.appspot.com/1923354735/MonoGS/7i7f5gjm/output.log?Expires=1716344785&GoogleAccessId=gorilla-files-url-signer-man%40wandb-production.iam.gserviceaccount.com&Signature=VLoFH2QdZgsVeMSF7%2BZme2jkQEB5BuWJAxPRoHnj5FpmgAhWt%2BYchg0RqCx7PqoSN03WZ48TzcE1HZY%2Fag0rhCj1rwVp5EzKy%2FSKz%2B5KjD8scah61BdOHMmprbP8zg20%2FgV25YS8%2FOIlmG2G1EbWJ6NgRpjmbFhmC4WPPQ0LMaJ36bnQynJS%2Forxr6%2BpfjJ5SugurpujGl1HCP2FHd5qIGo5fc2oL7RxoOKTKhW02hzUUUoYzhY5fON9KtU4ixGYyAkLpKTUBhzVl%2Fr7rx7pzQJTS8e5gQ3loeJZJoh%2Fj4kHeCpLWmVRkb7VMOchgUDivO0he6tvugSp17daenhjLQ%3D%3D: HTTPSConnectionPool(host='storage.googleapis.com', port=443): Max retries exceeded with url: /wandb-production.appspot.com/1923354735/MonoGS/7i7f5gjm/output.log?Expires=1716344785&GoogleAccessId=gorilla-files-url-signer-man%40wandb-production.iam.gserviceaccount.com&Signature=VLoFH2QdZgsVeMSF7%2BZme2jkQEB5BuWJAxPRoHnj5FpmgAhWt%2BYchg0RqCx7PqoSN03WZ48TzcE1HZY%2Fag0rhCj1rwVp5EzKy%2FSKz%2B5KjD8scah61BdOHMmprbP8zg20%2FgV25YS8%2FOIlmG2G1EbWJ6NgRpjmbFhmC4WPPQ0LMaJ36bnQynJS%2Forxr6%2BpfjJ5SugurpujGl1HCP2FHd5qIGo5fc2oL7RxoOKTKhW02hzUUUoYzhY5fON9KtU4ixGYyAkLpKTUBhzVl%2Fr7rx7pzQJTS8e5gQ3loeJZJoh%2Fj4kHeCpLWmVRkb7VMOchgUDivO0he6tvugSp17daenhjLQ%3D%3D (Caused by NewConnectionError('<urllib3.connection.HTTPSConnection object at 0x7f6e843938d0>: Failed to establish a new connection: [Errno 111] Connection refused'))
2024-05-21 10:47:22,071 ERROR   wandb-upload_2:1293572 [internal_api.py:upload_file():2769] upload_file request headers: {'User-Agent': 'python-requests/2.31.0', 'Accept-Encoding': 'gzip, deflate, br', 'Accept': '*/*', 'Connection': 'keep-alive', 'Content-Length': '1015'}
2024-05-21 10:47:22,071 ERROR   wandb-upload_2:1293572 [internal_api.py:upload_file():2771] upload_file response body: 
2024-05-21 10:47:36,030 ERROR   wandb-upload_1:1293572 [internal_api.py:upload_file():2767] upload_file exception https://storage.googleapis.com/wandb-production.appspot.com/1923354735/MonoGS/7i7f5gjm/wandb-summary.json?Expires=1716344785&GoogleAccessId=gorilla-files-url-signer-man%40wandb-production.iam.gserviceaccount.com&Signature=jeBYHZuazMllAswE5cCuYPIOXrsDk%2Fi%2Byxjsv9qWnxV%2BGNVzIHitPZSoDMj6MWk0TNlGqYZGlH4B%2BPF%2BhJiqKeqhL2OuOHBETtdtsiWdwH0tIXK1ZdLZnOfccEagnoMyHjd%2BI8iVtowEJcGh5WKQ7a4%2B47kjR3lcOIzwzXrjed270X%2FoNcanSDRgV8xNpf603zC1Vf1qsRhzc6BJ684LVu0rN5GfkVItbl5nymffb%2F%2B%2BzcjF%2BZLQmZ17RQ0QV7xUR7ur9fhcaGfCDFhLfuBOx%2BIisR%2BQ%2Bec%2BD9ldoKK0mB7eEItITzgUcPVBv2GxH5sqHE5OJHUsFgZ0AGP%2Fxp5TXQ%3D%3D: HTTPSConnectionPool(host='storage.googleapis.com', port=443): Max retries exceeded with url: /wandb-production.appspot.com/1923354735/MonoGS/7i7f5gjm/wandb-summary.json?Expires=1716344785&GoogleAccessId=gorilla-files-url-signer-man%40wandb-production.iam.gserviceaccount.com&Signature=jeBYHZuazMllAswE5cCuYPIOXrsDk%2Fi%2Byxjsv9qWnxV%2BGNVzIHitPZSoDMj6MWk0TNlGqYZGlH4B%2BPF%2BhJiqKeqhL2OuOHBETtdtsiWdwH0tIXK1ZdLZnOfccEagnoMyHjd%2BI8iVtowEJcGh5WKQ7a4%2B47kjR3lcOIzwzXrjed270X%2FoNcanSDRgV8xNpf603zC1Vf1qsRhzc6BJ684LVu0rN5GfkVItbl5nymffb%2F%2B%2BzcjF%2BZLQmZ17RQ0QV7xUR7ur9fhcaGfCDFhLfuBOx%2BIisR%2BQ%2Bec%2BD9ldoKK0mB7eEItITzgUcPVBv2GxH5sqHE5OJHUsFgZ0AGP%2Fxp5TXQ%3D%3D (Caused by NewConnectionError('<urllib3.connection.HTTPSConnection object at 0x7f6e8438e590>: Failed to establish a new connection: [Errno 111] Connection refused'))
2024-05-21 10:47:36,030 ERROR   wandb-upload_1:1293572 [internal_api.py:upload_file():2769] upload_file request headers: {'User-Agent': 'python-requests/2.31.0', 'Accept-Encoding': 'gzip, deflate, br', 'Accept': '*/*', 'Connection': 'keep-alive', 'Content-Length': '27'}
2024-05-21 10:47:36,030 ERROR   wandb-upload_1:1293572 [internal_api.py:upload_file():2771] upload_file response body: 
2024-05-21 10:48:11,184 ERROR   wandb-upload_3:1293572 [internal_api.py:upload_file():2767] upload_file exception https://storage.googleapis.com/wandb-production.appspot.com/1923354735/MonoGS/7i7f5gjm/requirements.txt?Expires=1716344785&GoogleAccessId=gorilla-files-url-signer-man%40wandb-production.iam.gserviceaccount.com&Signature=PUX7QA4OqH2opVL%2Be4xGiUyiSEcJKghhy2ZzJ0ADva78BQw5wvJXcgxmEJhDVPlLvZNtRuCTDz8V5b8xGLORRPLQOCVuu%2FJQrLuJ%2FLBwmKtWfURkzUEK4Bvp7hdQSXE9Bdo%2BIUELc%2FollYAUIR9cLuXGB4LcF3MbuEnRMsx0fmew59GnKSrUTM30OgPMe7XfvvyMYbcrsx0ad8QQYCZfT92VDfDcsSK9EkcnqibOKBeVz6c6NsG0mXNJy%2FjdmeikZD%2B0SnRLK%2B1DJ%2BM%2FD%2FM0HCIJyurX7%2BmrEqThDoVqPZ0dRfK4dmITQg3mu015FcX6P9lNVn6ovViNSvSU0t1JUA%3D%3D: HTTPSConnectionPool(host='storage.googleapis.com', port=443): Max retries exceeded with url: /wandb-production.appspot.com/1923354735/MonoGS/7i7f5gjm/requirements.txt?Expires=1716344785&GoogleAccessId=gorilla-files-url-signer-man%40wandb-production.iam.gserviceaccount.com&Signature=PUX7QA4OqH2opVL%2Be4xGiUyiSEcJKghhy2ZzJ0ADva78BQw5wvJXcgxmEJhDVPlLvZNtRuCTDz8V5b8xGLORRPLQOCVuu%2FJQrLuJ%2FLBwmKtWfURkzUEK4Bvp7hdQSXE9Bdo%2BIUELc%2FollYAUIR9cLuXGB4LcF3MbuEnRMsx0fmew59GnKSrUTM30OgPMe7XfvvyMYbcrsx0ad8QQYCZfT92VDfDcsSK9EkcnqibOKBeVz6c6NsG0mXNJy%2FjdmeikZD%2B0SnRLK%2B1DJ%2BM%2FD%2FM0HCIJyurX7%2BmrEqThDoVqPZ0dRfK4dmITQg3mu015FcX6P9lNVn6ovViNSvSU0t1JUA%3D%3D (Caused by NewConnectionError('<urllib3.connection.HTTPSConnection object at 0x7f6e8438e690>: Failed to establish a new connection: [Errno 111] Connection refused'))
2024-05-21 10:48:11,205 ERROR   wandb-upload_3:1293572 [internal_api.py:upload_file():2769] upload_file request headers: {'User-Agent': 'python-requests/2.31.0', 'Accept-Encoding': 'gzip, deflate, br', 'Accept': '*/*', 'Connection': 'keep-alive', 'Content-Length': '2267'}
2024-05-21 10:48:11,207 ERROR   wandb-upload_3:1293572 [internal_api.py:upload_file():2771] upload_file response body: 
2024-05-21 10:51:14,388 ERROR   wandb-upload_0:1293572 [internal_api.py:upload_file():2767] upload_file exception https://storage.googleapis.com/wandb-production.appspot.com/1923354735/MonoGS/7i7f5gjm/wandb-metadata.json?Expires=1716344732&GoogleAccessId=gorilla-files-url-signer-man%40wandb-production.iam.gserviceaccount.com&Signature=cDR3s4Btu8wUHMp7Bq8tJfPSneZs1lKn2s29OU2rf%2FQIynPqqnBm7KTt%2FUEbBkk02uPdYlSFQ9EV28DpKWGSjPzJUwI2lj6lzR%2FVCrCdrmNQF2B6LpGTVwfUfNo%2BgAMipws%2FssygMCuS0ObkO8Ckn4inWWTYBfrsEeAYuXXQ1MpkDWgrDTmFzIWIh7uhGxi5rRZGleTaZq3oxaGDid1%2FfSVTAKln9OgAsZRMb3CU44aJcHVk9lBYHWz9LI%2Fdrn9Se0ZlWbNUG9fX7iLx2N8X7pmCC2x1luKH8B87YHHaoGoUezsZnaVDfAWe31WtqGOpRQoXCjyFDeT%2FQZWmt8yRAA%3D%3D: HTTPSConnectionPool(host='storage.googleapis.com', port=443): Max retries exceeded with url: /wandb-production.appspot.com/1923354735/MonoGS/7i7f5gjm/wandb-metadata.json?Expires=1716344732&GoogleAccessId=gorilla-files-url-signer-man%40wandb-production.iam.gserviceaccount.com&Signature=cDR3s4Btu8wUHMp7Bq8tJfPSneZs1lKn2s29OU2rf%2FQIynPqqnBm7KTt%2FUEbBkk02uPdYlSFQ9EV28DpKWGSjPzJUwI2lj6lzR%2FVCrCdrmNQF2B6LpGTVwfUfNo%2BgAMipws%2FssygMCuS0ObkO8Ckn4inWWTYBfrsEeAYuXXQ1MpkDWgrDTmFzIWIh7uhGxi5rRZGleTaZq3oxaGDid1%2FfSVTAKln9OgAsZRMb3CU44aJcHVk9lBYHWz9LI%2Fdrn9Se0ZlWbNUG9fX7iLx2N8X7pmCC2x1luKH8B87YHHaoGoUezsZnaVDfAWe31WtqGOpRQoXCjyFDeT%2FQZWmt8yRAA%3D%3D (Caused by NewConnectionError('<urllib3.connection.HTTPSConnection object at 0x7f6e84395350>: Failed to establish a new connection: [Errno 111] Connection refused'))
2024-05-21 10:51:14,388 ERROR   wandb-upload_0:1293572 [internal_api.py:upload_file():2769] upload_file request headers: {'User-Agent': 'python-requests/2.31.0', 'Accept-Encoding': 'gzip, deflate, br', 'Accept': '*/*', 'Connection': 'keep-alive', 'Content-Length': '3405'}
2024-05-21 10:51:14,388 ERROR   wandb-upload_0:1293572 [internal_api.py:upload_file():2771] upload_file response body: 
2024-05-21 10:51:33,930 ERROR   wandb-upload_4:1293572 [internal_api.py:upload_file():2767] upload_file exception https://storage.googleapis.com/wandb-production.appspot.com/1923354735/MonoGS/7i7f5gjm/conda-environment.yaml?Expires=1716344785&GoogleAccessId=gorilla-files-url-signer-man%40wandb-production.iam.gserviceaccount.com&Signature=EVDYObbaalBfRuHPuIIs4NJTCdppmKpHxAnNLjdSe1QDN6a6hLjmiC11aQSD4qP%2FLgPOBp45zUTn6TBcUhpaHqlZNygjhiEZX7Ca6B8klTArywRWcGYmvUpGy7O%2BleSulQSIXobSwqU%2BnRTR07PRCuNcBPTnbqW4CuC37R8fHKLlfmAI1UHGfP2sI%2BlboaOgAd5r%2BM%2FcJppRU2DfKWKWnp6t7v4yZJja%2BYwr7UjygyGHX5lL9hp2spsgl904SnGzFL7U%2FmLKAckP6yFEIZwTv6OhtL0G4DCGbJCOtPnMRFsrapLi2lTX5L4uZH%2Fmk1S6S69x4FC7L5%2Bpmj6gh7nsiA%3D%3D: HTTPSConnectionPool(host='storage.googleapis.com', port=443): Max retries exceeded with url: /wandb-production.appspot.com/1923354735/MonoGS/7i7f5gjm/conda-environment.yaml?Expires=1716344785&GoogleAccessId=gorilla-files-url-signer-man%40wandb-production.iam.gserviceaccount.com&Signature=EVDYObbaalBfRuHPuIIs4NJTCdppmKpHxAnNLjdSe1QDN6a6hLjmiC11aQSD4qP%2FLgPOBp45zUTn6TBcUhpaHqlZNygjhiEZX7Ca6B8klTArywRWcGYmvUpGy7O%2BleSulQSIXobSwqU%2BnRTR07PRCuNcBPTnbqW4CuC37R8fHKLlfmAI1UHGfP2sI%2BlboaOgAd5r%2BM%2FcJppRU2DfKWKWnp6t7v4yZJja%2BYwr7UjygyGHX5lL9hp2spsgl904SnGzFL7U%2FmLKAckP6yFEIZwTv6OhtL0G4DCGbJCOtPnMRFsrapLi2lTX5L4uZH%2Fmk1S6S69x4FC7L5%2Bpmj6gh7nsiA%3D%3D (Caused by NewConnectionError('<urllib3.connection.HTTPSConnection object at 0x7f6e843b4090>: Failed to establish a new connection: [Errno 111] Connection refused'))
2024-05-21 10:51:33,931 ERROR   wandb-upload_4:1293572 [internal_api.py:upload_file():2769] upload_file request headers: {'User-Agent': 'python-requests/2.31.0', 'Accept-Encoding': 'gzip, deflate, br', 'Accept': '*/*', 'Connection': 'keep-alive', 'Content-Length': '4690'}
2024-05-21 10:51:33,931 ERROR   wandb-upload_4:1293572 [internal_api.py:upload_file():2771] upload_file response body: 
2024-05-21 10:52:18,346 ERROR   wandb-upload_5:1293572 [internal_api.py:upload_file():2767] upload_file exception https://storage.googleapis.com/wandb-production.appspot.com/1923354735/MonoGS/7i7f5gjm/config.yaml?Expires=1716344785&GoogleAccessId=gorilla-files-url-signer-man%40wandb-production.iam.gserviceaccount.com&Signature=BMJwBO0b014Q1rvgox%2BYqw0pIWvynCGKcHXP81FuKhooGhVUhYqaVBmViVNciwVsqNKp%2BvW6awp8zq7bi9R7C1S9SMcftKvFNNZTi3MFZUocgiR6bDXJN6BK87FW4A4x3HBA3lUNs%2BWeyT07hWtUTpF3yauVUa0ysE7bU4lqzsHw6wjbYscL%2BUPwtsOABX2fk5Cq9c2xOXBjo76eTHr2dXmLEuUI2yZjhoAw9dyVlAaRkeS3kpnJCE3msbu06izwRBdLpfjl2PnIPuJW32O1U80Rm8bWPcZ5hnthAMzzOX3Junrz0ThnCdN67XHlY6kYXWb2tSdx4J%2BT7ulxfZmRPw%3D%3D: HTTPSConnectionPool(host='storage.googleapis.com', port=443): Max retries exceeded with url: /wandb-production.appspot.com/1923354735/MonoGS/7i7f5gjm/config.yaml?Expires=1716344785&GoogleAccessId=gorilla-files-url-signer-man%40wandb-production.iam.gserviceaccount.com&Signature=BMJwBO0b014Q1rvgox%2BYqw0pIWvynCGKcHXP81FuKhooGhVUhYqaVBmViVNciwVsqNKp%2BvW6awp8zq7bi9R7C1S9SMcftKvFNNZTi3MFZUocgiR6bDXJN6BK87FW4A4x3HBA3lUNs%2BWeyT07hWtUTpF3yauVUa0ysE7bU4lqzsHw6wjbYscL%2BUPwtsOABX2fk5Cq9c2xOXBjo76eTHr2dXmLEuUI2yZjhoAw9dyVlAaRkeS3kpnJCE3msbu06izwRBdLpfjl2PnIPuJW32O1U80Rm8bWPcZ5hnthAMzzOX3Junrz0ThnCdN67XHlY6kYXWb2tSdx4J%2BT7ulxfZmRPw%3D%3D (Caused by NewConnectionError('<urllib3.connection.HTTPSConnection object at 0x7f6e84518850>: Failed to establish a new connection: [Errno 111] Connection refused'))
2024-05-21 10:52:18,347 ERROR   wandb-upload_5:1293572 [internal_api.py:upload_file():2769] upload_file request headers: {'User-Agent': 'python-requests/2.31.0', 'Accept-Encoding': 'gzip, deflate, br', 'Accept': '*/*', 'Connection': 'keep-alive', 'Content-Length': '2747'}
2024-05-21 10:52:18,347 ERROR   wandb-upload_5:1293572 [internal_api.py:upload_file():2771] upload_file response body: 
2024-05-21 10:52:33,688 ERROR   wandb-upload_2:1293572 [internal_api.py:upload_file():2767] upload_file exception https://storage.googleapis.com/wandb-production.appspot.com/1923354735/MonoGS/7i7f5gjm/output.log?Expires=1716344785&GoogleAccessId=gorilla-files-url-signer-man%40wandb-production.iam.gserviceaccount.com&Signature=VLoFH2QdZgsVeMSF7%2BZme2jkQEB5BuWJAxPRoHnj5FpmgAhWt%2BYchg0RqCx7PqoSN03WZ48TzcE1HZY%2Fag0rhCj1rwVp5EzKy%2FSKz%2B5KjD8scah61BdOHMmprbP8zg20%2FgV25YS8%2FOIlmG2G1EbWJ6NgRpjmbFhmC4WPPQ0LMaJ36bnQynJS%2Forxr6%2BpfjJ5SugurpujGl1HCP2FHd5qIGo5fc2oL7RxoOKTKhW02hzUUUoYzhY5fON9KtU4ixGYyAkLpKTUBhzVl%2Fr7rx7pzQJTS8e5gQ3loeJZJoh%2Fj4kHeCpLWmVRkb7VMOchgUDivO0he6tvugSp17daenhjLQ%3D%3D: HTTPSConnectionPool(host='storage.googleapis.com', port=443): Max retries exceeded with url: /wandb-production.appspot.com/1923354735/MonoGS/7i7f5gjm/output.log?Expires=1716344785&GoogleAccessId=gorilla-files-url-signer-man%40wandb-production.iam.gserviceaccount.com&Signature=VLoFH2QdZgsVeMSF7%2BZme2jkQEB5BuWJAxPRoHnj5FpmgAhWt%2BYchg0RqCx7PqoSN03WZ48TzcE1HZY%2Fag0rhCj1rwVp5EzKy%2FSKz%2B5KjD8scah61BdOHMmprbP8zg20%2FgV25YS8%2FOIlmG2G1EbWJ6NgRpjmbFhmC4WPPQ0LMaJ36bnQynJS%2Forxr6%2BpfjJ5SugurpujGl1HCP2FHd5qIGo5fc2oL7RxoOKTKhW02hzUUUoYzhY5fON9KtU4ixGYyAkLpKTUBhzVl%2Fr7rx7pzQJTS8e5gQ3loeJZJoh%2Fj4kHeCpLWmVRkb7VMOchgUDivO0he6tvugSp17daenhjLQ%3D%3D (Caused by NewConnectionError('<urllib3.connection.HTTPSConnection object at 0x7f6e843b8c10>: Failed to establish a new connection: [Errno 111] Connection refused'))
2024-05-21 10:52:33,688 ERROR   wandb-upload_2:1293572 [internal_api.py:upload_file():2769] upload_file request headers: {'User-Agent': 'python-requests/2.31.0', 'Accept-Encoding': 'gzip, deflate, br', 'Accept': '*/*', 'Connection': 'keep-alive', 'Content-Length': '1015'}
2024-05-21 10:52:33,688 ERROR   wandb-upload_2:1293572 [internal_api.py:upload_file():2771] upload_file response body: 
2024-05-21 10:53:33,571 ERROR   wandb-upload_1:1293572 [internal_api.py:upload_file():2767] upload_file exception https://storage.googleapis.com/wandb-production.appspot.com/1923354735/MonoGS/7i7f5gjm/wandb-summary.json?Expires=1716344785&GoogleAccessId=gorilla-files-url-signer-man%40wandb-production.iam.gserviceaccount.com&Signature=jeBYHZuazMllAswE5cCuYPIOXrsDk%2Fi%2Byxjsv9qWnxV%2BGNVzIHitPZSoDMj6MWk0TNlGqYZGlH4B%2BPF%2BhJiqKeqhL2OuOHBETtdtsiWdwH0tIXK1ZdLZnOfccEagnoMyHjd%2BI8iVtowEJcGh5WKQ7a4%2B47kjR3lcOIzwzXrjed270X%2FoNcanSDRgV8xNpf603zC1Vf1qsRhzc6BJ684LVu0rN5GfkVItbl5nymffb%2F%2B%2BzcjF%2BZLQmZ17RQ0QV7xUR7ur9fhcaGfCDFhLfuBOx%2BIisR%2BQ%2Bec%2BD9ldoKK0mB7eEItITzgUcPVBv2GxH5sqHE5OJHUsFgZ0AGP%2Fxp5TXQ%3D%3D: HTTPSConnectionPool(host='storage.googleapis.com', port=443): Max retries exceeded with url: /wandb-production.appspot.com/1923354735/MonoGS/7i7f5gjm/wandb-summary.json?Expires=1716344785&GoogleAccessId=gorilla-files-url-signer-man%40wandb-production.iam.gserviceaccount.com&Signature=jeBYHZuazMllAswE5cCuYPIOXrsDk%2Fi%2Byxjsv9qWnxV%2BGNVzIHitPZSoDMj6MWk0TNlGqYZGlH4B%2BPF%2BhJiqKeqhL2OuOHBETtdtsiWdwH0tIXK1ZdLZnOfccEagnoMyHjd%2BI8iVtowEJcGh5WKQ7a4%2B47kjR3lcOIzwzXrjed270X%2FoNcanSDRgV8xNpf603zC1Vf1qsRhzc6BJ684LVu0rN5GfkVItbl5nymffb%2F%2B%2BzcjF%2BZLQmZ17RQ0QV7xUR7ur9fhcaGfCDFhLfuBOx%2BIisR%2BQ%2Bec%2BD9ldoKK0mB7eEItITzgUcPVBv2GxH5sqHE5OJHUsFgZ0AGP%2Fxp5TXQ%3D%3D (Caused by NewConnectionError('<urllib3.connection.HTTPSConnection object at 0x7f6e843b4f90>: Failed to establish a new connection: [Errno 111] Connection refused'))
2024-05-21 10:53:33,571 ERROR   wandb-upload_1:1293572 [internal_api.py:upload_file():2769] upload_file request headers: {'User-Agent': 'python-requests/2.31.0', 'Accept-Encoding': 'gzip, deflate, br', 'Accept': '*/*', 'Connection': 'keep-alive', 'Content-Length': '27'}
2024-05-21 10:53:33,571 ERROR   wandb-upload_1:1293572 [internal_api.py:upload_file():2771] upload_file response body: 
2024-05-21 10:53:37,809 ERROR   wandb-upload_3:1293572 [internal_api.py:upload_file():2767] upload_file exception https://storage.googleapis.com/wandb-production.appspot.com/1923354735/MonoGS/7i7f5gjm/requirements.txt?Expires=1716344785&GoogleAccessId=gorilla-files-url-signer-man%40wandb-production.iam.gserviceaccount.com&Signature=PUX7QA4OqH2opVL%2Be4xGiUyiSEcJKghhy2ZzJ0ADva78BQw5wvJXcgxmEJhDVPlLvZNtRuCTDz8V5b8xGLORRPLQOCVuu%2FJQrLuJ%2FLBwmKtWfURkzUEK4Bvp7hdQSXE9Bdo%2BIUELc%2FollYAUIR9cLuXGB4LcF3MbuEnRMsx0fmew59GnKSrUTM30OgPMe7XfvvyMYbcrsx0ad8QQYCZfT92VDfDcsSK9EkcnqibOKBeVz6c6NsG0mXNJy%2FjdmeikZD%2B0SnRLK%2B1DJ%2BM%2FD%2FM0HCIJyurX7%2BmrEqThDoVqPZ0dRfK4dmITQg3mu015FcX6P9lNVn6ovViNSvSU0t1JUA%3D%3D: HTTPSConnectionPool(host='storage.googleapis.com', port=443): Max retries exceeded with url: /wandb-production.appspot.com/1923354735/MonoGS/7i7f5gjm/requirements.txt?Expires=1716344785&GoogleAccessId=gorilla-files-url-signer-man%40wandb-production.iam.gserviceaccount.com&Signature=PUX7QA4OqH2opVL%2Be4xGiUyiSEcJKghhy2ZzJ0ADva78BQw5wvJXcgxmEJhDVPlLvZNtRuCTDz8V5b8xGLORRPLQOCVuu%2FJQrLuJ%2FLBwmKtWfURkzUEK4Bvp7hdQSXE9Bdo%2BIUELc%2FollYAUIR9cLuXGB4LcF3MbuEnRMsx0fmew59GnKSrUTM30OgPMe7XfvvyMYbcrsx0ad8QQYCZfT92VDfDcsSK9EkcnqibOKBeVz6c6NsG0mXNJy%2FjdmeikZD%2B0SnRLK%2B1DJ%2BM%2FD%2FM0HCIJyurX7%2BmrEqThDoVqPZ0dRfK4dmITQg3mu015FcX6P9lNVn6ovViNSvSU0t1JUA%3D%3D (Caused by NewConnectionError('<urllib3.connection.HTTPSConnection object at 0x7f6e84378710>: Failed to establish a new connection: [Errno 111] Connection refused'))
2024-05-21 10:53:37,809 ERROR   wandb-upload_3:1293572 [internal_api.py:upload_file():2769] upload_file request headers: {'User-Agent': 'python-requests/2.31.0', 'Accept-Encoding': 'gzip, deflate, br', 'Accept': '*/*', 'Connection': 'keep-alive', 'Content-Length': '2267'}
2024-05-21 10:53:37,810 ERROR   wandb-upload_3:1293572 [internal_api.py:upload_file():2771] upload_file response body: 
2024-05-21 10:56:39,091 ERROR   wandb-upload_4:1293572 [internal_api.py:upload_file():2767] upload_file exception https://storage.googleapis.com/wandb-production.appspot.com/1923354735/MonoGS/7i7f5gjm/conda-environment.yaml?Expires=1716344785&GoogleAccessId=gorilla-files-url-signer-man%40wandb-production.iam.gserviceaccount.com&Signature=EVDYObbaalBfRuHPuIIs4NJTCdppmKpHxAnNLjdSe1QDN6a6hLjmiC11aQSD4qP%2FLgPOBp45zUTn6TBcUhpaHqlZNygjhiEZX7Ca6B8klTArywRWcGYmvUpGy7O%2BleSulQSIXobSwqU%2BnRTR07PRCuNcBPTnbqW4CuC37R8fHKLlfmAI1UHGfP2sI%2BlboaOgAd5r%2BM%2FcJppRU2DfKWKWnp6t7v4yZJja%2BYwr7UjygyGHX5lL9hp2spsgl904SnGzFL7U%2FmLKAckP6yFEIZwTv6OhtL0G4DCGbJCOtPnMRFsrapLi2lTX5L4uZH%2Fmk1S6S69x4FC7L5%2Bpmj6gh7nsiA%3D%3D: HTTPSConnectionPool(host='storage.googleapis.com', port=443): Max retries exceeded with url: /wandb-production.appspot.com/1923354735/MonoGS/7i7f5gjm/conda-environment.yaml?Expires=1716344785&GoogleAccessId=gorilla-files-url-signer-man%40wandb-production.iam.gserviceaccount.com&Signature=EVDYObbaalBfRuHPuIIs4NJTCdppmKpHxAnNLjdSe1QDN6a6hLjmiC11aQSD4qP%2FLgPOBp45zUTn6TBcUhpaHqlZNygjhiEZX7Ca6B8klTArywRWcGYmvUpGy7O%2BleSulQSIXobSwqU%2BnRTR07PRCuNcBPTnbqW4CuC37R8fHKLlfmAI1UHGfP2sI%2BlboaOgAd5r%2BM%2FcJppRU2DfKWKWnp6t7v4yZJja%2BYwr7UjygyGHX5lL9hp2spsgl904SnGzFL7U%2FmLKAckP6yFEIZwTv6OhtL0G4DCGbJCOtPnMRFsrapLi2lTX5L4uZH%2Fmk1S6S69x4FC7L5%2Bpmj6gh7nsiA%3D%3D (Caused by NewConnectionError('<urllib3.connection.HTTPSConnection object at 0x7f6e8438ee90>: Failed to establish a new connection: [Errno 111] Connection refused'))
2024-05-21 10:56:39,092 ERROR   wandb-upload_4:1293572 [internal_api.py:upload_file():2769] upload_file request headers: {'User-Agent': 'python-requests/2.31.0', 'Accept-Encoding': 'gzip, deflate, br', 'Accept': '*/*', 'Connection': 'keep-alive', 'Content-Length': '4690'}
2024-05-21 10:56:39,092 ERROR   wandb-upload_4:1293572 [internal_api.py:upload_file():2771] upload_file response body: 
2024-05-21 10:57:22,349 ERROR   wandb-upload_0:1293572 [internal_api.py:upload_file():2767] upload_file exception https://storage.googleapis.com/wandb-production.appspot.com/1923354735/MonoGS/7i7f5gjm/wandb-metadata.json?Expires=1716344732&GoogleAccessId=gorilla-files-url-signer-man%40wandb-production.iam.gserviceaccount.com&Signature=cDR3s4Btu8wUHMp7Bq8tJfPSneZs1lKn2s29OU2rf%2FQIynPqqnBm7KTt%2FUEbBkk02uPdYlSFQ9EV28DpKWGSjPzJUwI2lj6lzR%2FVCrCdrmNQF2B6LpGTVwfUfNo%2BgAMipws%2FssygMCuS0ObkO8Ckn4inWWTYBfrsEeAYuXXQ1MpkDWgrDTmFzIWIh7uhGxi5rRZGleTaZq3oxaGDid1%2FfSVTAKln9OgAsZRMb3CU44aJcHVk9lBYHWz9LI%2Fdrn9Se0ZlWbNUG9fX7iLx2N8X7pmCC2x1luKH8B87YHHaoGoUezsZnaVDfAWe31WtqGOpRQoXCjyFDeT%2FQZWmt8yRAA%3D%3D: HTTPSConnectionPool(host='storage.googleapis.com', port=443): Max retries exceeded with url: /wandb-production.appspot.com/1923354735/MonoGS/7i7f5gjm/wandb-metadata.json?Expires=1716344732&GoogleAccessId=gorilla-files-url-signer-man%40wandb-production.iam.gserviceaccount.com&Signature=cDR3s4Btu8wUHMp7Bq8tJfPSneZs1lKn2s29OU2rf%2FQIynPqqnBm7KTt%2FUEbBkk02uPdYlSFQ9EV28DpKWGSjPzJUwI2lj6lzR%2FVCrCdrmNQF2B6LpGTVwfUfNo%2BgAMipws%2FssygMCuS0ObkO8Ckn4inWWTYBfrsEeAYuXXQ1MpkDWgrDTmFzIWIh7uhGxi5rRZGleTaZq3oxaGDid1%2FfSVTAKln9OgAsZRMb3CU44aJcHVk9lBYHWz9LI%2Fdrn9Se0ZlWbNUG9fX7iLx2N8X7pmCC2x1luKH8B87YHHaoGoUezsZnaVDfAWe31WtqGOpRQoXCjyFDeT%2FQZWmt8yRAA%3D%3D (Caused by NewConnectionError('<urllib3.connection.HTTPSConnection object at 0x7f6e8438e8d0>: Failed to establish a new connection: [Errno 111] Connection refused'))
2024-05-21 10:57:22,349 ERROR   wandb-upload_0:1293572 [internal_api.py:upload_file():2769] upload_file request headers: {'User-Agent': 'python-requests/2.31.0', 'Accept-Encoding': 'gzip, deflate, br', 'Accept': '*/*', 'Connection': 'keep-alive', 'Content-Length': '3405'}
2024-05-21 10:57:22,349 ERROR   wandb-upload_0:1293572 [internal_api.py:upload_file():2771] upload_file response body: 
2024-05-21 10:58:12,110 ERROR   wandb-upload_5:1293572 [internal_api.py:upload_file():2767] upload_file exception https://storage.googleapis.com/wandb-production.appspot.com/1923354735/MonoGS/7i7f5gjm/config.yaml?Expires=1716344785&GoogleAccessId=gorilla-files-url-signer-man%40wandb-production.iam.gserviceaccount.com&Signature=BMJwBO0b014Q1rvgox%2BYqw0pIWvynCGKcHXP81FuKhooGhVUhYqaVBmViVNciwVsqNKp%2BvW6awp8zq7bi9R7C1S9SMcftKvFNNZTi3MFZUocgiR6bDXJN6BK87FW4A4x3HBA3lUNs%2BWeyT07hWtUTpF3yauVUa0ysE7bU4lqzsHw6wjbYscL%2BUPwtsOABX2fk5Cq9c2xOXBjo76eTHr2dXmLEuUI2yZjhoAw9dyVlAaRkeS3kpnJCE3msbu06izwRBdLpfjl2PnIPuJW32O1U80Rm8bWPcZ5hnthAMzzOX3Junrz0ThnCdN67XHlY6kYXWb2tSdx4J%2BT7ulxfZmRPw%3D%3D: HTTPSConnectionPool(host='storage.googleapis.com', port=443): Max retries exceeded with url: /wandb-production.appspot.com/1923354735/MonoGS/7i7f5gjm/config.yaml?Expires=1716344785&GoogleAccessId=gorilla-files-url-signer-man%40wandb-production.iam.gserviceaccount.com&Signature=BMJwBO0b014Q1rvgox%2BYqw0pIWvynCGKcHXP81FuKhooGhVUhYqaVBmViVNciwVsqNKp%2BvW6awp8zq7bi9R7C1S9SMcftKvFNNZTi3MFZUocgiR6bDXJN6BK87FW4A4x3HBA3lUNs%2BWeyT07hWtUTpF3yauVUa0ysE7bU4lqzsHw6wjbYscL%2BUPwtsOABX2fk5Cq9c2xOXBjo76eTHr2dXmLEuUI2yZjhoAw9dyVlAaRkeS3kpnJCE3msbu06izwRBdLpfjl2PnIPuJW32O1U80Rm8bWPcZ5hnthAMzzOX3Junrz0ThnCdN67XHlY6kYXWb2tSdx4J%2BT7ulxfZmRPw%3D%3D (Caused by NewConnectionError('<urllib3.connection.HTTPSConnection object at 0x7f6e843ad190>: Failed to establish a new connection: [Errno 111] Connection refused'))
2024-05-21 10:58:12,110 ERROR   wandb-upload_5:1293572 [internal_api.py:upload_file():2769] upload_file request headers: {'User-Agent': 'python-requests/2.31.0', 'Accept-Encoding': 'gzip, deflate, br', 'Accept': '*/*', 'Connection': 'keep-alive', 'Content-Length': '2747'}
2024-05-21 10:58:12,110 ERROR   wandb-upload_5:1293572 [internal_api.py:upload_file():2771] upload_file response body: 
