2024-05-21 10:24:45,200 INFO    StreamThr :1290853 [internal.py:wandb_internal():89] W&B internal server running at pid: 1290853, started at: 2024-05-21 10:24:45.199783
2024-05-21 10:24:45,202 DEBUG   HandlerThread:1290853 [handler.py:handle_request():146] handle_request: status
2024-05-21 10:24:45,204 INFO    WriterThread:1290853 [datastore.py:open_for_write():87] open: /home/lsr/MonoGS_Version_Control/MonoGS/wandb/run-20240521_102445-y7r8ow8y/run-y7r8ow8y.wandb
2024-05-21 10:24:45,205 DEBUG   SenderThread:1290853 [sender.py:send():379] send: header
2024-05-21 10:24:45,219 DEBUG   SenderThread:1290853 [sender.py:send():379] send: run
2024-05-21 10:24:45,821 INFO    SenderThread:1290853 [dir_watcher.py:__init__():211] watching files in: /home/lsr/MonoGS_Version_Control/MonoGS/wandb/run-20240521_102445-y7r8ow8y/files
2024-05-21 10:24:45,822 INFO    SenderThread:1290853 [sender.py:_start_run_threads():1127] run started: y7r8ow8y with start time 1716258285.199703
2024-05-21 10:24:45,835 DEBUG   HandlerThread:1290853 [handler.py:handle_request():146] handle_request: check_version
2024-05-21 10:24:45,835 DEBUG   SenderThread:1290853 [sender.py:send_request():406] send_request: check_version
2024-05-21 10:24:46,225 DEBUG   HandlerThread:1290853 [handler.py:handle_request():146] handle_request: run_start
2024-05-21 10:24:46,275 DEBUG   HandlerThread:1290853 [system_info.py:__init__():26] System info init
2024-05-21 10:24:46,275 DEBUG   HandlerThread:1290853 [system_info.py:__init__():41] System info init done
2024-05-21 10:24:46,275 INFO    HandlerThread:1290853 [system_monitor.py:start():194] Starting system monitor
2024-05-21 10:24:46,276 INFO    SystemMonitor:1290853 [system_monitor.py:_start():158] Starting system asset monitoring threads
2024-05-21 10:24:46,278 INFO    HandlerThread:1290853 [system_monitor.py:probe():214] Collecting system info
2024-05-21 10:24:46,278 INFO    SystemMonitor:1290853 [interfaces.py:start():190] Started cpu monitoring
2024-05-21 10:24:46,280 INFO    SystemMonitor:1290853 [interfaces.py:start():190] Started disk monitoring
2024-05-21 10:24:46,281 INFO    SystemMonitor:1290853 [interfaces.py:start():190] Started gpu monitoring
2024-05-21 10:24:46,283 INFO    SystemMonitor:1290853 [interfaces.py:start():190] Started memory monitoring
2024-05-21 10:24:46,284 INFO    SystemMonitor:1290853 [interfaces.py:start():190] Started network monitoring
2024-05-21 10:24:46,326 DEBUG   HandlerThread:1290853 [system_info.py:probe():150] Probing system
2024-05-21 10:24:46,337 DEBUG   HandlerThread:1290853 [system_info.py:_probe_git():135] Probing git
2024-05-21 10:24:46,356 DEBUG   HandlerThread:1290853 [system_info.py:_probe_git():143] Probing git done
2024-05-21 10:24:46,356 DEBUG   HandlerThread:1290853 [system_info.py:probe():198] Probing system done
2024-05-21 10:24:46,356 DEBUG   HandlerThread:1290853 [system_monitor.py:probe():223] {'os': 'Linux-5.15.0-105-generic-x86_64-with-debian-bullseye-sid', 'python': '3.7.13', 'heartbeatAt': '2024-05-21T02:24:46.327234', 'startedAt': '2024-05-21T02:24:45.191587', 'docker': None, 'cuda': None, 'args': ('--config', 'configs/rgbd/tum/fr4_office.yaml'), 'state': 'running', 'program': 'slam.py', 'codePathLocal': 'slam.py', 'codePath': 'slam.py', 'git': {'remote': 'https://github.com/IAMXII/MonoGS.git', 'commit': '55e124f658cb987b14427df85d23cc3b34296aa3'}, 'email': '675560021@qq.com', 'root': '/home/lsr/MonoGS_Version_Control/MonoGS', 'host': 'lsr', 'username': 'lsr', 'executable': '/home/lsr/anaconda3/envs/MonoGS/bin/python', 'cpu_count': 12, 'cpu_count_logical': 20, 'cpu_freq': {'current': 2099.7892500000003, 'min': 800.0, 'max': 4580.0}, 'cpu_freq_per_core': [{'current': 2603.956, 'min': 800.0, 'max': 4800.0}, {'current': 2100.0, 'min': 800.0, 'max': 4800.0}, {'current': 2100.0, 'min': 800.0, 'max': 4800.0}, {'current': 2100.0, 'min': 800.0, 'max': 4800.0}, {'current': 2100.0, 'min': 800.0, 'max': 4800.0}, {'current': 2100.0, 'min': 800.0, 'max': 4800.0}, {'current': 2100.0, 'min': 800.0, 'max': 4800.0}, {'current': 2100.0, 'min': 800.0, 'max': 4800.0}, {'current': 2100.0, 'min': 800.0, 'max': 4900.0}, {'current': 2100.0, 'min': 800.0, 'max': 4900.0}, {'current': 2100.0, 'min': 800.0, 'max': 4900.0}, {'current': 2100.0, 'min': 800.0, 'max': 4900.0}, {'current': 2100.0, 'min': 800.0, 'max': 4800.0}, {'current': 2100.0, 'min': 800.0, 'max': 4800.0}, {'current': 2100.0, 'min': 800.0, 'max': 4800.0}, {'current': 2100.0, 'min': 800.0, 'max': 4800.0}, {'current': 2100.0, 'min': 800.0, 'max': 3600.0}, {'current': 2100.0, 'min': 800.0, 'max': 3600.0}, {'current': 2100.0, 'min': 800.0, 'max': 3600.0}, {'current': 2100.0, 'min': 800.0, 'max': 3600.0}], 'disk': {'/': {'total': 548.9532012939453, 'used': 140.476806640625}}, 'gpu': 'NVIDIA GeForce RTX 4090', 'gpu_count': 1, 'gpu_devices': [{'name': 'NVIDIA GeForce RTX 4090', 'memory_total': 25757220864}], 'memory': {'total': 62.535736083984375}}
2024-05-21 10:24:46,356 INFO    HandlerThread:1290853 [system_monitor.py:probe():224] Finished collecting system info
2024-05-21 10:24:46,356 INFO    HandlerThread:1290853 [system_monitor.py:probe():227] Publishing system info
2024-05-21 10:24:46,356 DEBUG   HandlerThread:1290853 [system_info.py:_save_conda():208] Saving list of conda packages installed into the current environment
2024-05-21 10:24:46,822 INFO    Thread-12 :1290853 [dir_watcher.py:_on_file_created():271] file/dir created: /home/lsr/MonoGS_Version_Control/MonoGS/wandb/run-20240521_102445-y7r8ow8y/files/conda-environment.yaml
2024-05-21 10:24:48,977 DEBUG   HandlerThread:1290853 [system_info.py:_save_conda():222] Saving conda packages done
2024-05-21 10:24:48,979 INFO    HandlerThread:1290853 [system_monitor.py:probe():229] Finished publishing system info
2024-05-21 10:24:48,981 DEBUG   SenderThread:1290853 [sender.py:send():379] send: files
2024-05-21 10:24:48,981 INFO    SenderThread:1290853 [sender.py:_save_file():1390] saving file wandb-metadata.json with policy now
2024-05-21 10:24:49,032 DEBUG   HandlerThread:1290853 [handler.py:handle_request():146] handle_request: python_packages
2024-05-21 10:24:49,032 DEBUG   SenderThread:1290853 [sender.py:send_request():406] send_request: python_packages
2024-05-21 10:24:49,034 DEBUG   SenderThread:1290853 [sender.py:send():379] send: telemetry
2024-05-21 10:24:49,079 DEBUG   HandlerThread:1290853 [handler.py:handle_request():146] handle_request: internal_messages
2024-05-21 10:24:49,079 DEBUG   HandlerThread:1290853 [handler.py:handle_request():146] handle_request: stop_status
2024-05-21 10:24:49,080 DEBUG   SenderThread:1290853 [sender.py:send_request():406] send_request: stop_status
2024-05-21 10:24:49,456 ERROR   wandb-upload_0:1290853 [internal_api.py:upload_file():2767] upload_file exception https://storage.googleapis.com/wandb-production.appspot.com/1923354735/MonoGS/y7r8ow8y/wandb-metadata.json?Expires=1716344689&GoogleAccessId=gorilla-files-url-signer-man%40wandb-production.iam.gserviceaccount.com&Signature=XocjRmoIFbGhOWBuXHuQ1YhKHLYkoSCeErITJdS8ptWPCsz3MOZyInwqvfgV1AZwEKws5oPw3%2FDwg85hQPHAmupIZkrP%2FbzB80ItKNP%2FF37E4x7FatfKjo6Hx%2Blh6yxHbiVm%2BvTSvuL%2BRLunzyQhKrpBG8Qfx2K0vR52s0eIcahq37a1liZqh3oYSnC07NnlHFejfubqJTF65nXAiLz0%2B7IRQ6cPHAueqi4g6ath5yiztED2FGfOW2i73RW7lux%2FC8MDffiA0UrP30CrlqM6OVwjcoEbSqfaJxx7%2B0fnOFYZ3afMjjX5iJaH0ndAPKs0qCHPV%2FLlYU%2FKzWzLxt2GNA%3D%3D: HTTPSConnectionPool(host='storage.googleapis.com', port=443): Max retries exceeded with url: /wandb-production.appspot.com/1923354735/MonoGS/y7r8ow8y/wandb-metadata.json?Expires=1716344689&GoogleAccessId=gorilla-files-url-signer-man%40wandb-production.iam.gserviceaccount.com&Signature=XocjRmoIFbGhOWBuXHuQ1YhKHLYkoSCeErITJdS8ptWPCsz3MOZyInwqvfgV1AZwEKws5oPw3%2FDwg85hQPHAmupIZkrP%2FbzB80ItKNP%2FF37E4x7FatfKjo6Hx%2Blh6yxHbiVm%2BvTSvuL%2BRLunzyQhKrpBG8Qfx2K0vR52s0eIcahq37a1liZqh3oYSnC07NnlHFejfubqJTF65nXAiLz0%2B7IRQ6cPHAueqi4g6ath5yiztED2FGfOW2i73RW7lux%2FC8MDffiA0UrP30CrlqM6OVwjcoEbSqfaJxx7%2B0fnOFYZ3afMjjX5iJaH0ndAPKs0qCHPV%2FLlYU%2FKzWzLxt2GNA%3D%3D (Caused by NewConnectionError('<urllib3.connection.HTTPSConnection object at 0x7f9aec786fd0>: Failed to establish a new connection: [Errno 111] Connection refused'))
2024-05-21 10:24:49,456 ERROR   wandb-upload_0:1290853 [internal_api.py:upload_file():2769] upload_file request headers: {'User-Agent': 'python-requests/2.31.0', 'Accept-Encoding': 'gzip, deflate, br', 'Accept': '*/*', 'Connection': 'keep-alive', 'Content-Length': '3405'}
2024-05-21 10:24:49,456 ERROR   wandb-upload_0:1290853 [internal_api.py:upload_file():2771] upload_file response body: 
2024-05-21 10:24:49,484 DEBUG   SenderThread:1290853 [sender.py:send():379] send: metric
2024-05-21 10:24:49,484 DEBUG   SenderThread:1290853 [sender.py:send():379] send: telemetry
2024-05-21 10:24:49,484 DEBUG   SenderThread:1290853 [sender.py:send():379] send: metric
2024-05-21 10:24:49,484 WARNING SenderThread:1290853 [sender.py:send_metric():1341] Seen metric with glob (shouldn't happen)
2024-05-21 10:24:49,822 INFO    Thread-12 :1290853 [dir_watcher.py:_on_file_modified():288] file/dir modified: /home/lsr/MonoGS_Version_Control/MonoGS/wandb/run-20240521_102445-y7r8ow8y/files/conda-environment.yaml
2024-05-21 10:24:49,822 INFO    Thread-12 :1290853 [dir_watcher.py:_on_file_created():271] file/dir created: /home/lsr/MonoGS_Version_Control/MonoGS/wandb/run-20240521_102445-y7r8ow8y/files/wandb-metadata.json
2024-05-21 10:24:49,822 INFO    Thread-12 :1290853 [dir_watcher.py:_on_file_created():271] file/dir created: /home/lsr/MonoGS_Version_Control/MonoGS/wandb/run-20240521_102445-y7r8ow8y/files/requirements.txt
2024-05-21 10:24:50,484 DEBUG   HandlerThread:1290853 [handler.py:handle_request():146] handle_request: status_report
2024-05-21 10:24:50,651 ERROR   wandb-upload_0:1290853 [internal_api.py:upload_file():2767] upload_file exception https://storage.googleapis.com/wandb-production.appspot.com/1923354735/MonoGS/y7r8ow8y/wandb-metadata.json?Expires=1716344689&GoogleAccessId=gorilla-files-url-signer-man%40wandb-production.iam.gserviceaccount.com&Signature=XocjRmoIFbGhOWBuXHuQ1YhKHLYkoSCeErITJdS8ptWPCsz3MOZyInwqvfgV1AZwEKws5oPw3%2FDwg85hQPHAmupIZkrP%2FbzB80ItKNP%2FF37E4x7FatfKjo6Hx%2Blh6yxHbiVm%2BvTSvuL%2BRLunzyQhKrpBG8Qfx2K0vR52s0eIcahq37a1liZqh3oYSnC07NnlHFejfubqJTF65nXAiLz0%2B7IRQ6cPHAueqi4g6ath5yiztED2FGfOW2i73RW7lux%2FC8MDffiA0UrP30CrlqM6OVwjcoEbSqfaJxx7%2B0fnOFYZ3afMjjX5iJaH0ndAPKs0qCHPV%2FLlYU%2FKzWzLxt2GNA%3D%3D: HTTPSConnectionPool(host='storage.googleapis.com', port=443): Max retries exceeded with url: /wandb-production.appspot.com/1923354735/MonoGS/y7r8ow8y/wandb-metadata.json?Expires=1716344689&GoogleAccessId=gorilla-files-url-signer-man%40wandb-production.iam.gserviceaccount.com&Signature=XocjRmoIFbGhOWBuXHuQ1YhKHLYkoSCeErITJdS8ptWPCsz3MOZyInwqvfgV1AZwEKws5oPw3%2FDwg85hQPHAmupIZkrP%2FbzB80ItKNP%2FF37E4x7FatfKjo6Hx%2Blh6yxHbiVm%2BvTSvuL%2BRLunzyQhKrpBG8Qfx2K0vR52s0eIcahq37a1liZqh3oYSnC07NnlHFejfubqJTF65nXAiLz0%2B7IRQ6cPHAueqi4g6ath5yiztED2FGfOW2i73RW7lux%2FC8MDffiA0UrP30CrlqM6OVwjcoEbSqfaJxx7%2B0fnOFYZ3afMjjX5iJaH0ndAPKs0qCHPV%2FLlYU%2FKzWzLxt2GNA%3D%3D (Caused by NewConnectionError('<urllib3.connection.HTTPSConnection object at 0x7f9aec786750>: Failed to establish a new connection: [Errno 111] Connection refused'))
2024-05-21 10:24:50,651 ERROR   wandb-upload_0:1290853 [internal_api.py:upload_file():2769] upload_file request headers: {'User-Agent': 'python-requests/2.31.0', 'Accept-Encoding': 'gzip, deflate, br', 'Accept': '*/*', 'Connection': 'keep-alive', 'Content-Length': '3405'}
2024-05-21 10:24:50,651 ERROR   wandb-upload_0:1290853 [internal_api.py:upload_file():2771] upload_file response body: 
2024-05-21 10:24:52,752 ERROR   wandb-upload_0:1290853 [internal_api.py:upload_file():2767] upload_file exception https://storage.googleapis.com/wandb-production.appspot.com/1923354735/MonoGS/y7r8ow8y/wandb-metadata.json?Expires=1716344689&GoogleAccessId=gorilla-files-url-signer-man%40wandb-production.iam.gserviceaccount.com&Signature=XocjRmoIFbGhOWBuXHuQ1YhKHLYkoSCeErITJdS8ptWPCsz3MOZyInwqvfgV1AZwEKws5oPw3%2FDwg85hQPHAmupIZkrP%2FbzB80ItKNP%2FF37E4x7FatfKjo6Hx%2Blh6yxHbiVm%2BvTSvuL%2BRLunzyQhKrpBG8Qfx2K0vR52s0eIcahq37a1liZqh3oYSnC07NnlHFejfubqJTF65nXAiLz0%2B7IRQ6cPHAueqi4g6ath5yiztED2FGfOW2i73RW7lux%2FC8MDffiA0UrP30CrlqM6OVwjcoEbSqfaJxx7%2B0fnOFYZ3afMjjX5iJaH0ndAPKs0qCHPV%2FLlYU%2FKzWzLxt2GNA%3D%3D: HTTPSConnectionPool(host='storage.googleapis.com', port=443): Max retries exceeded with url: /wandb-production.appspot.com/1923354735/MonoGS/y7r8ow8y/wandb-metadata.json?Expires=1716344689&GoogleAccessId=gorilla-files-url-signer-man%40wandb-production.iam.gserviceaccount.com&Signature=XocjRmoIFbGhOWBuXHuQ1YhKHLYkoSCeErITJdS8ptWPCsz3MOZyInwqvfgV1AZwEKws5oPw3%2FDwg85hQPHAmupIZkrP%2FbzB80ItKNP%2FF37E4x7FatfKjo6Hx%2Blh6yxHbiVm%2BvTSvuL%2BRLunzyQhKrpBG8Qfx2K0vR52s0eIcahq37a1liZqh3oYSnC07NnlHFejfubqJTF65nXAiLz0%2B7IRQ6cPHAueqi4g6ath5yiztED2FGfOW2i73RW7lux%2FC8MDffiA0UrP30CrlqM6OVwjcoEbSqfaJxx7%2B0fnOFYZ3afMjjX5iJaH0ndAPKs0qCHPV%2FLlYU%2FKzWzLxt2GNA%3D%3D (Caused by NewConnectionError('<urllib3.connection.HTTPSConnection object at 0x7f9aec7ac210>: Failed to establish a new connection: [Errno 111] Connection refused'))
2024-05-21 10:24:52,752 ERROR   wandb-upload_0:1290853 [internal_api.py:upload_file():2769] upload_file request headers: {'User-Agent': 'python-requests/2.31.0', 'Accept-Encoding': 'gzip, deflate, br', 'Accept': '*/*', 'Connection': 'keep-alive', 'Content-Length': '3405'}
2024-05-21 10:24:52,752 ERROR   wandb-upload_0:1290853 [internal_api.py:upload_file():2771] upload_file response body: 
2024-05-21 10:24:52,752 INFO    wandb-upload_0:1290853 [retry.py:__call__():172] Retry attempt failed:
Traceback (most recent call last):
  File "/home/lsr/anaconda3/envs/MonoGS/lib/python3.7/site-packages/urllib3/connection.py", line 202, in _new_conn
    socket_options=self.socket_options,
  File "/home/lsr/anaconda3/envs/MonoGS/lib/python3.7/site-packages/urllib3/util/connection.py", line 85, in create_connection
    raise err
  File "/home/lsr/anaconda3/envs/MonoGS/lib/python3.7/site-packages/urllib3/util/connection.py", line 73, in create_connection
    sock.connect(sa)
ConnectionRefusedError: [Errno 111] Connection refused

The above exception was the direct cause of the following exception:

Traceback (most recent call last):
  File "/home/lsr/anaconda3/envs/MonoGS/lib/python3.7/site-packages/urllib3/connectionpool.py", line 805, in urlopen
    **response_kw,
  File "/home/lsr/anaconda3/envs/MonoGS/lib/python3.7/site-packages/urllib3/connectionpool.py", line 491, in _make_request
    raise new_e
  File "/home/lsr/anaconda3/envs/MonoGS/lib/python3.7/site-packages/urllib3/connectionpool.py", line 467, in _make_request
    self._validate_conn(conn)
  File "/home/lsr/anaconda3/envs/MonoGS/lib/python3.7/site-packages/urllib3/connectionpool.py", line 1099, in _validate_conn
    conn.connect()
  File "/home/lsr/anaconda3/envs/MonoGS/lib/python3.7/site-packages/urllib3/connection.py", line 616, in connect
    self.sock = sock = self._new_conn()
  File "/home/lsr/anaconda3/envs/MonoGS/lib/python3.7/site-packages/urllib3/connection.py", line 215, in _new_conn
    ) from e
urllib3.exceptions.NewConnectionError: <urllib3.connection.HTTPSConnection object at 0x7f9aec7ac210>: Failed to establish a new connection: [Errno 111] Connection refused

The above exception was the direct cause of the following exception:

Traceback (most recent call last):
  File "/home/lsr/anaconda3/envs/MonoGS/lib/python3.7/site-packages/requests/adapters.py", line 497, in send
    chunked=chunked,
  File "/home/lsr/anaconda3/envs/MonoGS/lib/python3.7/site-packages/urllib3/connectionpool.py", line 848, in urlopen
    method, url, error=new_e, _pool=self, _stacktrace=sys.exc_info()[2]
  File "/home/lsr/anaconda3/envs/MonoGS/lib/python3.7/site-packages/urllib3/util/retry.py", line 515, in increment
    raise MaxRetryError(_pool, url, reason) from reason  # type: ignore[arg-type]
urllib3.exceptions.MaxRetryError: HTTPSConnectionPool(host='storage.googleapis.com', port=443): Max retries exceeded with url: /wandb-production.appspot.com/1923354735/MonoGS/y7r8ow8y/wandb-metadata.json?Expires=1716344689&GoogleAccessId=gorilla-files-url-signer-man%40wandb-production.iam.gserviceaccount.com&Signature=XocjRmoIFbGhOWBuXHuQ1YhKHLYkoSCeErITJdS8ptWPCsz3MOZyInwqvfgV1AZwEKws5oPw3%2FDwg85hQPHAmupIZkrP%2FbzB80ItKNP%2FF37E4x7FatfKjo6Hx%2Blh6yxHbiVm%2BvTSvuL%2BRLunzyQhKrpBG8Qfx2K0vR52s0eIcahq37a1liZqh3oYSnC07NnlHFejfubqJTF65nXAiLz0%2B7IRQ6cPHAueqi4g6ath5yiztED2FGfOW2i73RW7lux%2FC8MDffiA0UrP30CrlqM6OVwjcoEbSqfaJxx7%2B0fnOFYZ3afMjjX5iJaH0ndAPKs0qCHPV%2FLlYU%2FKzWzLxt2GNA%3D%3D (Caused by NewConnectionError('<urllib3.connection.HTTPSConnection object at 0x7f9aec7ac210>: Failed to establish a new connection: [Errno 111] Connection refused'))

During handling of the above exception, another exception occurred:

Traceback (most recent call last):
  File "/home/lsr/anaconda3/envs/MonoGS/lib/python3.7/site-packages/wandb/sdk/internal/internal_api.py", line 2761, in upload_file
    url, data=progress, headers=extra_headers
  File "/home/lsr/anaconda3/envs/MonoGS/lib/python3.7/site-packages/requests/sessions.py", line 649, in put
    return self.request("PUT", url, data=data, **kwargs)
  File "/home/lsr/anaconda3/envs/MonoGS/lib/python3.7/site-packages/requests/sessions.py", line 589, in request
    resp = self.send(prep, **send_kwargs)
  File "/home/lsr/anaconda3/envs/MonoGS/lib/python3.7/site-packages/requests/sessions.py", line 703, in send
    r = adapter.send(request, **kwargs)
  File "/home/lsr/anaconda3/envs/MonoGS/lib/python3.7/site-packages/requests/adapters.py", line 519, in send
    raise ConnectionError(e, request=request)
requests.exceptions.ConnectionError: HTTPSConnectionPool(host='storage.googleapis.com', port=443): Max retries exceeded with url: /wandb-production.appspot.com/1923354735/MonoGS/y7r8ow8y/wandb-metadata.json?Expires=1716344689&GoogleAccessId=gorilla-files-url-signer-man%40wandb-production.iam.gserviceaccount.com&Signature=XocjRmoIFbGhOWBuXHuQ1YhKHLYkoSCeErITJdS8ptWPCsz3MOZyInwqvfgV1AZwEKws5oPw3%2FDwg85hQPHAmupIZkrP%2FbzB80ItKNP%2FF37E4x7FatfKjo6Hx%2Blh6yxHbiVm%2BvTSvuL%2BRLunzyQhKrpBG8Qfx2K0vR52s0eIcahq37a1liZqh3oYSnC07NnlHFejfubqJTF65nXAiLz0%2B7IRQ6cPHAueqi4g6ath5yiztED2FGfOW2i73RW7lux%2FC8MDffiA0UrP30CrlqM6OVwjcoEbSqfaJxx7%2B0fnOFYZ3afMjjX5iJaH0ndAPKs0qCHPV%2FLlYU%2FKzWzLxt2GNA%3D%3D (Caused by NewConnectionError('<urllib3.connection.HTTPSConnection object at 0x7f9aec7ac210>: Failed to establish a new connection: [Errno 111] Connection refused'))

During handling of the above exception, another exception occurred:

Traceback (most recent call last):
  File "/home/lsr/anaconda3/envs/MonoGS/lib/python3.7/site-packages/wandb/sdk/lib/retry.py", line 131, in __call__
    result = self._call_fn(*args, **kwargs)
  File "/home/lsr/anaconda3/envs/MonoGS/lib/python3.7/site-packages/wandb/sdk/internal/internal_api.py", line 2791, in upload_file
    raise _e.with_traceback(sys.exc_info()[2])
  File "/home/lsr/anaconda3/envs/MonoGS/lib/python3.7/site-packages/wandb/sdk/internal/internal_api.py", line 2761, in upload_file
    url, data=progress, headers=extra_headers
  File "/home/lsr/anaconda3/envs/MonoGS/lib/python3.7/site-packages/requests/sessions.py", line 649, in put
    return self.request("PUT", url, data=data, **kwargs)
  File "/home/lsr/anaconda3/envs/MonoGS/lib/python3.7/site-packages/requests/sessions.py", line 589, in request
    resp = self.send(prep, **send_kwargs)
  File "/home/lsr/anaconda3/envs/MonoGS/lib/python3.7/site-packages/requests/sessions.py", line 703, in send
    r = adapter.send(request, **kwargs)
  File "/home/lsr/anaconda3/envs/MonoGS/lib/python3.7/site-packages/requests/adapters.py", line 519, in send
    raise ConnectionError(e, request=request)
wandb.sdk.lib.retry.TransientError: None
2024-05-21 10:24:55,484 DEBUG   HandlerThread:1290853 [handler.py:handle_request():146] handle_request: status_report
2024-05-21 10:24:56,824 INFO    Thread-12 :1290853 [dir_watcher.py:_on_file_created():271] file/dir created: /home/lsr/MonoGS_Version_Control/MonoGS/wandb/run-20240521_102445-y7r8ow8y/files/output.log
2024-05-21 10:24:57,703 ERROR   wandb-upload_0:1290853 [internal_api.py:upload_file():2767] upload_file exception https://storage.googleapis.com/wandb-production.appspot.com/1923354735/MonoGS/y7r8ow8y/wandb-metadata.json?Expires=1716344689&GoogleAccessId=gorilla-files-url-signer-man%40wandb-production.iam.gserviceaccount.com&Signature=XocjRmoIFbGhOWBuXHuQ1YhKHLYkoSCeErITJdS8ptWPCsz3MOZyInwqvfgV1AZwEKws5oPw3%2FDwg85hQPHAmupIZkrP%2FbzB80ItKNP%2FF37E4x7FatfKjo6Hx%2Blh6yxHbiVm%2BvTSvuL%2BRLunzyQhKrpBG8Qfx2K0vR52s0eIcahq37a1liZqh3oYSnC07NnlHFejfubqJTF65nXAiLz0%2B7IRQ6cPHAueqi4g6ath5yiztED2FGfOW2i73RW7lux%2FC8MDffiA0UrP30CrlqM6OVwjcoEbSqfaJxx7%2B0fnOFYZ3afMjjX5iJaH0ndAPKs0qCHPV%2FLlYU%2FKzWzLxt2GNA%3D%3D: HTTPSConnectionPool(host='storage.googleapis.com', port=443): Max retries exceeded with url: /wandb-production.appspot.com/1923354735/MonoGS/y7r8ow8y/wandb-metadata.json?Expires=1716344689&GoogleAccessId=gorilla-files-url-signer-man%40wandb-production.iam.gserviceaccount.com&Signature=XocjRmoIFbGhOWBuXHuQ1YhKHLYkoSCeErITJdS8ptWPCsz3MOZyInwqvfgV1AZwEKws5oPw3%2FDwg85hQPHAmupIZkrP%2FbzB80ItKNP%2FF37E4x7FatfKjo6Hx%2Blh6yxHbiVm%2BvTSvuL%2BRLunzyQhKrpBG8Qfx2K0vR52s0eIcahq37a1liZqh3oYSnC07NnlHFejfubqJTF65nXAiLz0%2B7IRQ6cPHAueqi4g6ath5yiztED2FGfOW2i73RW7lux%2FC8MDffiA0UrP30CrlqM6OVwjcoEbSqfaJxx7%2B0fnOFYZ3afMjjX5iJaH0ndAPKs0qCHPV%2FLlYU%2FKzWzLxt2GNA%3D%3D (Caused by NewConnectionError('<urllib3.connection.HTTPSConnection object at 0x7f9aec67a8d0>: Failed to establish a new connection: [Errno 111] Connection refused'))
2024-05-21 10:24:57,704 ERROR   wandb-upload_0:1290853 [internal_api.py:upload_file():2769] upload_file request headers: {'User-Agent': 'python-requests/2.31.0', 'Accept-Encoding': 'gzip, deflate, br', 'Accept': '*/*', 'Connection': 'keep-alive', 'Content-Length': '3405'}
2024-05-21 10:24:57,704 ERROR   wandb-upload_0:1290853 [internal_api.py:upload_file():2771] upload_file response body: 
2024-05-21 10:24:58,824 INFO    Thread-12 :1290853 [dir_watcher.py:_on_file_modified():288] file/dir modified: /home/lsr/MonoGS_Version_Control/MonoGS/wandb/run-20240521_102445-y7r8ow8y/files/output.log
2024-05-21 10:25:00,924 DEBUG   HandlerThread:1290853 [handler.py:handle_request():146] handle_request: status_report
2024-05-21 10:25:04,033 DEBUG   HandlerThread:1290853 [handler.py:handle_request():146] handle_request: stop_status
2024-05-21 10:25:04,033 DEBUG   HandlerThread:1290853 [handler.py:handle_request():146] handle_request: internal_messages
2024-05-21 10:25:04,034 DEBUG   SenderThread:1290853 [sender.py:send_request():406] send_request: stop_status
2024-05-21 10:25:06,259 DEBUG   HandlerThread:1290853 [handler.py:handle_request():146] handle_request: status_report
2024-05-21 10:25:06,274 ERROR   wandb-upload_0:1290853 [internal_api.py:upload_file():2767] upload_file exception https://storage.googleapis.com/wandb-production.appspot.com/1923354735/MonoGS/y7r8ow8y/wandb-metadata.json?Expires=1716344689&GoogleAccessId=gorilla-files-url-signer-man%40wandb-production.iam.gserviceaccount.com&Signature=XocjRmoIFbGhOWBuXHuQ1YhKHLYkoSCeErITJdS8ptWPCsz3MOZyInwqvfgV1AZwEKws5oPw3%2FDwg85hQPHAmupIZkrP%2FbzB80ItKNP%2FF37E4x7FatfKjo6Hx%2Blh6yxHbiVm%2BvTSvuL%2BRLunzyQhKrpBG8Qfx2K0vR52s0eIcahq37a1liZqh3oYSnC07NnlHFejfubqJTF65nXAiLz0%2B7IRQ6cPHAueqi4g6ath5yiztED2FGfOW2i73RW7lux%2FC8MDffiA0UrP30CrlqM6OVwjcoEbSqfaJxx7%2B0fnOFYZ3afMjjX5iJaH0ndAPKs0qCHPV%2FLlYU%2FKzWzLxt2GNA%3D%3D: HTTPSConnectionPool(host='storage.googleapis.com', port=443): Max retries exceeded with url: /wandb-production.appspot.com/1923354735/MonoGS/y7r8ow8y/wandb-metadata.json?Expires=1716344689&GoogleAccessId=gorilla-files-url-signer-man%40wandb-production.iam.gserviceaccount.com&Signature=XocjRmoIFbGhOWBuXHuQ1YhKHLYkoSCeErITJdS8ptWPCsz3MOZyInwqvfgV1AZwEKws5oPw3%2FDwg85hQPHAmupIZkrP%2FbzB80ItKNP%2FF37E4x7FatfKjo6Hx%2Blh6yxHbiVm%2BvTSvuL%2BRLunzyQhKrpBG8Qfx2K0vR52s0eIcahq37a1liZqh3oYSnC07NnlHFejfubqJTF65nXAiLz0%2B7IRQ6cPHAueqi4g6ath5yiztED2FGfOW2i73RW7lux%2FC8MDffiA0UrP30CrlqM6OVwjcoEbSqfaJxx7%2B0fnOFYZ3afMjjX5iJaH0ndAPKs0qCHPV%2FLlYU%2FKzWzLxt2GNA%3D%3D (Caused by NewConnectionError('<urllib3.connection.HTTPSConnection object at 0x7f9aec786ad0>: Failed to establish a new connection: [Errno 111] Connection refused'))
2024-05-21 10:25:06,274 ERROR   wandb-upload_0:1290853 [internal_api.py:upload_file():2769] upload_file request headers: {'User-Agent': 'python-requests/2.31.0', 'Accept-Encoding': 'gzip, deflate, br', 'Accept': '*/*', 'Connection': 'keep-alive', 'Content-Length': '3405'}
2024-05-21 10:25:06,274 ERROR   wandb-upload_0:1290853 [internal_api.py:upload_file():2771] upload_file response body: 
2024-05-21 10:25:10,831 INFO    Thread-12 :1290853 [dir_watcher.py:_on_file_modified():288] file/dir modified: /home/lsr/MonoGS_Version_Control/MonoGS/wandb/run-20240521_102445-y7r8ow8y/files/output.log
2024-05-21 10:25:11,354 DEBUG   HandlerThread:1290853 [handler.py:handle_request():146] handle_request: status_report
2024-05-21 10:25:12,831 INFO    Thread-12 :1290853 [dir_watcher.py:_on_file_modified():288] file/dir modified: /home/lsr/MonoGS_Version_Control/MonoGS/wandb/run-20240521_102445-y7r8ow8y/files/output.log
2024-05-21 10:25:14,832 INFO    Thread-12 :1290853 [dir_watcher.py:_on_file_modified():288] file/dir modified: /home/lsr/MonoGS_Version_Control/MonoGS/wandb/run-20240521_102445-y7r8ow8y/files/output.log
2024-05-21 10:25:16,832 INFO    Thread-12 :1290853 [dir_watcher.py:_on_file_modified():288] file/dir modified: /home/lsr/MonoGS_Version_Control/MonoGS/wandb/run-20240521_102445-y7r8ow8y/files/output.log
2024-05-21 10:25:17,230 DEBUG   HandlerThread:1290853 [handler.py:handle_request():146] handle_request: status_report
2024-05-21 10:25:17,833 INFO    Thread-12 :1290853 [dir_watcher.py:_on_file_modified():288] file/dir modified: /home/lsr/MonoGS_Version_Control/MonoGS/wandb/run-20240521_102445-y7r8ow8y/files/config.yaml
2024-05-21 10:25:18,833 INFO    Thread-12 :1290853 [dir_watcher.py:_on_file_modified():288] file/dir modified: /home/lsr/MonoGS_Version_Control/MonoGS/wandb/run-20240521_102445-y7r8ow8y/files/output.log
2024-05-21 10:25:19,033 DEBUG   HandlerThread:1290853 [handler.py:handle_request():146] handle_request: stop_status
2024-05-21 10:25:19,033 DEBUG   SenderThread:1290853 [sender.py:send_request():406] send_request: stop_status
2024-05-21 10:25:19,034 DEBUG   HandlerThread:1290853 [handler.py:handle_request():146] handle_request: internal_messages
2024-05-21 10:25:21,650 DEBUG   SenderThread:1290853 [sender.py:send():379] send: exit
2024-05-21 10:25:21,650 INFO    SenderThread:1290853 [sender.py:send_exit():586] handling exit code: 255
2024-05-21 10:25:21,650 INFO    SenderThread:1290853 [sender.py:send_exit():588] handling runtime: 35
2024-05-21 10:25:21,650 INFO    SenderThread:1290853 [sender.py:_save_file():1390] saving file wandb-summary.json with policy end
2024-05-21 10:25:21,651 INFO    SenderThread:1290853 [sender.py:send_exit():594] send defer
2024-05-21 10:25:21,651 DEBUG   HandlerThread:1290853 [handler.py:handle_request():146] handle_request: defer
2024-05-21 10:25:21,651 INFO    HandlerThread:1290853 [handler.py:handle_request_defer():172] handle defer: 0
2024-05-21 10:25:21,651 DEBUG   SenderThread:1290853 [sender.py:send_request():406] send_request: defer
2024-05-21 10:25:21,651 INFO    SenderThread:1290853 [sender.py:send_request_defer():610] handle sender defer: 0
2024-05-21 10:25:21,652 INFO    SenderThread:1290853 [sender.py:transition_state():614] send defer: 1
2024-05-21 10:25:21,652 DEBUG   HandlerThread:1290853 [handler.py:handle_request():146] handle_request: defer
2024-05-21 10:25:21,652 INFO    HandlerThread:1290853 [handler.py:handle_request_defer():172] handle defer: 1
2024-05-21 10:25:21,652 DEBUG   SenderThread:1290853 [sender.py:send_request():406] send_request: defer
2024-05-21 10:25:21,652 INFO    SenderThread:1290853 [sender.py:send_request_defer():610] handle sender defer: 1
2024-05-21 10:25:21,652 INFO    SenderThread:1290853 [sender.py:transition_state():614] send defer: 2
2024-05-21 10:25:21,652 DEBUG   HandlerThread:1290853 [handler.py:handle_request():146] handle_request: defer
2024-05-21 10:25:21,652 INFO    HandlerThread:1290853 [handler.py:handle_request_defer():172] handle defer: 2
2024-05-21 10:25:21,652 INFO    HandlerThread:1290853 [system_monitor.py:finish():203] Stopping system monitor
2024-05-21 10:25:21,652 DEBUG   SystemMonitor:1290853 [system_monitor.py:_start():172] Starting system metrics aggregation loop
2024-05-21 10:25:21,652 DEBUG   SystemMonitor:1290853 [system_monitor.py:_start():179] Finished system metrics aggregation loop
2024-05-21 10:25:21,652 DEBUG   SystemMonitor:1290853 [system_monitor.py:_start():183] Publishing last batch of metrics
2024-05-21 10:25:21,653 INFO    HandlerThread:1290853 [interfaces.py:finish():202] Joined cpu monitor
2024-05-21 10:25:21,653 INFO    HandlerThread:1290853 [interfaces.py:finish():202] Joined disk monitor
2024-05-21 10:25:21,704 INFO    HandlerThread:1290853 [interfaces.py:finish():202] Joined gpu monitor
2024-05-21 10:25:21,704 INFO    HandlerThread:1290853 [interfaces.py:finish():202] Joined memory monitor
2024-05-21 10:25:21,704 INFO    HandlerThread:1290853 [interfaces.py:finish():202] Joined network monitor
2024-05-21 10:25:21,705 DEBUG   SenderThread:1290853 [sender.py:send_request():406] send_request: defer
2024-05-21 10:25:21,705 INFO    SenderThread:1290853 [sender.py:send_request_defer():610] handle sender defer: 2
2024-05-21 10:25:21,705 INFO    SenderThread:1290853 [sender.py:transition_state():614] send defer: 3
2024-05-21 10:25:21,705 DEBUG   SenderThread:1290853 [sender.py:send():379] send: stats
2024-05-21 10:25:21,705 DEBUG   HandlerThread:1290853 [handler.py:handle_request():146] handle_request: defer
2024-05-21 10:25:21,705 INFO    HandlerThread:1290853 [handler.py:handle_request_defer():172] handle defer: 3
2024-05-21 10:25:21,705 DEBUG   SenderThread:1290853 [sender.py:send_request():406] send_request: defer
2024-05-21 10:25:21,705 INFO    SenderThread:1290853 [sender.py:send_request_defer():610] handle sender defer: 3
2024-05-21 10:25:21,705 INFO    SenderThread:1290853 [sender.py:transition_state():614] send defer: 4
2024-05-21 10:25:21,705 DEBUG   HandlerThread:1290853 [handler.py:handle_request():146] handle_request: defer
2024-05-21 10:25:21,705 INFO    HandlerThread:1290853 [handler.py:handle_request_defer():172] handle defer: 4
2024-05-21 10:25:21,705 DEBUG   SenderThread:1290853 [sender.py:send_request():406] send_request: defer
2024-05-21 10:25:21,705 INFO    SenderThread:1290853 [sender.py:send_request_defer():610] handle sender defer: 4
2024-05-21 10:25:21,705 INFO    SenderThread:1290853 [sender.py:transition_state():614] send defer: 5
2024-05-21 10:25:21,705 DEBUG   HandlerThread:1290853 [handler.py:handle_request():146] handle_request: defer
2024-05-21 10:25:21,705 INFO    HandlerThread:1290853 [handler.py:handle_request_defer():172] handle defer: 5
2024-05-21 10:25:21,706 DEBUG   SenderThread:1290853 [sender.py:send():379] send: summary
2024-05-21 10:25:21,706 INFO    SenderThread:1290853 [sender.py:_save_file():1390] saving file wandb-summary.json with policy end
2024-05-21 10:25:21,706 DEBUG   SenderThread:1290853 [sender.py:send_request():406] send_request: defer
2024-05-21 10:25:21,706 INFO    SenderThread:1290853 [sender.py:send_request_defer():610] handle sender defer: 5
2024-05-21 10:25:21,706 INFO    SenderThread:1290853 [sender.py:transition_state():614] send defer: 6
2024-05-21 10:25:21,706 DEBUG   HandlerThread:1290853 [handler.py:handle_request():146] handle_request: defer
2024-05-21 10:25:21,706 INFO    HandlerThread:1290853 [handler.py:handle_request_defer():172] handle defer: 6
2024-05-21 10:25:21,706 DEBUG   SenderThread:1290853 [sender.py:send_request():406] send_request: defer
2024-05-21 10:25:21,706 INFO    SenderThread:1290853 [sender.py:send_request_defer():610] handle sender defer: 6
2024-05-21 10:25:21,706 INFO    SenderThread:1290853 [sender.py:transition_state():614] send defer: 7
2024-05-21 10:25:21,706 DEBUG   HandlerThread:1290853 [handler.py:handle_request():146] handle_request: status_report
2024-05-21 10:25:21,707 DEBUG   HandlerThread:1290853 [handler.py:handle_request():146] handle_request: defer
2024-05-21 10:25:21,707 INFO    HandlerThread:1290853 [handler.py:handle_request_defer():172] handle defer: 7
2024-05-21 10:25:21,707 DEBUG   SenderThread:1290853 [sender.py:send_request():406] send_request: defer
2024-05-21 10:25:21,707 INFO    SenderThread:1290853 [sender.py:send_request_defer():610] handle sender defer: 7
2024-05-21 10:25:21,834 INFO    Thread-12 :1290853 [dir_watcher.py:_on_file_created():271] file/dir created: /home/lsr/MonoGS_Version_Control/MonoGS/wandb/run-20240521_102445-y7r8ow8y/files/wandb-summary.json
2024-05-21 10:25:22,650 DEBUG   HandlerThread:1290853 [handler.py:handle_request():146] handle_request: poll_exit
2024-05-21 10:25:22,834 INFO    Thread-12 :1290853 [dir_watcher.py:_on_file_modified():288] file/dir modified: /home/lsr/MonoGS_Version_Control/MonoGS/wandb/run-20240521_102445-y7r8ow8y/files/output.log
2024-05-21 10:25:23,657 INFO    SenderThread:1290853 [sender.py:transition_state():614] send defer: 8
2024-05-21 10:25:23,657 DEBUG   SenderThread:1290853 [sender.py:send_request():406] send_request: poll_exit
2024-05-21 10:25:23,658 DEBUG   HandlerThread:1290853 [handler.py:handle_request():146] handle_request: defer
2024-05-21 10:25:23,658 INFO    HandlerThread:1290853 [handler.py:handle_request_defer():172] handle defer: 8
2024-05-21 10:25:23,659 DEBUG   SenderThread:1290853 [sender.py:send_request():406] send_request: defer
2024-05-21 10:25:23,659 INFO    SenderThread:1290853 [sender.py:send_request_defer():610] handle sender defer: 8
2024-05-21 10:25:23,659 INFO    SenderThread:1290853 [job_builder.py:build():318] Attempting to build job artifact
2024-05-21 10:25:23,660 INFO    SenderThread:1290853 [job_builder.py:_get_source_type():455] is repo sourced job
2024-05-21 10:25:23,687 INFO    SenderThread:1290853 [job_builder.py:build():431] adding wandb-job metadata file
2024-05-21 10:25:23,705 INFO    SenderThread:1290853 [sender.py:transition_state():614] send defer: 9
2024-05-21 10:25:23,705 DEBUG   HandlerThread:1290853 [handler.py:handle_request():146] handle_request: defer
2024-05-21 10:25:23,706 INFO    HandlerThread:1290853 [handler.py:handle_request_defer():172] handle defer: 9
2024-05-21 10:25:23,706 DEBUG   SenderThread:1290853 [sender.py:send():379] send: artifact
2024-05-21 10:25:23,834 INFO    Thread-12 :1290853 [dir_watcher.py:_on_file_modified():288] file/dir modified: /home/lsr/MonoGS_Version_Control/MonoGS/wandb/run-20240521_102445-y7r8ow8y/files/output.log
2024-05-21 10:25:24,356 ERROR   wandb-upload_0:1290853 [internal_api.py:upload_file():2767] upload_file exception https://storage.googleapis.com/wandb-production.appspot.com/1923354735/MonoGS/y7r8ow8y/wandb-metadata.json?Expires=1716344689&GoogleAccessId=gorilla-files-url-signer-man%40wandb-production.iam.gserviceaccount.com&Signature=XocjRmoIFbGhOWBuXHuQ1YhKHLYkoSCeErITJdS8ptWPCsz3MOZyInwqvfgV1AZwEKws5oPw3%2FDwg85hQPHAmupIZkrP%2FbzB80ItKNP%2FF37E4x7FatfKjo6Hx%2Blh6yxHbiVm%2BvTSvuL%2BRLunzyQhKrpBG8Qfx2K0vR52s0eIcahq37a1liZqh3oYSnC07NnlHFejfubqJTF65nXAiLz0%2B7IRQ6cPHAueqi4g6ath5yiztED2FGfOW2i73RW7lux%2FC8MDffiA0UrP30CrlqM6OVwjcoEbSqfaJxx7%2B0fnOFYZ3afMjjX5iJaH0ndAPKs0qCHPV%2FLlYU%2FKzWzLxt2GNA%3D%3D: HTTPSConnectionPool(host='storage.googleapis.com', port=443): Max retries exceeded with url: /wandb-production.appspot.com/1923354735/MonoGS/y7r8ow8y/wandb-metadata.json?Expires=1716344689&GoogleAccessId=gorilla-files-url-signer-man%40wandb-production.iam.gserviceaccount.com&Signature=XocjRmoIFbGhOWBuXHuQ1YhKHLYkoSCeErITJdS8ptWPCsz3MOZyInwqvfgV1AZwEKws5oPw3%2FDwg85hQPHAmupIZkrP%2FbzB80ItKNP%2FF37E4x7FatfKjo6Hx%2Blh6yxHbiVm%2BvTSvuL%2BRLunzyQhKrpBG8Qfx2K0vR52s0eIcahq37a1liZqh3oYSnC07NnlHFejfubqJTF65nXAiLz0%2B7IRQ6cPHAueqi4g6ath5yiztED2FGfOW2i73RW7lux%2FC8MDffiA0UrP30CrlqM6OVwjcoEbSqfaJxx7%2B0fnOFYZ3afMjjX5iJaH0ndAPKs0qCHPV%2FLlYU%2FKzWzLxt2GNA%3D%3D (Caused by NewConnectionError('<urllib3.connection.HTTPSConnection object at 0x7f9aec5e9510>: Failed to establish a new connection: [Errno 111] Connection refused'))
2024-05-21 10:25:24,357 ERROR   wandb-upload_0:1290853 [internal_api.py:upload_file():2769] upload_file request headers: {'User-Agent': 'python-requests/2.31.0', 'Accept-Encoding': 'gzip, deflate, br', 'Accept': '*/*', 'Connection': 'keep-alive', 'Content-Length': '3405'}
2024-05-21 10:25:24,357 ERROR   wandb-upload_0:1290853 [internal_api.py:upload_file():2771] upload_file response body: 
2024-05-21 10:25:24,651 DEBUG   HandlerThread:1290853 [handler.py:handle_request():146] handle_request: poll_exit
2024-05-21 10:25:24,880 INFO    SenderThread:1290853 [sender.py:send_artifact():1468] sent artifact job-https___github.com_IAMXII_MonoGS.git_slam.py - {'id': 'QXJ0aWZhY3Q6ODQzNTQ0NjQw', 'state': 'COMMITTED', 'artifactSequence': {'id': 'QXJ0aWZhY3RDb2xsZWN0aW9uOjE3NzE1NjYxOQ==', 'latestArtifact': {'id': 'QXJ0aWZhY3Q6ODQzNTQ0NjQw', 'versionIndex': 0}}}
2024-05-21 10:25:24,880 DEBUG   SenderThread:1290853 [sender.py:send_request():406] send_request: defer
2024-05-21 10:25:24,880 INFO    SenderThread:1290853 [sender.py:send_request_defer():610] handle sender defer: 9
2024-05-21 10:25:24,880 INFO    SenderThread:1290853 [dir_watcher.py:finish():358] shutting down directory watcher
2024-05-21 10:25:25,835 INFO    SenderThread:1290853 [dir_watcher.py:finish():388] scan: /home/lsr/MonoGS_Version_Control/MonoGS/wandb/run-20240521_102445-y7r8ow8y/files
2024-05-21 10:25:25,835 INFO    SenderThread:1290853 [dir_watcher.py:finish():402] scan save: /home/lsr/MonoGS_Version_Control/MonoGS/wandb/run-20240521_102445-y7r8ow8y/files/wandb-summary.json wandb-summary.json
2024-05-21 10:25:25,835 INFO    SenderThread:1290853 [dir_watcher.py:finish():402] scan save: /home/lsr/MonoGS_Version_Control/MonoGS/wandb/run-20240521_102445-y7r8ow8y/files/output.log output.log
2024-05-21 10:25:25,835 INFO    SenderThread:1290853 [dir_watcher.py:finish():402] scan save: /home/lsr/MonoGS_Version_Control/MonoGS/wandb/run-20240521_102445-y7r8ow8y/files/wandb-metadata.json wandb-metadata.json
2024-05-21 10:25:25,835 INFO    SenderThread:1290853 [dir_watcher.py:finish():402] scan save: /home/lsr/MonoGS_Version_Control/MonoGS/wandb/run-20240521_102445-y7r8ow8y/files/requirements.txt requirements.txt
2024-05-21 10:25:25,838 INFO    SenderThread:1290853 [dir_watcher.py:finish():402] scan save: /home/lsr/MonoGS_Version_Control/MonoGS/wandb/run-20240521_102445-y7r8ow8y/files/conda-environment.yaml conda-environment.yaml
2024-05-21 10:25:25,840 INFO    SenderThread:1290853 [dir_watcher.py:finish():402] scan save: /home/lsr/MonoGS_Version_Control/MonoGS/wandb/run-20240521_102445-y7r8ow8y/files/config.yaml config.yaml
2024-05-21 10:25:25,842 INFO    SenderThread:1290853 [sender.py:transition_state():614] send defer: 10
2024-05-21 10:25:25,842 DEBUG   SenderThread:1290853 [sender.py:send_request():406] send_request: poll_exit
2024-05-21 10:25:25,842 DEBUG   HandlerThread:1290853 [handler.py:handle_request():146] handle_request: defer
2024-05-21 10:25:25,843 INFO    HandlerThread:1290853 [handler.py:handle_request_defer():172] handle defer: 10
2024-05-21 10:25:25,844 DEBUG   SenderThread:1290853 [sender.py:send_request():406] send_request: defer
2024-05-21 10:25:25,844 INFO    SenderThread:1290853 [sender.py:send_request_defer():610] handle sender defer: 10
2024-05-21 10:25:25,844 INFO    SenderThread:1290853 [file_pusher.py:finish():172] shutting down file pusher
2024-05-21 10:25:26,058 ERROR   wandb-upload_1:1290853 [internal_api.py:upload_file():2767] upload_file exception https://storage.googleapis.com/wandb-production.appspot.com/1923354735/MonoGS/y7r8ow8y/wandb-summary.json?Expires=1716344726&GoogleAccessId=gorilla-files-url-signer-man%40wandb-production.iam.gserviceaccount.com&Signature=n3TmQTke7rSKTOCmV4yBzpiHwvu8vQPE5LqY5EPfq8lc0JXiqgCFiFHzkxawDiSoIUcT3kdxgc2aPTLq1LD2WEkY6%2FuVV8En4N40fMx5DpkYekTPQfNs60A7VrzXiwdiTse%2FK8x%2FzrxcTRGKL5PlVDbPIkJTXr7S4GamUrQu66SpK3x%2F2MXkJ8k3cxcj6u9OgJgPH558FhRJENn1qVzm7AEwxNviV2ROMH174SOmY07BcoW8rCBvf8RWcNxUJrLulhAQk3VasB2MusrZH8Jf%2FHi2MAv4YWRHVoTGBX%2Bzrqj9sOhlhVHl8aINJwVSm9S0qzb2KI9%2FvZPZ3%2BqOahzSRg%3D%3D: HTTPSConnectionPool(host='storage.googleapis.com', port=443): Max retries exceeded with url: /wandb-production.appspot.com/1923354735/MonoGS/y7r8ow8y/wandb-summary.json?Expires=1716344726&GoogleAccessId=gorilla-files-url-signer-man%40wandb-production.iam.gserviceaccount.com&Signature=n3TmQTke7rSKTOCmV4yBzpiHwvu8vQPE5LqY5EPfq8lc0JXiqgCFiFHzkxawDiSoIUcT3kdxgc2aPTLq1LD2WEkY6%2FuVV8En4N40fMx5DpkYekTPQfNs60A7VrzXiwdiTse%2FK8x%2FzrxcTRGKL5PlVDbPIkJTXr7S4GamUrQu66SpK3x%2F2MXkJ8k3cxcj6u9OgJgPH558FhRJENn1qVzm7AEwxNviV2ROMH174SOmY07BcoW8rCBvf8RWcNxUJrLulhAQk3VasB2MusrZH8Jf%2FHi2MAv4YWRHVoTGBX%2Bzrqj9sOhlhVHl8aINJwVSm9S0qzb2KI9%2FvZPZ3%2BqOahzSRg%3D%3D (Caused by NewConnectionError('<urllib3.connection.HTTPSConnection object at 0x7f9aec5daf90>: Failed to establish a new connection: [Errno 111] Connection refused'))
2024-05-21 10:25:26,059 ERROR   wandb-upload_1:1290853 [internal_api.py:upload_file():2769] upload_file request headers: {'User-Agent': 'python-requests/2.31.0', 'Accept-Encoding': 'gzip, deflate, br', 'Accept': '*/*', 'Connection': 'keep-alive', 'Content-Length': '27'}
2024-05-21 10:25:26,059 ERROR   wandb-upload_1:1290853 [internal_api.py:upload_file():2771] upload_file response body: 
2024-05-21 10:25:26,068 ERROR   wandb-upload_2:1290853 [internal_api.py:upload_file():2767] upload_file exception https://storage.googleapis.com/wandb-production.appspot.com/1923354735/MonoGS/y7r8ow8y/output.log?Expires=1716344726&GoogleAccessId=gorilla-files-url-signer-man%40wandb-production.iam.gserviceaccount.com&Signature=O7idKX8qxjOgQnoSk8t%2FEvZHFPDgj7JSXqoV7CpZlwFMS%2FvROKjPi8M3JagUT5wZ1inNHngyIU5scHIDo19KW%2Fxw0W%2FmJC%2FJfj2MZhGjDbxxnxx5aB4d%2BOoV7mxhAN9thVFs2jqWTNgNstrhhKFS%2BToiiRDtek%2BRxKJFLzjqTrqrZCJQO9usjTSGzzTHQLH%2F6Q0isKnkjj8HtIMoQpooN8s0cee02waCJy764hYUXOfj%2BXOvrLctCmMTiC04rFdK8juLoR0kM4uwRRmGkqjy2zRldzt%2F96rYeKQpv5GPvR1gVqtLd8Ie5gDieYQFYEwUdJw5wyXZMgJwm9kcUqF53w%3D%3D: HTTPSConnectionPool(host='storage.googleapis.com', port=443): Max retries exceeded with url: /wandb-production.appspot.com/1923354735/MonoGS/y7r8ow8y/output.log?Expires=1716344726&GoogleAccessId=gorilla-files-url-signer-man%40wandb-production.iam.gserviceaccount.com&Signature=O7idKX8qxjOgQnoSk8t%2FEvZHFPDgj7JSXqoV7CpZlwFMS%2FvROKjPi8M3JagUT5wZ1inNHngyIU5scHIDo19KW%2Fxw0W%2FmJC%2FJfj2MZhGjDbxxnxx5aB4d%2BOoV7mxhAN9thVFs2jqWTNgNstrhhKFS%2BToiiRDtek%2BRxKJFLzjqTrqrZCJQO9usjTSGzzTHQLH%2F6Q0isKnkjj8HtIMoQpooN8s0cee02waCJy764hYUXOfj%2BXOvrLctCmMTiC04rFdK8juLoR0kM4uwRRmGkqjy2zRldzt%2F96rYeKQpv5GPvR1gVqtLd8Ie5gDieYQFYEwUdJw5wyXZMgJwm9kcUqF53w%3D%3D (Caused by NewConnectionError('<urllib3.connection.HTTPSConnection object at 0x7f9aec5e9b90>: Failed to establish a new connection: [Errno 111] Connection refused'))
2024-05-21 10:25:26,068 ERROR   wandb-upload_2:1290853 [internal_api.py:upload_file():2769] upload_file request headers: {'User-Agent': 'python-requests/2.31.0', 'Accept-Encoding': 'gzip, deflate, br', 'Accept': '*/*', 'Connection': 'keep-alive', 'Content-Length': '1214'}
2024-05-21 10:25:26,068 ERROR   wandb-upload_2:1290853 [internal_api.py:upload_file():2771] upload_file response body: 
2024-05-21 10:25:26,156 ERROR   wandb-upload_5:1290853 [internal_api.py:upload_file():2767] upload_file exception https://storage.googleapis.com/wandb-production.appspot.com/1923354735/MonoGS/y7r8ow8y/config.yaml?Expires=1716344726&GoogleAccessId=gorilla-files-url-signer-man%40wandb-production.iam.gserviceaccount.com&Signature=I%2FNqKudC9MlfdRYAyMWFQvABnAS6abRNmQnfNVifsclZ4ceBglJy%2FoSd3mNSPDS9NKXypr69UhttUBb6HT4dYnStLUhTaBeqvaVAIboqb0qJixJW1nYbshU6oZOHN%2F2QXnXcTDMAcIqYyvjbX8%2FgNgcm62O%2FZfSG0rwQMsg36I%2BybxXDywQsR6Hj%2BHEviQaJ2BiWLrrG13wLXJRzU9Fy6cW8OxwP3EO3FtI7%2FkTijIvBF0hMcNI8v07X9K4HytchvYdA5f6h8ydDmckf6lnmf8SJ4ou%2FY30cBWODkVpKSmeEE7IW58O0%2BZ7gTvYz5pY3sDXUPAhXajZ5flsUieNmzg%3D%3D: HTTPSConnectionPool(host='storage.googleapis.com', port=443): Max retries exceeded with url: /wandb-production.appspot.com/1923354735/MonoGS/y7r8ow8y/config.yaml?Expires=1716344726&GoogleAccessId=gorilla-files-url-signer-man%40wandb-production.iam.gserviceaccount.com&Signature=I%2FNqKudC9MlfdRYAyMWFQvABnAS6abRNmQnfNVifsclZ4ceBglJy%2FoSd3mNSPDS9NKXypr69UhttUBb6HT4dYnStLUhTaBeqvaVAIboqb0qJixJW1nYbshU6oZOHN%2F2QXnXcTDMAcIqYyvjbX8%2FgNgcm62O%2FZfSG0rwQMsg36I%2BybxXDywQsR6Hj%2BHEviQaJ2BiWLrrG13wLXJRzU9Fy6cW8OxwP3EO3FtI7%2FkTijIvBF0hMcNI8v07X9K4HytchvYdA5f6h8ydDmckf6lnmf8SJ4ou%2FY30cBWODkVpKSmeEE7IW58O0%2BZ7gTvYz5pY3sDXUPAhXajZ5flsUieNmzg%3D%3D (Caused by NewConnectionError('<urllib3.connection.HTTPSConnection object at 0x7f9aec601f10>: Failed to establish a new connection: [Errno 111] Connection refused'))
2024-05-21 10:25:26,156 ERROR   wandb-upload_5:1290853 [internal_api.py:upload_file():2769] upload_file request headers: {'User-Agent': 'python-requests/2.31.0', 'Accept-Encoding': 'gzip, deflate, br', 'Accept': '*/*', 'Connection': 'keep-alive', 'Content-Length': '2747'}
2024-05-21 10:25:26,156 ERROR   wandb-upload_5:1290853 [internal_api.py:upload_file():2771] upload_file response body: 
2024-05-21 10:25:26,214 ERROR   wandb-upload_3:1290853 [internal_api.py:upload_file():2767] upload_file exception https://storage.googleapis.com/wandb-production.appspot.com/1923354735/MonoGS/y7r8ow8y/requirements.txt?Expires=1716344726&GoogleAccessId=gorilla-files-url-signer-man%40wandb-production.iam.gserviceaccount.com&Signature=L3wnj%2Fyq7ui%2BxLSSHbd3ZNhcWA4kK0ZtJyRG36fvMf2Y64WNPxFbuXgPhvC3rdidwqU2%2FOe%2FZTIIdUTKPbXzP9cEZ7sVF4Uwp3hSUNfDuTOFQaig%2F7JOiFRBJGv2X1R2iASbTo4JBQgGB9GC2veBdTUOc8aYkoZ5obUK%2FM%2BpCNVMPAzKdiJXEOZwIQ14bgSeH5mgaAwjpsla%2BJXsuIFxnyOcT%2FEZXY8VhWlqGJToRux8cvvjrvzrpp1jvjPgGnLacIrUtX0qi5kxdwvU79IAmi4m2uwJuuJryVhLfb1msk0BS4LjGHkfWl9hd4p6pZiXdVx7Q7s0g8yyBNyPv%2BnGhw%3D%3D: HTTPSConnectionPool(host='storage.googleapis.com', port=443): Max retries exceeded with url: /wandb-production.appspot.com/1923354735/MonoGS/y7r8ow8y/requirements.txt?Expires=1716344726&GoogleAccessId=gorilla-files-url-signer-man%40wandb-production.iam.gserviceaccount.com&Signature=L3wnj%2Fyq7ui%2BxLSSHbd3ZNhcWA4kK0ZtJyRG36fvMf2Y64WNPxFbuXgPhvC3rdidwqU2%2FOe%2FZTIIdUTKPbXzP9cEZ7sVF4Uwp3hSUNfDuTOFQaig%2F7JOiFRBJGv2X1R2iASbTo4JBQgGB9GC2veBdTUOc8aYkoZ5obUK%2FM%2BpCNVMPAzKdiJXEOZwIQ14bgSeH5mgaAwjpsla%2BJXsuIFxnyOcT%2FEZXY8VhWlqGJToRux8cvvjrvzrpp1jvjPgGnLacIrUtX0qi5kxdwvU79IAmi4m2uwJuuJryVhLfb1msk0BS4LjGHkfWl9hd4p6pZiXdVx7Q7s0g8yyBNyPv%2BnGhw%3D%3D (Caused by NewConnectionError('<urllib3.connection.HTTPSConnection object at 0x7f9aec5fe110>: Failed to establish a new connection: [Errno 111] Connection refused'))
2024-05-21 10:25:26,214 ERROR   wandb-upload_3:1290853 [internal_api.py:upload_file():2769] upload_file request headers: {'User-Agent': 'python-requests/2.31.0', 'Accept-Encoding': 'gzip, deflate, br', 'Accept': '*/*', 'Connection': 'keep-alive', 'Content-Length': '2267'}
2024-05-21 10:25:26,214 ERROR   wandb-upload_3:1290853 [internal_api.py:upload_file():2771] upload_file response body: 
2024-05-21 10:25:26,226 ERROR   wandb-upload_4:1290853 [internal_api.py:upload_file():2767] upload_file exception https://storage.googleapis.com/wandb-production.appspot.com/1923354735/MonoGS/y7r8ow8y/conda-environment.yaml?Expires=1716344726&GoogleAccessId=gorilla-files-url-signer-man%40wandb-production.iam.gserviceaccount.com&Signature=BERXsAthvA4uNy8KsTYhi4DK4yIggzBZzxjksCpYdoksYlIRNvLT6PY86cQfX4%2F%2BjJSxwiltJwadlf7g%2FjxRbz0mfhoLBBROL50A3sp35%2FjQLnhmncVF3iVe7ThBmHwLjMPjt5XtQu2jC34B8fea3GjY7wKFq3uaKTrwmPgWtcEOZCQMLMY0ChxkR%2BHE%2FSRiWt7xGeRrrVQ%2BErKoDuQRznC3TvhkhS1U4lAVl6wRnLTI7GfzP%2FPZmxvohZpdRMn5apJEuRQkvST8ta2NN1yZWfvi903GAtgKWuYwg06ZHKj%2BCN24I%2B035VMqzFQRTyKx2EL50XK4hJucrjFTtzt8uQ%3D%3D: HTTPSConnectionPool(host='storage.googleapis.com', port=443): Max retries exceeded with url: /wandb-production.appspot.com/1923354735/MonoGS/y7r8ow8y/conda-environment.yaml?Expires=1716344726&GoogleAccessId=gorilla-files-url-signer-man%40wandb-production.iam.gserviceaccount.com&Signature=BERXsAthvA4uNy8KsTYhi4DK4yIggzBZzxjksCpYdoksYlIRNvLT6PY86cQfX4%2F%2BjJSxwiltJwadlf7g%2FjxRbz0mfhoLBBROL50A3sp35%2FjQLnhmncVF3iVe7ThBmHwLjMPjt5XtQu2jC34B8fea3GjY7wKFq3uaKTrwmPgWtcEOZCQMLMY0ChxkR%2BHE%2FSRiWt7xGeRrrVQ%2BErKoDuQRznC3TvhkhS1U4lAVl6wRnLTI7GfzP%2FPZmxvohZpdRMn5apJEuRQkvST8ta2NN1yZWfvi903GAtgKWuYwg06ZHKj%2BCN24I%2B035VMqzFQRTyKx2EL50XK4hJucrjFTtzt8uQ%3D%3D (Caused by NewConnectionError('<urllib3.connection.HTTPSConnection object at 0x7f9aec770690>: Failed to establish a new connection: [Errno 111] Connection refused'))
2024-05-21 10:25:26,226 ERROR   wandb-upload_4:1290853 [internal_api.py:upload_file():2769] upload_file request headers: {'User-Agent': 'python-requests/2.31.0', 'Accept-Encoding': 'gzip, deflate, br', 'Accept': '*/*', 'Connection': 'keep-alive', 'Content-Length': '4690'}
2024-05-21 10:25:26,226 ERROR   wandb-upload_4:1290853 [internal_api.py:upload_file():2771] upload_file response body: 
2024-05-21 10:25:26,249 WARNING StreamThr :1290853 [internal.py:is_dead():415] Internal process exiting, parent pid 1290682 disappeared
2024-05-21 10:25:26,249 ERROR   StreamThr :1290853 [internal.py:wandb_internal():152] Internal process shutdown.
2024-05-21 10:25:26,652 DEBUG   HandlerThread:1290853 [handler.py:handle_request():146] handle_request: poll_exit
2024-05-21 10:25:26,652 INFO    HandlerThread:1290853 [handler.py:finish():866] shutting down handler
2024-05-21 10:25:26,652 INFO    WriterThread:1290853 [datastore.py:close():296] close: /home/lsr/MonoGS_Version_Control/MonoGS/wandb/run-20240521_102445-y7r8ow8y/run-y7r8ow8y.wandb
2024-05-21 10:25:26,652 DEBUG   SenderThread:1290853 [sender.py:send_request():406] send_request: poll_exit
2024-05-21 10:25:26,652 INFO    SenderThread:1290853 [sender.py:finish():1546] shutting down sender
2024-05-21 10:25:26,652 INFO    SenderThread:1290853 [file_pusher.py:finish():172] shutting down file pusher
2024-05-21 10:25:26,652 INFO    SenderThread:1290853 [file_pusher.py:join():178] waiting for file pusher
2024-05-21 10:25:27,222 ERROR   wandb-upload_5:1290853 [internal_api.py:upload_file():2767] upload_file exception https://storage.googleapis.com/wandb-production.appspot.com/1923354735/MonoGS/y7r8ow8y/config.yaml?Expires=1716344726&GoogleAccessId=gorilla-files-url-signer-man%40wandb-production.iam.gserviceaccount.com&Signature=I%2FNqKudC9MlfdRYAyMWFQvABnAS6abRNmQnfNVifsclZ4ceBglJy%2FoSd3mNSPDS9NKXypr69UhttUBb6HT4dYnStLUhTaBeqvaVAIboqb0qJixJW1nYbshU6oZOHN%2F2QXnXcTDMAcIqYyvjbX8%2FgNgcm62O%2FZfSG0rwQMsg36I%2BybxXDywQsR6Hj%2BHEviQaJ2BiWLrrG13wLXJRzU9Fy6cW8OxwP3EO3FtI7%2FkTijIvBF0hMcNI8v07X9K4HytchvYdA5f6h8ydDmckf6lnmf8SJ4ou%2FY30cBWODkVpKSmeEE7IW58O0%2BZ7gTvYz5pY3sDXUPAhXajZ5flsUieNmzg%3D%3D: HTTPSConnectionPool(host='storage.googleapis.com', port=443): Max retries exceeded with url: /wandb-production.appspot.com/1923354735/MonoGS/y7r8ow8y/config.yaml?Expires=1716344726&GoogleAccessId=gorilla-files-url-signer-man%40wandb-production.iam.gserviceaccount.com&Signature=I%2FNqKudC9MlfdRYAyMWFQvABnAS6abRNmQnfNVifsclZ4ceBglJy%2FoSd3mNSPDS9NKXypr69UhttUBb6HT4dYnStLUhTaBeqvaVAIboqb0qJixJW1nYbshU6oZOHN%2F2QXnXcTDMAcIqYyvjbX8%2FgNgcm62O%2FZfSG0rwQMsg36I%2BybxXDywQsR6Hj%2BHEviQaJ2BiWLrrG13wLXJRzU9Fy6cW8OxwP3EO3FtI7%2FkTijIvBF0hMcNI8v07X9K4HytchvYdA5f6h8ydDmckf6lnmf8SJ4ou%2FY30cBWODkVpKSmeEE7IW58O0%2BZ7gTvYz5pY3sDXUPAhXajZ5flsUieNmzg%3D%3D (Caused by NewConnectionError('<urllib3.connection.HTTPSConnection object at 0x7f9aec5fe950>: Failed to establish a new connection: [Errno 111] Connection refused'))
2024-05-21 10:25:27,222 ERROR   wandb-upload_5:1290853 [internal_api.py:upload_file():2769] upload_file request headers: {'User-Agent': 'python-requests/2.31.0', 'Accept-Encoding': 'gzip, deflate, br', 'Accept': '*/*', 'Connection': 'keep-alive', 'Content-Length': '2747'}
2024-05-21 10:25:27,222 ERROR   wandb-upload_5:1290853 [internal_api.py:upload_file():2771] upload_file response body: 
2024-05-21 10:25:27,255 ERROR   wandb-upload_4:1290853 [internal_api.py:upload_file():2767] upload_file exception https://storage.googleapis.com/wandb-production.appspot.com/1923354735/MonoGS/y7r8ow8y/conda-environment.yaml?Expires=1716344726&GoogleAccessId=gorilla-files-url-signer-man%40wandb-production.iam.gserviceaccount.com&Signature=BERXsAthvA4uNy8KsTYhi4DK4yIggzBZzxjksCpYdoksYlIRNvLT6PY86cQfX4%2F%2BjJSxwiltJwadlf7g%2FjxRbz0mfhoLBBROL50A3sp35%2FjQLnhmncVF3iVe7ThBmHwLjMPjt5XtQu2jC34B8fea3GjY7wKFq3uaKTrwmPgWtcEOZCQMLMY0ChxkR%2BHE%2FSRiWt7xGeRrrVQ%2BErKoDuQRznC3TvhkhS1U4lAVl6wRnLTI7GfzP%2FPZmxvohZpdRMn5apJEuRQkvST8ta2NN1yZWfvi903GAtgKWuYwg06ZHKj%2BCN24I%2B035VMqzFQRTyKx2EL50XK4hJucrjFTtzt8uQ%3D%3D: HTTPSConnectionPool(host='storage.googleapis.com', port=443): Max retries exceeded with url: /wandb-production.appspot.com/1923354735/MonoGS/y7r8ow8y/conda-environment.yaml?Expires=1716344726&GoogleAccessId=gorilla-files-url-signer-man%40wandb-production.iam.gserviceaccount.com&Signature=BERXsAthvA4uNy8KsTYhi4DK4yIggzBZzxjksCpYdoksYlIRNvLT6PY86cQfX4%2F%2BjJSxwiltJwadlf7g%2FjxRbz0mfhoLBBROL50A3sp35%2FjQLnhmncVF3iVe7ThBmHwLjMPjt5XtQu2jC34B8fea3GjY7wKFq3uaKTrwmPgWtcEOZCQMLMY0ChxkR%2BHE%2FSRiWt7xGeRrrVQ%2BErKoDuQRznC3TvhkhS1U4lAVl6wRnLTI7GfzP%2FPZmxvohZpdRMn5apJEuRQkvST8ta2NN1yZWfvi903GAtgKWuYwg06ZHKj%2BCN24I%2B035VMqzFQRTyKx2EL50XK4hJucrjFTtzt8uQ%3D%3D (Caused by NewConnectionError('<urllib3.connection.HTTPSConnection object at 0x7f9aec607dd0>: Failed to establish a new connection: [Errno 111] Connection refused'))
2024-05-21 10:25:27,256 ERROR   wandb-upload_4:1290853 [internal_api.py:upload_file():2769] upload_file request headers: {'User-Agent': 'python-requests/2.31.0', 'Accept-Encoding': 'gzip, deflate, br', 'Accept': '*/*', 'Connection': 'keep-alive', 'Content-Length': '4690'}
2024-05-21 10:25:27,256 ERROR   wandb-upload_4:1290853 [internal_api.py:upload_file():2771] upload_file response body: 
2024-05-21 10:25:27,256 INFO    wandb-upload_4:1290853 [retry.py:__call__():172] Retry attempt failed:
Traceback (most recent call last):
  File "/home/lsr/anaconda3/envs/MonoGS/lib/python3.7/site-packages/urllib3/connection.py", line 202, in _new_conn
    socket_options=self.socket_options,
  File "/home/lsr/anaconda3/envs/MonoGS/lib/python3.7/site-packages/urllib3/util/connection.py", line 85, in create_connection
    raise err
  File "/home/lsr/anaconda3/envs/MonoGS/lib/python3.7/site-packages/urllib3/util/connection.py", line 73, in create_connection
    sock.connect(sa)
ConnectionRefusedError: [Errno 111] Connection refused

The above exception was the direct cause of the following exception:

Traceback (most recent call last):
  File "/home/lsr/anaconda3/envs/MonoGS/lib/python3.7/site-packages/urllib3/connectionpool.py", line 805, in urlopen
    **response_kw,
  File "/home/lsr/anaconda3/envs/MonoGS/lib/python3.7/site-packages/urllib3/connectionpool.py", line 491, in _make_request
    raise new_e
  File "/home/lsr/anaconda3/envs/MonoGS/lib/python3.7/site-packages/urllib3/connectionpool.py", line 467, in _make_request
    self._validate_conn(conn)
  File "/home/lsr/anaconda3/envs/MonoGS/lib/python3.7/site-packages/urllib3/connectionpool.py", line 1099, in _validate_conn
    conn.connect()
  File "/home/lsr/anaconda3/envs/MonoGS/lib/python3.7/site-packages/urllib3/connection.py", line 616, in connect
    self.sock = sock = self._new_conn()
  File "/home/lsr/anaconda3/envs/MonoGS/lib/python3.7/site-packages/urllib3/connection.py", line 215, in _new_conn
    ) from e
urllib3.exceptions.NewConnectionError: <urllib3.connection.HTTPSConnection object at 0x7f9aec607dd0>: Failed to establish a new connection: [Errno 111] Connection refused

The above exception was the direct cause of the following exception:

Traceback (most recent call last):
  File "/home/lsr/anaconda3/envs/MonoGS/lib/python3.7/site-packages/requests/adapters.py", line 497, in send
    chunked=chunked,
  File "/home/lsr/anaconda3/envs/MonoGS/lib/python3.7/site-packages/urllib3/connectionpool.py", line 848, in urlopen
    method, url, error=new_e, _pool=self, _stacktrace=sys.exc_info()[2]
  File "/home/lsr/anaconda3/envs/MonoGS/lib/python3.7/site-packages/urllib3/util/retry.py", line 515, in increment
    raise MaxRetryError(_pool, url, reason) from reason  # type: ignore[arg-type]
urllib3.exceptions.MaxRetryError: HTTPSConnectionPool(host='storage.googleapis.com', port=443): Max retries exceeded with url: /wandb-production.appspot.com/1923354735/MonoGS/y7r8ow8y/conda-environment.yaml?Expires=1716344726&GoogleAccessId=gorilla-files-url-signer-man%40wandb-production.iam.gserviceaccount.com&Signature=BERXsAthvA4uNy8KsTYhi4DK4yIggzBZzxjksCpYdoksYlIRNvLT6PY86cQfX4%2F%2BjJSxwiltJwadlf7g%2FjxRbz0mfhoLBBROL50A3sp35%2FjQLnhmncVF3iVe7ThBmHwLjMPjt5XtQu2jC34B8fea3GjY7wKFq3uaKTrwmPgWtcEOZCQMLMY0ChxkR%2BHE%2FSRiWt7xGeRrrVQ%2BErKoDuQRznC3TvhkhS1U4lAVl6wRnLTI7GfzP%2FPZmxvohZpdRMn5apJEuRQkvST8ta2NN1yZWfvi903GAtgKWuYwg06ZHKj%2BCN24I%2B035VMqzFQRTyKx2EL50XK4hJucrjFTtzt8uQ%3D%3D (Caused by NewConnectionError('<urllib3.connection.HTTPSConnection object at 0x7f9aec607dd0>: Failed to establish a new connection: [Errno 111] Connection refused'))

During handling of the above exception, another exception occurred:

Traceback (most recent call last):
  File "/home/lsr/anaconda3/envs/MonoGS/lib/python3.7/site-packages/wandb/sdk/internal/internal_api.py", line 2761, in upload_file
    url, data=progress, headers=extra_headers
  File "/home/lsr/anaconda3/envs/MonoGS/lib/python3.7/site-packages/requests/sessions.py", line 649, in put
    return self.request("PUT", url, data=data, **kwargs)
  File "/home/lsr/anaconda3/envs/MonoGS/lib/python3.7/site-packages/requests/sessions.py", line 589, in request
    resp = self.send(prep, **send_kwargs)
  File "/home/lsr/anaconda3/envs/MonoGS/lib/python3.7/site-packages/requests/sessions.py", line 703, in send
    r = adapter.send(request, **kwargs)
  File "/home/lsr/anaconda3/envs/MonoGS/lib/python3.7/site-packages/requests/adapters.py", line 519, in send
    raise ConnectionError(e, request=request)
requests.exceptions.ConnectionError: HTTPSConnectionPool(host='storage.googleapis.com', port=443): Max retries exceeded with url: /wandb-production.appspot.com/1923354735/MonoGS/y7r8ow8y/conda-environment.yaml?Expires=1716344726&GoogleAccessId=gorilla-files-url-signer-man%40wandb-production.iam.gserviceaccount.com&Signature=BERXsAthvA4uNy8KsTYhi4DK4yIggzBZzxjksCpYdoksYlIRNvLT6PY86cQfX4%2F%2BjJSxwiltJwadlf7g%2FjxRbz0mfhoLBBROL50A3sp35%2FjQLnhmncVF3iVe7ThBmHwLjMPjt5XtQu2jC34B8fea3GjY7wKFq3uaKTrwmPgWtcEOZCQMLMY0ChxkR%2BHE%2FSRiWt7xGeRrrVQ%2BErKoDuQRznC3TvhkhS1U4lAVl6wRnLTI7GfzP%2FPZmxvohZpdRMn5apJEuRQkvST8ta2NN1yZWfvi903GAtgKWuYwg06ZHKj%2BCN24I%2B035VMqzFQRTyKx2EL50XK4hJucrjFTtzt8uQ%3D%3D (Caused by NewConnectionError('<urllib3.connection.HTTPSConnection object at 0x7f9aec607dd0>: Failed to establish a new connection: [Errno 111] Connection refused'))

During handling of the above exception, another exception occurred:

Traceback (most recent call last):
  File "/home/lsr/anaconda3/envs/MonoGS/lib/python3.7/site-packages/wandb/sdk/lib/retry.py", line 131, in __call__
    result = self._call_fn(*args, **kwargs)
  File "/home/lsr/anaconda3/envs/MonoGS/lib/python3.7/site-packages/wandb/sdk/internal/internal_api.py", line 2791, in upload_file
    raise _e.with_traceback(sys.exc_info()[2])
  File "/home/lsr/anaconda3/envs/MonoGS/lib/python3.7/site-packages/wandb/sdk/internal/internal_api.py", line 2761, in upload_file
    url, data=progress, headers=extra_headers
  File "/home/lsr/anaconda3/envs/MonoGS/lib/python3.7/site-packages/requests/sessions.py", line 649, in put
    return self.request("PUT", url, data=data, **kwargs)
  File "/home/lsr/anaconda3/envs/MonoGS/lib/python3.7/site-packages/requests/sessions.py", line 589, in request
    resp = self.send(prep, **send_kwargs)
  File "/home/lsr/anaconda3/envs/MonoGS/lib/python3.7/site-packages/requests/sessions.py", line 703, in send
    r = adapter.send(request, **kwargs)
  File "/home/lsr/anaconda3/envs/MonoGS/lib/python3.7/site-packages/requests/adapters.py", line 519, in send
    raise ConnectionError(e, request=request)
wandb.sdk.lib.retry.TransientError: None
2024-05-21 10:25:27,266 ERROR   wandb-upload_2:1290853 [internal_api.py:upload_file():2767] upload_file exception https://storage.googleapis.com/wandb-production.appspot.com/1923354735/MonoGS/y7r8ow8y/output.log?Expires=1716344726&GoogleAccessId=gorilla-files-url-signer-man%40wandb-production.iam.gserviceaccount.com&Signature=O7idKX8qxjOgQnoSk8t%2FEvZHFPDgj7JSXqoV7CpZlwFMS%2FvROKjPi8M3JagUT5wZ1inNHngyIU5scHIDo19KW%2Fxw0W%2FmJC%2FJfj2MZhGjDbxxnxx5aB4d%2BOoV7mxhAN9thVFs2jqWTNgNstrhhKFS%2BToiiRDtek%2BRxKJFLzjqTrqrZCJQO9usjTSGzzTHQLH%2F6Q0isKnkjj8HtIMoQpooN8s0cee02waCJy764hYUXOfj%2BXOvrLctCmMTiC04rFdK8juLoR0kM4uwRRmGkqjy2zRldzt%2F96rYeKQpv5GPvR1gVqtLd8Ie5gDieYQFYEwUdJw5wyXZMgJwm9kcUqF53w%3D%3D: HTTPSConnectionPool(host='storage.googleapis.com', port=443): Max retries exceeded with url: /wandb-production.appspot.com/1923354735/MonoGS/y7r8ow8y/output.log?Expires=1716344726&GoogleAccessId=gorilla-files-url-signer-man%40wandb-production.iam.gserviceaccount.com&Signature=O7idKX8qxjOgQnoSk8t%2FEvZHFPDgj7JSXqoV7CpZlwFMS%2FvROKjPi8M3JagUT5wZ1inNHngyIU5scHIDo19KW%2Fxw0W%2FmJC%2FJfj2MZhGjDbxxnxx5aB4d%2BOoV7mxhAN9thVFs2jqWTNgNstrhhKFS%2BToiiRDtek%2BRxKJFLzjqTrqrZCJQO9usjTSGzzTHQLH%2F6Q0isKnkjj8HtIMoQpooN8s0cee02waCJy764hYUXOfj%2BXOvrLctCmMTiC04rFdK8juLoR0kM4uwRRmGkqjy2zRldzt%2F96rYeKQpv5GPvR1gVqtLd8Ie5gDieYQFYEwUdJw5wyXZMgJwm9kcUqF53w%3D%3D (Caused by NewConnectionError('<urllib3.connection.HTTPSConnection object at 0x7f9aec5e95d0>: Failed to establish a new connection: [Errno 111] Connection refused'))
2024-05-21 10:25:27,266 ERROR   wandb-upload_2:1290853 [internal_api.py:upload_file():2769] upload_file request headers: {'User-Agent': 'python-requests/2.31.0', 'Accept-Encoding': 'gzip, deflate, br', 'Accept': '*/*', 'Connection': 'keep-alive', 'Content-Length': '1214'}
2024-05-21 10:25:27,266 ERROR   wandb-upload_2:1290853 [internal_api.py:upload_file():2771] upload_file response body: 
2024-05-21 10:25:27,298 ERROR   wandb-upload_1:1290853 [internal_api.py:upload_file():2767] upload_file exception https://storage.googleapis.com/wandb-production.appspot.com/1923354735/MonoGS/y7r8ow8y/wandb-summary.json?Expires=1716344726&GoogleAccessId=gorilla-files-url-signer-man%40wandb-production.iam.gserviceaccount.com&Signature=n3TmQTke7rSKTOCmV4yBzpiHwvu8vQPE5LqY5EPfq8lc0JXiqgCFiFHzkxawDiSoIUcT3kdxgc2aPTLq1LD2WEkY6%2FuVV8En4N40fMx5DpkYekTPQfNs60A7VrzXiwdiTse%2FK8x%2FzrxcTRGKL5PlVDbPIkJTXr7S4GamUrQu66SpK3x%2F2MXkJ8k3cxcj6u9OgJgPH558FhRJENn1qVzm7AEwxNviV2ROMH174SOmY07BcoW8rCBvf8RWcNxUJrLulhAQk3VasB2MusrZH8Jf%2FHi2MAv4YWRHVoTGBX%2Bzrqj9sOhlhVHl8aINJwVSm9S0qzb2KI9%2FvZPZ3%2BqOahzSRg%3D%3D: HTTPSConnectionPool(host='storage.googleapis.com', port=443): Max retries exceeded with url: /wandb-production.appspot.com/1923354735/MonoGS/y7r8ow8y/wandb-summary.json?Expires=1716344726&GoogleAccessId=gorilla-files-url-signer-man%40wandb-production.iam.gserviceaccount.com&Signature=n3TmQTke7rSKTOCmV4yBzpiHwvu8vQPE5LqY5EPfq8lc0JXiqgCFiFHzkxawDiSoIUcT3kdxgc2aPTLq1LD2WEkY6%2FuVV8En4N40fMx5DpkYekTPQfNs60A7VrzXiwdiTse%2FK8x%2FzrxcTRGKL5PlVDbPIkJTXr7S4GamUrQu66SpK3x%2F2MXkJ8k3cxcj6u9OgJgPH558FhRJENn1qVzm7AEwxNviV2ROMH174SOmY07BcoW8rCBvf8RWcNxUJrLulhAQk3VasB2MusrZH8Jf%2FHi2MAv4YWRHVoTGBX%2Bzrqj9sOhlhVHl8aINJwVSm9S0qzb2KI9%2FvZPZ3%2BqOahzSRg%3D%3D (Caused by NewConnectionError('<urllib3.connection.HTTPSConnection object at 0x7f9aec5e6750>: Failed to establish a new connection: [Errno 111] Connection refused'))
2024-05-21 10:25:27,298 ERROR   wandb-upload_1:1290853 [internal_api.py:upload_file():2769] upload_file request headers: {'User-Agent': 'python-requests/2.31.0', 'Accept-Encoding': 'gzip, deflate, br', 'Accept': '*/*', 'Connection': 'keep-alive', 'Content-Length': '27'}
2024-05-21 10:25:27,298 ERROR   wandb-upload_1:1290853 [internal_api.py:upload_file():2771] upload_file response body: 
2024-05-21 10:25:27,304 ERROR   wandb-upload_3:1290853 [internal_api.py:upload_file():2767] upload_file exception https://storage.googleapis.com/wandb-production.appspot.com/1923354735/MonoGS/y7r8ow8y/requirements.txt?Expires=1716344726&GoogleAccessId=gorilla-files-url-signer-man%40wandb-production.iam.gserviceaccount.com&Signature=L3wnj%2Fyq7ui%2BxLSSHbd3ZNhcWA4kK0ZtJyRG36fvMf2Y64WNPxFbuXgPhvC3rdidwqU2%2FOe%2FZTIIdUTKPbXzP9cEZ7sVF4Uwp3hSUNfDuTOFQaig%2F7JOiFRBJGv2X1R2iASbTo4JBQgGB9GC2veBdTUOc8aYkoZ5obUK%2FM%2BpCNVMPAzKdiJXEOZwIQ14bgSeH5mgaAwjpsla%2BJXsuIFxnyOcT%2FEZXY8VhWlqGJToRux8cvvjrvzrpp1jvjPgGnLacIrUtX0qi5kxdwvU79IAmi4m2uwJuuJryVhLfb1msk0BS4LjGHkfWl9hd4p6pZiXdVx7Q7s0g8yyBNyPv%2BnGhw%3D%3D: HTTPSConnectionPool(host='storage.googleapis.com', port=443): Max retries exceeded with url: /wandb-production.appspot.com/1923354735/MonoGS/y7r8ow8y/requirements.txt?Expires=1716344726&GoogleAccessId=gorilla-files-url-signer-man%40wandb-production.iam.gserviceaccount.com&Signature=L3wnj%2Fyq7ui%2BxLSSHbd3ZNhcWA4kK0ZtJyRG36fvMf2Y64WNPxFbuXgPhvC3rdidwqU2%2FOe%2FZTIIdUTKPbXzP9cEZ7sVF4Uwp3hSUNfDuTOFQaig%2F7JOiFRBJGv2X1R2iASbTo4JBQgGB9GC2veBdTUOc8aYkoZ5obUK%2FM%2BpCNVMPAzKdiJXEOZwIQ14bgSeH5mgaAwjpsla%2BJXsuIFxnyOcT%2FEZXY8VhWlqGJToRux8cvvjrvzrpp1jvjPgGnLacIrUtX0qi5kxdwvU79IAmi4m2uwJuuJryVhLfb1msk0BS4LjGHkfWl9hd4p6pZiXdVx7Q7s0g8yyBNyPv%2BnGhw%3D%3D (Caused by NewConnectionError('<urllib3.connection.HTTPSConnection object at 0x7f9aec5e6090>: Failed to establish a new connection: [Errno 111] Connection refused'))
2024-05-21 10:25:27,304 ERROR   wandb-upload_3:1290853 [internal_api.py:upload_file():2769] upload_file request headers: {'User-Agent': 'python-requests/2.31.0', 'Accept-Encoding': 'gzip, deflate, br', 'Accept': '*/*', 'Connection': 'keep-alive', 'Content-Length': '2267'}
2024-05-21 10:25:27,304 ERROR   wandb-upload_3:1290853 [internal_api.py:upload_file():2771] upload_file response body: 
2024-05-21 10:25:29,340 ERROR   wandb-upload_1:1290853 [internal_api.py:upload_file():2767] upload_file exception https://storage.googleapis.com/wandb-production.appspot.com/1923354735/MonoGS/y7r8ow8y/wandb-summary.json?Expires=1716344726&GoogleAccessId=gorilla-files-url-signer-man%40wandb-production.iam.gserviceaccount.com&Signature=n3TmQTke7rSKTOCmV4yBzpiHwvu8vQPE5LqY5EPfq8lc0JXiqgCFiFHzkxawDiSoIUcT3kdxgc2aPTLq1LD2WEkY6%2FuVV8En4N40fMx5DpkYekTPQfNs60A7VrzXiwdiTse%2FK8x%2FzrxcTRGKL5PlVDbPIkJTXr7S4GamUrQu66SpK3x%2F2MXkJ8k3cxcj6u9OgJgPH558FhRJENn1qVzm7AEwxNviV2ROMH174SOmY07BcoW8rCBvf8RWcNxUJrLulhAQk3VasB2MusrZH8Jf%2FHi2MAv4YWRHVoTGBX%2Bzrqj9sOhlhVHl8aINJwVSm9S0qzb2KI9%2FvZPZ3%2BqOahzSRg%3D%3D: HTTPSConnectionPool(host='storage.googleapis.com', port=443): Max retries exceeded with url: /wandb-production.appspot.com/1923354735/MonoGS/y7r8ow8y/wandb-summary.json?Expires=1716344726&GoogleAccessId=gorilla-files-url-signer-man%40wandb-production.iam.gserviceaccount.com&Signature=n3TmQTke7rSKTOCmV4yBzpiHwvu8vQPE5LqY5EPfq8lc0JXiqgCFiFHzkxawDiSoIUcT3kdxgc2aPTLq1LD2WEkY6%2FuVV8En4N40fMx5DpkYekTPQfNs60A7VrzXiwdiTse%2FK8x%2FzrxcTRGKL5PlVDbPIkJTXr7S4GamUrQu66SpK3x%2F2MXkJ8k3cxcj6u9OgJgPH558FhRJENn1qVzm7AEwxNviV2ROMH174SOmY07BcoW8rCBvf8RWcNxUJrLulhAQk3VasB2MusrZH8Jf%2FHi2MAv4YWRHVoTGBX%2Bzrqj9sOhlhVHl8aINJwVSm9S0qzb2KI9%2FvZPZ3%2BqOahzSRg%3D%3D (Caused by NewConnectionError('<urllib3.connection.HTTPSConnection object at 0x7f9aec6a5e90>: Failed to establish a new connection: [Errno 111] Connection refused'))
2024-05-21 10:25:29,340 ERROR   wandb-upload_1:1290853 [internal_api.py:upload_file():2769] upload_file request headers: {'User-Agent': 'python-requests/2.31.0', 'Accept-Encoding': 'gzip, deflate, br', 'Accept': '*/*', 'Connection': 'keep-alive', 'Content-Length': '27'}
2024-05-21 10:25:29,340 ERROR   wandb-upload_1:1290853 [internal_api.py:upload_file():2771] upload_file response body: 
2024-05-21 10:25:29,459 ERROR   wandb-upload_5:1290853 [internal_api.py:upload_file():2767] upload_file exception https://storage.googleapis.com/wandb-production.appspot.com/1923354735/MonoGS/y7r8ow8y/config.yaml?Expires=1716344726&GoogleAccessId=gorilla-files-url-signer-man%40wandb-production.iam.gserviceaccount.com&Signature=I%2FNqKudC9MlfdRYAyMWFQvABnAS6abRNmQnfNVifsclZ4ceBglJy%2FoSd3mNSPDS9NKXypr69UhttUBb6HT4dYnStLUhTaBeqvaVAIboqb0qJixJW1nYbshU6oZOHN%2F2QXnXcTDMAcIqYyvjbX8%2FgNgcm62O%2FZfSG0rwQMsg36I%2BybxXDywQsR6Hj%2BHEviQaJ2BiWLrrG13wLXJRzU9Fy6cW8OxwP3EO3FtI7%2FkTijIvBF0hMcNI8v07X9K4HytchvYdA5f6h8ydDmckf6lnmf8SJ4ou%2FY30cBWODkVpKSmeEE7IW58O0%2BZ7gTvYz5pY3sDXUPAhXajZ5flsUieNmzg%3D%3D: HTTPSConnectionPool(host='storage.googleapis.com', port=443): Max retries exceeded with url: /wandb-production.appspot.com/1923354735/MonoGS/y7r8ow8y/config.yaml?Expires=1716344726&GoogleAccessId=gorilla-files-url-signer-man%40wandb-production.iam.gserviceaccount.com&Signature=I%2FNqKudC9MlfdRYAyMWFQvABnAS6abRNmQnfNVifsclZ4ceBglJy%2FoSd3mNSPDS9NKXypr69UhttUBb6HT4dYnStLUhTaBeqvaVAIboqb0qJixJW1nYbshU6oZOHN%2F2QXnXcTDMAcIqYyvjbX8%2FgNgcm62O%2FZfSG0rwQMsg36I%2BybxXDywQsR6Hj%2BHEviQaJ2BiWLrrG13wLXJRzU9Fy6cW8OxwP3EO3FtI7%2FkTijIvBF0hMcNI8v07X9K4HytchvYdA5f6h8ydDmckf6lnmf8SJ4ou%2FY30cBWODkVpKSmeEE7IW58O0%2BZ7gTvYz5pY3sDXUPAhXajZ5flsUieNmzg%3D%3D (Caused by NewConnectionError('<urllib3.connection.HTTPSConnection object at 0x7f9aec6a5410>: Failed to establish a new connection: [Errno 111] Connection refused'))
2024-05-21 10:25:29,459 ERROR   wandb-upload_5:1290853 [internal_api.py:upload_file():2769] upload_file request headers: {'User-Agent': 'python-requests/2.31.0', 'Accept-Encoding': 'gzip, deflate, br', 'Accept': '*/*', 'Connection': 'keep-alive', 'Content-Length': '2747'}
2024-05-21 10:25:29,459 ERROR   wandb-upload_5:1290853 [internal_api.py:upload_file():2771] upload_file response body: 
2024-05-21 10:25:29,529 ERROR   wandb-upload_2:1290853 [internal_api.py:upload_file():2767] upload_file exception https://storage.googleapis.com/wandb-production.appspot.com/1923354735/MonoGS/y7r8ow8y/output.log?Expires=1716344726&GoogleAccessId=gorilla-files-url-signer-man%40wandb-production.iam.gserviceaccount.com&Signature=O7idKX8qxjOgQnoSk8t%2FEvZHFPDgj7JSXqoV7CpZlwFMS%2FvROKjPi8M3JagUT5wZ1inNHngyIU5scHIDo19KW%2Fxw0W%2FmJC%2FJfj2MZhGjDbxxnxx5aB4d%2BOoV7mxhAN9thVFs2jqWTNgNstrhhKFS%2BToiiRDtek%2BRxKJFLzjqTrqrZCJQO9usjTSGzzTHQLH%2F6Q0isKnkjj8HtIMoQpooN8s0cee02waCJy764hYUXOfj%2BXOvrLctCmMTiC04rFdK8juLoR0kM4uwRRmGkqjy2zRldzt%2F96rYeKQpv5GPvR1gVqtLd8Ie5gDieYQFYEwUdJw5wyXZMgJwm9kcUqF53w%3D%3D: HTTPSConnectionPool(host='storage.googleapis.com', port=443): Max retries exceeded with url: /wandb-production.appspot.com/1923354735/MonoGS/y7r8ow8y/output.log?Expires=1716344726&GoogleAccessId=gorilla-files-url-signer-man%40wandb-production.iam.gserviceaccount.com&Signature=O7idKX8qxjOgQnoSk8t%2FEvZHFPDgj7JSXqoV7CpZlwFMS%2FvROKjPi8M3JagUT5wZ1inNHngyIU5scHIDo19KW%2Fxw0W%2FmJC%2FJfj2MZhGjDbxxnxx5aB4d%2BOoV7mxhAN9thVFs2jqWTNgNstrhhKFS%2BToiiRDtek%2BRxKJFLzjqTrqrZCJQO9usjTSGzzTHQLH%2F6Q0isKnkjj8HtIMoQpooN8s0cee02waCJy764hYUXOfj%2BXOvrLctCmMTiC04rFdK8juLoR0kM4uwRRmGkqjy2zRldzt%2F96rYeKQpv5GPvR1gVqtLd8Ie5gDieYQFYEwUdJw5wyXZMgJwm9kcUqF53w%3D%3D (Caused by NewConnectionError('<urllib3.connection.HTTPSConnection object at 0x7f9aec5e6150>: Failed to establish a new connection: [Errno 111] Connection refused'))
2024-05-21 10:25:29,529 ERROR   wandb-upload_2:1290853 [internal_api.py:upload_file():2769] upload_file request headers: {'User-Agent': 'python-requests/2.31.0', 'Accept-Encoding': 'gzip, deflate, br', 'Accept': '*/*', 'Connection': 'keep-alive', 'Content-Length': '1214'}
2024-05-21 10:25:29,529 ERROR   wandb-upload_2:1290853 [internal_api.py:upload_file():2771] upload_file response body: 
2024-05-21 10:25:29,565 ERROR   wandb-upload_3:1290853 [internal_api.py:upload_file():2767] upload_file exception https://storage.googleapis.com/wandb-production.appspot.com/1923354735/MonoGS/y7r8ow8y/requirements.txt?Expires=1716344726&GoogleAccessId=gorilla-files-url-signer-man%40wandb-production.iam.gserviceaccount.com&Signature=L3wnj%2Fyq7ui%2BxLSSHbd3ZNhcWA4kK0ZtJyRG36fvMf2Y64WNPxFbuXgPhvC3rdidwqU2%2FOe%2FZTIIdUTKPbXzP9cEZ7sVF4Uwp3hSUNfDuTOFQaig%2F7JOiFRBJGv2X1R2iASbTo4JBQgGB9GC2veBdTUOc8aYkoZ5obUK%2FM%2BpCNVMPAzKdiJXEOZwIQ14bgSeH5mgaAwjpsla%2BJXsuIFxnyOcT%2FEZXY8VhWlqGJToRux8cvvjrvzrpp1jvjPgGnLacIrUtX0qi5kxdwvU79IAmi4m2uwJuuJryVhLfb1msk0BS4LjGHkfWl9hd4p6pZiXdVx7Q7s0g8yyBNyPv%2BnGhw%3D%3D: HTTPSConnectionPool(host='storage.googleapis.com', port=443): Max retries exceeded with url: /wandb-production.appspot.com/1923354735/MonoGS/y7r8ow8y/requirements.txt?Expires=1716344726&GoogleAccessId=gorilla-files-url-signer-man%40wandb-production.iam.gserviceaccount.com&Signature=L3wnj%2Fyq7ui%2BxLSSHbd3ZNhcWA4kK0ZtJyRG36fvMf2Y64WNPxFbuXgPhvC3rdidwqU2%2FOe%2FZTIIdUTKPbXzP9cEZ7sVF4Uwp3hSUNfDuTOFQaig%2F7JOiFRBJGv2X1R2iASbTo4JBQgGB9GC2veBdTUOc8aYkoZ5obUK%2FM%2BpCNVMPAzKdiJXEOZwIQ14bgSeH5mgaAwjpsla%2BJXsuIFxnyOcT%2FEZXY8VhWlqGJToRux8cvvjrvzrpp1jvjPgGnLacIrUtX0qi5kxdwvU79IAmi4m2uwJuuJryVhLfb1msk0BS4LjGHkfWl9hd4p6pZiXdVx7Q7s0g8yyBNyPv%2BnGhw%3D%3D (Caused by NewConnectionError('<urllib3.connection.HTTPSConnection object at 0x7f9aec5e6410>: Failed to establish a new connection: [Errno 111] Connection refused'))
2024-05-21 10:25:29,565 ERROR   wandb-upload_3:1290853 [internal_api.py:upload_file():2769] upload_file request headers: {'User-Agent': 'python-requests/2.31.0', 'Accept-Encoding': 'gzip, deflate, br', 'Accept': '*/*', 'Connection': 'keep-alive', 'Content-Length': '2267'}
2024-05-21 10:25:29,565 ERROR   wandb-upload_3:1290853 [internal_api.py:upload_file():2771] upload_file response body: 
2024-05-21 10:25:29,663 ERROR   wandb-upload_4:1290853 [internal_api.py:upload_file():2767] upload_file exception https://storage.googleapis.com/wandb-production.appspot.com/1923354735/MonoGS/y7r8ow8y/conda-environment.yaml?Expires=1716344726&GoogleAccessId=gorilla-files-url-signer-man%40wandb-production.iam.gserviceaccount.com&Signature=BERXsAthvA4uNy8KsTYhi4DK4yIggzBZzxjksCpYdoksYlIRNvLT6PY86cQfX4%2F%2BjJSxwiltJwadlf7g%2FjxRbz0mfhoLBBROL50A3sp35%2FjQLnhmncVF3iVe7ThBmHwLjMPjt5XtQu2jC34B8fea3GjY7wKFq3uaKTrwmPgWtcEOZCQMLMY0ChxkR%2BHE%2FSRiWt7xGeRrrVQ%2BErKoDuQRznC3TvhkhS1U4lAVl6wRnLTI7GfzP%2FPZmxvohZpdRMn5apJEuRQkvST8ta2NN1yZWfvi903GAtgKWuYwg06ZHKj%2BCN24I%2B035VMqzFQRTyKx2EL50XK4hJucrjFTtzt8uQ%3D%3D: HTTPSConnectionPool(host='storage.googleapis.com', port=443): Max retries exceeded with url: /wandb-production.appspot.com/1923354735/MonoGS/y7r8ow8y/conda-environment.yaml?Expires=1716344726&GoogleAccessId=gorilla-files-url-signer-man%40wandb-production.iam.gserviceaccount.com&Signature=BERXsAthvA4uNy8KsTYhi4DK4yIggzBZzxjksCpYdoksYlIRNvLT6PY86cQfX4%2F%2BjJSxwiltJwadlf7g%2FjxRbz0mfhoLBBROL50A3sp35%2FjQLnhmncVF3iVe7ThBmHwLjMPjt5XtQu2jC34B8fea3GjY7wKFq3uaKTrwmPgWtcEOZCQMLMY0ChxkR%2BHE%2FSRiWt7xGeRrrVQ%2BErKoDuQRznC3TvhkhS1U4lAVl6wRnLTI7GfzP%2FPZmxvohZpdRMn5apJEuRQkvST8ta2NN1yZWfvi903GAtgKWuYwg06ZHKj%2BCN24I%2B035VMqzFQRTyKx2EL50XK4hJucrjFTtzt8uQ%3D%3D (Caused by NewConnectionError('<urllib3.connection.HTTPSConnection object at 0x7f9aec692250>: Failed to establish a new connection: [Errno 111] Connection refused'))
2024-05-21 10:25:29,663 ERROR   wandb-upload_4:1290853 [internal_api.py:upload_file():2769] upload_file request headers: {'User-Agent': 'python-requests/2.31.0', 'Accept-Encoding': 'gzip, deflate, br', 'Accept': '*/*', 'Connection': 'keep-alive', 'Content-Length': '4690'}
2024-05-21 10:25:29,663 ERROR   wandb-upload_4:1290853 [internal_api.py:upload_file():2771] upload_file response body: 
2024-05-21 10:25:34,031 ERROR   wandb-upload_1:1290853 [internal_api.py:upload_file():2767] upload_file exception https://storage.googleapis.com/wandb-production.appspot.com/1923354735/MonoGS/y7r8ow8y/wandb-summary.json?Expires=1716344726&GoogleAccessId=gorilla-files-url-signer-man%40wandb-production.iam.gserviceaccount.com&Signature=n3TmQTke7rSKTOCmV4yBzpiHwvu8vQPE5LqY5EPfq8lc0JXiqgCFiFHzkxawDiSoIUcT3kdxgc2aPTLq1LD2WEkY6%2FuVV8En4N40fMx5DpkYekTPQfNs60A7VrzXiwdiTse%2FK8x%2FzrxcTRGKL5PlVDbPIkJTXr7S4GamUrQu66SpK3x%2F2MXkJ8k3cxcj6u9OgJgPH558FhRJENn1qVzm7AEwxNviV2ROMH174SOmY07BcoW8rCBvf8RWcNxUJrLulhAQk3VasB2MusrZH8Jf%2FHi2MAv4YWRHVoTGBX%2Bzrqj9sOhlhVHl8aINJwVSm9S0qzb2KI9%2FvZPZ3%2BqOahzSRg%3D%3D: HTTPSConnectionPool(host='storage.googleapis.com', port=443): Max retries exceeded with url: /wandb-production.appspot.com/1923354735/MonoGS/y7r8ow8y/wandb-summary.json?Expires=1716344726&GoogleAccessId=gorilla-files-url-signer-man%40wandb-production.iam.gserviceaccount.com&Signature=n3TmQTke7rSKTOCmV4yBzpiHwvu8vQPE5LqY5EPfq8lc0JXiqgCFiFHzkxawDiSoIUcT3kdxgc2aPTLq1LD2WEkY6%2FuVV8En4N40fMx5DpkYekTPQfNs60A7VrzXiwdiTse%2FK8x%2FzrxcTRGKL5PlVDbPIkJTXr7S4GamUrQu66SpK3x%2F2MXkJ8k3cxcj6u9OgJgPH558FhRJENn1qVzm7AEwxNviV2ROMH174SOmY07BcoW8rCBvf8RWcNxUJrLulhAQk3VasB2MusrZH8Jf%2FHi2MAv4YWRHVoTGBX%2Bzrqj9sOhlhVHl8aINJwVSm9S0qzb2KI9%2FvZPZ3%2BqOahzSRg%3D%3D (Caused by NewConnectionError('<urllib3.connection.HTTPSConnection object at 0x7f9aec5feed0>: Failed to establish a new connection: [Errno 111] Connection refused'))
2024-05-21 10:25:34,032 ERROR   wandb-upload_1:1290853 [internal_api.py:upload_file():2769] upload_file request headers: {'User-Agent': 'python-requests/2.31.0', 'Accept-Encoding': 'gzip, deflate, br', 'Accept': '*/*', 'Connection': 'keep-alive', 'Content-Length': '27'}
2024-05-21 10:25:34,032 ERROR   wandb-upload_1:1290853 [internal_api.py:upload_file():2771] upload_file response body: 
2024-05-21 10:25:34,211 ERROR   wandb-upload_2:1290853 [internal_api.py:upload_file():2767] upload_file exception https://storage.googleapis.com/wandb-production.appspot.com/1923354735/MonoGS/y7r8ow8y/output.log?Expires=1716344726&GoogleAccessId=gorilla-files-url-signer-man%40wandb-production.iam.gserviceaccount.com&Signature=O7idKX8qxjOgQnoSk8t%2FEvZHFPDgj7JSXqoV7CpZlwFMS%2FvROKjPi8M3JagUT5wZ1inNHngyIU5scHIDo19KW%2Fxw0W%2FmJC%2FJfj2MZhGjDbxxnxx5aB4d%2BOoV7mxhAN9thVFs2jqWTNgNstrhhKFS%2BToiiRDtek%2BRxKJFLzjqTrqrZCJQO9usjTSGzzTHQLH%2F6Q0isKnkjj8HtIMoQpooN8s0cee02waCJy764hYUXOfj%2BXOvrLctCmMTiC04rFdK8juLoR0kM4uwRRmGkqjy2zRldzt%2F96rYeKQpv5GPvR1gVqtLd8Ie5gDieYQFYEwUdJw5wyXZMgJwm9kcUqF53w%3D%3D: HTTPSConnectionPool(host='storage.googleapis.com', port=443): Max retries exceeded with url: /wandb-production.appspot.com/1923354735/MonoGS/y7r8ow8y/output.log?Expires=1716344726&GoogleAccessId=gorilla-files-url-signer-man%40wandb-production.iam.gserviceaccount.com&Signature=O7idKX8qxjOgQnoSk8t%2FEvZHFPDgj7JSXqoV7CpZlwFMS%2FvROKjPi8M3JagUT5wZ1inNHngyIU5scHIDo19KW%2Fxw0W%2FmJC%2FJfj2MZhGjDbxxnxx5aB4d%2BOoV7mxhAN9thVFs2jqWTNgNstrhhKFS%2BToiiRDtek%2BRxKJFLzjqTrqrZCJQO9usjTSGzzTHQLH%2F6Q0isKnkjj8HtIMoQpooN8s0cee02waCJy764hYUXOfj%2BXOvrLctCmMTiC04rFdK8juLoR0kM4uwRRmGkqjy2zRldzt%2F96rYeKQpv5GPvR1gVqtLd8Ie5gDieYQFYEwUdJw5wyXZMgJwm9kcUqF53w%3D%3D (Caused by NewConnectionError('<urllib3.connection.HTTPSConnection object at 0x7f9aec5fe290>: Failed to establish a new connection: [Errno 111] Connection refused'))
2024-05-21 10:25:34,211 ERROR   wandb-upload_2:1290853 [internal_api.py:upload_file():2769] upload_file request headers: {'User-Agent': 'python-requests/2.31.0', 'Accept-Encoding': 'gzip, deflate, br', 'Accept': '*/*', 'Connection': 'keep-alive', 'Content-Length': '1214'}
2024-05-21 10:25:34,211 ERROR   wandb-upload_2:1290853 [internal_api.py:upload_file():2771] upload_file response body: 
2024-05-21 10:25:34,370 ERROR   wandb-upload_3:1290853 [internal_api.py:upload_file():2767] upload_file exception https://storage.googleapis.com/wandb-production.appspot.com/1923354735/MonoGS/y7r8ow8y/requirements.txt?Expires=1716344726&GoogleAccessId=gorilla-files-url-signer-man%40wandb-production.iam.gserviceaccount.com&Signature=L3wnj%2Fyq7ui%2BxLSSHbd3ZNhcWA4kK0ZtJyRG36fvMf2Y64WNPxFbuXgPhvC3rdidwqU2%2FOe%2FZTIIdUTKPbXzP9cEZ7sVF4Uwp3hSUNfDuTOFQaig%2F7JOiFRBJGv2X1R2iASbTo4JBQgGB9GC2veBdTUOc8aYkoZ5obUK%2FM%2BpCNVMPAzKdiJXEOZwIQ14bgSeH5mgaAwjpsla%2BJXsuIFxnyOcT%2FEZXY8VhWlqGJToRux8cvvjrvzrpp1jvjPgGnLacIrUtX0qi5kxdwvU79IAmi4m2uwJuuJryVhLfb1msk0BS4LjGHkfWl9hd4p6pZiXdVx7Q7s0g8yyBNyPv%2BnGhw%3D%3D: HTTPSConnectionPool(host='storage.googleapis.com', port=443): Max retries exceeded with url: /wandb-production.appspot.com/1923354735/MonoGS/y7r8ow8y/requirements.txt?Expires=1716344726&GoogleAccessId=gorilla-files-url-signer-man%40wandb-production.iam.gserviceaccount.com&Signature=L3wnj%2Fyq7ui%2BxLSSHbd3ZNhcWA4kK0ZtJyRG36fvMf2Y64WNPxFbuXgPhvC3rdidwqU2%2FOe%2FZTIIdUTKPbXzP9cEZ7sVF4Uwp3hSUNfDuTOFQaig%2F7JOiFRBJGv2X1R2iASbTo4JBQgGB9GC2veBdTUOc8aYkoZ5obUK%2FM%2BpCNVMPAzKdiJXEOZwIQ14bgSeH5mgaAwjpsla%2BJXsuIFxnyOcT%2FEZXY8VhWlqGJToRux8cvvjrvzrpp1jvjPgGnLacIrUtX0qi5kxdwvU79IAmi4m2uwJuuJryVhLfb1msk0BS4LjGHkfWl9hd4p6pZiXdVx7Q7s0g8yyBNyPv%2BnGhw%3D%3D (Caused by NewConnectionError('<urllib3.connection.HTTPSConnection object at 0x7f9aec607550>: Failed to establish a new connection: [Errno 111] Connection refused'))
2024-05-21 10:25:34,371 ERROR   wandb-upload_3:1290853 [internal_api.py:upload_file():2769] upload_file request headers: {'User-Agent': 'python-requests/2.31.0', 'Accept-Encoding': 'gzip, deflate, br', 'Accept': '*/*', 'Connection': 'keep-alive', 'Content-Length': '2267'}
2024-05-21 10:25:34,371 ERROR   wandb-upload_3:1290853 [internal_api.py:upload_file():2771] upload_file response body: 
2024-05-21 10:25:34,398 ERROR   wandb-upload_5:1290853 [internal_api.py:upload_file():2767] upload_file exception https://storage.googleapis.com/wandb-production.appspot.com/1923354735/MonoGS/y7r8ow8y/config.yaml?Expires=1716344726&GoogleAccessId=gorilla-files-url-signer-man%40wandb-production.iam.gserviceaccount.com&Signature=I%2FNqKudC9MlfdRYAyMWFQvABnAS6abRNmQnfNVifsclZ4ceBglJy%2FoSd3mNSPDS9NKXypr69UhttUBb6HT4dYnStLUhTaBeqvaVAIboqb0qJixJW1nYbshU6oZOHN%2F2QXnXcTDMAcIqYyvjbX8%2FgNgcm62O%2FZfSG0rwQMsg36I%2BybxXDywQsR6Hj%2BHEviQaJ2BiWLrrG13wLXJRzU9Fy6cW8OxwP3EO3FtI7%2FkTijIvBF0hMcNI8v07X9K4HytchvYdA5f6h8ydDmckf6lnmf8SJ4ou%2FY30cBWODkVpKSmeEE7IW58O0%2BZ7gTvYz5pY3sDXUPAhXajZ5flsUieNmzg%3D%3D: HTTPSConnectionPool(host='storage.googleapis.com', port=443): Max retries exceeded with url: /wandb-production.appspot.com/1923354735/MonoGS/y7r8ow8y/config.yaml?Expires=1716344726&GoogleAccessId=gorilla-files-url-signer-man%40wandb-production.iam.gserviceaccount.com&Signature=I%2FNqKudC9MlfdRYAyMWFQvABnAS6abRNmQnfNVifsclZ4ceBglJy%2FoSd3mNSPDS9NKXypr69UhttUBb6HT4dYnStLUhTaBeqvaVAIboqb0qJixJW1nYbshU6oZOHN%2F2QXnXcTDMAcIqYyvjbX8%2FgNgcm62O%2FZfSG0rwQMsg36I%2BybxXDywQsR6Hj%2BHEviQaJ2BiWLrrG13wLXJRzU9Fy6cW8OxwP3EO3FtI7%2FkTijIvBF0hMcNI8v07X9K4HytchvYdA5f6h8ydDmckf6lnmf8SJ4ou%2FY30cBWODkVpKSmeEE7IW58O0%2BZ7gTvYz5pY3sDXUPAhXajZ5flsUieNmzg%3D%3D (Caused by NewConnectionError('<urllib3.connection.HTTPSConnection object at 0x7f9aec601150>: Failed to establish a new connection: [Errno 111] Connection refused'))
2024-05-21 10:25:34,398 ERROR   wandb-upload_5:1290853 [internal_api.py:upload_file():2769] upload_file request headers: {'User-Agent': 'python-requests/2.31.0', 'Accept-Encoding': 'gzip, deflate, br', 'Accept': '*/*', 'Connection': 'keep-alive', 'Content-Length': '2747'}
2024-05-21 10:25:34,398 ERROR   wandb-upload_5:1290853 [internal_api.py:upload_file():2771] upload_file response body: 
2024-05-21 10:25:34,431 ERROR   wandb-upload_4:1290853 [internal_api.py:upload_file():2767] upload_file exception https://storage.googleapis.com/wandb-production.appspot.com/1923354735/MonoGS/y7r8ow8y/conda-environment.yaml?Expires=1716344726&GoogleAccessId=gorilla-files-url-signer-man%40wandb-production.iam.gserviceaccount.com&Signature=BERXsAthvA4uNy8KsTYhi4DK4yIggzBZzxjksCpYdoksYlIRNvLT6PY86cQfX4%2F%2BjJSxwiltJwadlf7g%2FjxRbz0mfhoLBBROL50A3sp35%2FjQLnhmncVF3iVe7ThBmHwLjMPjt5XtQu2jC34B8fea3GjY7wKFq3uaKTrwmPgWtcEOZCQMLMY0ChxkR%2BHE%2FSRiWt7xGeRrrVQ%2BErKoDuQRznC3TvhkhS1U4lAVl6wRnLTI7GfzP%2FPZmxvohZpdRMn5apJEuRQkvST8ta2NN1yZWfvi903GAtgKWuYwg06ZHKj%2BCN24I%2B035VMqzFQRTyKx2EL50XK4hJucrjFTtzt8uQ%3D%3D: HTTPSConnectionPool(host='storage.googleapis.com', port=443): Max retries exceeded with url: /wandb-production.appspot.com/1923354735/MonoGS/y7r8ow8y/conda-environment.yaml?Expires=1716344726&GoogleAccessId=gorilla-files-url-signer-man%40wandb-production.iam.gserviceaccount.com&Signature=BERXsAthvA4uNy8KsTYhi4DK4yIggzBZzxjksCpYdoksYlIRNvLT6PY86cQfX4%2F%2BjJSxwiltJwadlf7g%2FjxRbz0mfhoLBBROL50A3sp35%2FjQLnhmncVF3iVe7ThBmHwLjMPjt5XtQu2jC34B8fea3GjY7wKFq3uaKTrwmPgWtcEOZCQMLMY0ChxkR%2BHE%2FSRiWt7xGeRrrVQ%2BErKoDuQRznC3TvhkhS1U4lAVl6wRnLTI7GfzP%2FPZmxvohZpdRMn5apJEuRQkvST8ta2NN1yZWfvi903GAtgKWuYwg06ZHKj%2BCN24I%2B035VMqzFQRTyKx2EL50XK4hJucrjFTtzt8uQ%3D%3D (Caused by NewConnectionError('<urllib3.connection.HTTPSConnection object at 0x7f9aec5e98d0>: Failed to establish a new connection: [Errno 111] Connection refused'))
2024-05-21 10:25:34,431 ERROR   wandb-upload_4:1290853 [internal_api.py:upload_file():2769] upload_file request headers: {'User-Agent': 'python-requests/2.31.0', 'Accept-Encoding': 'gzip, deflate, br', 'Accept': '*/*', 'Connection': 'keep-alive', 'Content-Length': '4690'}
2024-05-21 10:25:34,431 ERROR   wandb-upload_4:1290853 [internal_api.py:upload_file():2771] upload_file response body: 
2024-05-21 10:25:42,539 ERROR   wandb-upload_3:1290853 [internal_api.py:upload_file():2767] upload_file exception https://storage.googleapis.com/wandb-production.appspot.com/1923354735/MonoGS/y7r8ow8y/requirements.txt?Expires=1716344726&GoogleAccessId=gorilla-files-url-signer-man%40wandb-production.iam.gserviceaccount.com&Signature=L3wnj%2Fyq7ui%2BxLSSHbd3ZNhcWA4kK0ZtJyRG36fvMf2Y64WNPxFbuXgPhvC3rdidwqU2%2FOe%2FZTIIdUTKPbXzP9cEZ7sVF4Uwp3hSUNfDuTOFQaig%2F7JOiFRBJGv2X1R2iASbTo4JBQgGB9GC2veBdTUOc8aYkoZ5obUK%2FM%2BpCNVMPAzKdiJXEOZwIQ14bgSeH5mgaAwjpsla%2BJXsuIFxnyOcT%2FEZXY8VhWlqGJToRux8cvvjrvzrpp1jvjPgGnLacIrUtX0qi5kxdwvU79IAmi4m2uwJuuJryVhLfb1msk0BS4LjGHkfWl9hd4p6pZiXdVx7Q7s0g8yyBNyPv%2BnGhw%3D%3D: HTTPSConnectionPool(host='storage.googleapis.com', port=443): Max retries exceeded with url: /wandb-production.appspot.com/1923354735/MonoGS/y7r8ow8y/requirements.txt?Expires=1716344726&GoogleAccessId=gorilla-files-url-signer-man%40wandb-production.iam.gserviceaccount.com&Signature=L3wnj%2Fyq7ui%2BxLSSHbd3ZNhcWA4kK0ZtJyRG36fvMf2Y64WNPxFbuXgPhvC3rdidwqU2%2FOe%2FZTIIdUTKPbXzP9cEZ7sVF4Uwp3hSUNfDuTOFQaig%2F7JOiFRBJGv2X1R2iASbTo4JBQgGB9GC2veBdTUOc8aYkoZ5obUK%2FM%2BpCNVMPAzKdiJXEOZwIQ14bgSeH5mgaAwjpsla%2BJXsuIFxnyOcT%2FEZXY8VhWlqGJToRux8cvvjrvzrpp1jvjPgGnLacIrUtX0qi5kxdwvU79IAmi4m2uwJuuJryVhLfb1msk0BS4LjGHkfWl9hd4p6pZiXdVx7Q7s0g8yyBNyPv%2BnGhw%3D%3D (Caused by NewConnectionError('<urllib3.connection.HTTPSConnection object at 0x7f9aec5e9150>: Failed to establish a new connection: [Errno 111] Connection refused'))
2024-05-21 10:25:42,539 ERROR   wandb-upload_3:1290853 [internal_api.py:upload_file():2769] upload_file request headers: {'User-Agent': 'python-requests/2.31.0', 'Accept-Encoding': 'gzip, deflate, br', 'Accept': '*/*', 'Connection': 'keep-alive', 'Content-Length': '2267'}
2024-05-21 10:25:42,539 ERROR   wandb-upload_3:1290853 [internal_api.py:upload_file():2771] upload_file response body: 
2024-05-21 10:25:42,587 ERROR   wandb-upload_2:1290853 [internal_api.py:upload_file():2767] upload_file exception https://storage.googleapis.com/wandb-production.appspot.com/1923354735/MonoGS/y7r8ow8y/output.log?Expires=1716344726&GoogleAccessId=gorilla-files-url-signer-man%40wandb-production.iam.gserviceaccount.com&Signature=O7idKX8qxjOgQnoSk8t%2FEvZHFPDgj7JSXqoV7CpZlwFMS%2FvROKjPi8M3JagUT5wZ1inNHngyIU5scHIDo19KW%2Fxw0W%2FmJC%2FJfj2MZhGjDbxxnxx5aB4d%2BOoV7mxhAN9thVFs2jqWTNgNstrhhKFS%2BToiiRDtek%2BRxKJFLzjqTrqrZCJQO9usjTSGzzTHQLH%2F6Q0isKnkjj8HtIMoQpooN8s0cee02waCJy764hYUXOfj%2BXOvrLctCmMTiC04rFdK8juLoR0kM4uwRRmGkqjy2zRldzt%2F96rYeKQpv5GPvR1gVqtLd8Ie5gDieYQFYEwUdJw5wyXZMgJwm9kcUqF53w%3D%3D: HTTPSConnectionPool(host='storage.googleapis.com', port=443): Max retries exceeded with url: /wandb-production.appspot.com/1923354735/MonoGS/y7r8ow8y/output.log?Expires=1716344726&GoogleAccessId=gorilla-files-url-signer-man%40wandb-production.iam.gserviceaccount.com&Signature=O7idKX8qxjOgQnoSk8t%2FEvZHFPDgj7JSXqoV7CpZlwFMS%2FvROKjPi8M3JagUT5wZ1inNHngyIU5scHIDo19KW%2Fxw0W%2FmJC%2FJfj2MZhGjDbxxnxx5aB4d%2BOoV7mxhAN9thVFs2jqWTNgNstrhhKFS%2BToiiRDtek%2BRxKJFLzjqTrqrZCJQO9usjTSGzzTHQLH%2F6Q0isKnkjj8HtIMoQpooN8s0cee02waCJy764hYUXOfj%2BXOvrLctCmMTiC04rFdK8juLoR0kM4uwRRmGkqjy2zRldzt%2F96rYeKQpv5GPvR1gVqtLd8Ie5gDieYQFYEwUdJw5wyXZMgJwm9kcUqF53w%3D%3D (Caused by NewConnectionError('<urllib3.connection.HTTPSConnection object at 0x7f9aec7e7710>: Failed to establish a new connection: [Errno 111] Connection refused'))
2024-05-21 10:25:42,587 ERROR   wandb-upload_2:1290853 [internal_api.py:upload_file():2769] upload_file request headers: {'User-Agent': 'python-requests/2.31.0', 'Accept-Encoding': 'gzip, deflate, br', 'Accept': '*/*', 'Connection': 'keep-alive', 'Content-Length': '1214'}
2024-05-21 10:25:42,587 ERROR   wandb-upload_2:1290853 [internal_api.py:upload_file():2771] upload_file response body: 
2024-05-21 10:25:42,799 ERROR   wandb-upload_4:1290853 [internal_api.py:upload_file():2767] upload_file exception https://storage.googleapis.com/wandb-production.appspot.com/1923354735/MonoGS/y7r8ow8y/conda-environment.yaml?Expires=1716344726&GoogleAccessId=gorilla-files-url-signer-man%40wandb-production.iam.gserviceaccount.com&Signature=BERXsAthvA4uNy8KsTYhi4DK4yIggzBZzxjksCpYdoksYlIRNvLT6PY86cQfX4%2F%2BjJSxwiltJwadlf7g%2FjxRbz0mfhoLBBROL50A3sp35%2FjQLnhmncVF3iVe7ThBmHwLjMPjt5XtQu2jC34B8fea3GjY7wKFq3uaKTrwmPgWtcEOZCQMLMY0ChxkR%2BHE%2FSRiWt7xGeRrrVQ%2BErKoDuQRznC3TvhkhS1U4lAVl6wRnLTI7GfzP%2FPZmxvohZpdRMn5apJEuRQkvST8ta2NN1yZWfvi903GAtgKWuYwg06ZHKj%2BCN24I%2B035VMqzFQRTyKx2EL50XK4hJucrjFTtzt8uQ%3D%3D: HTTPSConnectionPool(host='storage.googleapis.com', port=443): Max retries exceeded with url: /wandb-production.appspot.com/1923354735/MonoGS/y7r8ow8y/conda-environment.yaml?Expires=1716344726&GoogleAccessId=gorilla-files-url-signer-man%40wandb-production.iam.gserviceaccount.com&Signature=BERXsAthvA4uNy8KsTYhi4DK4yIggzBZzxjksCpYdoksYlIRNvLT6PY86cQfX4%2F%2BjJSxwiltJwadlf7g%2FjxRbz0mfhoLBBROL50A3sp35%2FjQLnhmncVF3iVe7ThBmHwLjMPjt5XtQu2jC34B8fea3GjY7wKFq3uaKTrwmPgWtcEOZCQMLMY0ChxkR%2BHE%2FSRiWt7xGeRrrVQ%2BErKoDuQRznC3TvhkhS1U4lAVl6wRnLTI7GfzP%2FPZmxvohZpdRMn5apJEuRQkvST8ta2NN1yZWfvi903GAtgKWuYwg06ZHKj%2BCN24I%2B035VMqzFQRTyKx2EL50XK4hJucrjFTtzt8uQ%3D%3D (Caused by NewConnectionError('<urllib3.connection.HTTPSConnection object at 0x7f9aec5e9890>: Failed to establish a new connection: [Errno 111] Connection refused'))
2024-05-21 10:25:42,799 ERROR   wandb-upload_4:1290853 [internal_api.py:upload_file():2769] upload_file request headers: {'User-Agent': 'python-requests/2.31.0', 'Accept-Encoding': 'gzip, deflate, br', 'Accept': '*/*', 'Connection': 'keep-alive', 'Content-Length': '4690'}
2024-05-21 10:25:42,799 ERROR   wandb-upload_4:1290853 [internal_api.py:upload_file():2771] upload_file response body: 
2024-05-21 10:25:43,571 ERROR   wandb-upload_1:1290853 [internal_api.py:upload_file():2767] upload_file exception https://storage.googleapis.com/wandb-production.appspot.com/1923354735/MonoGS/y7r8ow8y/wandb-summary.json?Expires=1716344726&GoogleAccessId=gorilla-files-url-signer-man%40wandb-production.iam.gserviceaccount.com&Signature=n3TmQTke7rSKTOCmV4yBzpiHwvu8vQPE5LqY5EPfq8lc0JXiqgCFiFHzkxawDiSoIUcT3kdxgc2aPTLq1LD2WEkY6%2FuVV8En4N40fMx5DpkYekTPQfNs60A7VrzXiwdiTse%2FK8x%2FzrxcTRGKL5PlVDbPIkJTXr7S4GamUrQu66SpK3x%2F2MXkJ8k3cxcj6u9OgJgPH558FhRJENn1qVzm7AEwxNviV2ROMH174SOmY07BcoW8rCBvf8RWcNxUJrLulhAQk3VasB2MusrZH8Jf%2FHi2MAv4YWRHVoTGBX%2Bzrqj9sOhlhVHl8aINJwVSm9S0qzb2KI9%2FvZPZ3%2BqOahzSRg%3D%3D: HTTPSConnectionPool(host='storage.googleapis.com', port=443): Max retries exceeded with url: /wandb-production.appspot.com/1923354735/MonoGS/y7r8ow8y/wandb-summary.json?Expires=1716344726&GoogleAccessId=gorilla-files-url-signer-man%40wandb-production.iam.gserviceaccount.com&Signature=n3TmQTke7rSKTOCmV4yBzpiHwvu8vQPE5LqY5EPfq8lc0JXiqgCFiFHzkxawDiSoIUcT3kdxgc2aPTLq1LD2WEkY6%2FuVV8En4N40fMx5DpkYekTPQfNs60A7VrzXiwdiTse%2FK8x%2FzrxcTRGKL5PlVDbPIkJTXr7S4GamUrQu66SpK3x%2F2MXkJ8k3cxcj6u9OgJgPH558FhRJENn1qVzm7AEwxNviV2ROMH174SOmY07BcoW8rCBvf8RWcNxUJrLulhAQk3VasB2MusrZH8Jf%2FHi2MAv4YWRHVoTGBX%2Bzrqj9sOhlhVHl8aINJwVSm9S0qzb2KI9%2FvZPZ3%2BqOahzSRg%3D%3D (Caused by NewConnectionError('<urllib3.connection.HTTPSConnection object at 0x7f9aec601d90>: Failed to establish a new connection: [Errno 111] Connection refused'))
2024-05-21 10:25:43,571 ERROR   wandb-upload_1:1290853 [internal_api.py:upload_file():2769] upload_file request headers: {'User-Agent': 'python-requests/2.31.0', 'Accept-Encoding': 'gzip, deflate, br', 'Accept': '*/*', 'Connection': 'keep-alive', 'Content-Length': '27'}
2024-05-21 10:25:43,571 ERROR   wandb-upload_1:1290853 [internal_api.py:upload_file():2771] upload_file response body: 
2024-05-21 10:25:44,112 ERROR   wandb-upload_5:1290853 [internal_api.py:upload_file():2767] upload_file exception https://storage.googleapis.com/wandb-production.appspot.com/1923354735/MonoGS/y7r8ow8y/config.yaml?Expires=1716344726&GoogleAccessId=gorilla-files-url-signer-man%40wandb-production.iam.gserviceaccount.com&Signature=I%2FNqKudC9MlfdRYAyMWFQvABnAS6abRNmQnfNVifsclZ4ceBglJy%2FoSd3mNSPDS9NKXypr69UhttUBb6HT4dYnStLUhTaBeqvaVAIboqb0qJixJW1nYbshU6oZOHN%2F2QXnXcTDMAcIqYyvjbX8%2FgNgcm62O%2FZfSG0rwQMsg36I%2BybxXDywQsR6Hj%2BHEviQaJ2BiWLrrG13wLXJRzU9Fy6cW8OxwP3EO3FtI7%2FkTijIvBF0hMcNI8v07X9K4HytchvYdA5f6h8ydDmckf6lnmf8SJ4ou%2FY30cBWODkVpKSmeEE7IW58O0%2BZ7gTvYz5pY3sDXUPAhXajZ5flsUieNmzg%3D%3D: HTTPSConnectionPool(host='storage.googleapis.com', port=443): Max retries exceeded with url: /wandb-production.appspot.com/1923354735/MonoGS/y7r8ow8y/config.yaml?Expires=1716344726&GoogleAccessId=gorilla-files-url-signer-man%40wandb-production.iam.gserviceaccount.com&Signature=I%2FNqKudC9MlfdRYAyMWFQvABnAS6abRNmQnfNVifsclZ4ceBglJy%2FoSd3mNSPDS9NKXypr69UhttUBb6HT4dYnStLUhTaBeqvaVAIboqb0qJixJW1nYbshU6oZOHN%2F2QXnXcTDMAcIqYyvjbX8%2FgNgcm62O%2FZfSG0rwQMsg36I%2BybxXDywQsR6Hj%2BHEviQaJ2BiWLrrG13wLXJRzU9Fy6cW8OxwP3EO3FtI7%2FkTijIvBF0hMcNI8v07X9K4HytchvYdA5f6h8ydDmckf6lnmf8SJ4ou%2FY30cBWODkVpKSmeEE7IW58O0%2BZ7gTvYz5pY3sDXUPAhXajZ5flsUieNmzg%3D%3D (Caused by NewConnectionError('<urllib3.connection.HTTPSConnection object at 0x7f9aec601fd0>: Failed to establish a new connection: [Errno 111] Connection refused'))
2024-05-21 10:25:44,113 ERROR   wandb-upload_5:1290853 [internal_api.py:upload_file():2769] upload_file request headers: {'User-Agent': 'python-requests/2.31.0', 'Accept-Encoding': 'gzip, deflate, br', 'Accept': '*/*', 'Connection': 'keep-alive', 'Content-Length': '2747'}
2024-05-21 10:25:44,113 ERROR   wandb-upload_5:1290853 [internal_api.py:upload_file():2771] upload_file response body: 
2024-05-21 10:25:59,423 ERROR   wandb-upload_0:1290853 [internal_api.py:upload_file():2767] upload_file exception https://storage.googleapis.com/wandb-production.appspot.com/1923354735/MonoGS/y7r8ow8y/wandb-metadata.json?Expires=1716344689&GoogleAccessId=gorilla-files-url-signer-man%40wandb-production.iam.gserviceaccount.com&Signature=XocjRmoIFbGhOWBuXHuQ1YhKHLYkoSCeErITJdS8ptWPCsz3MOZyInwqvfgV1AZwEKws5oPw3%2FDwg85hQPHAmupIZkrP%2FbzB80ItKNP%2FF37E4x7FatfKjo6Hx%2Blh6yxHbiVm%2BvTSvuL%2BRLunzyQhKrpBG8Qfx2K0vR52s0eIcahq37a1liZqh3oYSnC07NnlHFejfubqJTF65nXAiLz0%2B7IRQ6cPHAueqi4g6ath5yiztED2FGfOW2i73RW7lux%2FC8MDffiA0UrP30CrlqM6OVwjcoEbSqfaJxx7%2B0fnOFYZ3afMjjX5iJaH0ndAPKs0qCHPV%2FLlYU%2FKzWzLxt2GNA%3D%3D: HTTPSConnectionPool(host='storage.googleapis.com', port=443): Max retries exceeded with url: /wandb-production.appspot.com/1923354735/MonoGS/y7r8ow8y/wandb-metadata.json?Expires=1716344689&GoogleAccessId=gorilla-files-url-signer-man%40wandb-production.iam.gserviceaccount.com&Signature=XocjRmoIFbGhOWBuXHuQ1YhKHLYkoSCeErITJdS8ptWPCsz3MOZyInwqvfgV1AZwEKws5oPw3%2FDwg85hQPHAmupIZkrP%2FbzB80ItKNP%2FF37E4x7FatfKjo6Hx%2Blh6yxHbiVm%2BvTSvuL%2BRLunzyQhKrpBG8Qfx2K0vR52s0eIcahq37a1liZqh3oYSnC07NnlHFejfubqJTF65nXAiLz0%2B7IRQ6cPHAueqi4g6ath5yiztED2FGfOW2i73RW7lux%2FC8MDffiA0UrP30CrlqM6OVwjcoEbSqfaJxx7%2B0fnOFYZ3afMjjX5iJaH0ndAPKs0qCHPV%2FLlYU%2FKzWzLxt2GNA%3D%3D (Caused by NewConnectionError('<urllib3.connection.HTTPSConnection object at 0x7f9aec62ec90>: Failed to establish a new connection: [Errno 111] Connection refused'))
2024-05-21 10:25:59,423 ERROR   wandb-upload_0:1290853 [internal_api.py:upload_file():2769] upload_file request headers: {'User-Agent': 'python-requests/2.31.0', 'Accept-Encoding': 'gzip, deflate, br', 'Accept': '*/*', 'Connection': 'keep-alive', 'Content-Length': '3405'}
2024-05-21 10:25:59,423 ERROR   wandb-upload_0:1290853 [internal_api.py:upload_file():2771] upload_file response body: 
2024-05-21 10:25:59,425 ERROR   wandb-upload_3:1290853 [internal_api.py:upload_file():2767] upload_file exception https://storage.googleapis.com/wandb-production.appspot.com/1923354735/MonoGS/y7r8ow8y/requirements.txt?Expires=1716344726&GoogleAccessId=gorilla-files-url-signer-man%40wandb-production.iam.gserviceaccount.com&Signature=L3wnj%2Fyq7ui%2BxLSSHbd3ZNhcWA4kK0ZtJyRG36fvMf2Y64WNPxFbuXgPhvC3rdidwqU2%2FOe%2FZTIIdUTKPbXzP9cEZ7sVF4Uwp3hSUNfDuTOFQaig%2F7JOiFRBJGv2X1R2iASbTo4JBQgGB9GC2veBdTUOc8aYkoZ5obUK%2FM%2BpCNVMPAzKdiJXEOZwIQ14bgSeH5mgaAwjpsla%2BJXsuIFxnyOcT%2FEZXY8VhWlqGJToRux8cvvjrvzrpp1jvjPgGnLacIrUtX0qi5kxdwvU79IAmi4m2uwJuuJryVhLfb1msk0BS4LjGHkfWl9hd4p6pZiXdVx7Q7s0g8yyBNyPv%2BnGhw%3D%3D: HTTPSConnectionPool(host='storage.googleapis.com', port=443): Max retries exceeded with url: /wandb-production.appspot.com/1923354735/MonoGS/y7r8ow8y/requirements.txt?Expires=1716344726&GoogleAccessId=gorilla-files-url-signer-man%40wandb-production.iam.gserviceaccount.com&Signature=L3wnj%2Fyq7ui%2BxLSSHbd3ZNhcWA4kK0ZtJyRG36fvMf2Y64WNPxFbuXgPhvC3rdidwqU2%2FOe%2FZTIIdUTKPbXzP9cEZ7sVF4Uwp3hSUNfDuTOFQaig%2F7JOiFRBJGv2X1R2iASbTo4JBQgGB9GC2veBdTUOc8aYkoZ5obUK%2FM%2BpCNVMPAzKdiJXEOZwIQ14bgSeH5mgaAwjpsla%2BJXsuIFxnyOcT%2FEZXY8VhWlqGJToRux8cvvjrvzrpp1jvjPgGnLacIrUtX0qi5kxdwvU79IAmi4m2uwJuuJryVhLfb1msk0BS4LjGHkfWl9hd4p6pZiXdVx7Q7s0g8yyBNyPv%2BnGhw%3D%3D (Caused by NewConnectionError('<urllib3.connection.HTTPSConnection object at 0x7f9aec5fe590>: Failed to establish a new connection: [Errno 111] Connection refused'))
2024-05-21 10:25:59,425 ERROR   wandb-upload_3:1290853 [internal_api.py:upload_file():2769] upload_file request headers: {'User-Agent': 'python-requests/2.31.0', 'Accept-Encoding': 'gzip, deflate, br', 'Accept': '*/*', 'Connection': 'keep-alive', 'Content-Length': '2267'}
2024-05-21 10:25:59,425 ERROR   wandb-upload_3:1290853 [internal_api.py:upload_file():2771] upload_file response body: 
2024-05-21 10:26:00,812 ERROR   wandb-upload_1:1290853 [internal_api.py:upload_file():2767] upload_file exception https://storage.googleapis.com/wandb-production.appspot.com/1923354735/MonoGS/y7r8ow8y/wandb-summary.json?Expires=1716344726&GoogleAccessId=gorilla-files-url-signer-man%40wandb-production.iam.gserviceaccount.com&Signature=n3TmQTke7rSKTOCmV4yBzpiHwvu8vQPE5LqY5EPfq8lc0JXiqgCFiFHzkxawDiSoIUcT3kdxgc2aPTLq1LD2WEkY6%2FuVV8En4N40fMx5DpkYekTPQfNs60A7VrzXiwdiTse%2FK8x%2FzrxcTRGKL5PlVDbPIkJTXr7S4GamUrQu66SpK3x%2F2MXkJ8k3cxcj6u9OgJgPH558FhRJENn1qVzm7AEwxNviV2ROMH174SOmY07BcoW8rCBvf8RWcNxUJrLulhAQk3VasB2MusrZH8Jf%2FHi2MAv4YWRHVoTGBX%2Bzrqj9sOhlhVHl8aINJwVSm9S0qzb2KI9%2FvZPZ3%2BqOahzSRg%3D%3D: HTTPSConnectionPool(host='storage.googleapis.com', port=443): Max retries exceeded with url: /wandb-production.appspot.com/1923354735/MonoGS/y7r8ow8y/wandb-summary.json?Expires=1716344726&GoogleAccessId=gorilla-files-url-signer-man%40wandb-production.iam.gserviceaccount.com&Signature=n3TmQTke7rSKTOCmV4yBzpiHwvu8vQPE5LqY5EPfq8lc0JXiqgCFiFHzkxawDiSoIUcT3kdxgc2aPTLq1LD2WEkY6%2FuVV8En4N40fMx5DpkYekTPQfNs60A7VrzXiwdiTse%2FK8x%2FzrxcTRGKL5PlVDbPIkJTXr7S4GamUrQu66SpK3x%2F2MXkJ8k3cxcj6u9OgJgPH558FhRJENn1qVzm7AEwxNviV2ROMH174SOmY07BcoW8rCBvf8RWcNxUJrLulhAQk3VasB2MusrZH8Jf%2FHi2MAv4YWRHVoTGBX%2Bzrqj9sOhlhVHl8aINJwVSm9S0qzb2KI9%2FvZPZ3%2BqOahzSRg%3D%3D (Caused by NewConnectionError('<urllib3.connection.HTTPSConnection object at 0x7f9aec5ee1d0>: Failed to establish a new connection: [Errno 111] Connection refused'))
2024-05-21 10:26:00,812 ERROR   wandb-upload_1:1290853 [internal_api.py:upload_file():2769] upload_file request headers: {'User-Agent': 'python-requests/2.31.0', 'Accept-Encoding': 'gzip, deflate, br', 'Accept': '*/*', 'Connection': 'keep-alive', 'Content-Length': '27'}
2024-05-21 10:26:00,812 ERROR   wandb-upload_1:1290853 [internal_api.py:upload_file():2771] upload_file response body: 
2024-05-21 10:26:00,851 ERROR   wandb-upload_2:1290853 [internal_api.py:upload_file():2767] upload_file exception https://storage.googleapis.com/wandb-production.appspot.com/1923354735/MonoGS/y7r8ow8y/output.log?Expires=1716344726&GoogleAccessId=gorilla-files-url-signer-man%40wandb-production.iam.gserviceaccount.com&Signature=O7idKX8qxjOgQnoSk8t%2FEvZHFPDgj7JSXqoV7CpZlwFMS%2FvROKjPi8M3JagUT5wZ1inNHngyIU5scHIDo19KW%2Fxw0W%2FmJC%2FJfj2MZhGjDbxxnxx5aB4d%2BOoV7mxhAN9thVFs2jqWTNgNstrhhKFS%2BToiiRDtek%2BRxKJFLzjqTrqrZCJQO9usjTSGzzTHQLH%2F6Q0isKnkjj8HtIMoQpooN8s0cee02waCJy764hYUXOfj%2BXOvrLctCmMTiC04rFdK8juLoR0kM4uwRRmGkqjy2zRldzt%2F96rYeKQpv5GPvR1gVqtLd8Ie5gDieYQFYEwUdJw5wyXZMgJwm9kcUqF53w%3D%3D: HTTPSConnectionPool(host='storage.googleapis.com', port=443): Max retries exceeded with url: /wandb-production.appspot.com/1923354735/MonoGS/y7r8ow8y/output.log?Expires=1716344726&GoogleAccessId=gorilla-files-url-signer-man%40wandb-production.iam.gserviceaccount.com&Signature=O7idKX8qxjOgQnoSk8t%2FEvZHFPDgj7JSXqoV7CpZlwFMS%2FvROKjPi8M3JagUT5wZ1inNHngyIU5scHIDo19KW%2Fxw0W%2FmJC%2FJfj2MZhGjDbxxnxx5aB4d%2BOoV7mxhAN9thVFs2jqWTNgNstrhhKFS%2BToiiRDtek%2BRxKJFLzjqTrqrZCJQO9usjTSGzzTHQLH%2F6Q0isKnkjj8HtIMoQpooN8s0cee02waCJy764hYUXOfj%2BXOvrLctCmMTiC04rFdK8juLoR0kM4uwRRmGkqjy2zRldzt%2F96rYeKQpv5GPvR1gVqtLd8Ie5gDieYQFYEwUdJw5wyXZMgJwm9kcUqF53w%3D%3D (Caused by NewConnectionError('<urllib3.connection.HTTPSConnection object at 0x7f9aec5e6990>: Failed to establish a new connection: [Errno 111] Connection refused'))
2024-05-21 10:26:00,851 ERROR   wandb-upload_2:1290853 [internal_api.py:upload_file():2769] upload_file request headers: {'User-Agent': 'python-requests/2.31.0', 'Accept-Encoding': 'gzip, deflate, br', 'Accept': '*/*', 'Connection': 'keep-alive', 'Content-Length': '1214'}
2024-05-21 10:26:00,851 ERROR   wandb-upload_2:1290853 [internal_api.py:upload_file():2771] upload_file response body: 
2024-05-21 10:26:01,996 ERROR   wandb-upload_4:1290853 [internal_api.py:upload_file():2767] upload_file exception https://storage.googleapis.com/wandb-production.appspot.com/1923354735/MonoGS/y7r8ow8y/conda-environment.yaml?Expires=1716344726&GoogleAccessId=gorilla-files-url-signer-man%40wandb-production.iam.gserviceaccount.com&Signature=BERXsAthvA4uNy8KsTYhi4DK4yIggzBZzxjksCpYdoksYlIRNvLT6PY86cQfX4%2F%2BjJSxwiltJwadlf7g%2FjxRbz0mfhoLBBROL50A3sp35%2FjQLnhmncVF3iVe7ThBmHwLjMPjt5XtQu2jC34B8fea3GjY7wKFq3uaKTrwmPgWtcEOZCQMLMY0ChxkR%2BHE%2FSRiWt7xGeRrrVQ%2BErKoDuQRznC3TvhkhS1U4lAVl6wRnLTI7GfzP%2FPZmxvohZpdRMn5apJEuRQkvST8ta2NN1yZWfvi903GAtgKWuYwg06ZHKj%2BCN24I%2B035VMqzFQRTyKx2EL50XK4hJucrjFTtzt8uQ%3D%3D: HTTPSConnectionPool(host='storage.googleapis.com', port=443): Max retries exceeded with url: /wandb-production.appspot.com/1923354735/MonoGS/y7r8ow8y/conda-environment.yaml?Expires=1716344726&GoogleAccessId=gorilla-files-url-signer-man%40wandb-production.iam.gserviceaccount.com&Signature=BERXsAthvA4uNy8KsTYhi4DK4yIggzBZzxjksCpYdoksYlIRNvLT6PY86cQfX4%2F%2BjJSxwiltJwadlf7g%2FjxRbz0mfhoLBBROL50A3sp35%2FjQLnhmncVF3iVe7ThBmHwLjMPjt5XtQu2jC34B8fea3GjY7wKFq3uaKTrwmPgWtcEOZCQMLMY0ChxkR%2BHE%2FSRiWt7xGeRrrVQ%2BErKoDuQRznC3TvhkhS1U4lAVl6wRnLTI7GfzP%2FPZmxvohZpdRMn5apJEuRQkvST8ta2NN1yZWfvi903GAtgKWuYwg06ZHKj%2BCN24I%2B035VMqzFQRTyKx2EL50XK4hJucrjFTtzt8uQ%3D%3D (Caused by NewConnectionError('<urllib3.connection.HTTPSConnection object at 0x7f9aec5e66d0>: Failed to establish a new connection: [Errno 111] Connection refused'))
2024-05-21 10:26:01,996 ERROR   wandb-upload_4:1290853 [internal_api.py:upload_file():2769] upload_file request headers: {'User-Agent': 'python-requests/2.31.0', 'Accept-Encoding': 'gzip, deflate, br', 'Accept': '*/*', 'Connection': 'keep-alive', 'Content-Length': '4690'}
2024-05-21 10:26:01,996 ERROR   wandb-upload_4:1290853 [internal_api.py:upload_file():2771] upload_file response body: 
2024-05-21 10:26:02,185 ERROR   wandb-upload_5:1290853 [internal_api.py:upload_file():2767] upload_file exception https://storage.googleapis.com/wandb-production.appspot.com/1923354735/MonoGS/y7r8ow8y/config.yaml?Expires=1716344726&GoogleAccessId=gorilla-files-url-signer-man%40wandb-production.iam.gserviceaccount.com&Signature=I%2FNqKudC9MlfdRYAyMWFQvABnAS6abRNmQnfNVifsclZ4ceBglJy%2FoSd3mNSPDS9NKXypr69UhttUBb6HT4dYnStLUhTaBeqvaVAIboqb0qJixJW1nYbshU6oZOHN%2F2QXnXcTDMAcIqYyvjbX8%2FgNgcm62O%2FZfSG0rwQMsg36I%2BybxXDywQsR6Hj%2BHEviQaJ2BiWLrrG13wLXJRzU9Fy6cW8OxwP3EO3FtI7%2FkTijIvBF0hMcNI8v07X9K4HytchvYdA5f6h8ydDmckf6lnmf8SJ4ou%2FY30cBWODkVpKSmeEE7IW58O0%2BZ7gTvYz5pY3sDXUPAhXajZ5flsUieNmzg%3D%3D: HTTPSConnectionPool(host='storage.googleapis.com', port=443): Max retries exceeded with url: /wandb-production.appspot.com/1923354735/MonoGS/y7r8ow8y/config.yaml?Expires=1716344726&GoogleAccessId=gorilla-files-url-signer-man%40wandb-production.iam.gserviceaccount.com&Signature=I%2FNqKudC9MlfdRYAyMWFQvABnAS6abRNmQnfNVifsclZ4ceBglJy%2FoSd3mNSPDS9NKXypr69UhttUBb6HT4dYnStLUhTaBeqvaVAIboqb0qJixJW1nYbshU6oZOHN%2F2QXnXcTDMAcIqYyvjbX8%2FgNgcm62O%2FZfSG0rwQMsg36I%2BybxXDywQsR6Hj%2BHEviQaJ2BiWLrrG13wLXJRzU9Fy6cW8OxwP3EO3FtI7%2FkTijIvBF0hMcNI8v07X9K4HytchvYdA5f6h8ydDmckf6lnmf8SJ4ou%2FY30cBWODkVpKSmeEE7IW58O0%2BZ7gTvYz5pY3sDXUPAhXajZ5flsUieNmzg%3D%3D (Caused by NewConnectionError('<urllib3.connection.HTTPSConnection object at 0x7f9aec6a5310>: Failed to establish a new connection: [Errno 111] Connection refused'))
2024-05-21 10:26:02,185 ERROR   wandb-upload_5:1290853 [internal_api.py:upload_file():2769] upload_file request headers: {'User-Agent': 'python-requests/2.31.0', 'Accept-Encoding': 'gzip, deflate, br', 'Accept': '*/*', 'Connection': 'keep-alive', 'Content-Length': '2747'}
2024-05-21 10:26:02,185 ERROR   wandb-upload_5:1290853 [internal_api.py:upload_file():2771] upload_file response body: 
2024-05-21 10:26:33,530 ERROR   wandb-upload_1:1290853 [internal_api.py:upload_file():2767] upload_file exception https://storage.googleapis.com/wandb-production.appspot.com/1923354735/MonoGS/y7r8ow8y/wandb-summary.json?Expires=1716344726&GoogleAccessId=gorilla-files-url-signer-man%40wandb-production.iam.gserviceaccount.com&Signature=n3TmQTke7rSKTOCmV4yBzpiHwvu8vQPE5LqY5EPfq8lc0JXiqgCFiFHzkxawDiSoIUcT3kdxgc2aPTLq1LD2WEkY6%2FuVV8En4N40fMx5DpkYekTPQfNs60A7VrzXiwdiTse%2FK8x%2FzrxcTRGKL5PlVDbPIkJTXr7S4GamUrQu66SpK3x%2F2MXkJ8k3cxcj6u9OgJgPH558FhRJENn1qVzm7AEwxNviV2ROMH174SOmY07BcoW8rCBvf8RWcNxUJrLulhAQk3VasB2MusrZH8Jf%2FHi2MAv4YWRHVoTGBX%2Bzrqj9sOhlhVHl8aINJwVSm9S0qzb2KI9%2FvZPZ3%2BqOahzSRg%3D%3D: HTTPSConnectionPool(host='storage.googleapis.com', port=443): Max retries exceeded with url: /wandb-production.appspot.com/1923354735/MonoGS/y7r8ow8y/wandb-summary.json?Expires=1716344726&GoogleAccessId=gorilla-files-url-signer-man%40wandb-production.iam.gserviceaccount.com&Signature=n3TmQTke7rSKTOCmV4yBzpiHwvu8vQPE5LqY5EPfq8lc0JXiqgCFiFHzkxawDiSoIUcT3kdxgc2aPTLq1LD2WEkY6%2FuVV8En4N40fMx5DpkYekTPQfNs60A7VrzXiwdiTse%2FK8x%2FzrxcTRGKL5PlVDbPIkJTXr7S4GamUrQu66SpK3x%2F2MXkJ8k3cxcj6u9OgJgPH558FhRJENn1qVzm7AEwxNviV2ROMH174SOmY07BcoW8rCBvf8RWcNxUJrLulhAQk3VasB2MusrZH8Jf%2FHi2MAv4YWRHVoTGBX%2Bzrqj9sOhlhVHl8aINJwVSm9S0qzb2KI9%2FvZPZ3%2BqOahzSRg%3D%3D (Caused by NewConnectionError('<urllib3.connection.HTTPSConnection object at 0x7f9aec5e6bd0>: Failed to establish a new connection: [Errno 111] Connection refused'))
2024-05-21 10:26:33,530 ERROR   wandb-upload_1:1290853 [internal_api.py:upload_file():2769] upload_file request headers: {'User-Agent': 'python-requests/2.31.0', 'Accept-Encoding': 'gzip, deflate, br', 'Accept': '*/*', 'Connection': 'keep-alive', 'Content-Length': '27'}
2024-05-21 10:26:33,530 ERROR   wandb-upload_1:1290853 [internal_api.py:upload_file():2771] upload_file response body: 
2024-05-21 10:26:36,724 ERROR   wandb-upload_2:1290853 [internal_api.py:upload_file():2767] upload_file exception https://storage.googleapis.com/wandb-production.appspot.com/1923354735/MonoGS/y7r8ow8y/output.log?Expires=1716344726&GoogleAccessId=gorilla-files-url-signer-man%40wandb-production.iam.gserviceaccount.com&Signature=O7idKX8qxjOgQnoSk8t%2FEvZHFPDgj7JSXqoV7CpZlwFMS%2FvROKjPi8M3JagUT5wZ1inNHngyIU5scHIDo19KW%2Fxw0W%2FmJC%2FJfj2MZhGjDbxxnxx5aB4d%2BOoV7mxhAN9thVFs2jqWTNgNstrhhKFS%2BToiiRDtek%2BRxKJFLzjqTrqrZCJQO9usjTSGzzTHQLH%2F6Q0isKnkjj8HtIMoQpooN8s0cee02waCJy764hYUXOfj%2BXOvrLctCmMTiC04rFdK8juLoR0kM4uwRRmGkqjy2zRldzt%2F96rYeKQpv5GPvR1gVqtLd8Ie5gDieYQFYEwUdJw5wyXZMgJwm9kcUqF53w%3D%3D: HTTPSConnectionPool(host='storage.googleapis.com', port=443): Max retries exceeded with url: /wandb-production.appspot.com/1923354735/MonoGS/y7r8ow8y/output.log?Expires=1716344726&GoogleAccessId=gorilla-files-url-signer-man%40wandb-production.iam.gserviceaccount.com&Signature=O7idKX8qxjOgQnoSk8t%2FEvZHFPDgj7JSXqoV7CpZlwFMS%2FvROKjPi8M3JagUT5wZ1inNHngyIU5scHIDo19KW%2Fxw0W%2FmJC%2FJfj2MZhGjDbxxnxx5aB4d%2BOoV7mxhAN9thVFs2jqWTNgNstrhhKFS%2BToiiRDtek%2BRxKJFLzjqTrqrZCJQO9usjTSGzzTHQLH%2F6Q0isKnkjj8HtIMoQpooN8s0cee02waCJy764hYUXOfj%2BXOvrLctCmMTiC04rFdK8juLoR0kM4uwRRmGkqjy2zRldzt%2F96rYeKQpv5GPvR1gVqtLd8Ie5gDieYQFYEwUdJw5wyXZMgJwm9kcUqF53w%3D%3D (Caused by NewConnectionError('<urllib3.connection.HTTPSConnection object at 0x7f9aec5e6a50>: Failed to establish a new connection: [Errno 111] Connection refused'))
2024-05-21 10:26:36,724 ERROR   wandb-upload_2:1290853 [internal_api.py:upload_file():2769] upload_file request headers: {'User-Agent': 'python-requests/2.31.0', 'Accept-Encoding': 'gzip, deflate, br', 'Accept': '*/*', 'Connection': 'keep-alive', 'Content-Length': '1214'}
2024-05-21 10:26:36,724 ERROR   wandb-upload_2:1290853 [internal_api.py:upload_file():2771] upload_file response body: 
2024-05-21 10:26:37,528 ERROR   wandb-upload_5:1290853 [internal_api.py:upload_file():2767] upload_file exception https://storage.googleapis.com/wandb-production.appspot.com/1923354735/MonoGS/y7r8ow8y/config.yaml?Expires=1716344726&GoogleAccessId=gorilla-files-url-signer-man%40wandb-production.iam.gserviceaccount.com&Signature=I%2FNqKudC9MlfdRYAyMWFQvABnAS6abRNmQnfNVifsclZ4ceBglJy%2FoSd3mNSPDS9NKXypr69UhttUBb6HT4dYnStLUhTaBeqvaVAIboqb0qJixJW1nYbshU6oZOHN%2F2QXnXcTDMAcIqYyvjbX8%2FgNgcm62O%2FZfSG0rwQMsg36I%2BybxXDywQsR6Hj%2BHEviQaJ2BiWLrrG13wLXJRzU9Fy6cW8OxwP3EO3FtI7%2FkTijIvBF0hMcNI8v07X9K4HytchvYdA5f6h8ydDmckf6lnmf8SJ4ou%2FY30cBWODkVpKSmeEE7IW58O0%2BZ7gTvYz5pY3sDXUPAhXajZ5flsUieNmzg%3D%3D: HTTPSConnectionPool(host='storage.googleapis.com', port=443): Max retries exceeded with url: /wandb-production.appspot.com/1923354735/MonoGS/y7r8ow8y/config.yaml?Expires=1716344726&GoogleAccessId=gorilla-files-url-signer-man%40wandb-production.iam.gserviceaccount.com&Signature=I%2FNqKudC9MlfdRYAyMWFQvABnAS6abRNmQnfNVifsclZ4ceBglJy%2FoSd3mNSPDS9NKXypr69UhttUBb6HT4dYnStLUhTaBeqvaVAIboqb0qJixJW1nYbshU6oZOHN%2F2QXnXcTDMAcIqYyvjbX8%2FgNgcm62O%2FZfSG0rwQMsg36I%2BybxXDywQsR6Hj%2BHEviQaJ2BiWLrrG13wLXJRzU9Fy6cW8OxwP3EO3FtI7%2FkTijIvBF0hMcNI8v07X9K4HytchvYdA5f6h8ydDmckf6lnmf8SJ4ou%2FY30cBWODkVpKSmeEE7IW58O0%2BZ7gTvYz5pY3sDXUPAhXajZ5flsUieNmzg%3D%3D (Caused by NewConnectionError('<urllib3.connection.HTTPSConnection object at 0x7f9aec5ee3d0>: Failed to establish a new connection: [Errno 111] Connection refused'))
2024-05-21 10:26:37,528 ERROR   wandb-upload_5:1290853 [internal_api.py:upload_file():2769] upload_file request headers: {'User-Agent': 'python-requests/2.31.0', 'Accept-Encoding': 'gzip, deflate, br', 'Accept': '*/*', 'Connection': 'keep-alive', 'Content-Length': '2747'}
2024-05-21 10:26:37,528 ERROR   wandb-upload_5:1290853 [internal_api.py:upload_file():2771] upload_file response body: 
2024-05-21 10:26:39,328 ERROR   wandb-upload_3:1290853 [internal_api.py:upload_file():2767] upload_file exception https://storage.googleapis.com/wandb-production.appspot.com/1923354735/MonoGS/y7r8ow8y/requirements.txt?Expires=1716344726&GoogleAccessId=gorilla-files-url-signer-man%40wandb-production.iam.gserviceaccount.com&Signature=L3wnj%2Fyq7ui%2BxLSSHbd3ZNhcWA4kK0ZtJyRG36fvMf2Y64WNPxFbuXgPhvC3rdidwqU2%2FOe%2FZTIIdUTKPbXzP9cEZ7sVF4Uwp3hSUNfDuTOFQaig%2F7JOiFRBJGv2X1R2iASbTo4JBQgGB9GC2veBdTUOc8aYkoZ5obUK%2FM%2BpCNVMPAzKdiJXEOZwIQ14bgSeH5mgaAwjpsla%2BJXsuIFxnyOcT%2FEZXY8VhWlqGJToRux8cvvjrvzrpp1jvjPgGnLacIrUtX0qi5kxdwvU79IAmi4m2uwJuuJryVhLfb1msk0BS4LjGHkfWl9hd4p6pZiXdVx7Q7s0g8yyBNyPv%2BnGhw%3D%3D: HTTPSConnectionPool(host='storage.googleapis.com', port=443): Max retries exceeded with url: /wandb-production.appspot.com/1923354735/MonoGS/y7r8ow8y/requirements.txt?Expires=1716344726&GoogleAccessId=gorilla-files-url-signer-man%40wandb-production.iam.gserviceaccount.com&Signature=L3wnj%2Fyq7ui%2BxLSSHbd3ZNhcWA4kK0ZtJyRG36fvMf2Y64WNPxFbuXgPhvC3rdidwqU2%2FOe%2FZTIIdUTKPbXzP9cEZ7sVF4Uwp3hSUNfDuTOFQaig%2F7JOiFRBJGv2X1R2iASbTo4JBQgGB9GC2veBdTUOc8aYkoZ5obUK%2FM%2BpCNVMPAzKdiJXEOZwIQ14bgSeH5mgaAwjpsla%2BJXsuIFxnyOcT%2FEZXY8VhWlqGJToRux8cvvjrvzrpp1jvjPgGnLacIrUtX0qi5kxdwvU79IAmi4m2uwJuuJryVhLfb1msk0BS4LjGHkfWl9hd4p6pZiXdVx7Q7s0g8yyBNyPv%2BnGhw%3D%3D (Caused by NewConnectionError('<urllib3.connection.HTTPSConnection object at 0x7f9aec62ed10>: Failed to establish a new connection: [Errno 111] Connection refused'))
2024-05-21 10:26:39,328 ERROR   wandb-upload_3:1290853 [internal_api.py:upload_file():2769] upload_file request headers: {'User-Agent': 'python-requests/2.31.0', 'Accept-Encoding': 'gzip, deflate, br', 'Accept': '*/*', 'Connection': 'keep-alive', 'Content-Length': '2267'}
2024-05-21 10:26:39,328 ERROR   wandb-upload_3:1290853 [internal_api.py:upload_file():2771] upload_file response body: 
2024-05-21 10:26:40,527 ERROR   wandb-upload_4:1290853 [internal_api.py:upload_file():2767] upload_file exception https://storage.googleapis.com/wandb-production.appspot.com/1923354735/MonoGS/y7r8ow8y/conda-environment.yaml?Expires=1716344726&GoogleAccessId=gorilla-files-url-signer-man%40wandb-production.iam.gserviceaccount.com&Signature=BERXsAthvA4uNy8KsTYhi4DK4yIggzBZzxjksCpYdoksYlIRNvLT6PY86cQfX4%2F%2BjJSxwiltJwadlf7g%2FjxRbz0mfhoLBBROL50A3sp35%2FjQLnhmncVF3iVe7ThBmHwLjMPjt5XtQu2jC34B8fea3GjY7wKFq3uaKTrwmPgWtcEOZCQMLMY0ChxkR%2BHE%2FSRiWt7xGeRrrVQ%2BErKoDuQRznC3TvhkhS1U4lAVl6wRnLTI7GfzP%2FPZmxvohZpdRMn5apJEuRQkvST8ta2NN1yZWfvi903GAtgKWuYwg06ZHKj%2BCN24I%2B035VMqzFQRTyKx2EL50XK4hJucrjFTtzt8uQ%3D%3D: HTTPSConnectionPool(host='storage.googleapis.com', port=443): Max retries exceeded with url: /wandb-production.appspot.com/1923354735/MonoGS/y7r8ow8y/conda-environment.yaml?Expires=1716344726&GoogleAccessId=gorilla-files-url-signer-man%40wandb-production.iam.gserviceaccount.com&Signature=BERXsAthvA4uNy8KsTYhi4DK4yIggzBZzxjksCpYdoksYlIRNvLT6PY86cQfX4%2F%2BjJSxwiltJwadlf7g%2FjxRbz0mfhoLBBROL50A3sp35%2FjQLnhmncVF3iVe7ThBmHwLjMPjt5XtQu2jC34B8fea3GjY7wKFq3uaKTrwmPgWtcEOZCQMLMY0ChxkR%2BHE%2FSRiWt7xGeRrrVQ%2BErKoDuQRznC3TvhkhS1U4lAVl6wRnLTI7GfzP%2FPZmxvohZpdRMn5apJEuRQkvST8ta2NN1yZWfvi903GAtgKWuYwg06ZHKj%2BCN24I%2B035VMqzFQRTyKx2EL50XK4hJucrjFTtzt8uQ%3D%3D (Caused by NewConnectionError('<urllib3.connection.HTTPSConnection object at 0x7f9aec6070d0>: Failed to establish a new connection: [Errno 111] Connection refused'))
2024-05-21 10:26:40,527 ERROR   wandb-upload_4:1290853 [internal_api.py:upload_file():2769] upload_file request headers: {'User-Agent': 'python-requests/2.31.0', 'Accept-Encoding': 'gzip, deflate, br', 'Accept': '*/*', 'Connection': 'keep-alive', 'Content-Length': '4690'}
2024-05-21 10:26:40,527 ERROR   wandb-upload_4:1290853 [internal_api.py:upload_file():2771] upload_file response body: 
2024-05-21 10:27:08,529 ERROR   wandb-upload_0:1290853 [internal_api.py:upload_file():2767] upload_file exception https://storage.googleapis.com/wandb-production.appspot.com/1923354735/MonoGS/y7r8ow8y/wandb-metadata.json?Expires=1716344689&GoogleAccessId=gorilla-files-url-signer-man%40wandb-production.iam.gserviceaccount.com&Signature=XocjRmoIFbGhOWBuXHuQ1YhKHLYkoSCeErITJdS8ptWPCsz3MOZyInwqvfgV1AZwEKws5oPw3%2FDwg85hQPHAmupIZkrP%2FbzB80ItKNP%2FF37E4x7FatfKjo6Hx%2Blh6yxHbiVm%2BvTSvuL%2BRLunzyQhKrpBG8Qfx2K0vR52s0eIcahq37a1liZqh3oYSnC07NnlHFejfubqJTF65nXAiLz0%2B7IRQ6cPHAueqi4g6ath5yiztED2FGfOW2i73RW7lux%2FC8MDffiA0UrP30CrlqM6OVwjcoEbSqfaJxx7%2B0fnOFYZ3afMjjX5iJaH0ndAPKs0qCHPV%2FLlYU%2FKzWzLxt2GNA%3D%3D: HTTPSConnectionPool(host='storage.googleapis.com', port=443): Max retries exceeded with url: /wandb-production.appspot.com/1923354735/MonoGS/y7r8ow8y/wandb-metadata.json?Expires=1716344689&GoogleAccessId=gorilla-files-url-signer-man%40wandb-production.iam.gserviceaccount.com&Signature=XocjRmoIFbGhOWBuXHuQ1YhKHLYkoSCeErITJdS8ptWPCsz3MOZyInwqvfgV1AZwEKws5oPw3%2FDwg85hQPHAmupIZkrP%2FbzB80ItKNP%2FF37E4x7FatfKjo6Hx%2Blh6yxHbiVm%2BvTSvuL%2BRLunzyQhKrpBG8Qfx2K0vR52s0eIcahq37a1liZqh3oYSnC07NnlHFejfubqJTF65nXAiLz0%2B7IRQ6cPHAueqi4g6ath5yiztED2FGfOW2i73RW7lux%2FC8MDffiA0UrP30CrlqM6OVwjcoEbSqfaJxx7%2B0fnOFYZ3afMjjX5iJaH0ndAPKs0qCHPV%2FLlYU%2FKzWzLxt2GNA%3D%3D (Caused by NewConnectionError('<urllib3.connection.HTTPSConnection object at 0x7f9aec601110>: Failed to establish a new connection: [Errno 111] Connection refused'))
2024-05-21 10:27:08,530 ERROR   wandb-upload_0:1290853 [internal_api.py:upload_file():2769] upload_file request headers: {'User-Agent': 'python-requests/2.31.0', 'Accept-Encoding': 'gzip, deflate, br', 'Accept': '*/*', 'Connection': 'keep-alive', 'Content-Length': '3405'}
2024-05-21 10:27:08,530 ERROR   wandb-upload_0:1290853 [internal_api.py:upload_file():2771] upload_file response body: 
2024-05-21 10:27:44,879 ERROR   wandb-upload_3:1290853 [internal_api.py:upload_file():2767] upload_file exception https://storage.googleapis.com/wandb-production.appspot.com/1923354735/MonoGS/y7r8ow8y/requirements.txt?Expires=1716344726&GoogleAccessId=gorilla-files-url-signer-man%40wandb-production.iam.gserviceaccount.com&Signature=L3wnj%2Fyq7ui%2BxLSSHbd3ZNhcWA4kK0ZtJyRG36fvMf2Y64WNPxFbuXgPhvC3rdidwqU2%2FOe%2FZTIIdUTKPbXzP9cEZ7sVF4Uwp3hSUNfDuTOFQaig%2F7JOiFRBJGv2X1R2iASbTo4JBQgGB9GC2veBdTUOc8aYkoZ5obUK%2FM%2BpCNVMPAzKdiJXEOZwIQ14bgSeH5mgaAwjpsla%2BJXsuIFxnyOcT%2FEZXY8VhWlqGJToRux8cvvjrvzrpp1jvjPgGnLacIrUtX0qi5kxdwvU79IAmi4m2uwJuuJryVhLfb1msk0BS4LjGHkfWl9hd4p6pZiXdVx7Q7s0g8yyBNyPv%2BnGhw%3D%3D: HTTPSConnectionPool(host='storage.googleapis.com', port=443): Max retries exceeded with url: /wandb-production.appspot.com/1923354735/MonoGS/y7r8ow8y/requirements.txt?Expires=1716344726&GoogleAccessId=gorilla-files-url-signer-man%40wandb-production.iam.gserviceaccount.com&Signature=L3wnj%2Fyq7ui%2BxLSSHbd3ZNhcWA4kK0ZtJyRG36fvMf2Y64WNPxFbuXgPhvC3rdidwqU2%2FOe%2FZTIIdUTKPbXzP9cEZ7sVF4Uwp3hSUNfDuTOFQaig%2F7JOiFRBJGv2X1R2iASbTo4JBQgGB9GC2veBdTUOc8aYkoZ5obUK%2FM%2BpCNVMPAzKdiJXEOZwIQ14bgSeH5mgaAwjpsla%2BJXsuIFxnyOcT%2FEZXY8VhWlqGJToRux8cvvjrvzrpp1jvjPgGnLacIrUtX0qi5kxdwvU79IAmi4m2uwJuuJryVhLfb1msk0BS4LjGHkfWl9hd4p6pZiXdVx7Q7s0g8yyBNyPv%2BnGhw%3D%3D (Caused by NewConnectionError('<urllib3.connection.HTTPSConnection object at 0x7f9aec601350>: Failed to establish a new connection: [Errno 111] Connection refused'))
2024-05-21 10:27:44,879 ERROR   wandb-upload_3:1290853 [internal_api.py:upload_file():2769] upload_file request headers: {'User-Agent': 'python-requests/2.31.0', 'Accept-Encoding': 'gzip, deflate, br', 'Accept': '*/*', 'Connection': 'keep-alive', 'Content-Length': '2267'}
2024-05-21 10:27:44,880 ERROR   wandb-upload_3:1290853 [internal_api.py:upload_file():2771] upload_file response body: 
2024-05-21 10:27:46,275 ERROR   wandb-upload_2:1290853 [internal_api.py:upload_file():2767] upload_file exception https://storage.googleapis.com/wandb-production.appspot.com/1923354735/MonoGS/y7r8ow8y/output.log?Expires=1716344726&GoogleAccessId=gorilla-files-url-signer-man%40wandb-production.iam.gserviceaccount.com&Signature=O7idKX8qxjOgQnoSk8t%2FEvZHFPDgj7JSXqoV7CpZlwFMS%2FvROKjPi8M3JagUT5wZ1inNHngyIU5scHIDo19KW%2Fxw0W%2FmJC%2FJfj2MZhGjDbxxnxx5aB4d%2BOoV7mxhAN9thVFs2jqWTNgNstrhhKFS%2BToiiRDtek%2BRxKJFLzjqTrqrZCJQO9usjTSGzzTHQLH%2F6Q0isKnkjj8HtIMoQpooN8s0cee02waCJy764hYUXOfj%2BXOvrLctCmMTiC04rFdK8juLoR0kM4uwRRmGkqjy2zRldzt%2F96rYeKQpv5GPvR1gVqtLd8Ie5gDieYQFYEwUdJw5wyXZMgJwm9kcUqF53w%3D%3D: HTTPSConnectionPool(host='storage.googleapis.com', port=443): Max retries exceeded with url: /wandb-production.appspot.com/1923354735/MonoGS/y7r8ow8y/output.log?Expires=1716344726&GoogleAccessId=gorilla-files-url-signer-man%40wandb-production.iam.gserviceaccount.com&Signature=O7idKX8qxjOgQnoSk8t%2FEvZHFPDgj7JSXqoV7CpZlwFMS%2FvROKjPi8M3JagUT5wZ1inNHngyIU5scHIDo19KW%2Fxw0W%2FmJC%2FJfj2MZhGjDbxxnxx5aB4d%2BOoV7mxhAN9thVFs2jqWTNgNstrhhKFS%2BToiiRDtek%2BRxKJFLzjqTrqrZCJQO9usjTSGzzTHQLH%2F6Q0isKnkjj8HtIMoQpooN8s0cee02waCJy764hYUXOfj%2BXOvrLctCmMTiC04rFdK8juLoR0kM4uwRRmGkqjy2zRldzt%2F96rYeKQpv5GPvR1gVqtLd8Ie5gDieYQFYEwUdJw5wyXZMgJwm9kcUqF53w%3D%3D (Caused by NewConnectionError('<urllib3.connection.HTTPSConnection object at 0x7f9aec5e9050>: Failed to establish a new connection: [Errno 111] Connection refused'))
2024-05-21 10:27:46,275 ERROR   wandb-upload_2:1290853 [internal_api.py:upload_file():2769] upload_file request headers: {'User-Agent': 'python-requests/2.31.0', 'Accept-Encoding': 'gzip, deflate, br', 'Accept': '*/*', 'Connection': 'keep-alive', 'Content-Length': '1214'}
2024-05-21 10:27:46,275 ERROR   wandb-upload_2:1290853 [internal_api.py:upload_file():2771] upload_file response body: 
2024-05-21 10:27:48,963 ERROR   wandb-upload_5:1290853 [internal_api.py:upload_file():2767] upload_file exception https://storage.googleapis.com/wandb-production.appspot.com/1923354735/MonoGS/y7r8ow8y/config.yaml?Expires=1716344726&GoogleAccessId=gorilla-files-url-signer-man%40wandb-production.iam.gserviceaccount.com&Signature=I%2FNqKudC9MlfdRYAyMWFQvABnAS6abRNmQnfNVifsclZ4ceBglJy%2FoSd3mNSPDS9NKXypr69UhttUBb6HT4dYnStLUhTaBeqvaVAIboqb0qJixJW1nYbshU6oZOHN%2F2QXnXcTDMAcIqYyvjbX8%2FgNgcm62O%2FZfSG0rwQMsg36I%2BybxXDywQsR6Hj%2BHEviQaJ2BiWLrrG13wLXJRzU9Fy6cW8OxwP3EO3FtI7%2FkTijIvBF0hMcNI8v07X9K4HytchvYdA5f6h8ydDmckf6lnmf8SJ4ou%2FY30cBWODkVpKSmeEE7IW58O0%2BZ7gTvYz5pY3sDXUPAhXajZ5flsUieNmzg%3D%3D: HTTPSConnectionPool(host='storage.googleapis.com', port=443): Max retries exceeded with url: /wandb-production.appspot.com/1923354735/MonoGS/y7r8ow8y/config.yaml?Expires=1716344726&GoogleAccessId=gorilla-files-url-signer-man%40wandb-production.iam.gserviceaccount.com&Signature=I%2FNqKudC9MlfdRYAyMWFQvABnAS6abRNmQnfNVifsclZ4ceBglJy%2FoSd3mNSPDS9NKXypr69UhttUBb6HT4dYnStLUhTaBeqvaVAIboqb0qJixJW1nYbshU6oZOHN%2F2QXnXcTDMAcIqYyvjbX8%2FgNgcm62O%2FZfSG0rwQMsg36I%2BybxXDywQsR6Hj%2BHEviQaJ2BiWLrrG13wLXJRzU9Fy6cW8OxwP3EO3FtI7%2FkTijIvBF0hMcNI8v07X9K4HytchvYdA5f6h8ydDmckf6lnmf8SJ4ou%2FY30cBWODkVpKSmeEE7IW58O0%2BZ7gTvYz5pY3sDXUPAhXajZ5flsUieNmzg%3D%3D (Caused by NewConnectionError('<urllib3.connection.HTTPSConnection object at 0x7f9aec5fe310>: Failed to establish a new connection: [Errno 111] Connection refused'))
2024-05-21 10:27:48,963 ERROR   wandb-upload_5:1290853 [internal_api.py:upload_file():2769] upload_file request headers: {'User-Agent': 'python-requests/2.31.0', 'Accept-Encoding': 'gzip, deflate, br', 'Accept': '*/*', 'Connection': 'keep-alive', 'Content-Length': '2747'}
2024-05-21 10:27:48,963 ERROR   wandb-upload_5:1290853 [internal_api.py:upload_file():2771] upload_file response body: 
2024-05-21 10:27:49,659 ERROR   wandb-upload_1:1290853 [internal_api.py:upload_file():2767] upload_file exception https://storage.googleapis.com/wandb-production.appspot.com/1923354735/MonoGS/y7r8ow8y/wandb-summary.json?Expires=1716344726&GoogleAccessId=gorilla-files-url-signer-man%40wandb-production.iam.gserviceaccount.com&Signature=n3TmQTke7rSKTOCmV4yBzpiHwvu8vQPE5LqY5EPfq8lc0JXiqgCFiFHzkxawDiSoIUcT3kdxgc2aPTLq1LD2WEkY6%2FuVV8En4N40fMx5DpkYekTPQfNs60A7VrzXiwdiTse%2FK8x%2FzrxcTRGKL5PlVDbPIkJTXr7S4GamUrQu66SpK3x%2F2MXkJ8k3cxcj6u9OgJgPH558FhRJENn1qVzm7AEwxNviV2ROMH174SOmY07BcoW8rCBvf8RWcNxUJrLulhAQk3VasB2MusrZH8Jf%2FHi2MAv4YWRHVoTGBX%2Bzrqj9sOhlhVHl8aINJwVSm9S0qzb2KI9%2FvZPZ3%2BqOahzSRg%3D%3D: HTTPSConnectionPool(host='storage.googleapis.com', port=443): Max retries exceeded with url: /wandb-production.appspot.com/1923354735/MonoGS/y7r8ow8y/wandb-summary.json?Expires=1716344726&GoogleAccessId=gorilla-files-url-signer-man%40wandb-production.iam.gserviceaccount.com&Signature=n3TmQTke7rSKTOCmV4yBzpiHwvu8vQPE5LqY5EPfq8lc0JXiqgCFiFHzkxawDiSoIUcT3kdxgc2aPTLq1LD2WEkY6%2FuVV8En4N40fMx5DpkYekTPQfNs60A7VrzXiwdiTse%2FK8x%2FzrxcTRGKL5PlVDbPIkJTXr7S4GamUrQu66SpK3x%2F2MXkJ8k3cxcj6u9OgJgPH558FhRJENn1qVzm7AEwxNviV2ROMH174SOmY07BcoW8rCBvf8RWcNxUJrLulhAQk3VasB2MusrZH8Jf%2FHi2MAv4YWRHVoTGBX%2Bzrqj9sOhlhVHl8aINJwVSm9S0qzb2KI9%2FvZPZ3%2BqOahzSRg%3D%3D (Caused by NewConnectionError('<urllib3.connection.HTTPSConnection object at 0x7f9aec5fe290>: Failed to establish a new connection: [Errno 111] Connection refused'))
2024-05-21 10:27:49,659 ERROR   wandb-upload_1:1290853 [internal_api.py:upload_file():2769] upload_file request headers: {'User-Agent': 'python-requests/2.31.0', 'Accept-Encoding': 'gzip, deflate, br', 'Accept': '*/*', 'Connection': 'keep-alive', 'Content-Length': '27'}
2024-05-21 10:27:49,659 ERROR   wandb-upload_1:1290853 [internal_api.py:upload_file():2771] upload_file response body: 
2024-05-21 10:27:52,269 ERROR   wandb-upload_4:1290853 [internal_api.py:upload_file():2767] upload_file exception https://storage.googleapis.com/wandb-production.appspot.com/1923354735/MonoGS/y7r8ow8y/conda-environment.yaml?Expires=1716344726&GoogleAccessId=gorilla-files-url-signer-man%40wandb-production.iam.gserviceaccount.com&Signature=BERXsAthvA4uNy8KsTYhi4DK4yIggzBZzxjksCpYdoksYlIRNvLT6PY86cQfX4%2F%2BjJSxwiltJwadlf7g%2FjxRbz0mfhoLBBROL50A3sp35%2FjQLnhmncVF3iVe7ThBmHwLjMPjt5XtQu2jC34B8fea3GjY7wKFq3uaKTrwmPgWtcEOZCQMLMY0ChxkR%2BHE%2FSRiWt7xGeRrrVQ%2BErKoDuQRznC3TvhkhS1U4lAVl6wRnLTI7GfzP%2FPZmxvohZpdRMn5apJEuRQkvST8ta2NN1yZWfvi903GAtgKWuYwg06ZHKj%2BCN24I%2B035VMqzFQRTyKx2EL50XK4hJucrjFTtzt8uQ%3D%3D: HTTPSConnectionPool(host='storage.googleapis.com', port=443): Max retries exceeded with url: /wandb-production.appspot.com/1923354735/MonoGS/y7r8ow8y/conda-environment.yaml?Expires=1716344726&GoogleAccessId=gorilla-files-url-signer-man%40wandb-production.iam.gserviceaccount.com&Signature=BERXsAthvA4uNy8KsTYhi4DK4yIggzBZzxjksCpYdoksYlIRNvLT6PY86cQfX4%2F%2BjJSxwiltJwadlf7g%2FjxRbz0mfhoLBBROL50A3sp35%2FjQLnhmncVF3iVe7ThBmHwLjMPjt5XtQu2jC34B8fea3GjY7wKFq3uaKTrwmPgWtcEOZCQMLMY0ChxkR%2BHE%2FSRiWt7xGeRrrVQ%2BErKoDuQRznC3TvhkhS1U4lAVl6wRnLTI7GfzP%2FPZmxvohZpdRMn5apJEuRQkvST8ta2NN1yZWfvi903GAtgKWuYwg06ZHKj%2BCN24I%2B035VMqzFQRTyKx2EL50XK4hJucrjFTtzt8uQ%3D%3D (Caused by NewConnectionError('<urllib3.connection.HTTPSConnection object at 0x7f9aec5da2d0>: Failed to establish a new connection: [Errno 111] Connection refused'))
2024-05-21 10:27:52,269 ERROR   wandb-upload_4:1290853 [internal_api.py:upload_file():2769] upload_file request headers: {'User-Agent': 'python-requests/2.31.0', 'Accept-Encoding': 'gzip, deflate, br', 'Accept': '*/*', 'Connection': 'keep-alive', 'Content-Length': '4690'}
2024-05-21 10:27:52,269 ERROR   wandb-upload_4:1290853 [internal_api.py:upload_file():2771] upload_file response body: 
2024-05-21 10:29:21,107 ERROR   wandb-upload_0:1290853 [internal_api.py:upload_file():2767] upload_file exception https://storage.googleapis.com/wandb-production.appspot.com/1923354735/MonoGS/y7r8ow8y/wandb-metadata.json?Expires=1716344689&GoogleAccessId=gorilla-files-url-signer-man%40wandb-production.iam.gserviceaccount.com&Signature=XocjRmoIFbGhOWBuXHuQ1YhKHLYkoSCeErITJdS8ptWPCsz3MOZyInwqvfgV1AZwEKws5oPw3%2FDwg85hQPHAmupIZkrP%2FbzB80ItKNP%2FF37E4x7FatfKjo6Hx%2Blh6yxHbiVm%2BvTSvuL%2BRLunzyQhKrpBG8Qfx2K0vR52s0eIcahq37a1liZqh3oYSnC07NnlHFejfubqJTF65nXAiLz0%2B7IRQ6cPHAueqi4g6ath5yiztED2FGfOW2i73RW7lux%2FC8MDffiA0UrP30CrlqM6OVwjcoEbSqfaJxx7%2B0fnOFYZ3afMjjX5iJaH0ndAPKs0qCHPV%2FLlYU%2FKzWzLxt2GNA%3D%3D: HTTPSConnectionPool(host='storage.googleapis.com', port=443): Max retries exceeded with url: /wandb-production.appspot.com/1923354735/MonoGS/y7r8ow8y/wandb-metadata.json?Expires=1716344689&GoogleAccessId=gorilla-files-url-signer-man%40wandb-production.iam.gserviceaccount.com&Signature=XocjRmoIFbGhOWBuXHuQ1YhKHLYkoSCeErITJdS8ptWPCsz3MOZyInwqvfgV1AZwEKws5oPw3%2FDwg85hQPHAmupIZkrP%2FbzB80ItKNP%2FF37E4x7FatfKjo6Hx%2Blh6yxHbiVm%2BvTSvuL%2BRLunzyQhKrpBG8Qfx2K0vR52s0eIcahq37a1liZqh3oYSnC07NnlHFejfubqJTF65nXAiLz0%2B7IRQ6cPHAueqi4g6ath5yiztED2FGfOW2i73RW7lux%2FC8MDffiA0UrP30CrlqM6OVwjcoEbSqfaJxx7%2B0fnOFYZ3afMjjX5iJaH0ndAPKs0qCHPV%2FLlYU%2FKzWzLxt2GNA%3D%3D (Caused by NewConnectionError('<urllib3.connection.HTTPSConnection object at 0x7f9aec601f10>: Failed to establish a new connection: [Errno 111] Connection refused'))
2024-05-21 10:29:21,107 ERROR   wandb-upload_0:1290853 [internal_api.py:upload_file():2769] upload_file request headers: {'User-Agent': 'python-requests/2.31.0', 'Accept-Encoding': 'gzip, deflate, br', 'Accept': '*/*', 'Connection': 'keep-alive', 'Content-Length': '3405'}
2024-05-21 10:29:21,108 ERROR   wandb-upload_0:1290853 [internal_api.py:upload_file():2771] upload_file response body: 
2024-05-21 10:30:04,792 ERROR   wandb-upload_1:1290853 [internal_api.py:upload_file():2767] upload_file exception https://storage.googleapis.com/wandb-production.appspot.com/1923354735/MonoGS/y7r8ow8y/wandb-summary.json?Expires=1716344726&GoogleAccessId=gorilla-files-url-signer-man%40wandb-production.iam.gserviceaccount.com&Signature=n3TmQTke7rSKTOCmV4yBzpiHwvu8vQPE5LqY5EPfq8lc0JXiqgCFiFHzkxawDiSoIUcT3kdxgc2aPTLq1LD2WEkY6%2FuVV8En4N40fMx5DpkYekTPQfNs60A7VrzXiwdiTse%2FK8x%2FzrxcTRGKL5PlVDbPIkJTXr7S4GamUrQu66SpK3x%2F2MXkJ8k3cxcj6u9OgJgPH558FhRJENn1qVzm7AEwxNviV2ROMH174SOmY07BcoW8rCBvf8RWcNxUJrLulhAQk3VasB2MusrZH8Jf%2FHi2MAv4YWRHVoTGBX%2Bzrqj9sOhlhVHl8aINJwVSm9S0qzb2KI9%2FvZPZ3%2BqOahzSRg%3D%3D: HTTPSConnectionPool(host='storage.googleapis.com', port=443): Max retries exceeded with url: /wandb-production.appspot.com/1923354735/MonoGS/y7r8ow8y/wandb-summary.json?Expires=1716344726&GoogleAccessId=gorilla-files-url-signer-man%40wandb-production.iam.gserviceaccount.com&Signature=n3TmQTke7rSKTOCmV4yBzpiHwvu8vQPE5LqY5EPfq8lc0JXiqgCFiFHzkxawDiSoIUcT3kdxgc2aPTLq1LD2WEkY6%2FuVV8En4N40fMx5DpkYekTPQfNs60A7VrzXiwdiTse%2FK8x%2FzrxcTRGKL5PlVDbPIkJTXr7S4GamUrQu66SpK3x%2F2MXkJ8k3cxcj6u9OgJgPH558FhRJENn1qVzm7AEwxNviV2ROMH174SOmY07BcoW8rCBvf8RWcNxUJrLulhAQk3VasB2MusrZH8Jf%2FHi2MAv4YWRHVoTGBX%2Bzrqj9sOhlhVHl8aINJwVSm9S0qzb2KI9%2FvZPZ3%2BqOahzSRg%3D%3D (Caused by NewConnectionError('<urllib3.connection.HTTPSConnection object at 0x7f9aec601950>: Failed to establish a new connection: [Errno 111] Connection refused'))
2024-05-21 10:30:04,792 ERROR   wandb-upload_1:1290853 [internal_api.py:upload_file():2769] upload_file request headers: {'User-Agent': 'python-requests/2.31.0', 'Accept-Encoding': 'gzip, deflate, br', 'Accept': '*/*', 'Connection': 'keep-alive', 'Content-Length': '27'}
2024-05-21 10:30:04,792 ERROR   wandb-upload_1:1290853 [internal_api.py:upload_file():2771] upload_file response body: 
2024-05-21 10:30:11,560 ERROR   wandb-upload_4:1290853 [internal_api.py:upload_file():2767] upload_file exception https://storage.googleapis.com/wandb-production.appspot.com/1923354735/MonoGS/y7r8ow8y/conda-environment.yaml?Expires=1716344726&GoogleAccessId=gorilla-files-url-signer-man%40wandb-production.iam.gserviceaccount.com&Signature=BERXsAthvA4uNy8KsTYhi4DK4yIggzBZzxjksCpYdoksYlIRNvLT6PY86cQfX4%2F%2BjJSxwiltJwadlf7g%2FjxRbz0mfhoLBBROL50A3sp35%2FjQLnhmncVF3iVe7ThBmHwLjMPjt5XtQu2jC34B8fea3GjY7wKFq3uaKTrwmPgWtcEOZCQMLMY0ChxkR%2BHE%2FSRiWt7xGeRrrVQ%2BErKoDuQRznC3TvhkhS1U4lAVl6wRnLTI7GfzP%2FPZmxvohZpdRMn5apJEuRQkvST8ta2NN1yZWfvi903GAtgKWuYwg06ZHKj%2BCN24I%2B035VMqzFQRTyKx2EL50XK4hJucrjFTtzt8uQ%3D%3D: HTTPSConnectionPool(host='storage.googleapis.com', port=443): Max retries exceeded with url: /wandb-production.appspot.com/1923354735/MonoGS/y7r8ow8y/conda-environment.yaml?Expires=1716344726&GoogleAccessId=gorilla-files-url-signer-man%40wandb-production.iam.gserviceaccount.com&Signature=BERXsAthvA4uNy8KsTYhi4DK4yIggzBZzxjksCpYdoksYlIRNvLT6PY86cQfX4%2F%2BjJSxwiltJwadlf7g%2FjxRbz0mfhoLBBROL50A3sp35%2FjQLnhmncVF3iVe7ThBmHwLjMPjt5XtQu2jC34B8fea3GjY7wKFq3uaKTrwmPgWtcEOZCQMLMY0ChxkR%2BHE%2FSRiWt7xGeRrrVQ%2BErKoDuQRznC3TvhkhS1U4lAVl6wRnLTI7GfzP%2FPZmxvohZpdRMn5apJEuRQkvST8ta2NN1yZWfvi903GAtgKWuYwg06ZHKj%2BCN24I%2B035VMqzFQRTyKx2EL50XK4hJucrjFTtzt8uQ%3D%3D (Caused by NewConnectionError('<urllib3.connection.HTTPSConnection object at 0x7f9aec692ed0>: Failed to establish a new connection: [Errno 111] Connection refused'))
2024-05-21 10:30:11,560 ERROR   wandb-upload_4:1290853 [internal_api.py:upload_file():2769] upload_file request headers: {'User-Agent': 'python-requests/2.31.0', 'Accept-Encoding': 'gzip, deflate, br', 'Accept': '*/*', 'Connection': 'keep-alive', 'Content-Length': '4690'}
2024-05-21 10:30:11,560 ERROR   wandb-upload_4:1290853 [internal_api.py:upload_file():2771] upload_file response body: 
2024-05-21 10:30:13,708 ERROR   wandb-upload_5:1290853 [internal_api.py:upload_file():2767] upload_file exception https://storage.googleapis.com/wandb-production.appspot.com/1923354735/MonoGS/y7r8ow8y/config.yaml?Expires=1716344726&GoogleAccessId=gorilla-files-url-signer-man%40wandb-production.iam.gserviceaccount.com&Signature=I%2FNqKudC9MlfdRYAyMWFQvABnAS6abRNmQnfNVifsclZ4ceBglJy%2FoSd3mNSPDS9NKXypr69UhttUBb6HT4dYnStLUhTaBeqvaVAIboqb0qJixJW1nYbshU6oZOHN%2F2QXnXcTDMAcIqYyvjbX8%2FgNgcm62O%2FZfSG0rwQMsg36I%2BybxXDywQsR6Hj%2BHEviQaJ2BiWLrrG13wLXJRzU9Fy6cW8OxwP3EO3FtI7%2FkTijIvBF0hMcNI8v07X9K4HytchvYdA5f6h8ydDmckf6lnmf8SJ4ou%2FY30cBWODkVpKSmeEE7IW58O0%2BZ7gTvYz5pY3sDXUPAhXajZ5flsUieNmzg%3D%3D: HTTPSConnectionPool(host='storage.googleapis.com', port=443): Max retries exceeded with url: /wandb-production.appspot.com/1923354735/MonoGS/y7r8ow8y/config.yaml?Expires=1716344726&GoogleAccessId=gorilla-files-url-signer-man%40wandb-production.iam.gserviceaccount.com&Signature=I%2FNqKudC9MlfdRYAyMWFQvABnAS6abRNmQnfNVifsclZ4ceBglJy%2FoSd3mNSPDS9NKXypr69UhttUBb6HT4dYnStLUhTaBeqvaVAIboqb0qJixJW1nYbshU6oZOHN%2F2QXnXcTDMAcIqYyvjbX8%2FgNgcm62O%2FZfSG0rwQMsg36I%2BybxXDywQsR6Hj%2BHEviQaJ2BiWLrrG13wLXJRzU9Fy6cW8OxwP3EO3FtI7%2FkTijIvBF0hMcNI8v07X9K4HytchvYdA5f6h8ydDmckf6lnmf8SJ4ou%2FY30cBWODkVpKSmeEE7IW58O0%2BZ7gTvYz5pY3sDXUPAhXajZ5flsUieNmzg%3D%3D (Caused by NewConnectionError('<urllib3.connection.HTTPSConnection object at 0x7f9aec5ee210>: Failed to establish a new connection: [Errno 111] Connection refused'))
2024-05-21 10:30:13,708 ERROR   wandb-upload_5:1290853 [internal_api.py:upload_file():2769] upload_file request headers: {'User-Agent': 'python-requests/2.31.0', 'Accept-Encoding': 'gzip, deflate, br', 'Accept': '*/*', 'Connection': 'keep-alive', 'Content-Length': '2747'}
2024-05-21 10:30:13,708 ERROR   wandb-upload_5:1290853 [internal_api.py:upload_file():2771] upload_file response body: 
2024-05-21 10:30:15,649 ERROR   wandb-upload_2:1290853 [internal_api.py:upload_file():2767] upload_file exception https://storage.googleapis.com/wandb-production.appspot.com/1923354735/MonoGS/y7r8ow8y/output.log?Expires=1716344726&GoogleAccessId=gorilla-files-url-signer-man%40wandb-production.iam.gserviceaccount.com&Signature=O7idKX8qxjOgQnoSk8t%2FEvZHFPDgj7JSXqoV7CpZlwFMS%2FvROKjPi8M3JagUT5wZ1inNHngyIU5scHIDo19KW%2Fxw0W%2FmJC%2FJfj2MZhGjDbxxnxx5aB4d%2BOoV7mxhAN9thVFs2jqWTNgNstrhhKFS%2BToiiRDtek%2BRxKJFLzjqTrqrZCJQO9usjTSGzzTHQLH%2F6Q0isKnkjj8HtIMoQpooN8s0cee02waCJy764hYUXOfj%2BXOvrLctCmMTiC04rFdK8juLoR0kM4uwRRmGkqjy2zRldzt%2F96rYeKQpv5GPvR1gVqtLd8Ie5gDieYQFYEwUdJw5wyXZMgJwm9kcUqF53w%3D%3D: HTTPSConnectionPool(host='storage.googleapis.com', port=443): Max retries exceeded with url: /wandb-production.appspot.com/1923354735/MonoGS/y7r8ow8y/output.log?Expires=1716344726&GoogleAccessId=gorilla-files-url-signer-man%40wandb-production.iam.gserviceaccount.com&Signature=O7idKX8qxjOgQnoSk8t%2FEvZHFPDgj7JSXqoV7CpZlwFMS%2FvROKjPi8M3JagUT5wZ1inNHngyIU5scHIDo19KW%2Fxw0W%2FmJC%2FJfj2MZhGjDbxxnxx5aB4d%2BOoV7mxhAN9thVFs2jqWTNgNstrhhKFS%2BToiiRDtek%2BRxKJFLzjqTrqrZCJQO9usjTSGzzTHQLH%2F6Q0isKnkjj8HtIMoQpooN8s0cee02waCJy764hYUXOfj%2BXOvrLctCmMTiC04rFdK8juLoR0kM4uwRRmGkqjy2zRldzt%2F96rYeKQpv5GPvR1gVqtLd8Ie5gDieYQFYEwUdJw5wyXZMgJwm9kcUqF53w%3D%3D (Caused by NewConnectionError('<urllib3.connection.HTTPSConnection object at 0x7f9aec5e6fd0>: Failed to establish a new connection: [Errno 111] Connection refused'))
2024-05-21 10:30:15,649 ERROR   wandb-upload_2:1290853 [internal_api.py:upload_file():2769] upload_file request headers: {'User-Agent': 'python-requests/2.31.0', 'Accept-Encoding': 'gzip, deflate, br', 'Accept': '*/*', 'Connection': 'keep-alive', 'Content-Length': '1214'}
2024-05-21 10:30:15,649 ERROR   wandb-upload_2:1290853 [internal_api.py:upload_file():2771] upload_file response body: 
2024-05-21 10:30:18,037 ERROR   wandb-upload_3:1290853 [internal_api.py:upload_file():2767] upload_file exception https://storage.googleapis.com/wandb-production.appspot.com/1923354735/MonoGS/y7r8ow8y/requirements.txt?Expires=1716344726&GoogleAccessId=gorilla-files-url-signer-man%40wandb-production.iam.gserviceaccount.com&Signature=L3wnj%2Fyq7ui%2BxLSSHbd3ZNhcWA4kK0ZtJyRG36fvMf2Y64WNPxFbuXgPhvC3rdidwqU2%2FOe%2FZTIIdUTKPbXzP9cEZ7sVF4Uwp3hSUNfDuTOFQaig%2F7JOiFRBJGv2X1R2iASbTo4JBQgGB9GC2veBdTUOc8aYkoZ5obUK%2FM%2BpCNVMPAzKdiJXEOZwIQ14bgSeH5mgaAwjpsla%2BJXsuIFxnyOcT%2FEZXY8VhWlqGJToRux8cvvjrvzrpp1jvjPgGnLacIrUtX0qi5kxdwvU79IAmi4m2uwJuuJryVhLfb1msk0BS4LjGHkfWl9hd4p6pZiXdVx7Q7s0g8yyBNyPv%2BnGhw%3D%3D: HTTPSConnectionPool(host='storage.googleapis.com', port=443): Max retries exceeded with url: /wandb-production.appspot.com/1923354735/MonoGS/y7r8ow8y/requirements.txt?Expires=1716344726&GoogleAccessId=gorilla-files-url-signer-man%40wandb-production.iam.gserviceaccount.com&Signature=L3wnj%2Fyq7ui%2BxLSSHbd3ZNhcWA4kK0ZtJyRG36fvMf2Y64WNPxFbuXgPhvC3rdidwqU2%2FOe%2FZTIIdUTKPbXzP9cEZ7sVF4Uwp3hSUNfDuTOFQaig%2F7JOiFRBJGv2X1R2iASbTo4JBQgGB9GC2veBdTUOc8aYkoZ5obUK%2FM%2BpCNVMPAzKdiJXEOZwIQ14bgSeH5mgaAwjpsla%2BJXsuIFxnyOcT%2FEZXY8VhWlqGJToRux8cvvjrvzrpp1jvjPgGnLacIrUtX0qi5kxdwvU79IAmi4m2uwJuuJryVhLfb1msk0BS4LjGHkfWl9hd4p6pZiXdVx7Q7s0g8yyBNyPv%2BnGhw%3D%3D (Caused by NewConnectionError('<urllib3.connection.HTTPSConnection object at 0x7f9aec6a5350>: Failed to establish a new connection: [Errno 111] Connection refused'))
2024-05-21 10:30:18,037 ERROR   wandb-upload_3:1290853 [internal_api.py:upload_file():2769] upload_file request headers: {'User-Agent': 'python-requests/2.31.0', 'Accept-Encoding': 'gzip, deflate, br', 'Accept': '*/*', 'Connection': 'keep-alive', 'Content-Length': '2267'}
2024-05-21 10:30:18,037 ERROR   wandb-upload_3:1290853 [internal_api.py:upload_file():2771] upload_file response body: 
2024-05-21 10:33:47,543 ERROR   wandb-upload_0:1290853 [internal_api.py:upload_file():2767] upload_file exception https://storage.googleapis.com/wandb-production.appspot.com/1923354735/MonoGS/y7r8ow8y/wandb-metadata.json?Expires=1716344689&GoogleAccessId=gorilla-files-url-signer-man%40wandb-production.iam.gserviceaccount.com&Signature=XocjRmoIFbGhOWBuXHuQ1YhKHLYkoSCeErITJdS8ptWPCsz3MOZyInwqvfgV1AZwEKws5oPw3%2FDwg85hQPHAmupIZkrP%2FbzB80ItKNP%2FF37E4x7FatfKjo6Hx%2Blh6yxHbiVm%2BvTSvuL%2BRLunzyQhKrpBG8Qfx2K0vR52s0eIcahq37a1liZqh3oYSnC07NnlHFejfubqJTF65nXAiLz0%2B7IRQ6cPHAueqi4g6ath5yiztED2FGfOW2i73RW7lux%2FC8MDffiA0UrP30CrlqM6OVwjcoEbSqfaJxx7%2B0fnOFYZ3afMjjX5iJaH0ndAPKs0qCHPV%2FLlYU%2FKzWzLxt2GNA%3D%3D: HTTPSConnectionPool(host='storage.googleapis.com', port=443): Max retries exceeded with url: /wandb-production.appspot.com/1923354735/MonoGS/y7r8ow8y/wandb-metadata.json?Expires=1716344689&GoogleAccessId=gorilla-files-url-signer-man%40wandb-production.iam.gserviceaccount.com&Signature=XocjRmoIFbGhOWBuXHuQ1YhKHLYkoSCeErITJdS8ptWPCsz3MOZyInwqvfgV1AZwEKws5oPw3%2FDwg85hQPHAmupIZkrP%2FbzB80ItKNP%2FF37E4x7FatfKjo6Hx%2Blh6yxHbiVm%2BvTSvuL%2BRLunzyQhKrpBG8Qfx2K0vR52s0eIcahq37a1liZqh3oYSnC07NnlHFejfubqJTF65nXAiLz0%2B7IRQ6cPHAueqi4g6ath5yiztED2FGfOW2i73RW7lux%2FC8MDffiA0UrP30CrlqM6OVwjcoEbSqfaJxx7%2B0fnOFYZ3afMjjX5iJaH0ndAPKs0qCHPV%2FLlYU%2FKzWzLxt2GNA%3D%3D (Caused by NewConnectionError('<urllib3.connection.HTTPSConnection object at 0x7f9aec5fef90>: Failed to establish a new connection: [Errno 111] Connection refused'))
2024-05-21 10:33:47,544 ERROR   wandb-upload_0:1290853 [internal_api.py:upload_file():2769] upload_file request headers: {'User-Agent': 'python-requests/2.31.0', 'Accept-Encoding': 'gzip, deflate, br', 'Accept': '*/*', 'Connection': 'keep-alive', 'Content-Length': '3405'}
2024-05-21 10:33:47,544 ERROR   wandb-upload_0:1290853 [internal_api.py:upload_file():2771] upload_file response body: 
2024-05-21 10:34:45,256 ERROR   wandb-upload_5:1290853 [internal_api.py:upload_file():2767] upload_file exception https://storage.googleapis.com/wandb-production.appspot.com/1923354735/MonoGS/y7r8ow8y/config.yaml?Expires=1716344726&GoogleAccessId=gorilla-files-url-signer-man%40wandb-production.iam.gserviceaccount.com&Signature=I%2FNqKudC9MlfdRYAyMWFQvABnAS6abRNmQnfNVifsclZ4ceBglJy%2FoSd3mNSPDS9NKXypr69UhttUBb6HT4dYnStLUhTaBeqvaVAIboqb0qJixJW1nYbshU6oZOHN%2F2QXnXcTDMAcIqYyvjbX8%2FgNgcm62O%2FZfSG0rwQMsg36I%2BybxXDywQsR6Hj%2BHEviQaJ2BiWLrrG13wLXJRzU9Fy6cW8OxwP3EO3FtI7%2FkTijIvBF0hMcNI8v07X9K4HytchvYdA5f6h8ydDmckf6lnmf8SJ4ou%2FY30cBWODkVpKSmeEE7IW58O0%2BZ7gTvYz5pY3sDXUPAhXajZ5flsUieNmzg%3D%3D: HTTPSConnectionPool(host='storage.googleapis.com', port=443): Max retries exceeded with url: /wandb-production.appspot.com/1923354735/MonoGS/y7r8ow8y/config.yaml?Expires=1716344726&GoogleAccessId=gorilla-files-url-signer-man%40wandb-production.iam.gserviceaccount.com&Signature=I%2FNqKudC9MlfdRYAyMWFQvABnAS6abRNmQnfNVifsclZ4ceBglJy%2FoSd3mNSPDS9NKXypr69UhttUBb6HT4dYnStLUhTaBeqvaVAIboqb0qJixJW1nYbshU6oZOHN%2F2QXnXcTDMAcIqYyvjbX8%2FgNgcm62O%2FZfSG0rwQMsg36I%2BybxXDywQsR6Hj%2BHEviQaJ2BiWLrrG13wLXJRzU9Fy6cW8OxwP3EO3FtI7%2FkTijIvBF0hMcNI8v07X9K4HytchvYdA5f6h8ydDmckf6lnmf8SJ4ou%2FY30cBWODkVpKSmeEE7IW58O0%2BZ7gTvYz5pY3sDXUPAhXajZ5flsUieNmzg%3D%3D (Caused by NewConnectionError('<urllib3.connection.HTTPSConnection object at 0x7f9aec5f12d0>: Failed to establish a new connection: [Errno 111] Connection refused'))
2024-05-21 10:34:45,256 ERROR   wandb-upload_5:1290853 [internal_api.py:upload_file():2769] upload_file request headers: {'User-Agent': 'python-requests/2.31.0', 'Accept-Encoding': 'gzip, deflate, br', 'Accept': '*/*', 'Connection': 'keep-alive', 'Content-Length': '2747'}
2024-05-21 10:34:45,256 ERROR   wandb-upload_5:1290853 [internal_api.py:upload_file():2771] upload_file response body: 
2024-05-21 10:34:57,544 ERROR   wandb-upload_2:1290853 [internal_api.py:upload_file():2767] upload_file exception https://storage.googleapis.com/wandb-production.appspot.com/1923354735/MonoGS/y7r8ow8y/output.log?Expires=1716344726&GoogleAccessId=gorilla-files-url-signer-man%40wandb-production.iam.gserviceaccount.com&Signature=O7idKX8qxjOgQnoSk8t%2FEvZHFPDgj7JSXqoV7CpZlwFMS%2FvROKjPi8M3JagUT5wZ1inNHngyIU5scHIDo19KW%2Fxw0W%2FmJC%2FJfj2MZhGjDbxxnxx5aB4d%2BOoV7mxhAN9thVFs2jqWTNgNstrhhKFS%2BToiiRDtek%2BRxKJFLzjqTrqrZCJQO9usjTSGzzTHQLH%2F6Q0isKnkjj8HtIMoQpooN8s0cee02waCJy764hYUXOfj%2BXOvrLctCmMTiC04rFdK8juLoR0kM4uwRRmGkqjy2zRldzt%2F96rYeKQpv5GPvR1gVqtLd8Ie5gDieYQFYEwUdJw5wyXZMgJwm9kcUqF53w%3D%3D: HTTPSConnectionPool(host='storage.googleapis.com', port=443): Max retries exceeded with url: /wandb-production.appspot.com/1923354735/MonoGS/y7r8ow8y/output.log?Expires=1716344726&GoogleAccessId=gorilla-files-url-signer-man%40wandb-production.iam.gserviceaccount.com&Signature=O7idKX8qxjOgQnoSk8t%2FEvZHFPDgj7JSXqoV7CpZlwFMS%2FvROKjPi8M3JagUT5wZ1inNHngyIU5scHIDo19KW%2Fxw0W%2FmJC%2FJfj2MZhGjDbxxnxx5aB4d%2BOoV7mxhAN9thVFs2jqWTNgNstrhhKFS%2BToiiRDtek%2BRxKJFLzjqTrqrZCJQO9usjTSGzzTHQLH%2F6Q0isKnkjj8HtIMoQpooN8s0cee02waCJy764hYUXOfj%2BXOvrLctCmMTiC04rFdK8juLoR0kM4uwRRmGkqjy2zRldzt%2F96rYeKQpv5GPvR1gVqtLd8Ie5gDieYQFYEwUdJw5wyXZMgJwm9kcUqF53w%3D%3D (Caused by NewConnectionError('<urllib3.connection.HTTPSConnection object at 0x7f9aec609c10>: Failed to establish a new connection: [Errno 111] Connection refused'))
2024-05-21 10:34:57,544 ERROR   wandb-upload_2:1290853 [internal_api.py:upload_file():2769] upload_file request headers: {'User-Agent': 'python-requests/2.31.0', 'Accept-Encoding': 'gzip, deflate, br', 'Accept': '*/*', 'Connection': 'keep-alive', 'Content-Length': '1214'}
2024-05-21 10:34:57,544 ERROR   wandb-upload_2:1290853 [internal_api.py:upload_file():2771] upload_file response body: 
2024-05-21 10:34:59,411 ERROR   wandb-upload_1:1290853 [internal_api.py:upload_file():2767] upload_file exception https://storage.googleapis.com/wandb-production.appspot.com/1923354735/MonoGS/y7r8ow8y/wandb-summary.json?Expires=1716344726&GoogleAccessId=gorilla-files-url-signer-man%40wandb-production.iam.gserviceaccount.com&Signature=n3TmQTke7rSKTOCmV4yBzpiHwvu8vQPE5LqY5EPfq8lc0JXiqgCFiFHzkxawDiSoIUcT3kdxgc2aPTLq1LD2WEkY6%2FuVV8En4N40fMx5DpkYekTPQfNs60A7VrzXiwdiTse%2FK8x%2FzrxcTRGKL5PlVDbPIkJTXr7S4GamUrQu66SpK3x%2F2MXkJ8k3cxcj6u9OgJgPH558FhRJENn1qVzm7AEwxNviV2ROMH174SOmY07BcoW8rCBvf8RWcNxUJrLulhAQk3VasB2MusrZH8Jf%2FHi2MAv4YWRHVoTGBX%2Bzrqj9sOhlhVHl8aINJwVSm9S0qzb2KI9%2FvZPZ3%2BqOahzSRg%3D%3D: HTTPSConnectionPool(host='storage.googleapis.com', port=443): Max retries exceeded with url: /wandb-production.appspot.com/1923354735/MonoGS/y7r8ow8y/wandb-summary.json?Expires=1716344726&GoogleAccessId=gorilla-files-url-signer-man%40wandb-production.iam.gserviceaccount.com&Signature=n3TmQTke7rSKTOCmV4yBzpiHwvu8vQPE5LqY5EPfq8lc0JXiqgCFiFHzkxawDiSoIUcT3kdxgc2aPTLq1LD2WEkY6%2FuVV8En4N40fMx5DpkYekTPQfNs60A7VrzXiwdiTse%2FK8x%2FzrxcTRGKL5PlVDbPIkJTXr7S4GamUrQu66SpK3x%2F2MXkJ8k3cxcj6u9OgJgPH558FhRJENn1qVzm7AEwxNviV2ROMH174SOmY07BcoW8rCBvf8RWcNxUJrLulhAQk3VasB2MusrZH8Jf%2FHi2MAv4YWRHVoTGBX%2Bzrqj9sOhlhVHl8aINJwVSm9S0qzb2KI9%2FvZPZ3%2BqOahzSRg%3D%3D (Caused by NewConnectionError('<urllib3.connection.HTTPSConnection object at 0x7f9aec5f1550>: Failed to establish a new connection: [Errno 111] Connection refused'))
2024-05-21 10:34:59,411 ERROR   wandb-upload_1:1290853 [internal_api.py:upload_file():2769] upload_file request headers: {'User-Agent': 'python-requests/2.31.0', 'Accept-Encoding': 'gzip, deflate, br', 'Accept': '*/*', 'Connection': 'keep-alive', 'Content-Length': '27'}
2024-05-21 10:34:59,411 ERROR   wandb-upload_1:1290853 [internal_api.py:upload_file():2771] upload_file response body: 
2024-05-21 10:35:17,432 ERROR   wandb-upload_3:1290853 [internal_api.py:upload_file():2767] upload_file exception https://storage.googleapis.com/wandb-production.appspot.com/1923354735/MonoGS/y7r8ow8y/requirements.txt?Expires=1716344726&GoogleAccessId=gorilla-files-url-signer-man%40wandb-production.iam.gserviceaccount.com&Signature=L3wnj%2Fyq7ui%2BxLSSHbd3ZNhcWA4kK0ZtJyRG36fvMf2Y64WNPxFbuXgPhvC3rdidwqU2%2FOe%2FZTIIdUTKPbXzP9cEZ7sVF4Uwp3hSUNfDuTOFQaig%2F7JOiFRBJGv2X1R2iASbTo4JBQgGB9GC2veBdTUOc8aYkoZ5obUK%2FM%2BpCNVMPAzKdiJXEOZwIQ14bgSeH5mgaAwjpsla%2BJXsuIFxnyOcT%2FEZXY8VhWlqGJToRux8cvvjrvzrpp1jvjPgGnLacIrUtX0qi5kxdwvU79IAmi4m2uwJuuJryVhLfb1msk0BS4LjGHkfWl9hd4p6pZiXdVx7Q7s0g8yyBNyPv%2BnGhw%3D%3D: ('Connection aborted.', ConnectionResetError(104, 'Connection reset by peer'))
2024-05-21 10:35:17,432 ERROR   wandb-upload_3:1290853 [internal_api.py:upload_file():2769] upload_file request headers: {'User-Agent': 'python-requests/2.31.0', 'Accept-Encoding': 'gzip, deflate, br', 'Accept': '*/*', 'Connection': 'keep-alive', 'Content-Length': '2267'}
2024-05-21 10:35:17,432 ERROR   wandb-upload_3:1290853 [internal_api.py:upload_file():2771] upload_file response body: 
2024-05-21 10:35:19,475 ERROR   wandb-upload_4:1290853 [internal_api.py:upload_file():2767] upload_file exception https://storage.googleapis.com/wandb-production.appspot.com/1923354735/MonoGS/y7r8ow8y/conda-environment.yaml?Expires=1716344726&GoogleAccessId=gorilla-files-url-signer-man%40wandb-production.iam.gserviceaccount.com&Signature=BERXsAthvA4uNy8KsTYhi4DK4yIggzBZzxjksCpYdoksYlIRNvLT6PY86cQfX4%2F%2BjJSxwiltJwadlf7g%2FjxRbz0mfhoLBBROL50A3sp35%2FjQLnhmncVF3iVe7ThBmHwLjMPjt5XtQu2jC34B8fea3GjY7wKFq3uaKTrwmPgWtcEOZCQMLMY0ChxkR%2BHE%2FSRiWt7xGeRrrVQ%2BErKoDuQRznC3TvhkhS1U4lAVl6wRnLTI7GfzP%2FPZmxvohZpdRMn5apJEuRQkvST8ta2NN1yZWfvi903GAtgKWuYwg06ZHKj%2BCN24I%2B035VMqzFQRTyKx2EL50XK4hJucrjFTtzt8uQ%3D%3D: HTTPSConnectionPool(host='storage.googleapis.com', port=443): Max retries exceeded with url: /wandb-production.appspot.com/1923354735/MonoGS/y7r8ow8y/conda-environment.yaml?Expires=1716344726&GoogleAccessId=gorilla-files-url-signer-man%40wandb-production.iam.gserviceaccount.com&Signature=BERXsAthvA4uNy8KsTYhi4DK4yIggzBZzxjksCpYdoksYlIRNvLT6PY86cQfX4%2F%2BjJSxwiltJwadlf7g%2FjxRbz0mfhoLBBROL50A3sp35%2FjQLnhmncVF3iVe7ThBmHwLjMPjt5XtQu2jC34B8fea3GjY7wKFq3uaKTrwmPgWtcEOZCQMLMY0ChxkR%2BHE%2FSRiWt7xGeRrrVQ%2BErKoDuQRznC3TvhkhS1U4lAVl6wRnLTI7GfzP%2FPZmxvohZpdRMn5apJEuRQkvST8ta2NN1yZWfvi903GAtgKWuYwg06ZHKj%2BCN24I%2B035VMqzFQRTyKx2EL50XK4hJucrjFTtzt8uQ%3D%3D (Caused by NewConnectionError('<urllib3.connection.HTTPSConnection object at 0x7f9aec5e6c90>: Failed to establish a new connection: [Errno 111] Connection refused'))
2024-05-21 10:35:19,476 ERROR   wandb-upload_4:1290853 [internal_api.py:upload_file():2769] upload_file request headers: {'User-Agent': 'python-requests/2.31.0', 'Accept-Encoding': 'gzip, deflate, br', 'Accept': '*/*', 'Connection': 'keep-alive', 'Content-Length': '4690'}
2024-05-21 10:35:19,476 ERROR   wandb-upload_4:1290853 [internal_api.py:upload_file():2771] upload_file response body: 
2024-05-21 10:39:32,462 ERROR   wandb-upload_0:1290853 [internal_api.py:upload_file():2767] upload_file exception https://storage.googleapis.com/wandb-production.appspot.com/1923354735/MonoGS/y7r8ow8y/wandb-metadata.json?Expires=1716344689&GoogleAccessId=gorilla-files-url-signer-man%40wandb-production.iam.gserviceaccount.com&Signature=XocjRmoIFbGhOWBuXHuQ1YhKHLYkoSCeErITJdS8ptWPCsz3MOZyInwqvfgV1AZwEKws5oPw3%2FDwg85hQPHAmupIZkrP%2FbzB80ItKNP%2FF37E4x7FatfKjo6Hx%2Blh6yxHbiVm%2BvTSvuL%2BRLunzyQhKrpBG8Qfx2K0vR52s0eIcahq37a1liZqh3oYSnC07NnlHFejfubqJTF65nXAiLz0%2B7IRQ6cPHAueqi4g6ath5yiztED2FGfOW2i73RW7lux%2FC8MDffiA0UrP30CrlqM6OVwjcoEbSqfaJxx7%2B0fnOFYZ3afMjjX5iJaH0ndAPKs0qCHPV%2FLlYU%2FKzWzLxt2GNA%3D%3D: HTTPSConnectionPool(host='storage.googleapis.com', port=443): Max retries exceeded with url: /wandb-production.appspot.com/1923354735/MonoGS/y7r8ow8y/wandb-metadata.json?Expires=1716344689&GoogleAccessId=gorilla-files-url-signer-man%40wandb-production.iam.gserviceaccount.com&Signature=XocjRmoIFbGhOWBuXHuQ1YhKHLYkoSCeErITJdS8ptWPCsz3MOZyInwqvfgV1AZwEKws5oPw3%2FDwg85hQPHAmupIZkrP%2FbzB80ItKNP%2FF37E4x7FatfKjo6Hx%2Blh6yxHbiVm%2BvTSvuL%2BRLunzyQhKrpBG8Qfx2K0vR52s0eIcahq37a1liZqh3oYSnC07NnlHFejfubqJTF65nXAiLz0%2B7IRQ6cPHAueqi4g6ath5yiztED2FGfOW2i73RW7lux%2FC8MDffiA0UrP30CrlqM6OVwjcoEbSqfaJxx7%2B0fnOFYZ3afMjjX5iJaH0ndAPKs0qCHPV%2FLlYU%2FKzWzLxt2GNA%3D%3D (Caused by NewConnectionError('<urllib3.connection.HTTPSConnection object at 0x7f9aec607450>: Failed to establish a new connection: [Errno 111] Connection refused'))
2024-05-21 10:39:32,462 ERROR   wandb-upload_0:1290853 [internal_api.py:upload_file():2769] upload_file request headers: {'User-Agent': 'python-requests/2.31.0', 'Accept-Encoding': 'gzip, deflate, br', 'Accept': '*/*', 'Connection': 'keep-alive', 'Content-Length': '3405'}
2024-05-21 10:39:32,462 ERROR   wandb-upload_0:1290853 [internal_api.py:upload_file():2771] upload_file response body: 
2024-05-21 10:40:27,357 ERROR   wandb-upload_5:1290853 [internal_api.py:upload_file():2767] upload_file exception https://storage.googleapis.com/wandb-production.appspot.com/1923354735/MonoGS/y7r8ow8y/config.yaml?Expires=1716344726&GoogleAccessId=gorilla-files-url-signer-man%40wandb-production.iam.gserviceaccount.com&Signature=I%2FNqKudC9MlfdRYAyMWFQvABnAS6abRNmQnfNVifsclZ4ceBglJy%2FoSd3mNSPDS9NKXypr69UhttUBb6HT4dYnStLUhTaBeqvaVAIboqb0qJixJW1nYbshU6oZOHN%2F2QXnXcTDMAcIqYyvjbX8%2FgNgcm62O%2FZfSG0rwQMsg36I%2BybxXDywQsR6Hj%2BHEviQaJ2BiWLrrG13wLXJRzU9Fy6cW8OxwP3EO3FtI7%2FkTijIvBF0hMcNI8v07X9K4HytchvYdA5f6h8ydDmckf6lnmf8SJ4ou%2FY30cBWODkVpKSmeEE7IW58O0%2BZ7gTvYz5pY3sDXUPAhXajZ5flsUieNmzg%3D%3D: ('Connection aborted.', ConnectionResetError(104, 'Connection reset by peer'))
2024-05-21 10:40:27,357 ERROR   wandb-upload_5:1290853 [internal_api.py:upload_file():2769] upload_file request headers: {'User-Agent': 'python-requests/2.31.0', 'Accept-Encoding': 'gzip, deflate, br', 'Accept': '*/*', 'Connection': 'keep-alive', 'Content-Length': '2747'}
2024-05-21 10:40:27,357 ERROR   wandb-upload_5:1290853 [internal_api.py:upload_file():2771] upload_file response body: 
2024-05-21 10:40:36,395 ERROR   wandb-upload_1:1290853 [internal_api.py:upload_file():2767] upload_file exception https://storage.googleapis.com/wandb-production.appspot.com/1923354735/MonoGS/y7r8ow8y/wandb-summary.json?Expires=1716344726&GoogleAccessId=gorilla-files-url-signer-man%40wandb-production.iam.gserviceaccount.com&Signature=n3TmQTke7rSKTOCmV4yBzpiHwvu8vQPE5LqY5EPfq8lc0JXiqgCFiFHzkxawDiSoIUcT3kdxgc2aPTLq1LD2WEkY6%2FuVV8En4N40fMx5DpkYekTPQfNs60A7VrzXiwdiTse%2FK8x%2FzrxcTRGKL5PlVDbPIkJTXr7S4GamUrQu66SpK3x%2F2MXkJ8k3cxcj6u9OgJgPH558FhRJENn1qVzm7AEwxNviV2ROMH174SOmY07BcoW8rCBvf8RWcNxUJrLulhAQk3VasB2MusrZH8Jf%2FHi2MAv4YWRHVoTGBX%2Bzrqj9sOhlhVHl8aINJwVSm9S0qzb2KI9%2FvZPZ3%2BqOahzSRg%3D%3D: HTTPSConnectionPool(host='storage.googleapis.com', port=443): Max retries exceeded with url: /wandb-production.appspot.com/1923354735/MonoGS/y7r8ow8y/wandb-summary.json?Expires=1716344726&GoogleAccessId=gorilla-files-url-signer-man%40wandb-production.iam.gserviceaccount.com&Signature=n3TmQTke7rSKTOCmV4yBzpiHwvu8vQPE5LqY5EPfq8lc0JXiqgCFiFHzkxawDiSoIUcT3kdxgc2aPTLq1LD2WEkY6%2FuVV8En4N40fMx5DpkYekTPQfNs60A7VrzXiwdiTse%2FK8x%2FzrxcTRGKL5PlVDbPIkJTXr7S4GamUrQu66SpK3x%2F2MXkJ8k3cxcj6u9OgJgPH558FhRJENn1qVzm7AEwxNviV2ROMH174SOmY07BcoW8rCBvf8RWcNxUJrLulhAQk3VasB2MusrZH8Jf%2FHi2MAv4YWRHVoTGBX%2Bzrqj9sOhlhVHl8aINJwVSm9S0qzb2KI9%2FvZPZ3%2BqOahzSRg%3D%3D (Caused by NewConnectionError('<urllib3.connection.HTTPSConnection object at 0x7f9aec5feed0>: Failed to establish a new connection: [Errno 111] Connection refused'))
2024-05-21 10:40:36,395 ERROR   wandb-upload_1:1290853 [internal_api.py:upload_file():2769] upload_file request headers: {'User-Agent': 'python-requests/2.31.0', 'Accept-Encoding': 'gzip, deflate, br', 'Accept': '*/*', 'Connection': 'keep-alive', 'Content-Length': '27'}
2024-05-21 10:40:36,395 ERROR   wandb-upload_1:1290853 [internal_api.py:upload_file():2771] upload_file response body: 
2024-05-21 10:40:41,444 ERROR   wandb-upload_2:1290853 [internal_api.py:upload_file():2767] upload_file exception https://storage.googleapis.com/wandb-production.appspot.com/1923354735/MonoGS/y7r8ow8y/output.log?Expires=1716344726&GoogleAccessId=gorilla-files-url-signer-man%40wandb-production.iam.gserviceaccount.com&Signature=O7idKX8qxjOgQnoSk8t%2FEvZHFPDgj7JSXqoV7CpZlwFMS%2FvROKjPi8M3JagUT5wZ1inNHngyIU5scHIDo19KW%2Fxw0W%2FmJC%2FJfj2MZhGjDbxxnxx5aB4d%2BOoV7mxhAN9thVFs2jqWTNgNstrhhKFS%2BToiiRDtek%2BRxKJFLzjqTrqrZCJQO9usjTSGzzTHQLH%2F6Q0isKnkjj8HtIMoQpooN8s0cee02waCJy764hYUXOfj%2BXOvrLctCmMTiC04rFdK8juLoR0kM4uwRRmGkqjy2zRldzt%2F96rYeKQpv5GPvR1gVqtLd8Ie5gDieYQFYEwUdJw5wyXZMgJwm9kcUqF53w%3D%3D: HTTPSConnectionPool(host='storage.googleapis.com', port=443): Max retries exceeded with url: /wandb-production.appspot.com/1923354735/MonoGS/y7r8ow8y/output.log?Expires=1716344726&GoogleAccessId=gorilla-files-url-signer-man%40wandb-production.iam.gserviceaccount.com&Signature=O7idKX8qxjOgQnoSk8t%2FEvZHFPDgj7JSXqoV7CpZlwFMS%2FvROKjPi8M3JagUT5wZ1inNHngyIU5scHIDo19KW%2Fxw0W%2FmJC%2FJfj2MZhGjDbxxnxx5aB4d%2BOoV7mxhAN9thVFs2jqWTNgNstrhhKFS%2BToiiRDtek%2BRxKJFLzjqTrqrZCJQO9usjTSGzzTHQLH%2F6Q0isKnkjj8HtIMoQpooN8s0cee02waCJy764hYUXOfj%2BXOvrLctCmMTiC04rFdK8juLoR0kM4uwRRmGkqjy2zRldzt%2F96rYeKQpv5GPvR1gVqtLd8Ie5gDieYQFYEwUdJw5wyXZMgJwm9kcUqF53w%3D%3D (Caused by NewConnectionError('<urllib3.connection.HTTPSConnection object at 0x7f9aec5e97d0>: Failed to establish a new connection: [Errno 111] Connection refused'))
2024-05-21 10:40:41,444 ERROR   wandb-upload_2:1290853 [internal_api.py:upload_file():2769] upload_file request headers: {'User-Agent': 'python-requests/2.31.0', 'Accept-Encoding': 'gzip, deflate, br', 'Accept': '*/*', 'Connection': 'keep-alive', 'Content-Length': '1214'}
2024-05-21 10:40:41,444 ERROR   wandb-upload_2:1290853 [internal_api.py:upload_file():2771] upload_file response body: 
2024-05-21 10:41:02,240 ERROR   wandb-upload_4:1290853 [internal_api.py:upload_file():2767] upload_file exception https://storage.googleapis.com/wandb-production.appspot.com/1923354735/MonoGS/y7r8ow8y/conda-environment.yaml?Expires=1716344726&GoogleAccessId=gorilla-files-url-signer-man%40wandb-production.iam.gserviceaccount.com&Signature=BERXsAthvA4uNy8KsTYhi4DK4yIggzBZzxjksCpYdoksYlIRNvLT6PY86cQfX4%2F%2BjJSxwiltJwadlf7g%2FjxRbz0mfhoLBBROL50A3sp35%2FjQLnhmncVF3iVe7ThBmHwLjMPjt5XtQu2jC34B8fea3GjY7wKFq3uaKTrwmPgWtcEOZCQMLMY0ChxkR%2BHE%2FSRiWt7xGeRrrVQ%2BErKoDuQRznC3TvhkhS1U4lAVl6wRnLTI7GfzP%2FPZmxvohZpdRMn5apJEuRQkvST8ta2NN1yZWfvi903GAtgKWuYwg06ZHKj%2BCN24I%2B035VMqzFQRTyKx2EL50XK4hJucrjFTtzt8uQ%3D%3D: HTTPSConnectionPool(host='storage.googleapis.com', port=443): Max retries exceeded with url: /wandb-production.appspot.com/1923354735/MonoGS/y7r8ow8y/conda-environment.yaml?Expires=1716344726&GoogleAccessId=gorilla-files-url-signer-man%40wandb-production.iam.gserviceaccount.com&Signature=BERXsAthvA4uNy8KsTYhi4DK4yIggzBZzxjksCpYdoksYlIRNvLT6PY86cQfX4%2F%2BjJSxwiltJwadlf7g%2FjxRbz0mfhoLBBROL50A3sp35%2FjQLnhmncVF3iVe7ThBmHwLjMPjt5XtQu2jC34B8fea3GjY7wKFq3uaKTrwmPgWtcEOZCQMLMY0ChxkR%2BHE%2FSRiWt7xGeRrrVQ%2BErKoDuQRznC3TvhkhS1U4lAVl6wRnLTI7GfzP%2FPZmxvohZpdRMn5apJEuRQkvST8ta2NN1yZWfvi903GAtgKWuYwg06ZHKj%2BCN24I%2B035VMqzFQRTyKx2EL50XK4hJucrjFTtzt8uQ%3D%3D (Caused by NewConnectionError('<urllib3.connection.HTTPSConnection object at 0x7f9aec5fef10>: Failed to establish a new connection: [Errno 111] Connection refused'))
2024-05-21 10:41:02,240 ERROR   wandb-upload_4:1290853 [internal_api.py:upload_file():2769] upload_file request headers: {'User-Agent': 'python-requests/2.31.0', 'Accept-Encoding': 'gzip, deflate, br', 'Accept': '*/*', 'Connection': 'keep-alive', 'Content-Length': '4690'}
2024-05-21 10:41:02,240 ERROR   wandb-upload_4:1290853 [internal_api.py:upload_file():2771] upload_file response body: 
2024-05-21 10:41:02,496 ERROR   wandb-upload_3:1290853 [internal_api.py:upload_file():2767] upload_file exception https://storage.googleapis.com/wandb-production.appspot.com/1923354735/MonoGS/y7r8ow8y/requirements.txt?Expires=1716344726&GoogleAccessId=gorilla-files-url-signer-man%40wandb-production.iam.gserviceaccount.com&Signature=L3wnj%2Fyq7ui%2BxLSSHbd3ZNhcWA4kK0ZtJyRG36fvMf2Y64WNPxFbuXgPhvC3rdidwqU2%2FOe%2FZTIIdUTKPbXzP9cEZ7sVF4Uwp3hSUNfDuTOFQaig%2F7JOiFRBJGv2X1R2iASbTo4JBQgGB9GC2veBdTUOc8aYkoZ5obUK%2FM%2BpCNVMPAzKdiJXEOZwIQ14bgSeH5mgaAwjpsla%2BJXsuIFxnyOcT%2FEZXY8VhWlqGJToRux8cvvjrvzrpp1jvjPgGnLacIrUtX0qi5kxdwvU79IAmi4m2uwJuuJryVhLfb1msk0BS4LjGHkfWl9hd4p6pZiXdVx7Q7s0g8yyBNyPv%2BnGhw%3D%3D: HTTPSConnectionPool(host='storage.googleapis.com', port=443): Max retries exceeded with url: /wandb-production.appspot.com/1923354735/MonoGS/y7r8ow8y/requirements.txt?Expires=1716344726&GoogleAccessId=gorilla-files-url-signer-man%40wandb-production.iam.gserviceaccount.com&Signature=L3wnj%2Fyq7ui%2BxLSSHbd3ZNhcWA4kK0ZtJyRG36fvMf2Y64WNPxFbuXgPhvC3rdidwqU2%2FOe%2FZTIIdUTKPbXzP9cEZ7sVF4Uwp3hSUNfDuTOFQaig%2F7JOiFRBJGv2X1R2iASbTo4JBQgGB9GC2veBdTUOc8aYkoZ5obUK%2FM%2BpCNVMPAzKdiJXEOZwIQ14bgSeH5mgaAwjpsla%2BJXsuIFxnyOcT%2FEZXY8VhWlqGJToRux8cvvjrvzrpp1jvjPgGnLacIrUtX0qi5kxdwvU79IAmi4m2uwJuuJryVhLfb1msk0BS4LjGHkfWl9hd4p6pZiXdVx7Q7s0g8yyBNyPv%2BnGhw%3D%3D (Caused by NewConnectionError('<urllib3.connection.HTTPSConnection object at 0x7f9aec60e1d0>: Failed to establish a new connection: [Errno 111] Connection refused'))
2024-05-21 10:41:02,496 ERROR   wandb-upload_3:1290853 [internal_api.py:upload_file():2769] upload_file request headers: {'User-Agent': 'python-requests/2.31.0', 'Accept-Encoding': 'gzip, deflate, br', 'Accept': '*/*', 'Connection': 'keep-alive', 'Content-Length': '2267'}
2024-05-21 10:41:02,496 ERROR   wandb-upload_3:1290853 [internal_api.py:upload_file():2771] upload_file response body: 
2024-05-21 10:45:17,952 ERROR   wandb-upload_0:1290853 [internal_api.py:upload_file():2767] upload_file exception https://storage.googleapis.com/wandb-production.appspot.com/1923354735/MonoGS/y7r8ow8y/wandb-metadata.json?Expires=1716344689&GoogleAccessId=gorilla-files-url-signer-man%40wandb-production.iam.gserviceaccount.com&Signature=XocjRmoIFbGhOWBuXHuQ1YhKHLYkoSCeErITJdS8ptWPCsz3MOZyInwqvfgV1AZwEKws5oPw3%2FDwg85hQPHAmupIZkrP%2FbzB80ItKNP%2FF37E4x7FatfKjo6Hx%2Blh6yxHbiVm%2BvTSvuL%2BRLunzyQhKrpBG8Qfx2K0vR52s0eIcahq37a1liZqh3oYSnC07NnlHFejfubqJTF65nXAiLz0%2B7IRQ6cPHAueqi4g6ath5yiztED2FGfOW2i73RW7lux%2FC8MDffiA0UrP30CrlqM6OVwjcoEbSqfaJxx7%2B0fnOFYZ3afMjjX5iJaH0ndAPKs0qCHPV%2FLlYU%2FKzWzLxt2GNA%3D%3D: HTTPSConnectionPool(host='storage.googleapis.com', port=443): Max retries exceeded with url: /wandb-production.appspot.com/1923354735/MonoGS/y7r8ow8y/wandb-metadata.json?Expires=1716344689&GoogleAccessId=gorilla-files-url-signer-man%40wandb-production.iam.gserviceaccount.com&Signature=XocjRmoIFbGhOWBuXHuQ1YhKHLYkoSCeErITJdS8ptWPCsz3MOZyInwqvfgV1AZwEKws5oPw3%2FDwg85hQPHAmupIZkrP%2FbzB80ItKNP%2FF37E4x7FatfKjo6Hx%2Blh6yxHbiVm%2BvTSvuL%2BRLunzyQhKrpBG8Qfx2K0vR52s0eIcahq37a1liZqh3oYSnC07NnlHFejfubqJTF65nXAiLz0%2B7IRQ6cPHAueqi4g6ath5yiztED2FGfOW2i73RW7lux%2FC8MDffiA0UrP30CrlqM6OVwjcoEbSqfaJxx7%2B0fnOFYZ3afMjjX5iJaH0ndAPKs0qCHPV%2FLlYU%2FKzWzLxt2GNA%3D%3D (Caused by NewConnectionError('<urllib3.connection.HTTPSConnection object at 0x7f9aec60e850>: Failed to establish a new connection: [Errno 111] Connection refused'))
2024-05-21 10:45:17,954 ERROR   wandb-upload_0:1290853 [internal_api.py:upload_file():2769] upload_file request headers: {'User-Agent': 'python-requests/2.31.0', 'Accept-Encoding': 'gzip, deflate, br', 'Accept': '*/*', 'Connection': 'keep-alive', 'Content-Length': '3405'}
2024-05-21 10:45:17,954 ERROR   wandb-upload_0:1290853 [internal_api.py:upload_file():2771] upload_file response body: 
2024-05-21 10:45:41,211 ERROR   wandb-upload_1:1290853 [internal_api.py:upload_file():2767] upload_file exception https://storage.googleapis.com/wandb-production.appspot.com/1923354735/MonoGS/y7r8ow8y/wandb-summary.json?Expires=1716344726&GoogleAccessId=gorilla-files-url-signer-man%40wandb-production.iam.gserviceaccount.com&Signature=n3TmQTke7rSKTOCmV4yBzpiHwvu8vQPE5LqY5EPfq8lc0JXiqgCFiFHzkxawDiSoIUcT3kdxgc2aPTLq1LD2WEkY6%2FuVV8En4N40fMx5DpkYekTPQfNs60A7VrzXiwdiTse%2FK8x%2FzrxcTRGKL5PlVDbPIkJTXr7S4GamUrQu66SpK3x%2F2MXkJ8k3cxcj6u9OgJgPH558FhRJENn1qVzm7AEwxNviV2ROMH174SOmY07BcoW8rCBvf8RWcNxUJrLulhAQk3VasB2MusrZH8Jf%2FHi2MAv4YWRHVoTGBX%2Bzrqj9sOhlhVHl8aINJwVSm9S0qzb2KI9%2FvZPZ3%2BqOahzSRg%3D%3D: HTTPSConnectionPool(host='storage.googleapis.com', port=443): Max retries exceeded with url: /wandb-production.appspot.com/1923354735/MonoGS/y7r8ow8y/wandb-summary.json?Expires=1716344726&GoogleAccessId=gorilla-files-url-signer-man%40wandb-production.iam.gserviceaccount.com&Signature=n3TmQTke7rSKTOCmV4yBzpiHwvu8vQPE5LqY5EPfq8lc0JXiqgCFiFHzkxawDiSoIUcT3kdxgc2aPTLq1LD2WEkY6%2FuVV8En4N40fMx5DpkYekTPQfNs60A7VrzXiwdiTse%2FK8x%2FzrxcTRGKL5PlVDbPIkJTXr7S4GamUrQu66SpK3x%2F2MXkJ8k3cxcj6u9OgJgPH558FhRJENn1qVzm7AEwxNviV2ROMH174SOmY07BcoW8rCBvf8RWcNxUJrLulhAQk3VasB2MusrZH8Jf%2FHi2MAv4YWRHVoTGBX%2Bzrqj9sOhlhVHl8aINJwVSm9S0qzb2KI9%2FvZPZ3%2BqOahzSRg%3D%3D (Caused by NewConnectionError('<urllib3.connection.HTTPSConnection object at 0x7f9aec5e9350>: Failed to establish a new connection: [Errno 111] Connection refused'))
2024-05-21 10:45:41,211 ERROR   wandb-upload_1:1290853 [internal_api.py:upload_file():2769] upload_file request headers: {'User-Agent': 'python-requests/2.31.0', 'Accept-Encoding': 'gzip, deflate, br', 'Accept': '*/*', 'Connection': 'keep-alive', 'Content-Length': '27'}
2024-05-21 10:45:41,211 ERROR   wandb-upload_1:1290853 [internal_api.py:upload_file():2771] upload_file response body: 
2024-05-21 10:46:18,145 ERROR   wandb-upload_5:1290853 [internal_api.py:upload_file():2767] upload_file exception https://storage.googleapis.com/wandb-production.appspot.com/1923354735/MonoGS/y7r8ow8y/config.yaml?Expires=1716344726&GoogleAccessId=gorilla-files-url-signer-man%40wandb-production.iam.gserviceaccount.com&Signature=I%2FNqKudC9MlfdRYAyMWFQvABnAS6abRNmQnfNVifsclZ4ceBglJy%2FoSd3mNSPDS9NKXypr69UhttUBb6HT4dYnStLUhTaBeqvaVAIboqb0qJixJW1nYbshU6oZOHN%2F2QXnXcTDMAcIqYyvjbX8%2FgNgcm62O%2FZfSG0rwQMsg36I%2BybxXDywQsR6Hj%2BHEviQaJ2BiWLrrG13wLXJRzU9Fy6cW8OxwP3EO3FtI7%2FkTijIvBF0hMcNI8v07X9K4HytchvYdA5f6h8ydDmckf6lnmf8SJ4ou%2FY30cBWODkVpKSmeEE7IW58O0%2BZ7gTvYz5pY3sDXUPAhXajZ5flsUieNmzg%3D%3D: HTTPSConnectionPool(host='storage.googleapis.com', port=443): Max retries exceeded with url: /wandb-production.appspot.com/1923354735/MonoGS/y7r8ow8y/config.yaml?Expires=1716344726&GoogleAccessId=gorilla-files-url-signer-man%40wandb-production.iam.gserviceaccount.com&Signature=I%2FNqKudC9MlfdRYAyMWFQvABnAS6abRNmQnfNVifsclZ4ceBglJy%2FoSd3mNSPDS9NKXypr69UhttUBb6HT4dYnStLUhTaBeqvaVAIboqb0qJixJW1nYbshU6oZOHN%2F2QXnXcTDMAcIqYyvjbX8%2FgNgcm62O%2FZfSG0rwQMsg36I%2BybxXDywQsR6Hj%2BHEviQaJ2BiWLrrG13wLXJRzU9Fy6cW8OxwP3EO3FtI7%2FkTijIvBF0hMcNI8v07X9K4HytchvYdA5f6h8ydDmckf6lnmf8SJ4ou%2FY30cBWODkVpKSmeEE7IW58O0%2BZ7gTvYz5pY3sDXUPAhXajZ5flsUieNmzg%3D%3D (Caused by NewConnectionError('<urllib3.connection.HTTPSConnection object at 0x7f9aec5fea90>: Failed to establish a new connection: [Errno 111] Connection refused'))
2024-05-21 10:46:18,145 ERROR   wandb-upload_5:1290853 [internal_api.py:upload_file():2769] upload_file request headers: {'User-Agent': 'python-requests/2.31.0', 'Accept-Encoding': 'gzip, deflate, br', 'Accept': '*/*', 'Connection': 'keep-alive', 'Content-Length': '2747'}
2024-05-21 10:46:18,145 ERROR   wandb-upload_5:1290853 [internal_api.py:upload_file():2771] upload_file response body: 
2024-05-21 10:46:20,039 ERROR   wandb-upload_2:1290853 [internal_api.py:upload_file():2767] upload_file exception https://storage.googleapis.com/wandb-production.appspot.com/1923354735/MonoGS/y7r8ow8y/output.log?Expires=1716344726&GoogleAccessId=gorilla-files-url-signer-man%40wandb-production.iam.gserviceaccount.com&Signature=O7idKX8qxjOgQnoSk8t%2FEvZHFPDgj7JSXqoV7CpZlwFMS%2FvROKjPi8M3JagUT5wZ1inNHngyIU5scHIDo19KW%2Fxw0W%2FmJC%2FJfj2MZhGjDbxxnxx5aB4d%2BOoV7mxhAN9thVFs2jqWTNgNstrhhKFS%2BToiiRDtek%2BRxKJFLzjqTrqrZCJQO9usjTSGzzTHQLH%2F6Q0isKnkjj8HtIMoQpooN8s0cee02waCJy764hYUXOfj%2BXOvrLctCmMTiC04rFdK8juLoR0kM4uwRRmGkqjy2zRldzt%2F96rYeKQpv5GPvR1gVqtLd8Ie5gDieYQFYEwUdJw5wyXZMgJwm9kcUqF53w%3D%3D: HTTPSConnectionPool(host='storage.googleapis.com', port=443): Max retries exceeded with url: /wandb-production.appspot.com/1923354735/MonoGS/y7r8ow8y/output.log?Expires=1716344726&GoogleAccessId=gorilla-files-url-signer-man%40wandb-production.iam.gserviceaccount.com&Signature=O7idKX8qxjOgQnoSk8t%2FEvZHFPDgj7JSXqoV7CpZlwFMS%2FvROKjPi8M3JagUT5wZ1inNHngyIU5scHIDo19KW%2Fxw0W%2FmJC%2FJfj2MZhGjDbxxnxx5aB4d%2BOoV7mxhAN9thVFs2jqWTNgNstrhhKFS%2BToiiRDtek%2BRxKJFLzjqTrqrZCJQO9usjTSGzzTHQLH%2F6Q0isKnkjj8HtIMoQpooN8s0cee02waCJy764hYUXOfj%2BXOvrLctCmMTiC04rFdK8juLoR0kM4uwRRmGkqjy2zRldzt%2F96rYeKQpv5GPvR1gVqtLd8Ie5gDieYQFYEwUdJw5wyXZMgJwm9kcUqF53w%3D%3D (Caused by NewConnectionError('<urllib3.connection.HTTPSConnection object at 0x7f9aec601510>: Failed to establish a new connection: [Errno 111] Connection refused'))
2024-05-21 10:46:20,039 ERROR   wandb-upload_2:1290853 [internal_api.py:upload_file():2769] upload_file request headers: {'User-Agent': 'python-requests/2.31.0', 'Accept-Encoding': 'gzip, deflate, br', 'Accept': '*/*', 'Connection': 'keep-alive', 'Content-Length': '1214'}
2024-05-21 10:46:20,039 ERROR   wandb-upload_2:1290853 [internal_api.py:upload_file():2771] upload_file response body: 
2024-05-21 10:46:35,649 ERROR   wandb-upload_4:1290853 [internal_api.py:upload_file():2767] upload_file exception https://storage.googleapis.com/wandb-production.appspot.com/1923354735/MonoGS/y7r8ow8y/conda-environment.yaml?Expires=1716344726&GoogleAccessId=gorilla-files-url-signer-man%40wandb-production.iam.gserviceaccount.com&Signature=BERXsAthvA4uNy8KsTYhi4DK4yIggzBZzxjksCpYdoksYlIRNvLT6PY86cQfX4%2F%2BjJSxwiltJwadlf7g%2FjxRbz0mfhoLBBROL50A3sp35%2FjQLnhmncVF3iVe7ThBmHwLjMPjt5XtQu2jC34B8fea3GjY7wKFq3uaKTrwmPgWtcEOZCQMLMY0ChxkR%2BHE%2FSRiWt7xGeRrrVQ%2BErKoDuQRznC3TvhkhS1U4lAVl6wRnLTI7GfzP%2FPZmxvohZpdRMn5apJEuRQkvST8ta2NN1yZWfvi903GAtgKWuYwg06ZHKj%2BCN24I%2B035VMqzFQRTyKx2EL50XK4hJucrjFTtzt8uQ%3D%3D: HTTPSConnectionPool(host='storage.googleapis.com', port=443): Max retries exceeded with url: /wandb-production.appspot.com/1923354735/MonoGS/y7r8ow8y/conda-environment.yaml?Expires=1716344726&GoogleAccessId=gorilla-files-url-signer-man%40wandb-production.iam.gserviceaccount.com&Signature=BERXsAthvA4uNy8KsTYhi4DK4yIggzBZzxjksCpYdoksYlIRNvLT6PY86cQfX4%2F%2BjJSxwiltJwadlf7g%2FjxRbz0mfhoLBBROL50A3sp35%2FjQLnhmncVF3iVe7ThBmHwLjMPjt5XtQu2jC34B8fea3GjY7wKFq3uaKTrwmPgWtcEOZCQMLMY0ChxkR%2BHE%2FSRiWt7xGeRrrVQ%2BErKoDuQRznC3TvhkhS1U4lAVl6wRnLTI7GfzP%2FPZmxvohZpdRMn5apJEuRQkvST8ta2NN1yZWfvi903GAtgKWuYwg06ZHKj%2BCN24I%2B035VMqzFQRTyKx2EL50XK4hJucrjFTtzt8uQ%3D%3D (Caused by NewConnectionError('<urllib3.connection.HTTPSConnection object at 0x7f9aec5ee3d0>: Failed to establish a new connection: [Errno 111] Connection refused'))
2024-05-21 10:46:35,650 ERROR   wandb-upload_4:1290853 [internal_api.py:upload_file():2769] upload_file request headers: {'User-Agent': 'python-requests/2.31.0', 'Accept-Encoding': 'gzip, deflate, br', 'Accept': '*/*', 'Connection': 'keep-alive', 'Content-Length': '4690'}
2024-05-21 10:46:35,650 ERROR   wandb-upload_4:1290853 [internal_api.py:upload_file():2771] upload_file response body: 
2024-05-21 10:47:04,121 ERROR   wandb-upload_3:1290853 [internal_api.py:upload_file():2767] upload_file exception https://storage.googleapis.com/wandb-production.appspot.com/1923354735/MonoGS/y7r8ow8y/requirements.txt?Expires=1716344726&GoogleAccessId=gorilla-files-url-signer-man%40wandb-production.iam.gserviceaccount.com&Signature=L3wnj%2Fyq7ui%2BxLSSHbd3ZNhcWA4kK0ZtJyRG36fvMf2Y64WNPxFbuXgPhvC3rdidwqU2%2FOe%2FZTIIdUTKPbXzP9cEZ7sVF4Uwp3hSUNfDuTOFQaig%2F7JOiFRBJGv2X1R2iASbTo4JBQgGB9GC2veBdTUOc8aYkoZ5obUK%2FM%2BpCNVMPAzKdiJXEOZwIQ14bgSeH5mgaAwjpsla%2BJXsuIFxnyOcT%2FEZXY8VhWlqGJToRux8cvvjrvzrpp1jvjPgGnLacIrUtX0qi5kxdwvU79IAmi4m2uwJuuJryVhLfb1msk0BS4LjGHkfWl9hd4p6pZiXdVx7Q7s0g8yyBNyPv%2BnGhw%3D%3D: HTTPSConnectionPool(host='storage.googleapis.com', port=443): Max retries exceeded with url: /wandb-production.appspot.com/1923354735/MonoGS/y7r8ow8y/requirements.txt?Expires=1716344726&GoogleAccessId=gorilla-files-url-signer-man%40wandb-production.iam.gserviceaccount.com&Signature=L3wnj%2Fyq7ui%2BxLSSHbd3ZNhcWA4kK0ZtJyRG36fvMf2Y64WNPxFbuXgPhvC3rdidwqU2%2FOe%2FZTIIdUTKPbXzP9cEZ7sVF4Uwp3hSUNfDuTOFQaig%2F7JOiFRBJGv2X1R2iASbTo4JBQgGB9GC2veBdTUOc8aYkoZ5obUK%2FM%2BpCNVMPAzKdiJXEOZwIQ14bgSeH5mgaAwjpsla%2BJXsuIFxnyOcT%2FEZXY8VhWlqGJToRux8cvvjrvzrpp1jvjPgGnLacIrUtX0qi5kxdwvU79IAmi4m2uwJuuJryVhLfb1msk0BS4LjGHkfWl9hd4p6pZiXdVx7Q7s0g8yyBNyPv%2BnGhw%3D%3D (Caused by NewConnectionError('<urllib3.connection.HTTPSConnection object at 0x7f9aec5e6ad0>: Failed to establish a new connection: [Errno 111] Connection refused'))
2024-05-21 10:47:04,121 ERROR   wandb-upload_3:1290853 [internal_api.py:upload_file():2769] upload_file request headers: {'User-Agent': 'python-requests/2.31.0', 'Accept-Encoding': 'gzip, deflate, br', 'Accept': '*/*', 'Connection': 'keep-alive', 'Content-Length': '2267'}
2024-05-21 10:47:04,121 ERROR   wandb-upload_3:1290853 [internal_api.py:upload_file():2771] upload_file response body: 
2024-05-21 10:51:08,493 ERROR   wandb-upload_1:1290853 [internal_api.py:upload_file():2767] upload_file exception https://storage.googleapis.com/wandb-production.appspot.com/1923354735/MonoGS/y7r8ow8y/wandb-summary.json?Expires=1716344726&GoogleAccessId=gorilla-files-url-signer-man%40wandb-production.iam.gserviceaccount.com&Signature=n3TmQTke7rSKTOCmV4yBzpiHwvu8vQPE5LqY5EPfq8lc0JXiqgCFiFHzkxawDiSoIUcT3kdxgc2aPTLq1LD2WEkY6%2FuVV8En4N40fMx5DpkYekTPQfNs60A7VrzXiwdiTse%2FK8x%2FzrxcTRGKL5PlVDbPIkJTXr7S4GamUrQu66SpK3x%2F2MXkJ8k3cxcj6u9OgJgPH558FhRJENn1qVzm7AEwxNviV2ROMH174SOmY07BcoW8rCBvf8RWcNxUJrLulhAQk3VasB2MusrZH8Jf%2FHi2MAv4YWRHVoTGBX%2Bzrqj9sOhlhVHl8aINJwVSm9S0qzb2KI9%2FvZPZ3%2BqOahzSRg%3D%3D: HTTPSConnectionPool(host='storage.googleapis.com', port=443): Max retries exceeded with url: /wandb-production.appspot.com/1923354735/MonoGS/y7r8ow8y/wandb-summary.json?Expires=1716344726&GoogleAccessId=gorilla-files-url-signer-man%40wandb-production.iam.gserviceaccount.com&Signature=n3TmQTke7rSKTOCmV4yBzpiHwvu8vQPE5LqY5EPfq8lc0JXiqgCFiFHzkxawDiSoIUcT3kdxgc2aPTLq1LD2WEkY6%2FuVV8En4N40fMx5DpkYekTPQfNs60A7VrzXiwdiTse%2FK8x%2FzrxcTRGKL5PlVDbPIkJTXr7S4GamUrQu66SpK3x%2F2MXkJ8k3cxcj6u9OgJgPH558FhRJENn1qVzm7AEwxNviV2ROMH174SOmY07BcoW8rCBvf8RWcNxUJrLulhAQk3VasB2MusrZH8Jf%2FHi2MAv4YWRHVoTGBX%2Bzrqj9sOhlhVHl8aINJwVSm9S0qzb2KI9%2FvZPZ3%2BqOahzSRg%3D%3D (Caused by NewConnectionError('<urllib3.connection.HTTPSConnection object at 0x7f9aec6a5850>: Failed to establish a new connection: [Errno 111] Connection refused'))
2024-05-21 10:51:08,493 ERROR   wandb-upload_1:1290853 [internal_api.py:upload_file():2769] upload_file request headers: {'User-Agent': 'python-requests/2.31.0', 'Accept-Encoding': 'gzip, deflate, br', 'Accept': '*/*', 'Connection': 'keep-alive', 'Content-Length': '27'}
2024-05-21 10:51:08,493 ERROR   wandb-upload_1:1290853 [internal_api.py:upload_file():2771] upload_file response body: 
2024-05-21 10:51:28,293 ERROR   wandb-upload_0:1290853 [internal_api.py:upload_file():2767] upload_file exception https://storage.googleapis.com/wandb-production.appspot.com/1923354735/MonoGS/y7r8ow8y/wandb-metadata.json?Expires=1716344689&GoogleAccessId=gorilla-files-url-signer-man%40wandb-production.iam.gserviceaccount.com&Signature=XocjRmoIFbGhOWBuXHuQ1YhKHLYkoSCeErITJdS8ptWPCsz3MOZyInwqvfgV1AZwEKws5oPw3%2FDwg85hQPHAmupIZkrP%2FbzB80ItKNP%2FF37E4x7FatfKjo6Hx%2Blh6yxHbiVm%2BvTSvuL%2BRLunzyQhKrpBG8Qfx2K0vR52s0eIcahq37a1liZqh3oYSnC07NnlHFejfubqJTF65nXAiLz0%2B7IRQ6cPHAueqi4g6ath5yiztED2FGfOW2i73RW7lux%2FC8MDffiA0UrP30CrlqM6OVwjcoEbSqfaJxx7%2B0fnOFYZ3afMjjX5iJaH0ndAPKs0qCHPV%2FLlYU%2FKzWzLxt2GNA%3D%3D: HTTPSConnectionPool(host='storage.googleapis.com', port=443): Max retries exceeded with url: /wandb-production.appspot.com/1923354735/MonoGS/y7r8ow8y/wandb-metadata.json?Expires=1716344689&GoogleAccessId=gorilla-files-url-signer-man%40wandb-production.iam.gserviceaccount.com&Signature=XocjRmoIFbGhOWBuXHuQ1YhKHLYkoSCeErITJdS8ptWPCsz3MOZyInwqvfgV1AZwEKws5oPw3%2FDwg85hQPHAmupIZkrP%2FbzB80ItKNP%2FF37E4x7FatfKjo6Hx%2Blh6yxHbiVm%2BvTSvuL%2BRLunzyQhKrpBG8Qfx2K0vR52s0eIcahq37a1liZqh3oYSnC07NnlHFejfubqJTF65nXAiLz0%2B7IRQ6cPHAueqi4g6ath5yiztED2FGfOW2i73RW7lux%2FC8MDffiA0UrP30CrlqM6OVwjcoEbSqfaJxx7%2B0fnOFYZ3afMjjX5iJaH0ndAPKs0qCHPV%2FLlYU%2FKzWzLxt2GNA%3D%3D (Caused by NewConnectionError('<urllib3.connection.HTTPSConnection object at 0x7f9aec5f1b90>: Failed to establish a new connection: [Errno 111] Connection refused'))
2024-05-21 10:51:28,293 ERROR   wandb-upload_0:1290853 [internal_api.py:upload_file():2769] upload_file request headers: {'User-Agent': 'python-requests/2.31.0', 'Accept-Encoding': 'gzip, deflate, br', 'Accept': '*/*', 'Connection': 'keep-alive', 'Content-Length': '3405'}
2024-05-21 10:51:28,293 ERROR   wandb-upload_0:1290853 [internal_api.py:upload_file():2771] upload_file response body: 
2024-05-21 10:51:41,468 ERROR   wandb-upload_5:1290853 [internal_api.py:upload_file():2767] upload_file exception https://storage.googleapis.com/wandb-production.appspot.com/1923354735/MonoGS/y7r8ow8y/config.yaml?Expires=1716344726&GoogleAccessId=gorilla-files-url-signer-man%40wandb-production.iam.gserviceaccount.com&Signature=I%2FNqKudC9MlfdRYAyMWFQvABnAS6abRNmQnfNVifsclZ4ceBglJy%2FoSd3mNSPDS9NKXypr69UhttUBb6HT4dYnStLUhTaBeqvaVAIboqb0qJixJW1nYbshU6oZOHN%2F2QXnXcTDMAcIqYyvjbX8%2FgNgcm62O%2FZfSG0rwQMsg36I%2BybxXDywQsR6Hj%2BHEviQaJ2BiWLrrG13wLXJRzU9Fy6cW8OxwP3EO3FtI7%2FkTijIvBF0hMcNI8v07X9K4HytchvYdA5f6h8ydDmckf6lnmf8SJ4ou%2FY30cBWODkVpKSmeEE7IW58O0%2BZ7gTvYz5pY3sDXUPAhXajZ5flsUieNmzg%3D%3D: ('Connection aborted.', ConnectionResetError(104, 'Connection reset by peer'))
2024-05-21 10:51:41,468 ERROR   wandb-upload_5:1290853 [internal_api.py:upload_file():2769] upload_file request headers: {'User-Agent': 'python-requests/2.31.0', 'Accept-Encoding': 'gzip, deflate, br', 'Accept': '*/*', 'Connection': 'keep-alive', 'Content-Length': '2747'}
2024-05-21 10:51:41,468 ERROR   wandb-upload_5:1290853 [internal_api.py:upload_file():2771] upload_file response body: 
2024-05-21 10:51:43,270 ERROR   wandb-upload_4:1290853 [internal_api.py:upload_file():2767] upload_file exception https://storage.googleapis.com/wandb-production.appspot.com/1923354735/MonoGS/y7r8ow8y/conda-environment.yaml?Expires=1716344726&GoogleAccessId=gorilla-files-url-signer-man%40wandb-production.iam.gserviceaccount.com&Signature=BERXsAthvA4uNy8KsTYhi4DK4yIggzBZzxjksCpYdoksYlIRNvLT6PY86cQfX4%2F%2BjJSxwiltJwadlf7g%2FjxRbz0mfhoLBBROL50A3sp35%2FjQLnhmncVF3iVe7ThBmHwLjMPjt5XtQu2jC34B8fea3GjY7wKFq3uaKTrwmPgWtcEOZCQMLMY0ChxkR%2BHE%2FSRiWt7xGeRrrVQ%2BErKoDuQRznC3TvhkhS1U4lAVl6wRnLTI7GfzP%2FPZmxvohZpdRMn5apJEuRQkvST8ta2NN1yZWfvi903GAtgKWuYwg06ZHKj%2BCN24I%2B035VMqzFQRTyKx2EL50XK4hJucrjFTtzt8uQ%3D%3D: HTTPSConnectionPool(host='storage.googleapis.com', port=443): Max retries exceeded with url: /wandb-production.appspot.com/1923354735/MonoGS/y7r8ow8y/conda-environment.yaml?Expires=1716344726&GoogleAccessId=gorilla-files-url-signer-man%40wandb-production.iam.gserviceaccount.com&Signature=BERXsAthvA4uNy8KsTYhi4DK4yIggzBZzxjksCpYdoksYlIRNvLT6PY86cQfX4%2F%2BjJSxwiltJwadlf7g%2FjxRbz0mfhoLBBROL50A3sp35%2FjQLnhmncVF3iVe7ThBmHwLjMPjt5XtQu2jC34B8fea3GjY7wKFq3uaKTrwmPgWtcEOZCQMLMY0ChxkR%2BHE%2FSRiWt7xGeRrrVQ%2BErKoDuQRznC3TvhkhS1U4lAVl6wRnLTI7GfzP%2FPZmxvohZpdRMn5apJEuRQkvST8ta2NN1yZWfvi903GAtgKWuYwg06ZHKj%2BCN24I%2B035VMqzFQRTyKx2EL50XK4hJucrjFTtzt8uQ%3D%3D (Caused by NewConnectionError('<urllib3.connection.HTTPSConnection object at 0x7f9aec60ee10>: Failed to establish a new connection: [Errno 111] Connection refused'))
2024-05-21 10:51:43,271 ERROR   wandb-upload_4:1290853 [internal_api.py:upload_file():2769] upload_file request headers: {'User-Agent': 'python-requests/2.31.0', 'Accept-Encoding': 'gzip, deflate, br', 'Accept': '*/*', 'Connection': 'keep-alive', 'Content-Length': '4690'}
2024-05-21 10:51:43,271 ERROR   wandb-upload_4:1290853 [internal_api.py:upload_file():2771] upload_file response body: 
2024-05-21 10:52:26,576 ERROR   wandb-upload_2:1290853 [internal_api.py:upload_file():2767] upload_file exception https://storage.googleapis.com/wandb-production.appspot.com/1923354735/MonoGS/y7r8ow8y/output.log?Expires=1716344726&GoogleAccessId=gorilla-files-url-signer-man%40wandb-production.iam.gserviceaccount.com&Signature=O7idKX8qxjOgQnoSk8t%2FEvZHFPDgj7JSXqoV7CpZlwFMS%2FvROKjPi8M3JagUT5wZ1inNHngyIU5scHIDo19KW%2Fxw0W%2FmJC%2FJfj2MZhGjDbxxnxx5aB4d%2BOoV7mxhAN9thVFs2jqWTNgNstrhhKFS%2BToiiRDtek%2BRxKJFLzjqTrqrZCJQO9usjTSGzzTHQLH%2F6Q0isKnkjj8HtIMoQpooN8s0cee02waCJy764hYUXOfj%2BXOvrLctCmMTiC04rFdK8juLoR0kM4uwRRmGkqjy2zRldzt%2F96rYeKQpv5GPvR1gVqtLd8Ie5gDieYQFYEwUdJw5wyXZMgJwm9kcUqF53w%3D%3D: HTTPSConnectionPool(host='storage.googleapis.com', port=443): Max retries exceeded with url: /wandb-production.appspot.com/1923354735/MonoGS/y7r8ow8y/output.log?Expires=1716344726&GoogleAccessId=gorilla-files-url-signer-man%40wandb-production.iam.gserviceaccount.com&Signature=O7idKX8qxjOgQnoSk8t%2FEvZHFPDgj7JSXqoV7CpZlwFMS%2FvROKjPi8M3JagUT5wZ1inNHngyIU5scHIDo19KW%2Fxw0W%2FmJC%2FJfj2MZhGjDbxxnxx5aB4d%2BOoV7mxhAN9thVFs2jqWTNgNstrhhKFS%2BToiiRDtek%2BRxKJFLzjqTrqrZCJQO9usjTSGzzTHQLH%2F6Q0isKnkjj8HtIMoQpooN8s0cee02waCJy764hYUXOfj%2BXOvrLctCmMTiC04rFdK8juLoR0kM4uwRRmGkqjy2zRldzt%2F96rYeKQpv5GPvR1gVqtLd8Ie5gDieYQFYEwUdJw5wyXZMgJwm9kcUqF53w%3D%3D (Caused by NewConnectionError('<urllib3.connection.HTTPSConnection object at 0x7f9aec60e590>: Failed to establish a new connection: [Errno 111] Connection refused'))
2024-05-21 10:52:26,578 ERROR   wandb-upload_2:1290853 [internal_api.py:upload_file():2769] upload_file request headers: {'User-Agent': 'python-requests/2.31.0', 'Accept-Encoding': 'gzip, deflate, br', 'Accept': '*/*', 'Connection': 'keep-alive', 'Content-Length': '1214'}
2024-05-21 10:52:26,578 ERROR   wandb-upload_2:1290853 [internal_api.py:upload_file():2771] upload_file response body: 
2024-05-21 10:52:51,420 ERROR   wandb-upload_3:1290853 [internal_api.py:upload_file():2767] upload_file exception https://storage.googleapis.com/wandb-production.appspot.com/1923354735/MonoGS/y7r8ow8y/requirements.txt?Expires=1716344726&GoogleAccessId=gorilla-files-url-signer-man%40wandb-production.iam.gserviceaccount.com&Signature=L3wnj%2Fyq7ui%2BxLSSHbd3ZNhcWA4kK0ZtJyRG36fvMf2Y64WNPxFbuXgPhvC3rdidwqU2%2FOe%2FZTIIdUTKPbXzP9cEZ7sVF4Uwp3hSUNfDuTOFQaig%2F7JOiFRBJGv2X1R2iASbTo4JBQgGB9GC2veBdTUOc8aYkoZ5obUK%2FM%2BpCNVMPAzKdiJXEOZwIQ14bgSeH5mgaAwjpsla%2BJXsuIFxnyOcT%2FEZXY8VhWlqGJToRux8cvvjrvzrpp1jvjPgGnLacIrUtX0qi5kxdwvU79IAmi4m2uwJuuJryVhLfb1msk0BS4LjGHkfWl9hd4p6pZiXdVx7Q7s0g8yyBNyPv%2BnGhw%3D%3D: HTTPSConnectionPool(host='storage.googleapis.com', port=443): Max retries exceeded with url: /wandb-production.appspot.com/1923354735/MonoGS/y7r8ow8y/requirements.txt?Expires=1716344726&GoogleAccessId=gorilla-files-url-signer-man%40wandb-production.iam.gserviceaccount.com&Signature=L3wnj%2Fyq7ui%2BxLSSHbd3ZNhcWA4kK0ZtJyRG36fvMf2Y64WNPxFbuXgPhvC3rdidwqU2%2FOe%2FZTIIdUTKPbXzP9cEZ7sVF4Uwp3hSUNfDuTOFQaig%2F7JOiFRBJGv2X1R2iASbTo4JBQgGB9GC2veBdTUOc8aYkoZ5obUK%2FM%2BpCNVMPAzKdiJXEOZwIQ14bgSeH5mgaAwjpsla%2BJXsuIFxnyOcT%2FEZXY8VhWlqGJToRux8cvvjrvzrpp1jvjPgGnLacIrUtX0qi5kxdwvU79IAmi4m2uwJuuJryVhLfb1msk0BS4LjGHkfWl9hd4p6pZiXdVx7Q7s0g8yyBNyPv%2BnGhw%3D%3D (Caused by NewConnectionError('<urllib3.connection.HTTPSConnection object at 0x7f9aec6094d0>: Failed to establish a new connection: [Errno 111] Connection refused'))
2024-05-21 10:52:51,428 ERROR   wandb-upload_3:1290853 [internal_api.py:upload_file():2769] upload_file request headers: {'User-Agent': 'python-requests/2.31.0', 'Accept-Encoding': 'gzip, deflate, br', 'Accept': '*/*', 'Connection': 'keep-alive', 'Content-Length': '2267'}
2024-05-21 10:52:51,428 ERROR   wandb-upload_3:1290853 [internal_api.py:upload_file():2771] upload_file response body: 
2024-05-21 10:56:47,030 ERROR   wandb-upload_1:1290853 [internal_api.py:upload_file():2767] upload_file exception https://storage.googleapis.com/wandb-production.appspot.com/1923354735/MonoGS/y7r8ow8y/wandb-summary.json?Expires=1716344726&GoogleAccessId=gorilla-files-url-signer-man%40wandb-production.iam.gserviceaccount.com&Signature=n3TmQTke7rSKTOCmV4yBzpiHwvu8vQPE5LqY5EPfq8lc0JXiqgCFiFHzkxawDiSoIUcT3kdxgc2aPTLq1LD2WEkY6%2FuVV8En4N40fMx5DpkYekTPQfNs60A7VrzXiwdiTse%2FK8x%2FzrxcTRGKL5PlVDbPIkJTXr7S4GamUrQu66SpK3x%2F2MXkJ8k3cxcj6u9OgJgPH558FhRJENn1qVzm7AEwxNviV2ROMH174SOmY07BcoW8rCBvf8RWcNxUJrLulhAQk3VasB2MusrZH8Jf%2FHi2MAv4YWRHVoTGBX%2Bzrqj9sOhlhVHl8aINJwVSm9S0qzb2KI9%2FvZPZ3%2BqOahzSRg%3D%3D: HTTPSConnectionPool(host='storage.googleapis.com', port=443): Max retries exceeded with url: /wandb-production.appspot.com/1923354735/MonoGS/y7r8ow8y/wandb-summary.json?Expires=1716344726&GoogleAccessId=gorilla-files-url-signer-man%40wandb-production.iam.gserviceaccount.com&Signature=n3TmQTke7rSKTOCmV4yBzpiHwvu8vQPE5LqY5EPfq8lc0JXiqgCFiFHzkxawDiSoIUcT3kdxgc2aPTLq1LD2WEkY6%2FuVV8En4N40fMx5DpkYekTPQfNs60A7VrzXiwdiTse%2FK8x%2FzrxcTRGKL5PlVDbPIkJTXr7S4GamUrQu66SpK3x%2F2MXkJ8k3cxcj6u9OgJgPH558FhRJENn1qVzm7AEwxNviV2ROMH174SOmY07BcoW8rCBvf8RWcNxUJrLulhAQk3VasB2MusrZH8Jf%2FHi2MAv4YWRHVoTGBX%2Bzrqj9sOhlhVHl8aINJwVSm9S0qzb2KI9%2FvZPZ3%2BqOahzSRg%3D%3D (Caused by NewConnectionError('<urllib3.connection.HTTPSConnection object at 0x7f9aec5f1450>: Failed to establish a new connection: [Errno 111] Connection refused'))
2024-05-21 10:56:47,031 ERROR   wandb-upload_1:1290853 [internal_api.py:upload_file():2769] upload_file request headers: {'User-Agent': 'python-requests/2.31.0', 'Accept-Encoding': 'gzip, deflate, br', 'Accept': '*/*', 'Connection': 'keep-alive', 'Content-Length': '27'}
2024-05-21 10:56:47,031 ERROR   wandb-upload_1:1290853 [internal_api.py:upload_file():2771] upload_file response body: 
2024-05-21 10:57:14,477 ERROR   wandb-upload_4:1290853 [internal_api.py:upload_file():2767] upload_file exception https://storage.googleapis.com/wandb-production.appspot.com/1923354735/MonoGS/y7r8ow8y/conda-environment.yaml?Expires=1716344726&GoogleAccessId=gorilla-files-url-signer-man%40wandb-production.iam.gserviceaccount.com&Signature=BERXsAthvA4uNy8KsTYhi4DK4yIggzBZzxjksCpYdoksYlIRNvLT6PY86cQfX4%2F%2BjJSxwiltJwadlf7g%2FjxRbz0mfhoLBBROL50A3sp35%2FjQLnhmncVF3iVe7ThBmHwLjMPjt5XtQu2jC34B8fea3GjY7wKFq3uaKTrwmPgWtcEOZCQMLMY0ChxkR%2BHE%2FSRiWt7xGeRrrVQ%2BErKoDuQRznC3TvhkhS1U4lAVl6wRnLTI7GfzP%2FPZmxvohZpdRMn5apJEuRQkvST8ta2NN1yZWfvi903GAtgKWuYwg06ZHKj%2BCN24I%2B035VMqzFQRTyKx2EL50XK4hJucrjFTtzt8uQ%3D%3D: HTTPSConnectionPool(host='storage.googleapis.com', port=443): Max retries exceeded with url: /wandb-production.appspot.com/1923354735/MonoGS/y7r8ow8y/conda-environment.yaml?Expires=1716344726&GoogleAccessId=gorilla-files-url-signer-man%40wandb-production.iam.gserviceaccount.com&Signature=BERXsAthvA4uNy8KsTYhi4DK4yIggzBZzxjksCpYdoksYlIRNvLT6PY86cQfX4%2F%2BjJSxwiltJwadlf7g%2FjxRbz0mfhoLBBROL50A3sp35%2FjQLnhmncVF3iVe7ThBmHwLjMPjt5XtQu2jC34B8fea3GjY7wKFq3uaKTrwmPgWtcEOZCQMLMY0ChxkR%2BHE%2FSRiWt7xGeRrrVQ%2BErKoDuQRznC3TvhkhS1U4lAVl6wRnLTI7GfzP%2FPZmxvohZpdRMn5apJEuRQkvST8ta2NN1yZWfvi903GAtgKWuYwg06ZHKj%2BCN24I%2B035VMqzFQRTyKx2EL50XK4hJucrjFTtzt8uQ%3D%3D (Caused by NewConnectionError('<urllib3.connection.HTTPSConnection object at 0x7f9aec6a5a90>: Failed to establish a new connection: [Errno 111] Connection refused'))
2024-05-21 10:57:14,478 ERROR   wandb-upload_4:1290853 [internal_api.py:upload_file():2769] upload_file request headers: {'User-Agent': 'python-requests/2.31.0', 'Accept-Encoding': 'gzip, deflate, br', 'Accept': '*/*', 'Connection': 'keep-alive', 'Content-Length': '4690'}
2024-05-21 10:57:14,478 ERROR   wandb-upload_4:1290853 [internal_api.py:upload_file():2771] upload_file response body: 
2024-05-21 10:57:37,103 ERROR   wandb-upload_5:1290853 [internal_api.py:upload_file():2767] upload_file exception https://storage.googleapis.com/wandb-production.appspot.com/1923354735/MonoGS/y7r8ow8y/config.yaml?Expires=1716344726&GoogleAccessId=gorilla-files-url-signer-man%40wandb-production.iam.gserviceaccount.com&Signature=I%2FNqKudC9MlfdRYAyMWFQvABnAS6abRNmQnfNVifsclZ4ceBglJy%2FoSd3mNSPDS9NKXypr69UhttUBb6HT4dYnStLUhTaBeqvaVAIboqb0qJixJW1nYbshU6oZOHN%2F2QXnXcTDMAcIqYyvjbX8%2FgNgcm62O%2FZfSG0rwQMsg36I%2BybxXDywQsR6Hj%2BHEviQaJ2BiWLrrG13wLXJRzU9Fy6cW8OxwP3EO3FtI7%2FkTijIvBF0hMcNI8v07X9K4HytchvYdA5f6h8ydDmckf6lnmf8SJ4ou%2FY30cBWODkVpKSmeEE7IW58O0%2BZ7gTvYz5pY3sDXUPAhXajZ5flsUieNmzg%3D%3D: HTTPSConnectionPool(host='storage.googleapis.com', port=443): Max retries exceeded with url: /wandb-production.appspot.com/1923354735/MonoGS/y7r8ow8y/config.yaml?Expires=1716344726&GoogleAccessId=gorilla-files-url-signer-man%40wandb-production.iam.gserviceaccount.com&Signature=I%2FNqKudC9MlfdRYAyMWFQvABnAS6abRNmQnfNVifsclZ4ceBglJy%2FoSd3mNSPDS9NKXypr69UhttUBb6HT4dYnStLUhTaBeqvaVAIboqb0qJixJW1nYbshU6oZOHN%2F2QXnXcTDMAcIqYyvjbX8%2FgNgcm62O%2FZfSG0rwQMsg36I%2BybxXDywQsR6Hj%2BHEviQaJ2BiWLrrG13wLXJRzU9Fy6cW8OxwP3EO3FtI7%2FkTijIvBF0hMcNI8v07X9K4HytchvYdA5f6h8ydDmckf6lnmf8SJ4ou%2FY30cBWODkVpKSmeEE7IW58O0%2BZ7gTvYz5pY3sDXUPAhXajZ5flsUieNmzg%3D%3D (Caused by NewConnectionError('<urllib3.connection.HTTPSConnection object at 0x7f9aec5e6d50>: Failed to establish a new connection: [Errno 111] Connection refused'))
2024-05-21 10:57:37,104 ERROR   wandb-upload_5:1290853 [internal_api.py:upload_file():2769] upload_file request headers: {'User-Agent': 'python-requests/2.31.0', 'Accept-Encoding': 'gzip, deflate, br', 'Accept': '*/*', 'Connection': 'keep-alive', 'Content-Length': '2747'}
2024-05-21 10:57:37,104 ERROR   wandb-upload_5:1290853 [internal_api.py:upload_file():2771] upload_file response body: 
2024-05-21 10:57:41,176 ERROR   wandb-upload_0:1290853 [internal_api.py:upload_file():2767] upload_file exception https://storage.googleapis.com/wandb-production.appspot.com/1923354735/MonoGS/y7r8ow8y/wandb-metadata.json?Expires=1716344689&GoogleAccessId=gorilla-files-url-signer-man%40wandb-production.iam.gserviceaccount.com&Signature=XocjRmoIFbGhOWBuXHuQ1YhKHLYkoSCeErITJdS8ptWPCsz3MOZyInwqvfgV1AZwEKws5oPw3%2FDwg85hQPHAmupIZkrP%2FbzB80ItKNP%2FF37E4x7FatfKjo6Hx%2Blh6yxHbiVm%2BvTSvuL%2BRLunzyQhKrpBG8Qfx2K0vR52s0eIcahq37a1liZqh3oYSnC07NnlHFejfubqJTF65nXAiLz0%2B7IRQ6cPHAueqi4g6ath5yiztED2FGfOW2i73RW7lux%2FC8MDffiA0UrP30CrlqM6OVwjcoEbSqfaJxx7%2B0fnOFYZ3afMjjX5iJaH0ndAPKs0qCHPV%2FLlYU%2FKzWzLxt2GNA%3D%3D: HTTPSConnectionPool(host='storage.googleapis.com', port=443): Max retries exceeded with url: /wandb-production.appspot.com/1923354735/MonoGS/y7r8ow8y/wandb-metadata.json?Expires=1716344689&GoogleAccessId=gorilla-files-url-signer-man%40wandb-production.iam.gserviceaccount.com&Signature=XocjRmoIFbGhOWBuXHuQ1YhKHLYkoSCeErITJdS8ptWPCsz3MOZyInwqvfgV1AZwEKws5oPw3%2FDwg85hQPHAmupIZkrP%2FbzB80ItKNP%2FF37E4x7FatfKjo6Hx%2Blh6yxHbiVm%2BvTSvuL%2BRLunzyQhKrpBG8Qfx2K0vR52s0eIcahq37a1liZqh3oYSnC07NnlHFejfubqJTF65nXAiLz0%2B7IRQ6cPHAueqi4g6ath5yiztED2FGfOW2i73RW7lux%2FC8MDffiA0UrP30CrlqM6OVwjcoEbSqfaJxx7%2B0fnOFYZ3afMjjX5iJaH0ndAPKs0qCHPV%2FLlYU%2FKzWzLxt2GNA%3D%3D (Caused by NewConnectionError('<urllib3.connection.HTTPSConnection object at 0x7f9aec601b90>: Failed to establish a new connection: [Errno 111] Connection refused'))
2024-05-21 10:57:41,176 ERROR   wandb-upload_0:1290853 [internal_api.py:upload_file():2769] upload_file request headers: {'User-Agent': 'python-requests/2.31.0', 'Accept-Encoding': 'gzip, deflate, br', 'Accept': '*/*', 'Connection': 'keep-alive', 'Content-Length': '3405'}
2024-05-21 10:57:41,176 ERROR   wandb-upload_0:1290853 [internal_api.py:upload_file():2771] upload_file response body: 
2024-05-21 10:57:52,857 ERROR   wandb-upload_3:1290853 [internal_api.py:upload_file():2767] upload_file exception https://storage.googleapis.com/wandb-production.appspot.com/1923354735/MonoGS/y7r8ow8y/requirements.txt?Expires=1716344726&GoogleAccessId=gorilla-files-url-signer-man%40wandb-production.iam.gserviceaccount.com&Signature=L3wnj%2Fyq7ui%2BxLSSHbd3ZNhcWA4kK0ZtJyRG36fvMf2Y64WNPxFbuXgPhvC3rdidwqU2%2FOe%2FZTIIdUTKPbXzP9cEZ7sVF4Uwp3hSUNfDuTOFQaig%2F7JOiFRBJGv2X1R2iASbTo4JBQgGB9GC2veBdTUOc8aYkoZ5obUK%2FM%2BpCNVMPAzKdiJXEOZwIQ14bgSeH5mgaAwjpsla%2BJXsuIFxnyOcT%2FEZXY8VhWlqGJToRux8cvvjrvzrpp1jvjPgGnLacIrUtX0qi5kxdwvU79IAmi4m2uwJuuJryVhLfb1msk0BS4LjGHkfWl9hd4p6pZiXdVx7Q7s0g8yyBNyPv%2BnGhw%3D%3D: HTTPSConnectionPool(host='storage.googleapis.com', port=443): Max retries exceeded with url: /wandb-production.appspot.com/1923354735/MonoGS/y7r8ow8y/requirements.txt?Expires=1716344726&GoogleAccessId=gorilla-files-url-signer-man%40wandb-production.iam.gserviceaccount.com&Signature=L3wnj%2Fyq7ui%2BxLSSHbd3ZNhcWA4kK0ZtJyRG36fvMf2Y64WNPxFbuXgPhvC3rdidwqU2%2FOe%2FZTIIdUTKPbXzP9cEZ7sVF4Uwp3hSUNfDuTOFQaig%2F7JOiFRBJGv2X1R2iASbTo4JBQgGB9GC2veBdTUOc8aYkoZ5obUK%2FM%2BpCNVMPAzKdiJXEOZwIQ14bgSeH5mgaAwjpsla%2BJXsuIFxnyOcT%2FEZXY8VhWlqGJToRux8cvvjrvzrpp1jvjPgGnLacIrUtX0qi5kxdwvU79IAmi4m2uwJuuJryVhLfb1msk0BS4LjGHkfWl9hd4p6pZiXdVx7Q7s0g8yyBNyPv%2BnGhw%3D%3D (Caused by NewConnectionError('<urllib3.connection.HTTPSConnection object at 0x7f9aec5feed0>: Failed to establish a new connection: [Errno 111] Connection refused'))
2024-05-21 10:57:52,858 ERROR   wandb-upload_3:1290853 [internal_api.py:upload_file():2769] upload_file request headers: {'User-Agent': 'python-requests/2.31.0', 'Accept-Encoding': 'gzip, deflate, br', 'Accept': '*/*', 'Connection': 'keep-alive', 'Content-Length': '2267'}
2024-05-21 10:57:52,858 ERROR   wandb-upload_3:1290853 [internal_api.py:upload_file():2771] upload_file response body: 
2024-05-21 10:58:13,319 ERROR   wandb-upload_2:1290853 [internal_api.py:upload_file():2767] upload_file exception https://storage.googleapis.com/wandb-production.appspot.com/1923354735/MonoGS/y7r8ow8y/output.log?Expires=1716344726&GoogleAccessId=gorilla-files-url-signer-man%40wandb-production.iam.gserviceaccount.com&Signature=O7idKX8qxjOgQnoSk8t%2FEvZHFPDgj7JSXqoV7CpZlwFMS%2FvROKjPi8M3JagUT5wZ1inNHngyIU5scHIDo19KW%2Fxw0W%2FmJC%2FJfj2MZhGjDbxxnxx5aB4d%2BOoV7mxhAN9thVFs2jqWTNgNstrhhKFS%2BToiiRDtek%2BRxKJFLzjqTrqrZCJQO9usjTSGzzTHQLH%2F6Q0isKnkjj8HtIMoQpooN8s0cee02waCJy764hYUXOfj%2BXOvrLctCmMTiC04rFdK8juLoR0kM4uwRRmGkqjy2zRldzt%2F96rYeKQpv5GPvR1gVqtLd8Ie5gDieYQFYEwUdJw5wyXZMgJwm9kcUqF53w%3D%3D: HTTPSConnectionPool(host='storage.googleapis.com', port=443): Max retries exceeded with url: /wandb-production.appspot.com/1923354735/MonoGS/y7r8ow8y/output.log?Expires=1716344726&GoogleAccessId=gorilla-files-url-signer-man%40wandb-production.iam.gserviceaccount.com&Signature=O7idKX8qxjOgQnoSk8t%2FEvZHFPDgj7JSXqoV7CpZlwFMS%2FvROKjPi8M3JagUT5wZ1inNHngyIU5scHIDo19KW%2Fxw0W%2FmJC%2FJfj2MZhGjDbxxnxx5aB4d%2BOoV7mxhAN9thVFs2jqWTNgNstrhhKFS%2BToiiRDtek%2BRxKJFLzjqTrqrZCJQO9usjTSGzzTHQLH%2F6Q0isKnkjj8HtIMoQpooN8s0cee02waCJy764hYUXOfj%2BXOvrLctCmMTiC04rFdK8juLoR0kM4uwRRmGkqjy2zRldzt%2F96rYeKQpv5GPvR1gVqtLd8Ie5gDieYQFYEwUdJw5wyXZMgJwm9kcUqF53w%3D%3D (Caused by NewConnectionError('<urllib3.connection.HTTPSConnection object at 0x7f9aec5fe8d0>: Failed to establish a new connection: [Errno 111] Connection refused'))
2024-05-21 10:58:13,319 ERROR   wandb-upload_2:1290853 [internal_api.py:upload_file():2769] upload_file request headers: {'User-Agent': 'python-requests/2.31.0', 'Accept-Encoding': 'gzip, deflate, br', 'Accept': '*/*', 'Connection': 'keep-alive', 'Content-Length': '1214'}
2024-05-21 10:58:13,319 ERROR   wandb-upload_2:1290853 [internal_api.py:upload_file():2771] upload_file response body: 
